Workbook

Sheet 연간
A1: VRAIN 솔루션 Model
A2: 모를 땐 보수적으로 | B2: (단위: 백만엔) | C2: 2월 결산 · 일본 기준 · 2027.2Q = 2027년 2월 결산기 2분기 | Y2: (추정: 파란 글씨 = 직접 입력)
A3: 항목 | B3: 참고 | C3: 2024.3Q | D3: 2024.4Q | E3: 2025.1Q | F3: 2025.2Q | G3: 2025.3Q | H3: 2025.4Q | I3: 2026.1Q | J3: 2026.2Q | K3: 2026.3Q | L3: 2026.4Q | M3: 2027.1Q | N3: 2027.2Q | O3: 2017 | P3: 2018 | Q3: 2019 | R3: 2020 | S3: 2021 | T3: 2022 | U3: 2023 | V3: 2024 | W3: 2025 | X3: 2026 | Y3: 2027(MW) | Z3: 2028(MW) | AA3: 2029(MW) | AB3: 2030(MW) | AC3: 2031(MW)
A4: 매출액 | B4: MW 직접 입력 | D4: 358.214 | E4: 366 | F4: 442 | G4: 392 | H4: 944 | I4: 195 | J4: 852 | K4: 581 | L4: 1650 | M4: 648 | N4: 1236 | U4: 617.397 | V4: 1411.008 | W4: 2144 | X4: 3278 | Y4: =IF(COUNT(Y7)=0,"",SUM(Y7)) | Z4: =IF(COUNT(Z7)=0,"",SUM(Z7)) | AA4: =IF(COUNT(AA7)=0,"",SUM(AA7)) | AB4: =IF(COUNT(AB7)=0,"",SUM(AB7)) | AC4: =IF(COUNT(AC7)=0,"",SUM(AC7))
A5: YoY | G5: =IF(OR(G4="",C4=""),"",IFERROR(G4/C4-1,"")) | H5: =IF(OR(H4="",D4=""),"",IFERROR(H4/D4-1,"")) | I5: =IF(OR(I4="",E4=""),"",IFERROR(I4/E4-1,"")) | J5: =IF(OR(J4="",F4=""),"",IFERROR(J4/F4-1,"")) | K5: =IF(OR(K4="",G4=""),"",IFERROR(K4/G4-1,"")) | L5: =IF(OR(L4="",H4=""),"",IFERROR(L4/H4-1,"")) | M5: =IF(OR(M4="",I4=""),"",IFERROR(M4/I4-1,"")) | N5: =IF(OR(N4="",J4=""),"",IFERROR(N4/J4-1,"")) | P5: =IF(OR(P4="",O4=""),"",IFERROR(P4/O4-1,"")) | Q5: =IF(OR(Q4="",P4=""),"",IFERROR(Q4/P4-1,"")) | R5: =IF(OR(R4="",Q4=""),"",IFERROR(R4/Q4-1,"")) | S5: =IF(OR(S4="",R4=""),"",IFERROR(S4/R4-1,"")) | T5: =IF(OR(T4="",S4=""),"",IFERROR(T4/S4-1,"")) | U5: =IF(OR(U4="",T4=""),"",IFERROR(U4/T4-1,"")) | V5: =IF(OR(V4="",U4=""),"",IFERROR(V4/U4-1,"")) | W5: =IF(OR(W4="",V4=""),"",IFERROR(W4/V4-1,"")) | ... AC5: =IF(OR(AC4="",AB4=""),"",IFERROR(AC4/AB4-1,""))
A6: 제품별 매출 분류 | B6: 사업보고서 매출실적
A7: (제품별 매출 미공시 — 직접 입력)
A8: 비중 | C8: =IF(OR(C7="",C4=""),"",IFERROR(C7/C4,"")) | D8: =IF(OR(D7="",D4=""),"",IFERROR(D7/D4,"")) | E8: =IF(OR(E7="",E4=""),"",IFERROR(E7/E4,"")) | F8: =IF(OR(F7="",F4=""),"",IFERROR(F7/F4,"")) | G8: =IF(OR(G7="",G4=""),"",IFERROR(G7/G4,"")) | H8: =IF(OR(H7="",H4=""),"",IFERROR(H7/H4,"")) | I8: =IF(OR(I7="",I4=""),"",IFERROR(I7/I4,"")) | J8: =IF(OR(J7="",J4=""),"",IFERROR(J7/J4,"")) | ... AC8: =IF(OR(AC7="",AC4=""),"",IFERROR(AC7/AC4,""))
A9: YoY | G9: =IF(OR(G7="",C7=""),"",IFERROR(G7/C7-1,"")) | H9: =IF(OR(H7="",D7=""),"",IFERROR(H7/D7-1,"")) | I9: =IF(OR(I7="",E7=""),"",IFERROR(I7/E7-1,"")) | J9: =IF(OR(J7="",F7=""),"",IFERROR(J7/F7-1,"")) | K9: =IF(OR(K7="",G7=""),"",IFERROR(K7/G7-1,"")) | L9: =IF(OR(L7="",H7=""),"",IFERROR(L7/H7-1,"")) | M9: =IF(OR(M7="",I7=""),"",IFERROR(M7/I7-1,"")) | N9: =IF(OR(N7="",J7=""),"",IFERROR(N7/J7-1,"")) | P9: =IF(OR(P7="",O7=""),"",IFERROR(P7/O7-1,"")) | Q9: =IF(OR(Q7="",P7=""),"",IFERROR(Q7/P7-1,"")) | R9: =IF(OR(R7="",Q7=""),"",IFERROR(R7/Q7-1,"")) | S9: =IF(OR(S7="",R7=""),"",IFERROR(S7/R7-1,"")) | T9: =IF(OR(T7="",S7=""),"",IFERROR(T7/S7-1,"")) | U9: =IF(OR(U7="",T7=""),"",IFERROR(U7/T7-1,"")) | V9: =IF(OR(V7="",U7=""),"",IFERROR(V7/U7-1,"")) | W9: =IF(OR(W7="",V7=""),"",IFERROR(W7/V7-1,"")) | ... AC9: =IF(OR(AC7="",AB7=""),"",IFERROR(AC7/AB7-1,""))
A10: 매출원가
A11: 전체 매출원가 | D11: 54.88 | E11: 103 | F11: 90 | G11: 82 | H11: 187 | I11: 51 | J11: 154 | K11: 146 | L11: 341 | M11: 152 | N11: 296 | U11: 70.307 | V11: 275.711 | W11: 462 | X11: 692
A12: YoY | G12: =IF(OR(G11="",C11=""),"",IF(C11<=0,"",IFERROR(G11/C11-1,""))) | H12: =IF(OR(H11="",D11=""),"",IF(D11<=0,"",IFERROR(H11/D11-1,""))) | I12: =IF(OR(I11="",E11=""),"",IF(E11<=0,"",IFERROR(I11/E11-1,""))) | J12: =IF(OR(J11="",F11=""),"",IF(F11<=0,"",IFERROR(J11/F11-1,""))) | K12: =IF(OR(K11="",G11=""),"",IF(G11<=0,"",IFERROR(K11/G11-1,""))) | L12: =IF(OR(L11="",H11=""),"",IF(H11<=0,"",IFERROR(L11/H11-1,""))) | M12: =IF(OR(M11="",I11=""),"",IF(I11<=0,"",IFERROR(M11/I11-1,""))) | N12: =IF(OR(N11="",J11=""),"",IF(J11<=0,"",IFERROR(N11/J11-1,""))) | P12: =IF(OR(P11="",O11=""),"",IF(O11<=0,"",IFERROR(P11/O11-1,""))) | Q12: =IF(OR(Q11="",P11=""),"",IF(P11<=0,"",IFERROR(Q11/P11-1,""))) | R12: =IF(OR(R11="",Q11=""),"",IF(Q11<=0,"",IFERROR(R11/Q11-1,""))) | S12: =IF(OR(S11="",R11=""),"",IF(R11<=0,"",IFERROR(S11/R11-1,""))) | T12: =IF(OR(T11="",S11=""),"",IF(S11<=0,"",IFERROR(T11/S11-1,""))) | U12: =IF(OR(U11="",T11=""),"",IF(T11<=0,"",IFERROR(U11/T11-1,""))) | V12: =IF(OR(V11="",U11=""),"",IF(U11<=0,"",IFERROR(V11/U11-1,""))) | W12: =IF(OR(W11="",V11=""),"",IF(V11<=0,"",IFERROR(W11/V11-1,""))) | ... AC12: =IF(OR(AC11="",AB11=""),"",IF(AB11<=0,"",IFERROR(AC11/AB11-1,"")))
A13: 매출총이익 | C13: =IF(OR(C4="",C11=""),"",IFERROR(C4-C11,"")) | D13: =IF(OR(D4="",D11=""),"",IFERROR(D4-D11,"")) | E13: =IF(OR(E4="",E11=""),"",IFERROR(E4-E11,"")) | F13: =IF(OR(F4="",F11=""),"",IFERROR(F4-F11,"")) | G13: =IF(OR(G4="",G11=""),"",IFERROR(G4-G11,"")) | H13: =IF(OR(H4="",H11=""),"",IFERROR(H4-H11,"")) | I13: =IF(OR(I4="",I11=""),"",IFERROR(I4-I11,"")) | J13: =IF(OR(J4="",J11=""),"",IFERROR(J4-J11,"")) | ... X13: =IF(OR(X4="",X11=""),"",IFERROR(X4-X11,""))
A14: GPM | C14: =IF(OR(C13="",C4=""),"",IFERROR(C13/C4,"")) | D14: =IF(OR(D13="",D4=""),"",IFERROR(D13/D4,"")) | E14: =IF(OR(E13="",E4=""),"",IFERROR(E13/E4,"")) | F14: =IF(OR(F13="",F4=""),"",IFERROR(F13/F4,"")) | G14: =IF(OR(G13="",G4=""),"",IFERROR(G13/G4,"")) | H14: =IF(OR(H13="",H4=""),"",IFERROR(H13/H4,"")) | I14: =IF(OR(I13="",I4=""),"",IFERROR(I13/I4,"")) | J14: =IF(OR(J13="",J4=""),"",IFERROR(J13/J4,"")) | ... AC14: =IF(OR(AC13="",AC4=""),"",IFERROR(AC13/AC4,""))
A15: YoY | G15: =IF(OR(G13="",C13=""),"",IF(C13<=0,"",IFERROR(G13/C13-1,""))) | H15: =IF(OR(H13="",D13=""),"",IF(D13<=0,"",IFERROR(H13/D13-1,""))) | I15: =IF(OR(I13="",E13=""),"",IF(E13<=0,"",IFERROR(I13/E13-1,""))) | J15: =IF(OR(J13="",F13=""),"",IF(F13<=0,"",IFERROR(J13/F13-1,""))) | K15: =IF(OR(K13="",G13=""),"",IF(G13<=0,"",IFERROR(K13/G13-1,""))) | L15: =IF(OR(L13="",H13=""),"",IF(H13<=0,"",IFERROR(L13/H13-1,""))) | M15: =IF(OR(M13="",I13=""),"",IF(I13<=0,"",IFERROR(M13/I13-1,""))) | N15: =IF(OR(N13="",J13=""),"",IF(J13<=0,"",IFERROR(N13/J13-1,""))) | P15: =IF(OR(P13="",O13=""),"",IF(O13<=0,"",IFERROR(P13/O13-1,""))) | Q15: =IF(OR(Q13="",P13=""),"",IF(P13<=0,"",IFERROR(Q13/P13-1,""))) | R15: =IF(OR(R13="",Q13=""),"",IF(Q13<=0,"",IFERROR(R13/Q13-1,""))) | S15: =IF(OR(S13="",R13=""),"",IF(R13<=0,"",IFERROR(S13/R13-1,""))) | T15: =IF(OR(T13="",S13=""),"",IF(S13<=0,"",IFERROR(T13/S13-1,""))) | U15: =IF(OR(U13="",T13=""),"",IF(T13<=0,"",IFERROR(U13/T13-1,""))) | V15: =IF(OR(V13="",U13=""),"",IF(U13<=0,"",IFERROR(V13/U13-1,""))) | W15: =IF(OR(W13="",V13=""),"",IF(V13<=0,"",IFERROR(W13/V13-1,""))) | ... AC15: =IF(OR(AC13="",AB13=""),"",IF(AB13<=0,"",IFERROR(AC13/AB13-1,"")))
A16: 판매관리비
A17: 전체 판관비 | D17: 179.239 | E17: 199 | F17: 225 | G17: 315 | H17: 348 | I17: 373 | J17: 373 | K17: 456 | L17: 468 | M17: 527 | N17: 499 | U17: 482.771 | V17: 627.14 | W17: 1087 | X17: 1670
A18: YoY | G18: =IF(OR(G17="",C17=""),"",IF(C17<=0,"",IFERROR(G17/C17-1,""))) | H18: =IF(OR(H17="",D17=""),"",IF(D17<=0,"",IFERROR(H17/D17-1,""))) | I18: =IF(OR(I17="",E17=""),"",IF(E17<=0,"",IFERROR(I17/E17-1,""))) | J18: =IF(OR(J17="",F17=""),"",IF(F17<=0,"",IFERROR(J17/F17-1,""))) | K18: =IF(OR(K17="",G17=""),"",IF(G17<=0,"",IFERROR(K17/G17-1,""))) | L18: =IF(OR(L17="",H17=""),"",IF(H17<=0,"",IFERROR(L17/H17-1,""))) | M18: =IF(OR(M17="",I17=""),"",IF(I17<=0,"",IFERROR(M17/I17-1,""))) | N18: =IF(OR(N17="",J17=""),"",IF(J17<=0,"",IFERROR(N17/J17-1,""))) | P18: =IF(OR(P17="",O17=""),"",IF(O17<=0,"",IFERROR(P17/O17-1,""))) | Q18: =IF(OR(Q17="",P17=""),"",IF(P17<=0,"",IFERROR(Q17/P17-1,""))) | R18: =IF(OR(R17="",Q17=""),"",IF(Q17<=0,"",IFERROR(R17/Q17-1,""))) | S18: =IF(OR(S17="",R17=""),"",IF(R17<=0,"",IFERROR(S17/R17-1,""))) | T18: =IF(OR(T17="",S17=""),"",IF(S17<=0,"",IFERROR(T17/S17-1,""))) | U18: =IF(OR(U17="",T17=""),"",IF(T17<=0,"",IFERROR(U17/T17-1,""))) | V18: =IF(OR(V17="",U17=""),"",IF(U17<=0,"",IFERROR(V17/U17-1,""))) | W18: =IF(OR(W17="",V17=""),"",IF(V17<=0,"",IFERROR(W17/V17-1,""))) | ... AC18: =IF(OR(AC17="",AB17=""),"",IF(AB17<=0,"",IFERROR(AC17/AB17-1,"")))
A19: 영업이익 | B19: MW = 매출 × OPM | D19: 124.095 | E19: 63 | F19: 126 | G19: -4 | H19: 409 | I19: -228 | J19: 323 | K19: -21 | L19: 840 | M19: -31 | N19: 440 | U19: 64.319 | V19: 508.156 | W19: 594 | X19: 914 | Y19: =IF(OR(Y4="",Y20=""),"",IFERROR(Y4*Y20,"")) | Z19: =IF(OR(Z4="",Z20=""),"",IFERROR(Z4*Z20,"")) | AA19: =IF(OR(AA4="",AA20=""),"",IFERROR(AA4*AA20,"")) | AB19: =IF(OR(AB4="",AB20=""),"",IFERROR(AB4*AB20,"")) | AC19: =IF(OR(AC4="",AC20=""),"",IFERROR(AC4*AC20,""))
A20: OPM | B20: MW 입력 | C20: =IF(OR(C19="",C4=""),"",IFERROR(C19/C4,"")) | D20: =IF(OR(D19="",D4=""),"",IFERROR(D19/D4,"")) | E20: =IF(OR(E19="",E4=""),"",IFERROR(E19/E4,"")) | F20: =IF(OR(F19="",F4=""),"",IFERROR(F19/F4,"")) | G20: =IF(OR(G19="",G4=""),"",IFERROR(G19/G4,"")) | H20: =IF(OR(H19="",H4=""),"",IFERROR(H19/H4,"")) | I20: =IF(OR(I19="",I4=""),"",IFERROR(I19/I4,"")) | J20: =IF(OR(J19="",J4=""),"",IFERROR(J19/J4,"")) | ... X20: =IF(OR(X19="",X4=""),"",IFERROR(X19/X4,""))
A21: 증가율 | G21: =IF(OR(G19="",C19=""),"",IFERROR(G19/C19-1,"")) | H21: =IF(OR(H19="",D19=""),"",IFERROR(H19/D19-1,"")) | I21: =IF(OR(I19="",E19=""),"",IFERROR(I19/E19-1,"")) | J21: =IF(OR(J19="",F19=""),"",IFERROR(J19/F19-1,"")) | K21: =IF(OR(K19="",G19=""),"",IFERROR(K19/G19-1,"")) | L21: =IF(OR(L19="",H19=""),"",IFERROR(L19/H19-1,"")) | M21: =IF(OR(M19="",I19=""),"",IFERROR(M19/I19-1,"")) | N21: =IF(OR(N19="",J19=""),"",IFERROR(N19/J19-1,"")) | P21: =IF(OR(P19="",O19=""),"",IFERROR(P19/O19-1,"")) | Q21: =IF(OR(Q19="",P19=""),"",IFERROR(Q19/P19-1,"")) | R21: =IF(OR(R19="",Q19=""),"",IFERROR(R19/Q19-1,"")) | S21: =IF(OR(S19="",R19=""),"",IFERROR(S19/R19-1,"")) | T21: =IF(OR(T19="",S19=""),"",IFERROR(T19/S19-1,"")) | U21: =IF(OR(U19="",T19=""),"",IFERROR(U19/T19-1,"")) | V21: =IF(OR(V19="",U19=""),"",IFERROR(V19/U19-1,"")) | W21: =IF(OR(W19="",V19=""),"",IFERROR(W19/V19-1,"")) | ... AC21: =IF(OR(AC19="",AB19=""),"",IFERROR(AC19/AB19-1,""))
A22: 비용의 성격별 분류 | B22: 참고 데이터
A23: 총 판관비 | O23: =IF(O17="","",O17) | P23: =IF(P17="","",P17) | Q23: =IF(Q17="","",Q17) | R23: =IF(R17="","",R17) | S23: =IF(S17="","",S17) | T23: =IF(T17="","",T17) | U23: =IF(U17="","",U17) | V23: =IF(V17="","",V17) | ... X23: =IF(X17="","",X17)
A24: 급여 | B24: 고정비
A25: % of Sales | O25: =IF(OR(O24="",O4=""),"",IFERROR(O24/O4,"")) | P25: =IF(OR(P24="",P4=""),"",IFERROR(P24/P4,"")) | Q25: =IF(OR(Q24="",Q4=""),"",IFERROR(Q24/Q4,"")) | R25: =IF(OR(R24="",R4=""),"",IFERROR(R24/R4,"")) | S25: =IF(OR(S24="",S4=""),"",IFERROR(S24/S4,"")) | T25: =IF(OR(T24="",T4=""),"",IFERROR(T24/T4,"")) | U25: =IF(OR(U24="",U4=""),"",IFERROR(U24/U4,"")) | V25: =IF(OR(V24="",V4=""),"",IFERROR(V24/V4,"")) | ... X25: =IF(OR(X24="",X4=""),"",IFERROR(X24/X4,""))
A26: 감가상각비 | B26: 고정비
A27: % of Sales | O27: =IF(OR(O26="",O4=""),"",IFERROR(O26/O4,"")) | P27: =IF(OR(P26="",P4=""),"",IFERROR(P26/P4,"")) | Q27: =IF(OR(Q26="",Q4=""),"",IFERROR(Q26/Q4,"")) | R27: =IF(OR(R26="",R4=""),"",IFERROR(R26/R4,"")) | S27: =IF(OR(S26="",S4=""),"",IFERROR(S26/S4,"")) | T27: =IF(OR(T26="",T4=""),"",IFERROR(T26/T4,"")) | U27: =IF(OR(U26="",U4=""),"",IFERROR(U26/U4,"")) | V27: =IF(OR(V26="",V4=""),"",IFERROR(V26/V4,"")) | ... X27: =IF(OR(X26="",X4=""),"",IFERROR(X26/X4,""))
A28: 지급수수료 | B28: 고정비
A29: % of Sales | O29: =IF(OR(O28="",O4=""),"",IFERROR(O28/O4,"")) | P29: =IF(OR(P28="",P4=""),"",IFERROR(P28/P4,"")) | Q29: =IF(OR(Q28="",Q4=""),"",IFERROR(Q28/Q4,"")) | R29: =IF(OR(R28="",R4=""),"",IFERROR(R28/R4,"")) | S29: =IF(OR(S28="",S4=""),"",IFERROR(S28/S4,"")) | T29: =IF(OR(T28="",T4=""),"",IFERROR(T28/T4,"")) | U29: =IF(OR(U28="",U4=""),"",IFERROR(U28/U4,"")) | V29: =IF(OR(V28="",V4=""),"",IFERROR(V28/V4,"")) | ... X29: =IF(OR(X28="",X4=""),"",IFERROR(X28/X4,""))
A30: 연구개발비 | B30: 변동비
A31: % of Sales | O31: =IF(OR(O30="",O4=""),"",IFERROR(O30/O4,"")) | P31: =IF(OR(P30="",P4=""),"",IFERROR(P30/P4,"")) | Q31: =IF(OR(Q30="",Q4=""),"",IFERROR(Q30/Q4,"")) | R31: =IF(OR(R30="",R4=""),"",IFERROR(R30/R4,"")) | S31: =IF(OR(S30="",S4=""),"",IFERROR(S30/S4,"")) | T31: =IF(OR(T30="",T4=""),"",IFERROR(T30/T4,"")) | U31: =IF(OR(U30="",U4=""),"",IFERROR(U30/U4,"")) | V31: =IF(OR(V30="",V4=""),"",IFERROR(V30/V4,"")) | ... X31: =IF(OR(X30="",X4=""),"",IFERROR(X30/X4,""))
A32: 기타비용 | B32: 변동비 | O32: =IF(OR(O23="",O24="",O26="",O28="",O30=""),"",IFERROR(O23-O24-O26-O28-O30,"")) | P32: =IF(OR(P23="",P24="",P26="",P28="",P30=""),"",IFERROR(P23-P24-P26-P28-P30,"")) | Q32: =IF(OR(Q23="",Q24="",Q26="",Q28="",Q30=""),"",IFERROR(Q23-Q24-Q26-Q28-Q30,"")) | R32: =IF(OR(R23="",R24="",R26="",R28="",R30=""),"",IFERROR(R23-R24-R26-R28-R30,"")) | S32: =IF(OR(S23="",S24="",S26="",S28="",S30=""),"",IFERROR(S23-S24-S26-S28-S30,"")) | T32: =IF(OR(T23="",T24="",T26="",T28="",T30=""),"",IFERROR(T23-T24-T26-T28-T30,"")) | U32: =IF(OR(U23="",U24="",U26="",U28="",U30=""),"",IFERROR(U23-U24-U26-U28-U30,"")) | V32: =IF(OR(V23="",V24="",V26="",V28="",V30=""),"",IFERROR(V23-V24-V26-V28-V30,"")) | ... X32: =IF(OR(X23="",X24="",X26="",X28="",X30=""),"",IFERROR(X23-X24-X26-X28-X30,""))
A33: % of Sales | O33: =IF(OR(O32="",O4=""),"",IFERROR(O32/O4,"")) | P33: =IF(OR(P32="",P4=""),"",IFERROR(P32/P4,"")) | Q33: =IF(OR(Q32="",Q4=""),"",IFERROR(Q32/Q4,"")) | R33: =IF(OR(R32="",R4=""),"",IFERROR(R32/R4,"")) | S33: =IF(OR(S32="",S4=""),"",IFERROR(S32/S4,"")) | T33: =IF(OR(T32="",T4=""),"",IFERROR(T32/T4,"")) | U33: =IF(OR(U32="",U4=""),"",IFERROR(U32/U4,"")) | V33: =IF(OR(V32="",V4=""),"",IFERROR(V32/V4,"")) | ... X33: =IF(OR(X32="",X4=""),"",IFERROR(X32/X4,""))
A34: 당기순이익 추정
A35: 특별이익 | Y35: =IF(OR(Y4="",Y36=""),"",IFERROR(Y4*Y36,"")) | Z35: =IF(OR(Z4="",Z36=""),"",IFERROR(Z4*Z36,"")) | AA35: =IF(OR(AA4="",AA36=""),"",IFERROR(AA4*AA36,"")) | AB35: =IF(OR(AB4="",AB36=""),"",IFERROR(AB4*AB36,"")) | AC35: =IF(OR(AC4="",AC36=""),"",IFERROR(AC4*AC36,""))
A36: % of Sales | B36: MW = 최근 3년 평균 | C36: =IF(OR(C35="",C4=""),"",IFERROR(C35/C4,"")) | D36: =IF(OR(D35="",D4=""),"",IFERROR(D35/D4,"")) | E36: =IF(OR(E35="",E4=""),"",IFERROR(E35/E4,"")) | F36: =IF(OR(F35="",F4=""),"",IFERROR(F35/F4,"")) | G36: =IF(OR(G35="",G4=""),"",IFERROR(G35/G4,"")) | H36: =IF(OR(H35="",H4=""),"",IFERROR(H35/H4,"")) | I36: =IF(OR(I35="",I4=""),"",IFERROR(I35/I4,"")) | J36: =IF(OR(J35="",J4=""),"",IFERROR(J35/J4,"")) | ... X36: =IF(OR(X35="",X4=""),"",IFERROR(X35/X4,"")) | Y36: =IFERROR(AVERAGE(V36,W36,X36),"") | Z36: =Y36 | AA36: =Z36 | AB36: =AA36 | AC36: =AB36
A37: 특별손실 | U37: 3.609 | V37: 0 | Y37: =IF(OR(Y4="",Y38=""),"",IFERROR(Y4*Y38,"")) | Z37: =IF(OR(Z4="",Z38=""),"",IFERROR(Z4*Z38,"")) | AA37: =IF(OR(AA4="",AA38=""),"",IFERROR(AA4*AA38,"")) | AB37: =IF(OR(AB4="",AB38=""),"",IFERROR(AB4*AB38,"")) | AC37: =IF(OR(AC4="",AC38=""),"",IFERROR(AC4*AC38,""))
A38: % of Sales | C38: =IF(OR(C37="",C4=""),"",IFERROR(C37/C4,"")) | D38: =IF(OR(D37="",D4=""),"",IFERROR(D37/D4,"")) | E38: =IF(OR(E37="",E4=""),"",IFERROR(E37/E4,"")) | F38: =IF(OR(F37="",F4=""),"",IFERROR(F37/F4,"")) | G38: =IF(OR(G37="",G4=""),"",IFERROR(G37/G4,"")) | H38: =IF(OR(H37="",H4=""),"",IFERROR(H37/H4,"")) | I38: =IF(OR(I37="",I4=""),"",IFERROR(I37/I4,"")) | J38: =IF(OR(J37="",J4=""),"",IFERROR(J37/J4,"")) | ... X38: =IF(OR(X37="",X4=""),"",IFERROR(X37/X4,"")) | Y38: =IFERROR(AVERAGE(V38,W38,X38),"") | Z38: =Y38 | AA38: =Z38 | AB38: =AA38 | AC38: =AB38
A39: 영업외수익 | D39: -0.017 | E39: 0 | F39: 0 | G39: 0 | H39: 0 | I39: 0 | J39: 0 | K39: 0 | L39: 0 | M39: 0 | N39: 0 | U39: 0.244 | V39: 0.108 | W39: 0 | X39: 0 | Y39: =IF(OR(Y4="",Y40=""),"",IFERROR(Y4*Y40,"")) | Z39: =IF(OR(Z4="",Z40=""),"",IFERROR(Z4*Z40,"")) | AA39: =IF(OR(AA4="",AA40=""),"",IFERROR(AA4*AA40,"")) | AB39: =IF(OR(AB4="",AB40=""),"",IFERROR(AB4*AB40,"")) | AC39: =IF(OR(AC4="",AC40=""),"",IFERROR(AC4*AC40,""))
A40: % of Sales | C40: =IF(OR(C39="",C4=""),"",IFERROR(C39/C4,"")) | D40: =IF(OR(D39="",D4=""),"",IFERROR(D39/D4,"")) | E40: =IF(OR(E39="",E4=""),"",IFERROR(E39/E4,"")) | F40: =IF(OR(F39="",F4=""),"",IFERROR(F39/F4,"")) | G40: =IF(OR(G39="",G4=""),"",IFERROR(G39/G4,"")) | H40: =IF(OR(H39="",H4=""),"",IFERROR(H39/H4,"")) | I40: =IF(OR(I39="",I4=""),"",IFERROR(I39/I4,"")) | J40: =IF(OR(J39="",J4=""),"",IFERROR(J39/J4,"")) | ... X40: =IF(OR(X39="",X4=""),"",IFERROR(X39/X4,"")) | Y40: =IFERROR(AVERAGE(V40,W40,X40),"") | Z40: =Y40 | AA40: =Z40 | AB40: =AA40 | AC40: =AB40
...

Sheet 재무상태표
A1: VRAIN 솔루션 재무상태표
A2: 재무비율은 기말 잔액 기준 · 분기 손익은 최근 4분기 합산(TTM) | B2: (단위: 백만엔)
A3: 항목 | B3: 참고 | C3: 2026.2Q | D3: 2026.3Q | E3: 2026.4Q | F3: 2027.1Q | G3: 2027.2Q | H3: 2023 | I3: 2024 | J3: 2025 | K3: 2026
A4: 자산
A5: 유동자산 | C5: 1707 | D5: 1916 | E5: 2747 | F5: 2024 | G5: 2402 | H5: 231.816 | I5: 1337.928 | J5: 1539 | K5: 2747
A6: 현금및현금성자산 | C6: 89 | D6: 74 | E6: 427 | F6: 308 | G6: 138 | H6: 18.086 | I6: 962.104 | J6: 488 | K6: 427
A7: 단기금융상품
A8: 매출채권 | E8: 1957 | I8: 292.989 | J8: 838 | K8: 1957
A9: 재고자산 | C9: 135 | D9: 191 | E9: 206 | F9: 269 | G9: 252 | H9: 41.593 | I9: 59.912 | J9: 96 | K9: 206
A10: 기타유동자산 | B10: 총계 − 위 항목 | C10: =IF(OR(C5=""),"",IFERROR(C5-SUM(C6,C7,C8,C9),"")) | D10: =IF(OR(D5=""),"",IFERROR(D5-SUM(D6,D7,D8,D9),"")) | E10: =IF(OR(E5=""),"",IFERROR(E5-SUM(E6,E7,E8,E9),"")) | F10: =IF(OR(F5=""),"",IFERROR(F5-SUM(F6,F7,F8,F9),"")) | G10: =IF(OR(G5=""),"",IFERROR(G5-SUM(G6,G7,G8,G9),"")) | H10: =IF(OR(H5=""),"",IFERROR(H5-SUM(H6,H7,H8,H9),"")) | I10: =IF(OR(I5=""),"",IFERROR(I5-SUM(I6,I7,I8,I9),"")) | J10: =IF(OR(J5=""),"",IFERROR(J5-SUM(J6,J7,J8,J9),"")) | K10: =IF(OR(K5=""),"",IFERROR(K5-SUM(K6,K7,K8,K9),""))
A11: 비유동자산 | C11: 341 | D11: 359 | E11: 468 | F11: 481 | G11: 448 | H11: 109.298 | I11: 111.973 | J11: 333 | K11: 468
A12: 유형자산 | C12: 128 | D12: 127 | E12: 130 | F12: 206 | G12: 207 | H12: 44.01 | I12: 42.954 | J12: 85 | K12: 130
A13: 무형자산 | C13: 1 | D13: 2 | E13: 2 | F13: 2 | G13: 1 | I13: 0 | J13: 1 | K13: 2
A14: 투자부동산
A15: 기타비유동자산 | B15: 총계 − 위 항목 | C15: =IF(OR(C11=""),"",IFERROR(C11-SUM(C12,C13,C14),"")) | D15: =IF(OR(D11=""),"",IFERROR(D11-SUM(D12,D13,D14),"")) | E15: =IF(OR(E11=""),"",IFERROR(E11-SUM(E12,E13,E14),"")) | F15: =IF(OR(F11=""),"",IFERROR(F11-SUM(F12,F13,F14),"")) | G15: =IF(OR(G11=""),"",IFERROR(G11-SUM(G12,G13,G14),"")) | H15: =IF(OR(H11=""),"",IFERROR(H11-SUM(H12,H13,H14),"")) | I15: =IF(OR(I11=""),"",IFERROR(I11-SUM(I12,I13,I14),"")) | J15: =IF(OR(J11=""),"",IFERROR(J11-SUM(J12,J13,J14),"")) | K15: =IF(OR(K11=""),"",IFERROR(K11-SUM(K12,K13,K14),""))
A16: 자산총계 | C16: 2048 | D16: 2276 | E16: 3215 | F16: 2505 | G16: 2850 | H16: 341.115 | I16: 1449.901 | J16: 1873 | K16: 3215
A17: 부채
A18: 유동부채 | C18: 559 | D18: 798 | E18: 1129 | F18: 439 | G18: 496 | H18: 183.213 | I18: 430.92 | J18: 451 | K18: 1129
A19: 매입채무 | C19: 48 | D19: 74 | E19: 160 | F19: 52 | G19: 75 | H19: 0 | I19: 1.202 | J19: 34 | K19: 160
A20: 단기차입금 | C20: 170 | D20: 400 | E20: 400 | F20: 0 | G20: 0 | J20: 0 | K20: 400
A21: 유동성장기부채 | C21: 0 | D21: 0 | E21: 0 | H21: 50.964 | I21: 46.751 | J21: 5 | K21: 0
A22: 기타유동부채 | B22: 총계 − 위 항목 | C22: =IF(OR(C18=""),"",IFERROR(C18-SUM(C19,C20,C21),"")) | D22: =IF(OR(D18=""),"",IFERROR(D18-SUM(D19,D20,D21),"")) | E22: =IF(OR(E18=""),"",IFERROR(E18-SUM(E19,E20,E21),"")) | F22: =IF(OR(F18=""),"",IFERROR(F18-SUM(F19,F20,F21),"")) | G22: =IF(OR(G18=""),"",IFERROR(G18-SUM(G19,G20,G21),"")) | H22: =IF(OR(H18=""),"",IFERROR(H18-SUM(H19,H20,H21),"")) | I22: =IF(OR(I18=""),"",IFERROR(I18-SUM(I19,I20,I21),"")) | J22: =IF(OR(J18=""),"",IFERROR(J18-SUM(J19,J20,J21),"")) | K22: =IF(OR(K18=""),"",IFERROR(K18-SUM(K19,K20,K21),""))
A23: 비유동부채 | H23: 68.691 | I23: 21.94 | J23: 0
A24: 장기차입금 | H24: 68.691 | I24: 21.94 | J24: 0
A25: 사채
A26: 기타비유동부채 | B26: 총계 − 위 항목 | C26: =IF(OR(C23=""),"",IFERROR(C23-SUM(C24,C25),"")) | D26: =IF(OR(D23=""),"",IFERROR(D23-SUM(D24,D25),"")) | E26: =IF(OR(E23=""),"",IFERROR(E23-SUM(E24,E25),"")) | F26: =IF(OR(F23=""),"",IFERROR(F23-SUM(F24,F25),"")) | G26: =IF(OR(G23=""),"",IFERROR(G23-SUM(G24,G25),"")) | H26: =IF(OR(H23=""),"",IFERROR(H23-SUM(H24,H25),"")) | I26: =IF(OR(I23=""),"",IFERROR(I23-SUM(I24,I25),"")) | J26: =IF(OR(J23=""),"",IFERROR(J23-SUM(J24,J25),"")) | K26: =IF(OR(K23=""),"",IFERROR(K23-SUM(K24,K25),""))
A27: 부채총계 | C27: 559 | D27: 798 | E27: 1129 | F27: 439 | G27: 496 | H27: 251.904 | I27: 452.86 | J27: 451 | K27: 1129
A28: 총차입금 | B28: 단기+유동성장기+장기+사채 | C28: =SUM(C20,C21,C24,C25) | D28: =SUM(D20,D21,D24,D25) | E28: =SUM(E20,E21,E24,E25) | F28: =SUM(F20,F21,F24,F25) | G28: =SUM(G20,G21,G24,G25) | H28: =SUM(H20,H21,H24,H25) | I28: =SUM(I20,I21,I24,I25) | J28: =SUM(J20,J21,J24,J25) | K28: =SUM(K20,K21,K24,K25)
A29: 순차입금 | B29: 음수 = 순현금 | C29: =C28-C6-N(C7) | D29: =D28-D6-N(D7) | E29: =E28-E6-N(E7) | F29: =F28-F6-N(F7) | G29: =G28-G6-N(G7) | H29: =H28-H6-N(H7) | I29: =I28-I6-N(I7) | J29: =J28-J6-N(J7) | K29: =K28-K6-N(K7)
A30: 자본
A31: 지배주주지분 | C31: 1489 | D31: 1477 | E31: 2086 | F31: 2066 | G31: 2353 | H31: 89.211 | I31: 997.04 | J31: 1422 | K31: 2086
A32: 자본금 | C32: 13 | D32: 13 | E32: 16 | F32: 16 | G32: 16 | H32: 9.9 | I32: 298.734 | J32: 10 | K32: 16
A33: 이익잉여금 | C33: 895 | D33: 884 | E33: 1486 | F33: 1466 | G33: 1753 | H33: 79.311 | I33: 409.472 | J33: 834 | K33: 1486
A34: 비지배지분
A35: 자본총계 | C35: 1489 | D35: 1477 | E35: 2086 | F35: 2066 | G35: 2353 | H35: 89.211 | I35: 997.04 | J35: 1422 | K35: 2086
A36: 현금흐름 요약 | B36: 분기 = TTM (있을 때만)
A37: 영업활동현금흐름 | C37: -398 | E37: -374 | G37: 317 | H37: -40.931 | I37: 435.922 | J37: -161 | K37: -374
A38: CAPEX (유·무형 취득) | B38: 양수로 입력 | C38: 126 | E38: 101 | G38: 130 | H38: 47.061 | I38: 18.073 | J38: 79 | K38: 101
A39: FCF | C39: =IF(OR(C37="",C38=""),"",IFERROR(C37-C38,"")) | D39: =IF(OR(D37="",D38=""),"",IFERROR(D37-D38,"")) | E39: =IF(OR(E37="",E38=""),"",IFERROR(E37-E38,"")) | F39: =IF(OR(F37="",F38=""),"",IFERROR(F37-F38,"")) | G39: =IF(OR(G37="",G38=""),"",IFERROR(G37-G38,"")) | H39: =IF(OR(H37="",H38=""),"",IFERROR(H37-H38,"")) | I39: =IF(OR(I37="",I38=""),"",IFERROR(I37-I38,"")) | J39: =IF(OR(J37="",J38=""),"",IFERROR(J37-J38,"")) | K39: =IF(OR(K37="",K38=""),"",IFERROR(K37-K38,""))
A40: 배당금 지급 | B40: 양수로 입력
...

Sheet 섹터 데이터
A1: VRAIN 솔루션 섹터·사업 데이터
A2: 2단계 보고서를 만들 때 모은 자료 · 월차 · 출처는 맨 오른쪽
A4: THIS RESULT · 2Q standalone
A5: 항목 | B5: 값 | C5: 출처
A6: 매출 | B6: 12.36 | C6: 2단계 보고서 자료(회사 설명회 자료·공시)
A7: gp | B7: 9.4
A8: 매출총이익률 | B8: 76
A9: sga | B9: 4.99
A10: 영업이익 | B10: 4.4
A11: 영업이익률 | B11: 35.7
A12: ordinary | B12: 4.41
A13: 순이익 | B13: 2.87
A14: YoY 매출 | B14: 45.2
A15: YoY 영업이익 | B15: 35.9
A16: QoQ 매출 | B16: 90.6
A17: ly 매출 | B17: 8.51
A18: ly gp | B18: 6.97
... A22: ly 영업이익률 | B22: 38.1
A24: THIS RESULT · 상반기 cum
A25: 항목 | B25: 값 | C25: 출처
A26: 매출 | B26: 18.84 | C26: 2단계 보고서 자료(회사 설명회 자료·공시)
A27: 매출 YoY | B27: 80
A28: cogs | B28: 4.48
A29: gp | B29: 14.36
A30: 매출총이익률 | B30: 76.2
A31: 매출총이익률 ly | B31: 80.4
A32: sga | B32: 10.26
A33: 영업이익 | B33: 4.09
A34: 영업이익 YoY | B34: 328.1
A35: 영업이익률 | B35: 21.7
A36: ordinary | B36: 4.09
A37: pbt | B37: 4.09
A38: tax | B38: 1.42
... A40: EPS 상반기 | B40: 26.06
A42: THIS RESULT · 가이던스 fy27
A43: 항목 | B43: 값 | C43: 출처
A44: 매출 | B44: 48.23 | C44: 2단계 보고서 자료(회사 설명회 자료·공시)
A45: 매출 YoY | B45: 47.1
A46: gp | B46: 38.58
A47: 매출총이익률 | B47: 80
...

Sheet 출처
A1: 출처 · 쓴 결산단신
A3: 공시일 | B3: 문서 | C3: PDF
A4: 2026-10-14 | B4: 2027년 2월 결산기 ２분기 결산단신 | C4: https://www2.jpx.co.jp/disc/135A0/140120260831528808.pdf
A5: 2026-07-14 | B5: 2027년 2월 결산기 １분기 결산단신 | C5: https://www2.jpx.co.jp/disc/135A0/140120260630584464.pdf
A6: 2026-04-14 | B6: 2026년 2월 결산기 연간 결산단신 | C6: https://www2.jpx.co.jp/disc/135A0/140120260401596757.pdf
A7: 2026-01-14 | B7: 2026년 2월 결산기 ３분기 결산단신 | C7: https://www2.jpx.co.jp/disc/135A0/140120251225526650.pdf
A8: 2025-10-14 | B8: 2026년 2월 결산기 ２분기 결산단신 | C8: https://www2.jpx.co.jp/disc/135A0/140120251008570370.pdf
A9: 2025-07-14 | B9: 2026년 2월 결산기 １분기 결산단신 | C9: https://www2.jpx.co.jp/disc/135A0/140120250625599004.pdf
A10: 2025-04-14 | B10: 2025년 2월 결산기 연간 결산단신 | C10: https://www2.jpx.co.jp/disc/135A0/140120250414514580.pdf
A11: 2025-01-14 | B11: 2025년 2월 결산기 ３분기 결산단신 | C11: https://www2.jpx.co.jp/disc/135A0/140120250108548165.pdf
A12: 2024-10-15 | B12: 2025년 2월 결산기 ２분기 결산단신 | C12: https://www2.jpx.co.jp/disc/135A0/140120240927590144.pdf
A13: 2024-07-11 | B13: 2025년 2월 결산기 １분기 결산단신 | C13: https://www2.jpx.co.jp/disc/135A0/140120240704544655.pdf
A14: 2024-04-15 | B14: 2024년 2월 결산기 연간 결산단신 | C14: https://www2.jpx.co.jp/disc/135A0/140120240412570387.pdf
