Workbook

Sheet 연간
A1: 2760 Model
A2: 모를 땐 보수적으로 | B2: (단위: 백만엔) | C2: 3월 결산 · 일본 기준 · 2027.1Q = 2027년 3월 결산기 1분기 | Y2: (추정: 파란 글씨 = 직접 입력)
A3: 항목 | B3: 참고 | C3: 2024.2Q | D3: 2024.3Q | E3: 2024.4Q | F3: 2025.1Q | G3: 2025.2Q | H3: 2025.3Q | I3: 2025.4Q | J3: 2026.1Q | K3: 2026.2Q | L3: 2026.3Q | M3: 2026.4Q | N3: 2027.1Q | O3: 2017 | P3: 2018 | Q3: 2019 | R3: 2020 | S3: 2021 | T3: 2022 | U3: 2023 | V3: 2024 | W3: 2025 | X3: 2026 | Y3: 2027(MW) | Z3: 2028(MW) | AA3: 2029(MW) | AB3: 2030(MW) | AC3: 2031(MW)
A4: 매출액 | B4: MW = 제품 합계 | C4: 60686 | D4: 60050 | E4: 63140 | F4: 56607 | G4: 55105 | H4: 50384 | I4: 54283 | J4: 45136 | K4: 51108 | L4: 50472 | M4: 57032 | N4: 60322 | O4: 131855 | P4: 159841 | Q4: 141000 | R4: 135394 | S4: 143268 | T4: 179907 | U4: 240350 | V4: 242888 | W4: 216379 | X4: 203748 | Y4: =IF(COUNT(Y7,Y10,Y13)=0,"",SUM(Y7,Y10,Y13)) | Z4: =IF(COUNT(Z7,Z10,Z13)=0,"",SUM(Z7,Z10,Z13)) | AA4: =IF(COUNT(AA7,AA10,AA13)=0,"",SUM(AA7,AA10,AA13)) | AB4: =IF(COUNT(AB7,AB10,AB13)=0,"",SUM(AB7,AB10,AB13)) | AC4: =IF(COUNT(AC7,AC10,AC13)=0,"",SUM(AC7,AC10,AC13))
A5: YoY | G5: =IF(OR(G4="",C4=""),"",IFERROR(G4/C4-1,"")) | H5: =IF(OR(H4="",D4=""),"",IFERROR(H4/D4-1,"")) | I5: =IF(OR(I4="",E4=""),"",IFERROR(I4/E4-1,"")) | J5: =IF(OR(J4="",F4=""),"",IFERROR(J4/F4-1,"")) | K5: =IF(OR(K4="",G4=""),"",IFERROR(K4/G4-1,"")) | L5: =IF(OR(L4="",H4=""),"",IFERROR(L4/H4-1,"")) | M5: =IF(OR(M4="",I4=""),"",IFERROR(M4/I4-1,"")) | N5: =IF(OR(N4="",J4=""),"",IFERROR(N4/J4-1,"")) | P5: =IF(OR(P4="",O4=""),"",IFERROR(P4/O4-1,"")) | Q5: =IF(OR(Q4="",P4=""),"",IFERROR(Q4/P4-1,"")) | R5: =IF(OR(R4="",Q4=""),"",IFERROR(R4/Q4-1,"")) | S5: =IF(OR(S4="",R4=""),"",IFERROR(S4/R4-1,"")) | T5: =IF(OR(T4="",S4=""),"",IFERROR(T4/S4-1,"")) | U5: =IF(OR(U4="",T4=""),"",IFERROR(U4/T4-1,"")) | V5: =IF(OR(V4="",U4=""),"",IFERROR(V4/U4-1,"")) | W5: =IF(OR(W4="",V4=""),"",IFERROR(W4/V4-1,"")) | ... AC5: =IF(OR(AC4="",AB4=""),"",IFERROR(AC4/AB4-1,""))
A6: 제품별 매출 분류 | B6: 사업보고서 매출실적
A7: SemiconductorAndElectronicDeviceReportableSegmentsMember | C7: 53432 | D7: 53463 | E7: 51102 | F7: 47865 | G7: 46159 | H7: 41924 | I7: 43103 | J7: 36394 | K7: 40654 | L7: 40256 | M7: 45239 | N7: 50354 | V7: 209909 | W7: 179051 | X7: 162543
A8: 비중 | C8: =IF(OR(C7="",C4=""),"",IFERROR(C7/C4,"")) | D8: =IF(OR(D7="",D4=""),"",IFERROR(D7/D4,"")) | E8: =IF(OR(E7="",E4=""),"",IFERROR(E7/E4,"")) | F8: =IF(OR(F7="",F4=""),"",IFERROR(F7/F4,"")) | G8: =IF(OR(G7="",G4=""),"",IFERROR(G7/G4,"")) | H8: =IF(OR(H7="",H4=""),"",IFERROR(H7/H4,"")) | I8: =IF(OR(I7="",I4=""),"",IFERROR(I7/I4,"")) | J8: =IF(OR(J7="",J4=""),"",IFERROR(J7/J4,"")) | ... AC8: =IF(OR(AC7="",AC4=""),"",IFERROR(AC7/AC4,""))
A9: YoY | G9: =IF(OR(G7="",C7=""),"",IFERROR(G7/C7-1,"")) | H9: =IF(OR(H7="",D7=""),"",IFERROR(H7/D7-1,"")) | I9: =IF(OR(I7="",E7=""),"",IFERROR(I7/E7-1,"")) | J9: =IF(OR(J7="",F7=""),"",IFERROR(J7/F7-1,"")) | K9: =IF(OR(K7="",G7=""),"",IFERROR(K7/G7-1,"")) | L9: =IF(OR(L7="",H7=""),"",IFERROR(L7/H7-1,"")) | M9: =IF(OR(M7="",I7=""),"",IFERROR(M7/I7-1,"")) | N9: =IF(OR(N7="",J7=""),"",IFERROR(N7/J7-1,"")) | P9: =IF(OR(P7="",O7=""),"",IFERROR(P7/O7-1,"")) | Q9: =IF(OR(Q7="",P7=""),"",IFERROR(Q7/P7-1,"")) | R9: =IF(OR(R7="",Q7=""),"",IFERROR(R7/Q7-1,"")) | S9: =IF(OR(S7="",R7=""),"",IFERROR(S7/R7-1,"")) | T9: =IF(OR(T7="",S7=""),"",IFERROR(T7/S7-1,"")) | U9: =IF(OR(U7="",T7=""),"",IFERROR(U7/T7-1,"")) | V9: =IF(OR(V7="",U7=""),"",IFERROR(V7/U7-1,"")) | W9: =IF(OR(W7="",V7=""),"",IFERROR(W7/V7-1,"")) | ... AC9: =IF(OR(AC7="",AB7=""),"",IFERROR(AC7/AB7-1,""))
A10: ComputerSystemReportableSegmentsMember | C10: 7254 | D10: 6587 | E10: 12038 | F10: 8741 | G10: 8946 | H10: 8460 | I10: 11180 | J10: 8741 | K10: 10454 | L10: 10216 | M10: 11793 | N10: 9967 | V10: 32978 | W10: 37327 | X10: 41204
A11: 비중 | C11: =IF(OR(C10="",C4=""),"",IFERROR(C10/C4,"")) | D11: =IF(OR(D10="",D4=""),"",IFERROR(D10/D4,"")) | E11: =IF(OR(E10="",E4=""),"",IFERROR(E10/E4,"")) | F11: =IF(OR(F10="",F4=""),"",IFERROR(F10/F4,"")) | G11: =IF(OR(G10="",G4=""),"",IFERROR(G10/G4,"")) | H11: =IF(OR(H10="",H4=""),"",IFERROR(H10/H4,"")) | I11: =IF(OR(I10="",I4=""),"",IFERROR(I10/I4,"")) | J11: =IF(OR(J10="",J4=""),"",IFERROR(J10/J4,"")) | ... AC11: =IF(OR(AC10="",AC4=""),"",IFERROR(AC10/AC4,""))
A12: YoY | G12: =IF(OR(G10="",C10=""),"",IFERROR(G10/C10-1,"")) | H12: =IF(OR(H10="",D10=""),"",IFERROR(H10/D10-1,"")) | I12: =IF(OR(I10="",E10=""),"",IFERROR(I10/E10-1,"")) | J12: =IF(OR(J10="",F10=""),"",IFERROR(J10/F10-1,"")) | K12: =IF(OR(K10="",G10=""),"",IFERROR(K10/G10-1,"")) | L12: =IF(OR(L10="",H10=""),"",IFERROR(L10/H10-1,"")) | M12: =IF(OR(M10="",I10=""),"",IFERROR(M10/I10-1,"")) | N12: =IF(OR(N10="",J10=""),"",IFERROR(N10/J10-1,"")) | P12: =IF(OR(P10="",O10=""),"",IFERROR(P10/O10-1,"")) | Q12: =IF(OR(Q10="",P10=""),"",IFERROR(Q10/P10-1,"")) | R12: =IF(OR(R10="",Q10=""),"",IFERROR(R10/Q10-1,"")) | S12: =IF(OR(S10="",R10=""),"",IFERROR(S10/R10-1,"")) | T12: =IF(OR(T10="",S10=""),"",IFERROR(T10/S10-1,"")) | U12: =IF(OR(U10="",T10=""),"",IFERROR(U10/T10-1,"")) | V12: =IF(OR(V10="",U10=""),"",IFERROR(V10/U10-1,"")) | W12: =IF(OR(W10="",V10=""),"",IFERROR(W10/V10-1,"")) | ... AC12: =IF(OR(AC10="",AB10=""),"",IFERROR(AC10/AB10-1,""))
A13: EntityTotalMember | F13: 56607 | J13: 45136 | N13: 60322
A14: 비중 | C14: =IF(OR(C13="",C4=""),"",IFERROR(C13/C4,"")) | D14: =IF(OR(D13="",D4=""),"",IFERROR(D13/D4,"")) | E14: =IF(OR(E13="",E4=""),"",IFERROR(E13/E4,"")) | F14: =IF(OR(F13="",F4=""),"",IFERROR(F13/F4,"")) | G14: =IF(OR(G13="",G4=""),"",IFERROR(G13/G4,"")) | H14: =IF(OR(H13="",H4=""),"",IFERROR(H13/H4,"")) | I14: =IF(OR(I13="",I4=""),"",IFERROR(I13/I4,"")) | J14: =IF(OR(J13="",J4=""),"",IFERROR(J13/J4,"")) | ... AC14: =IF(OR(AC13="",AC4=""),"",IFERROR(AC13/AC4,""))
A15: YoY | G15: =IF(OR(G13="",C13=""),"",IFERROR(G13/C13-1,"")) | H15: =IF(OR(H13="",D13=""),"",IFERROR(H13/D13-1,"")) | I15: =IF(OR(I13="",E13=""),"",IFERROR(I13/E13-1,"")) | J15: =IF(OR(J13="",F13=""),"",IFERROR(J13/F13-1,"")) | K15: =IF(OR(K13="",G13=""),"",IFERROR(K13/G13-1,"")) | L15: =IF(OR(L13="",H13=""),"",IFERROR(L13/H13-1,"")) | M15: =IF(OR(M13="",I13=""),"",IFERROR(M13/I13-1,"")) | N15: =IF(OR(N13="",J13=""),"",IFERROR(N13/J13-1,"")) | P15: =IF(OR(P13="",O13=""),"",IFERROR(P13/O13-1,"")) | Q15: =IF(OR(Q13="",P13=""),"",IFERROR(Q13/P13-1,"")) | R15: =IF(OR(R13="",Q13=""),"",IFERROR(R13/Q13-1,"")) | S15: =IF(OR(S13="",R13=""),"",IFERROR(S13/R13-1,"")) | T15: =IF(OR(T13="",S13=""),"",IFERROR(T13/S13-1,"")) | U15: =IF(OR(U13="",T13=""),"",IFERROR(U13/T13-1,"")) | V15: =IF(OR(V13="",U13=""),"",IFERROR(V13/U13-1,"")) | W15: =IF(OR(W13="",V13=""),"",IFERROR(W13/V13-1,"")) | ... AC15: =IF(OR(AC13="",AB13=""),"",IFERROR(AC13/AB13-1,""))
A16: 매출원가
A17: 전체 매출원가 | C17: 51595 | D17: 51050 | E17: 52984 | F17: 47411 | G17: 47877 | H17: 42132 | I17: 45226 | J17: 38681 | K17: 43717 | L17: 42392 | M17: 47416 | N17: 51015 | O17: 116709 | P17: 142160 | Q17: 121295 | R17: 115491 | S17: 122666 | T17: 154268 | U17: 206106 | V17: 205720 | W17: 182646 | X17: 172206
A18: 매출총이익 | C18: =IF(OR(C4="",C17=""),"",IFERROR(C4-C17,"")) | D18: =IF(OR(D4="",D17=""),"",IFERROR(D4-D17,"")) | E18: =IF(OR(E4="",E17=""),"",IFERROR(E4-E17,"")) | F18: =IF(OR(F4="",F17=""),"",IFERROR(F4-F17,"")) | G18: =IF(OR(G4="",G17=""),"",IFERROR(G4-G17,"")) | H18: =IF(OR(H4="",H17=""),"",IFERROR(H4-H17,"")) | I18: =IF(OR(I4="",I17=""),"",IFERROR(I4-I17,"")) | J18: =IF(OR(J4="",J17=""),"",IFERROR(J4-J17,"")) | ... X18: =IF(OR(X4="",X17=""),"",IFERROR(X4-X17,""))
A19: GPM | C19: =IF(OR(C18="",C4=""),"",IFERROR(C18/C4,"")) | D19: =IF(OR(D18="",D4=""),"",IFERROR(D18/D4,"")) | E19: =IF(OR(E18="",E4=""),"",IFERROR(E18/E4,"")) | F19: =IF(OR(F18="",F4=""),"",IFERROR(F18/F4,"")) | G19: =IF(OR(G18="",G4=""),"",IFERROR(G18/G4,"")) | H19: =IF(OR(H18="",H4=""),"",IFERROR(H18/H4,"")) | I19: =IF(OR(I18="",I4=""),"",IFERROR(I18/I4,"")) | J19: =IF(OR(J18="",J4=""),"",IFERROR(J18/J4,"")) | ... AC19: =IF(OR(AC18="",AC4=""),"",IFERROR(AC18/AC4,""))
A20: 판매관리비
A21: 전체 판관비 | C21: 5566 | D21: 5293 | E21: 5588 | F21: 4942 | G21: 5189 | H21: 5686 | I21: 5457 | J21: 4999 | K21: 5284 | L21: 5336 | M21: 5669 | N21: 5240 | O21: 13481 | P21: 14924 | Q21: 16179 | R21: 16091 | S21: 15981 | T21: 17506 | U21: 20016 | V21: 21739 | W21: 21274 | X21: 21288
A22: 영업이익 | B22: MW = 매출 × OPM | C22: 3525 | D22: 3707 | E22: 4568 | F22: 4252 | G22: 2040 | H22: 2566 | I22: 3599 | J22: 1455 | K22: 2106 | L22: 2745 | M22: 3947 | N22: 4066 | O22: 1665 | P22: 2755 | Q22: 3525 | R22: 3810 | S22: 4620 | T22: 8131 | U22: 14227 | V22: 15428 | W22: 12457 | X22: 10253 | Y22: =IF(OR(Y4="",Y23=""),"",IFERROR(Y4*Y23,"")) | Z22: =IF(OR(Z4="",Z23=""),"",IFERROR(Z4*Z23,"")) | AA22: =IF(OR(AA4="",AA23=""),"",IFERROR(AA4*AA23,"")) | AB22: =IF(OR(AB4="",AB23=""),"",IFERROR(AB4*AB23,"")) | AC22: =IF(OR(AC4="",AC23=""),"",IFERROR(AC4*AC23,""))
A23: OPM | B23: MW 입력 | C23: =IF(OR(C22="",C4=""),"",IFERROR(C22/C4,"")) | D23: =IF(OR(D22="",D4=""),"",IFERROR(D22/D4,"")) | E23: =IF(OR(E22="",E4=""),"",IFERROR(E22/E4,"")) | F23: =IF(OR(F22="",F4=""),"",IFERROR(F22/F4,"")) | G23: =IF(OR(G22="",G4=""),"",IFERROR(G22/G4,"")) | H23: =IF(OR(H22="",H4=""),"",IFERROR(H22/H4,"")) | I23: =IF(OR(I22="",I4=""),"",IFERROR(I22/I4,"")) | J23: =IF(OR(J22="",J4=""),"",IFERROR(J22/J4,"")) | ... X23: =IF(OR(X22="",X4=""),"",IFERROR(X22/X4,""))
A24: 증가율 | G24: =IF(OR(G22="",C22=""),"",IFERROR(G22/C22-1,"")) | H24: =IF(OR(H22="",D22=""),"",IFERROR(H22/D22-1,"")) | I24: =IF(OR(I22="",E22=""),"",IFERROR(I22/E22-1,"")) | J24: =IF(OR(J22="",F22=""),"",IFERROR(J22/F22-1,"")) | K24: =IF(OR(K22="",G22=""),"",IFERROR(K22/G22-1,"")) | L24: =IF(OR(L22="",H22=""),"",IFERROR(L22/H22-1,"")) | M24: =IF(OR(M22="",I22=""),"",IFERROR(M22/I22-1,"")) | N24: =IF(OR(N22="",J22=""),"",IFERROR(N22/J22-1,"")) | P24: =IF(OR(P22="",O22=""),"",IFERROR(P22/O22-1,"")) | Q24: =IF(OR(Q22="",P22=""),"",IFERROR(Q22/P22-1,"")) | R24: =IF(OR(R22="",Q22=""),"",IFERROR(R22/Q22-1,"")) | S24: =IF(OR(S22="",R22=""),"",IFERROR(S22/R22-1,"")) | T24: =IF(OR(T22="",S22=""),"",IFERROR(T22/S22-1,"")) | U24: =IF(OR(U22="",T22=""),"",IFERROR(U22/T22-1,"")) | V24: =IF(OR(V22="",U22=""),"",IFERROR(V22/U22-1,"")) | W24: =IF(OR(W22="",V22=""),"",IFERROR(W22/V22-1,"")) | ... AC24: =IF(OR(AC22="",AB22=""),"",IFERROR(AC22/AB22-1,""))
A25: 비용의 성격별 분류 | B25: 참고 데이터
A26: 총 판관비 | O26: =IF(O21="","",O21) | P26: =IF(P21="","",P21) | Q26: =IF(Q21="","",Q21) | R26: =IF(R21="","",R21) | S26: =IF(S21="","",S21) | T26: =IF(T21="","",T21) | U26: =IF(U21="","",U21) | V26: =IF(V21="","",V21) | ... X26: =IF(X21="","",X21)
A27: 급여 | B27: 고정비 | O27: 5595 | P27: 5764 | Q27: 6252 | R27: 6471 | S27: 6670 | T27: 6925 | U27: 7129 | V27: 7463 | W27: 7930 | X27: 8400
A28: % of Sales | O28: =IF(OR(O27="",O4=""),"",IFERROR(O27/O4,"")) | P28: =IF(OR(P27="",P4=""),"",IFERROR(P27/P4,"")) | Q28: =IF(OR(Q27="",Q4=""),"",IFERROR(Q27/Q4,"")) | R28: =IF(OR(R27="",R4=""),"",IFERROR(R27/R4,"")) | S28: =IF(OR(S27="",S4=""),"",IFERROR(S27/S4,"")) | T28: =IF(OR(T27="",T4=""),"",IFERROR(T27/T4,"")) | U28: =IF(OR(U27="",U4=""),"",IFERROR(U27/U4,"")) | V28: =IF(OR(V27="",V4=""),"",IFERROR(V27/V4,"")) | ... X28: =IF(OR(X27="",X4=""),"",IFERROR(X27/X4,""))
A29: 감가상각비 | B29: 고정비
A30: % of Sales | O30: =IF(OR(O29="",O4=""),"",IFERROR(O29/O4,"")) | P30: =IF(OR(P29="",P4=""),"",IFERROR(P29/P4,"")) | Q30: =IF(OR(Q29="",Q4=""),"",IFERROR(Q29/Q4,"")) | R30: =IF(OR(R29="",R4=""),"",IFERROR(R29/R4,"")) | S30: =IF(OR(S29="",S4=""),"",IFERROR(S29/S4,"")) | T30: =IF(OR(T29="",T4=""),"",IFERROR(T29/T4,"")) | U30: =IF(OR(U29="",U4=""),"",IFERROR(U29/U4,"")) | V30: =IF(OR(V29="",V4=""),"",IFERROR(V29/V4,"")) | ... X30: =IF(OR(X29="",X4=""),"",IFERROR(X29/X4,""))
A31: 지급수수료 | B31: 고정비
A32: % of Sales | O32: =IF(OR(O31="",O4=""),"",IFERROR(O31/O4,"")) | P32: =IF(OR(P31="",P4=""),"",IFERROR(P31/P4,"")) | Q32: =IF(OR(Q31="",Q4=""),"",IFERROR(Q31/Q4,"")) | R32: =IF(OR(R31="",R4=""),"",IFERROR(R31/R4,"")) | S32: =IF(OR(S31="",S4=""),"",IFERROR(S31/S4,"")) | T32: =IF(OR(T31="",T4=""),"",IFERROR(T31/T4,"")) | U32: =IF(OR(U31="",U4=""),"",IFERROR(U31/U4,"")) | V32: =IF(OR(V31="",V4=""),"",IFERROR(V31/V4,"")) | ... X32: =IF(OR(X31="",X4=""),"",IFERROR(X31/X4,""))
A33: 연구개발비 | B33: 변동비
A34: % of Sales | O34: =IF(OR(O33="",O4=""),"",IFERROR(O33/O4,"")) | P34: =IF(OR(P33="",P4=""),"",IFERROR(P33/P4,"")) | Q34: =IF(OR(Q33="",Q4=""),"",IFERROR(Q33/Q4,"")) | R34: =IF(OR(R33="",R4=""),"",IFERROR(R33/R4,"")) | S34: =IF(OR(S33="",S4=""),"",IFERROR(S33/S4,"")) | T34: =IF(OR(T33="",T4=""),"",IFERROR(T33/T4,"")) | U34: =IF(OR(U33="",U4=""),"",IFERROR(U33/U4,"")) | V34: =IF(OR(V33="",V4=""),"",IFERROR(V33/V4,"")) | ... X34: =IF(OR(X33="",X4=""),"",IFERROR(X33/X4,""))
A35: 기타비용 | B35: 변동비 | O35: =IF(OR(O26="",O27="",O29="",O31="",O33=""),"",IFERROR(O26-O27-O29-O31-O33,"")) | P35: =IF(OR(P26="",P27="",P29="",P31="",P33=""),"",IFERROR(P26-P27-P29-P31-P33,"")) | Q35: =IF(OR(Q26="",Q27="",Q29="",Q31="",Q33=""),"",IFERROR(Q26-Q27-Q29-Q31-Q33,"")) | R35: =IF(OR(R26="",R27="",R29="",R31="",R33=""),"",IFERROR(R26-R27-R29-R31-R33,"")) | S35: =IF(OR(S26="",S27="",S29="",S31="",S33=""),"",IFERROR(S26-S27-S29-S31-S33,"")) | T35: =IF(OR(T26="",T27="",T29="",T31="",T33=""),"",IFERROR(T26-T27-T29-T31-T33,"")) | U35: =IF(OR(U26="",U27="",U29="",U31="",U33=""),"",IFERROR(U26-U27-U29-U31-U33,"")) | V35: =IF(OR(V26="",V27="",V29="",V31="",V33=""),"",IFERROR(V26-V27-V29-V31-V33,"")) | ... X35: =IF(OR(X26="",X27="",X29="",X31="",X33=""),"",IFERROR(X26-X27-X29-X31-X33,""))
A36: % of Sales | O36: =IF(OR(O35="",O4=""),"",IFERROR(O35/O4,"")) | P36: =IF(OR(P35="",P4=""),"",IFERROR(P35/P4,"")) | Q36: =IF(OR(Q35="",Q4=""),"",IFERROR(Q35/Q4,"")) | R36: =IF(OR(R35="",R4=""),"",IFERROR(R35/R4,"")) | S36: =IF(OR(S35="",S4=""),"",IFERROR(S35/S4,"")) | T36: =IF(OR(T35="",T4=""),"",IFERROR(T35/T4,"")) | U36: =IF(OR(U35="",U4=""),"",IFERROR(U35/U4,"")) | V36: =IF(OR(V35="",V4=""),"",IFERROR(V35/V4,"")) | ... X36: =IF(OR(X35="",X4=""),"",IFERROR(X35/X4,""))
A37: 당기순이익 추정
A38: 특별이익 | C38: 0 | D38: 0 | E38: 0 | F38: 0 | G38: 0 | H38: 0 | I38: 0 | J38: 0 | K38: 0 | L38: 1066 | M38: 72 | N38: 0 | O38: 61 | P38: 46 | Q38: 207 | R38: 0 | S38: 1 | T38: 2061 | U38: 0 | V38: 4 | W38: 0 | X38: 1138 | Y38: =IF(OR(Y4="",Y39=""),"",IFERROR(Y4*Y39,"")) | Z38: =IF(OR(Z4="",Z39=""),"",IFERROR(Z4*Z39,"")) | AA38: =IF(OR(AA4="",AA39=""),"",IFERROR(AA4*AA39,"")) | AB38: =IF(OR(AB4="",AB39=""),"",IFERROR(AB4*AB39,"")) | AC38: =IF(OR(AC4="",AC39=""),"",IFERROR(AC4*AC39,""))
A39: % of Sales | B39: MW = 최근 3년 평균 | C39: =IF(OR(C38="",C4=""),"",IFERROR(C38/C4,"")) | D39: =IF(OR(D38="",D4=""),"",IFERROR(D38/D4,"")) | E39: =IF(OR(E38="",E4=""),"",IFERROR(E38/E4,"")) | F39: =IF(OR(F38="",F4=""),"",IFERROR(F38/F4,"")) | G39: =IF(OR(G38="",G4=""),"",IFERROR(G38/G4,"")) | H39: =IF(OR(H38="",H4=""),"",IFERROR(H38/H4,"")) | I39: =IF(OR(I38="",I4=""),"",IFERROR(I38/I4,"")) | J39: =IF(OR(J38="",J4=""),"",IFERROR(J38/J4,"")) | ... X39: =IF(OR(X38="",X4=""),"",IFERROR(X38/X4,"")) | Y39: =IFERROR(AVERAGE(V39,W39,X39),"") | Z39: =Y39 | AA39: =Z39 | AB39: =AA39 | AC39: =AB39
A40: 특별손실 | C40: 1 | D40: 33 | E40: 4 | F40: 0 | G40: 1 | H40: 1 | I40: 5 | J40: 0 | K40: 1 | L40: 1 | M40: 3 | N40: 0 | O40: 4 | P40: 199 | Q40: 27 | R40: 346 | S40: 37 | T40: 1468 | U40: 8 | V40: 38 | W40: 7 | X40: 5 | Y40: =IF(OR(Y4="",Y41=""),"",IFERROR(Y4*Y41,"")) | Z40: =IF(OR(Z4="",Z41=""),"",IFERROR(Z4*Z41,"")) | AA40: =IF(OR(AA4="",AA41=""),"",IFERROR(AA4*AA41,"")) | AB40: =IF(OR(AB4="",AB41=""),"",IFERROR(AB4*AB41,"")) | AC40: =IF(OR(AC4="",AC41=""),"",IFERROR(AC4*AC41,""))
...

Sheet 재무상태표
A1: 2760 재무상태표
A2: 재무비율은 기말 잔액 기준 · 분기 손익은 최근 4분기 합산(TTM) | B2: (단위: 백만엔)
A3: 항목 | B3: 참고 | C3: 2026.1Q | D3: 2026.2Q | E3: 2026.3Q | F3: 2026.4Q | G3: 2027.1Q | H3: 2022 | I3: 2023 | J3: 2024 | K3: 2025 | L3: 2026
A4: 자산
A5: 유동자산 | C5: 131545 | D5: 142401 | E5: 145873 | F5: 150337 | G5: 151685 | H5: 98895 | I5: 134309 | J5: 151336 | K5: 144186 | L5: 150337
A6: 현금및현금성자산 | C6: 7013 | D6: 8695 | E6: 5641 | F6: 7622 | G6: 5445 | H6: 5134 | I6: 6538 | J6: 6867 | K6: 8384 | L6: 7622
A7: 단기금융상품
A8: 매출채권 | C8: 40798 | D8: 48567 | E8: 54075 | F8: 54434 | G8: 56164 | H8: 0 | I8: 57737 | J8: 57234 | K8: 49226 | L8: 54434
A9: 재고자산 | C9: 49386 | D9: 50332 | E9: 46061 | F9: 48965 | G9: 49758 | H9: 27507 | I9: 43082 | J9: 56436 | K9: 52867 | L9: 48965
A10: 기타유동자산 | B10: 총계 − 위 항목 | C10: =IF(OR(C5=""),"",IFERROR(C5-SUM(C6,C7,C8,C9),"")) | D10: =IF(OR(D5=""),"",IFERROR(D5-SUM(D6,D7,D8,D9),"")) | E10: =IF(OR(E5=""),"",IFERROR(E5-SUM(E6,E7,E8,E9),"")) | F10: =IF(OR(F5=""),"",IFERROR(F5-SUM(F6,F7,F8,F9),"")) | G10: =IF(OR(G5=""),"",IFERROR(G5-SUM(G6,G7,G8,G9),"")) | H10: =IF(OR(H5=""),"",IFERROR(H5-SUM(H6,H7,H8,H9),"")) | I10: =IF(OR(I5=""),"",IFERROR(I5-SUM(I6,I7,I8,I9),"")) | J10: =IF(OR(J5=""),"",IFERROR(J5-SUM(J6,J7,J8,J9),"")) | ... L10: =IF(OR(L5=""),"",IFERROR(L5-SUM(L6,L7,L8,L9),""))
A11: 비유동자산 | C11: 12575 | D11: 12524 | E11: 12457 | F11: 11874 | G11: 11908 | H11: 8906 | I11: 9143 | J11: 11231 | K11: 12655 | L11: 11874
A12: 유형자산 | C12: 4303 | D12: 4282 | E12: 4272 | F12: 3809 | G12: 3738 | H12: 3662 | I12: 3481 | J12: 3356 | K12: 4319 | L12: 3809
A13: 무형자산 | C13: 1804 | D13: 1714 | E13: 1679 | F13: 1580 | G13: 1607 | H13: 157 | I13: 226 | J13: 2192 | K13: 1912 | L13: 1580
A14: 투자부동산
A15: 기타비유동자산 | B15: 총계 − 위 항목 | C15: =IF(OR(C11=""),"",IFERROR(C11-SUM(C12,C13,C14),"")) | D15: =IF(OR(D11=""),"",IFERROR(D11-SUM(D12,D13,D14),"")) | E15: =IF(OR(E11=""),"",IFERROR(E11-SUM(E12,E13,E14),"")) | F15: =IF(OR(F11=""),"",IFERROR(F11-SUM(F12,F13,F14),"")) | G15: =IF(OR(G11=""),"",IFERROR(G11-SUM(G12,G13,G14),"")) | H15: =IF(OR(H11=""),"",IFERROR(H11-SUM(H12,H13,H14),"")) | I15: =IF(OR(I11=""),"",IFERROR(I11-SUM(I12,I13,I14),"")) | J15: =IF(OR(J11=""),"",IFERROR(J11-SUM(J12,J13,J14),"")) | ... L15: =IF(OR(L11=""),"",IFERROR(L11-SUM(L12,L13,L14),""))
A16: 자산총계 | C16: 144121 | D16: 154925 | E16: 158331 | F16: 162211 | G16: 163594 | H16: 107801 | I16: 143452 | J16: 162567 | K16: 156841 | L16: 162211
A17: 부채
A18: 유동부채 | C18: 63017 | D18: 73467 | E18: 84288 | F18: 85000 | G18: 85963 | H18: 56622 | I18: 70595 | J18: 89035 | K18: 74605 | L18: 85000
A19: 매입채무 | C19: 17935 | D19: 17787 | E19: 20915 | F19: 23650 | G19: 21769 | H19: 15434 | I19: 20214 | J19: 22690 | K19: 19407 | L19: 23650
A20: 단기차입금 | C20: 1303 | D20: 5258 | E20: 5825 | F20: 2339 | G20: 5604 | H20: 14521 | I20: 20949 | J20: 22401 | K20: 8200 | L20: 2339
A21: 유동성장기부채 | C21: 2700 | D21: 2700 | E21: 9800 | F21: 9000 | G21: 9000 | H21: 4840 | I21: 3 | J21: 7000 | K21: 2700 | L21: 9000
A22: 기타유동부채 | B22: 총계 − 위 항목 | C22: =IF(OR(C18=""),"",IFERROR(C18-SUM(C19,C20,C21),"")) | D22: =IF(OR(D18=""),"",IFERROR(D18-SUM(D19,D20,D21),"")) | E22: =IF(OR(E18=""),"",IFERROR(E18-SUM(E19,E20,E21),"")) | F22: =IF(OR(F18=""),"",IFERROR(F18-SUM(F19,F20,F21),"")) | G22: =IF(OR(G18=""),"",IFERROR(G18-SUM(G19,G20,G21),"")) | H22: =IF(OR(H18=""),"",IFERROR(H18-SUM(H19,H20,H21),"")) | I22: =IF(OR(I18=""),"",IFERROR(I18-SUM(I19,I20,I21),"")) | J22: =IF(OR(J18=""),"",IFERROR(J18-SUM(J19,J20,J21),"")) | ... L22: =IF(OR(L18=""),"",IFERROR(L18-SUM(L19,L20,L21),""))
A23: 비유동부채 | C23: 33007 | D23: 33051 | E23: 23953 | F23: 23454 | G23: 23268 | H23: 19160 | I23: 33859 | J23: 27341 | K23: 33232 | L23: 23454
A24: 장기차입금 | C24: 24495 | D24: 24347 | E24: 15200 | F24: 15094 | G24: 14926 | H24: 9963 | I24: 24700 | J24: 17700 | K24: 24660 | L24: 15094
A25: 사채
A26: 기타비유동부채 | B26: 총계 − 위 항목 | C26: =IF(OR(C23=""),"",IFERROR(C23-SUM(C24,C25),"")) | D26: =IF(OR(D23=""),"",IFERROR(D23-SUM(D24,D25),"")) | E26: =IF(OR(E23=""),"",IFERROR(E23-SUM(E24,E25),"")) | F26: =IF(OR(F23=""),"",IFERROR(F23-SUM(F24,F25),"")) | G26: =IF(OR(G23=""),"",IFERROR(G23-SUM(G24,G25),"")) | H26: =IF(OR(H23=""),"",IFERROR(H23-SUM(H24,H25),"")) | I26: =IF(OR(I23=""),"",IFERROR(I23-SUM(I24,I25),"")) | J26: =IF(OR(J23=""),"",IFERROR(J23-SUM(J24,J25),"")) | ... L26: =IF(OR(L23=""),"",IFERROR(L23-SUM(L24,L25),""))
A27: 부채총계 | C27: 96025 | D27: 106518 | E27: 108241 | F27: 108455 | G27: 109232 | H27: 75783 | I27: 104455 | J27: 116377 | K27: 107837 | L27: 108455
A28: 총차입금 | B28: 단기+유동성장기+장기+사채 | C28: =SUM(C20,C21,C24,C25) | D28: =SUM(D20,D21,D24,D25) | E28: =SUM(E20,E21,E24,E25) | F28: =SUM(F20,F21,F24,F25) | G28: =SUM(G20,G21,G24,G25) | H28: =SUM(H20,H21,H24,H25) | I28: =SUM(I20,I21,I24,I25) | J28: =SUM(J20,J21,J24,J25) | ... L28: =SUM(L20,L21,L24,L25)
A29: 순차입금 | B29: 음수 = 순현금 | C29: =C28-C6-N(C7) | D29: =D28-D6-N(D7) | E29: =E28-E6-N(E7) | F29: =F28-F6-N(F7) | G29: =G28-G6-N(G7) | H29: =H28-H6-N(H7) | I29: =I28-I6-N(I7) | J29: =J28-J6-N(J7) | ... L29: =L28-L6-N(L7)
A30: 자본
A31: 지배주주지분 | C31: 46939 | D31: 47244 | E31: 49177 | F31: 52831 | G31: 53432 | H31: 30953 | I31: 37849 | J31: 45042 | K31: 47861 | L31: 52831
A32: 자본금 | C32: 2495 | D32: 2495 | E32: 2495 | F32: 2495 | G32: 2495 | H32: 2495 | I32: 2495 | J32: 2495 | K32: 2495 | L32: 2495
A33: 이익잉여금 | C33: 40408 | D33: 41770 | E33: 43124 | F33: 45936 | G33: 46332 | H33: 24262 | I33: 30482 | J33: 36363 | K33: 41289 | L33: 45936
A34: 비지배지분 | C34: 1156 | D34: 1162 | E34: 912 | F34: 925 | G34: 929 | H34: 1065 | I34: 1148 | J34: 1148 | K34: 1143 | L34: 925
A35: 자본총계 | C35: 48095 | D35: 48406 | E35: 50089 | F35: 53756 | G35: 54361 | H35: 32018 | I35: 38997 | J35: 46190 | K35: 49004 | L35: 53756
A36: 현금흐름 요약 | B36: 분기 = TTM (있을 때만)
A37: 영업활동현금흐름 | C37: 23395 | D37: 21082 | E37: 17403 | F37: 15684 | G37: 1129 | H37: -891 | I37: -12185 | J37: 301 | K37: 18915 | L37: 15684
A38: CAPEX (유·무형 취득) | B38: 양수로 입력 | C38: 1525 | D38: 744 | E38: 379 | F38: 381 | G38: 471 | H38: 380 | I38: 270 | J38: 903 | K38: 1762 | L38: 381
A39: FCF | C39: =IF(OR(C37="",C38=""),"",IFERROR(C37-C38,"")) | D39: =IF(OR(D37="",D38=""),"",IFERROR(D37-D38,"")) | E39: =IF(OR(E37="",E38=""),"",IFERROR(E37-E38,"")) | F39: =IF(OR(F37="",F38=""),"",IFERROR(F37-F38,"")) | G39: =IF(OR(G37="",G38=""),"",IFERROR(G37-G38,"")) | H39: =IF(OR(H37="",H38=""),"",IFERROR(H37-H38,"")) | I39: =IF(OR(I37="",I38=""),"",IFERROR(I37-I38,"")) | J39: =IF(OR(J37="",J38=""),"",IFERROR(J37-J38,"")) | ... L39: =IF(OR(L37="",L38=""),"",IFERROR(L37-L38,""))
A40: 배당금 지급 | B40: 양수로 입력 | C40: 3540 | D40: 3540 | E40: 3002 | F40: 3002 | G40: 3148 | H40: 1894 | I40: 2428 | J40: 3916 | K40: 3786 | L40: 3002
...

Sheet 출처
A1: 출처 · 쓴 결산단신
A3: 공시일 | B3: 문서 | C3: PDF
A4: 2026-07-29 | B4: 2027년 3월 결산기 1분기 결산단신 | C4: https://www2.jpx.co.jp/disc/27600/140120260728501090.pdf
A5: 2026-04-27 | B5: 2026년 3월 결산기 연간 결산단신 | C5: https://www2.jpx.co.jp/disc/27600/140120260427511634.pdf
A6: 2026-02-02 | B6: 2026년 3월 결산기 3분기 결산단신 | C6: https://www2.jpx.co.jp/disc/27600/140120260202544463.pdf
A7: 2025-10-29 | B7: 2026년 3월 결산기 2분기 결산단신 | C7: https://www2.jpx.co.jp/disc/27600/140120251029581081.pdf
A8: 2025-07-29 | B8: 2026년 3월 결산기 1분기 결산단신 | C8: https://www2.jpx.co.jp/disc/27600/140120250729522201.pdf
A9: 2025-04-28 | B9: 2025년 3월 결산기 연간 결산단신 | C9: https://www2.jpx.co.jp/disc/27600/140120250428525656.pdf
A10: 2025-01-31 | B10: 2025년 3월 결산기 3분기 결산단신 | C10: https://www2.jpx.co.jp/disc/27600/140120250131559662.pdf
A11: 2024-11-01 | B11: 2025년 3월 결산기 2분기 결산단신 | C11: https://www2.jpx.co.jp/disc/27600/140120241101509315.pdf
A12: 2024-07-31 | B12: 2025년 3월 결산기 1분기 결산단신 | C12: https://www2.jpx.co.jp/disc/27600/140120240731559046.pdf
A13: 2024-04-30 | B13: 2024년 3월 결산기 연간 결산단신 | C13: https://www2.jpx.co.jp/disc/27600/140120240430579664.pdf
A14: 2024-02-02 | B14: 2024년 3월 결산기 3분기 결산단신 | C14: https://www2.jpx.co.jp/disc/27600/140120240201524684.pdf
... A24: 2018-04-24 | B24: 연간 결산단신 | C24: https://www2.jpx.co.jp/disc/27600/140120180423417807.pdf
