Workbook

Sheet 연간
A1: 필컴퍼니 Model
A2: 모를 땐 보수적으로 | B2: (단위: 백만엔) | C2: 11월 결산 · 일본 기준 · 2026.3Q = 2026년 11월 결산기 3분기 | Y2: (추정: 파란 글씨 = 직접 입력)
A3: 항목 | B3: 참고 | C3: 2023.4Q | D3: 2024.1Q | E3: 2024.2Q | F3: 2024.3Q | G3: 2024.4Q | H3: 2025.1Q | I3: 2025.2Q | J3: 2025.3Q | K3: 2025.4Q | L3: 2026.1Q | M3: 2026.2Q | N3: 2026.3Q | O3: 2016 | P3: 2017 | Q3: 2018 | R3: 2019 | S3: 2020 | T3: 2021 | U3: 2022 | V3: 2023 | W3: 2024 | X3: 2025 | Y3: 2026(MW) | Z3: 2027(MW) | AA3: 2028(MW) | AB3: 2029(MW) | AC3: 2030(MW)
A4: 매출액 | B4: MW 직접 입력 | C4: 2927.053 | D4: 606.083 | E4: 720.626 | F4: 2538.831 | G4: 3319.417 | H4: 1772.464 | I4: 2171.803 | J4: 1684.552 | K4: 2604.686 | L4: 2043.037 | M4: 1209.707 | N4: 2843.707 | O4: 1668.312 | P4: 2950.117 | Q4: 4739.078 | R4: 7024.711 | S4: 3970.76 | T4: 5432.354 | U4: 4378.593 | V4: 5963.519 | W4: 7184.957 | X4: 8233.505 | Y4: =IF(COUNT(Y7)=0,"",SUM(Y7)) | Z4: =IF(COUNT(Z7)=0,"",SUM(Z7)) | AA4: =IF(COUNT(AA7)=0,"",SUM(AA7)) | AB4: =IF(COUNT(AB7)=0,"",SUM(AB7)) | AC4: =IF(COUNT(AC7)=0,"",SUM(AC7))
A5: YoY | G5: =IF(OR(G4="",C4=""),"",IFERROR(G4/C4-1,"")) | H5: =IF(OR(H4="",D4=""),"",IFERROR(H4/D4-1,"")) | I5: =IF(OR(I4="",E4=""),"",IFERROR(I4/E4-1,"")) | J5: =IF(OR(J4="",F4=""),"",IFERROR(J4/F4-1,"")) | K5: =IF(OR(K4="",G4=""),"",IFERROR(K4/G4-1,"")) | L5: =IF(OR(L4="",H4=""),"",IFERROR(L4/H4-1,"")) | M5: =IF(OR(M4="",I4=""),"",IFERROR(M4/I4-1,"")) | N5: =IF(OR(N4="",J4=""),"",IFERROR(N4/J4-1,"")) | P5: =IF(OR(P4="",O4=""),"",IFERROR(P4/O4-1,"")) | Q5: =IF(OR(Q4="",P4=""),"",IFERROR(Q4/P4-1,"")) | R5: =IF(OR(R4="",Q4=""),"",IFERROR(R4/Q4-1,"")) | S5: =IF(OR(S4="",R4=""),"",IFERROR(S4/R4-1,"")) | T5: =IF(OR(T4="",S4=""),"",IFERROR(T4/S4-1,"")) | U5: =IF(OR(U4="",T4=""),"",IFERROR(U4/T4-1,"")) | V5: =IF(OR(V4="",U4=""),"",IFERROR(V4/U4-1,"")) | W5: =IF(OR(W4="",V4=""),"",IFERROR(W4/V4-1,"")) | ... AC5: =IF(OR(AC4="",AB4=""),"",IFERROR(AC4/AB4-1,""))
A6: 제품별 매출 분류 | B6: 사업보고서 매출실적
A7: (제품별 매출 미공시 — 직접 입력)
A8: 비중 | C8: =IF(OR(C7="",C4=""),"",IFERROR(C7/C4,"")) | D8: =IF(OR(D7="",D4=""),"",IFERROR(D7/D4,"")) | E8: =IF(OR(E7="",E4=""),"",IFERROR(E7/E4,"")) | F8: =IF(OR(F7="",F4=""),"",IFERROR(F7/F4,"")) | G8: =IF(OR(G7="",G4=""),"",IFERROR(G7/G4,"")) | H8: =IF(OR(H7="",H4=""),"",IFERROR(H7/H4,"")) | I8: =IF(OR(I7="",I4=""),"",IFERROR(I7/I4,"")) | J8: =IF(OR(J7="",J4=""),"",IFERROR(J7/J4,"")) | ... AC8: =IF(OR(AC7="",AC4=""),"",IFERROR(AC7/AC4,""))
A9: YoY | G9: =IF(OR(G7="",C7=""),"",IFERROR(G7/C7-1,"")) | H9: =IF(OR(H7="",D7=""),"",IFERROR(H7/D7-1,"")) | I9: =IF(OR(I7="",E7=""),"",IFERROR(I7/E7-1,"")) | J9: =IF(OR(J7="",F7=""),"",IFERROR(J7/F7-1,"")) | K9: =IF(OR(K7="",G7=""),"",IFERROR(K7/G7-1,"")) | L9: =IF(OR(L7="",H7=""),"",IFERROR(L7/H7-1,"")) | M9: =IF(OR(M7="",I7=""),"",IFERROR(M7/I7-1,"")) | N9: =IF(OR(N7="",J7=""),"",IFERROR(N7/J7-1,"")) | P9: =IF(OR(P7="",O7=""),"",IFERROR(P7/O7-1,"")) | Q9: =IF(OR(Q7="",P7=""),"",IFERROR(Q7/P7-1,"")) | R9: =IF(OR(R7="",Q7=""),"",IFERROR(R7/Q7-1,"")) | S9: =IF(OR(S7="",R7=""),"",IFERROR(S7/R7-1,"")) | T9: =IF(OR(T7="",S7=""),"",IFERROR(T7/S7-1,"")) | U9: =IF(OR(U7="",T7=""),"",IFERROR(U7/T7-1,"")) | V9: =IF(OR(V7="",U7=""),"",IFERROR(V7/U7-1,"")) | W9: =IF(OR(W7="",V7=""),"",IFERROR(W7/V7-1,"")) | ... AC9: =IF(OR(AC7="",AB7=""),"",IFERROR(AC7/AB7-1,""))
A10: 매출원가
A11: 전체 매출원가 | C11: 2204.773 | D11: 398.395 | E11: 503.784 | F11: 1834.995 | G11: 2637.378 | H11: 1283.981 | I11: 1716.724 | J11: 1216.941 | K11: 1791.833 | L11: 1591.071 | M11: 924.291 | N11: 2015.685 | O11: 1215.858 | P11: 2303.501 | Q11: 3521.5 | R11: 5137.812 | S11: 3101.083 | T11: 3726.568 | U11: 3350.502 | V11: 4526.857 | W11: 5374.552 | X11: 6009.479
A12: YoY | G12: =IF(OR(G11="",C11=""),"",IF(C11<=0,"",IFERROR(G11/C11-1,""))) | H12: =IF(OR(H11="",D11=""),"",IF(D11<=0,"",IFERROR(H11/D11-1,""))) | I12: =IF(OR(I11="",E11=""),"",IF(E11<=0,"",IFERROR(I11/E11-1,""))) | J12: =IF(OR(J11="",F11=""),"",IF(F11<=0,"",IFERROR(J11/F11-1,""))) | K12: =IF(OR(K11="",G11=""),"",IF(G11<=0,"",IFERROR(K11/G11-1,""))) | L12: =IF(OR(L11="",H11=""),"",IF(H11<=0,"",IFERROR(L11/H11-1,""))) | M12: =IF(OR(M11="",I11=""),"",IF(I11<=0,"",IFERROR(M11/I11-1,""))) | N12: =IF(OR(N11="",J11=""),"",IF(J11<=0,"",IFERROR(N11/J11-1,""))) | P12: =IF(OR(P11="",O11=""),"",IF(O11<=0,"",IFERROR(P11/O11-1,""))) | Q12: =IF(OR(Q11="",P11=""),"",IF(P11<=0,"",IFERROR(Q11/P11-1,""))) | R12: =IF(OR(R11="",Q11=""),"",IF(Q11<=0,"",IFERROR(R11/Q11-1,""))) | S12: =IF(OR(S11="",R11=""),"",IF(R11<=0,"",IFERROR(S11/R11-1,""))) | T12: =IF(OR(T11="",S11=""),"",IF(S11<=0,"",IFERROR(T11/S11-1,""))) | U12: =IF(OR(U11="",T11=""),"",IF(T11<=0,"",IFERROR(U11/T11-1,""))) | V12: =IF(OR(V11="",U11=""),"",IF(U11<=0,"",IFERROR(V11/U11-1,""))) | W12: =IF(OR(W11="",V11=""),"",IF(V11<=0,"",IFERROR(W11/V11-1,""))) | ... AC12: =IF(OR(AC11="",AB11=""),"",IF(AB11<=0,"",IFERROR(AC11/AB11-1,"")))
A13: 매출총이익 | C13: =IF(OR(C4="",C11=""),"",IFERROR(C4-C11,"")) | D13: =IF(OR(D4="",D11=""),"",IFERROR(D4-D11,"")) | E13: =IF(OR(E4="",E11=""),"",IFERROR(E4-E11,"")) | F13: =IF(OR(F4="",F11=""),"",IFERROR(F4-F11,"")) | G13: =IF(OR(G4="",G11=""),"",IFERROR(G4-G11,"")) | H13: =IF(OR(H4="",H11=""),"",IFERROR(H4-H11,"")) | I13: =IF(OR(I4="",I11=""),"",IFERROR(I4-I11,"")) | J13: =IF(OR(J4="",J11=""),"",IFERROR(J4-J11,"")) | ... X13: =IF(OR(X4="",X11=""),"",IFERROR(X4-X11,""))
A14: GPM | C14: =IF(OR(C13="",C4=""),"",IFERROR(C13/C4,"")) | D14: =IF(OR(D13="",D4=""),"",IFERROR(D13/D4,"")) | E14: =IF(OR(E13="",E4=""),"",IFERROR(E13/E4,"")) | F14: =IF(OR(F13="",F4=""),"",IFERROR(F13/F4,"")) | G14: =IF(OR(G13="",G4=""),"",IFERROR(G13/G4,"")) | H14: =IF(OR(H13="",H4=""),"",IFERROR(H13/H4,"")) | I14: =IF(OR(I13="",I4=""),"",IFERROR(I13/I4,"")) | J14: =IF(OR(J13="",J4=""),"",IFERROR(J13/J4,"")) | ... AC14: =IF(OR(AC13="",AC4=""),"",IFERROR(AC13/AC4,""))
A15: YoY | G15: =IF(OR(G13="",C13=""),"",IF(C13<=0,"",IFERROR(G13/C13-1,""))) | H15: =IF(OR(H13="",D13=""),"",IF(D13<=0,"",IFERROR(H13/D13-1,""))) | I15: =IF(OR(I13="",E13=""),"",IF(E13<=0,"",IFERROR(I13/E13-1,""))) | J15: =IF(OR(J13="",F13=""),"",IF(F13<=0,"",IFERROR(J13/F13-1,""))) | K15: =IF(OR(K13="",G13=""),"",IF(G13<=0,"",IFERROR(K13/G13-1,""))) | L15: =IF(OR(L13="",H13=""),"",IF(H13<=0,"",IFERROR(L13/H13-1,""))) | M15: =IF(OR(M13="",I13=""),"",IF(I13<=0,"",IFERROR(M13/I13-1,""))) | N15: =IF(OR(N13="",J13=""),"",IF(J13<=0,"",IFERROR(N13/J13-1,""))) | P15: =IF(OR(P13="",O13=""),"",IF(O13<=0,"",IFERROR(P13/O13-1,""))) | Q15: =IF(OR(Q13="",P13=""),"",IF(P13<=0,"",IFERROR(Q13/P13-1,""))) | R15: =IF(OR(R13="",Q13=""),"",IF(Q13<=0,"",IFERROR(R13/Q13-1,""))) | S15: =IF(OR(S13="",R13=""),"",IF(R13<=0,"",IFERROR(S13/R13-1,""))) | T15: =IF(OR(T13="",S13=""),"",IF(S13<=0,"",IFERROR(T13/S13-1,""))) | U15: =IF(OR(U13="",T13=""),"",IF(T13<=0,"",IFERROR(U13/T13-1,""))) | V15: =IF(OR(V13="",U13=""),"",IF(U13<=0,"",IFERROR(V13/U13-1,""))) | W15: =IF(OR(W13="",V13=""),"",IF(V13<=0,"",IFERROR(W13/V13-1,""))) | ... AC15: =IF(OR(AC13="",AB13=""),"",IF(AB13<=0,"",IFERROR(AC13/AB13-1,"")))
A16: 판매관리비
A17: 전체 판관비 | C17: 355.604 | D17: 296.342 | E17: 312.202 | F17: 365.879 | G17: 411.891 | H17: 360.576 | I17: 383.18 | J17: 406.022 | K17: 485.543 | L17: 427.669 | M17: 430.506 | N17: 436.903 | O17: 246.009 | P17: 350.217 | Q17: 580.449 | R17: 790.553 | S17: 739.42 | T17: 980.873 | U17: 858.25 | V17: 1221.847 | W17: 1386.314 | X17: 1635.321
A18: YoY | G18: =IF(OR(G17="",C17=""),"",IF(C17<=0,"",IFERROR(G17/C17-1,""))) | H18: =IF(OR(H17="",D17=""),"",IF(D17<=0,"",IFERROR(H17/D17-1,""))) | I18: =IF(OR(I17="",E17=""),"",IF(E17<=0,"",IFERROR(I17/E17-1,""))) | J18: =IF(OR(J17="",F17=""),"",IF(F17<=0,"",IFERROR(J17/F17-1,""))) | K18: =IF(OR(K17="",G17=""),"",IF(G17<=0,"",IFERROR(K17/G17-1,""))) | L18: =IF(OR(L17="",H17=""),"",IF(H17<=0,"",IFERROR(L17/H17-1,""))) | M18: =IF(OR(M17="",I17=""),"",IF(I17<=0,"",IFERROR(M17/I17-1,""))) | N18: =IF(OR(N17="",J17=""),"",IF(J17<=0,"",IFERROR(N17/J17-1,""))) | P18: =IF(OR(P17="",O17=""),"",IF(O17<=0,"",IFERROR(P17/O17-1,""))) | Q18: =IF(OR(Q17="",P17=""),"",IF(P17<=0,"",IFERROR(Q17/P17-1,""))) | R18: =IF(OR(R17="",Q17=""),"",IF(Q17<=0,"",IFERROR(R17/Q17-1,""))) | S18: =IF(OR(S17="",R17=""),"",IF(R17<=0,"",IFERROR(S17/R17-1,""))) | T18: =IF(OR(T17="",S17=""),"",IF(S17<=0,"",IFERROR(T17/S17-1,""))) | U18: =IF(OR(U17="",T17=""),"",IF(T17<=0,"",IFERROR(U17/T17-1,""))) | V18: =IF(OR(V17="",U17=""),"",IF(U17<=0,"",IFERROR(V17/U17-1,""))) | W18: =IF(OR(W17="",V17=""),"",IF(V17<=0,"",IFERROR(W17/V17-1,""))) | ... AC18: =IF(OR(AC17="",AB17=""),"",IF(AB17<=0,"",IFERROR(AC17/AB17-1,"")))
A19: 영업이익 | B19: MW = 매출 × OPM | C19: 366.675 | D19: -88.654 | E19: -95.36 | F19: 337.956 | G19: 270.149 | H19: 127.906 | I19: 71.898 | J19: 61.59 | K19: 327.311 | L19: 24.296 | M19: -145.088 | N19: 391.116 | O19: 206.443 | P19: 296.398 | Q19: 637.128 | R19: 1096.344 | S19: 130.256 | T19: 724.912 | U19: 169.84 | V19: 214.815 | W19: 424.091 | X19: 588.705 | Y19: =IF(OR(Y4="",Y20=""),"",IFERROR(Y4*Y20,"")) | Z19: =IF(OR(Z4="",Z20=""),"",IFERROR(Z4*Z20,"")) | AA19: =IF(OR(AA4="",AA20=""),"",IFERROR(AA4*AA20,"")) | AB19: =IF(OR(AB4="",AB20=""),"",IFERROR(AB4*AB20,"")) | AC19: =IF(OR(AC4="",AC20=""),"",IFERROR(AC4*AC20,""))
A20: OPM | B20: MW 입력 | C20: =IF(OR(C19="",C4=""),"",IFERROR(C19/C4,"")) | D20: =IF(OR(D19="",D4=""),"",IFERROR(D19/D4,"")) | E20: =IF(OR(E19="",E4=""),"",IFERROR(E19/E4,"")) | F20: =IF(OR(F19="",F4=""),"",IFERROR(F19/F4,"")) | G20: =IF(OR(G19="",G4=""),"",IFERROR(G19/G4,"")) | H20: =IF(OR(H19="",H4=""),"",IFERROR(H19/H4,"")) | I20: =IF(OR(I19="",I4=""),"",IFERROR(I19/I4,"")) | J20: =IF(OR(J19="",J4=""),"",IFERROR(J19/J4,"")) | ... X20: =IF(OR(X19="",X4=""),"",IFERROR(X19/X4,""))
A21: 증가율 | G21: =IF(OR(G19="",C19=""),"",IFERROR(G19/C19-1,"")) | H21: =IF(OR(H19="",D19=""),"",IFERROR(H19/D19-1,"")) | I21: =IF(OR(I19="",E19=""),"",IFERROR(I19/E19-1,"")) | J21: =IF(OR(J19="",F19=""),"",IFERROR(J19/F19-1,"")) | K21: =IF(OR(K19="",G19=""),"",IFERROR(K19/G19-1,"")) | L21: =IF(OR(L19="",H19=""),"",IFERROR(L19/H19-1,"")) | M21: =IF(OR(M19="",I19=""),"",IFERROR(M19/I19-1,"")) | N21: =IF(OR(N19="",J19=""),"",IFERROR(N19/J19-1,"")) | P21: =IF(OR(P19="",O19=""),"",IFERROR(P19/O19-1,"")) | Q21: =IF(OR(Q19="",P19=""),"",IFERROR(Q19/P19-1,"")) | R21: =IF(OR(R19="",Q19=""),"",IFERROR(R19/Q19-1,"")) | S21: =IF(OR(S19="",R19=""),"",IFERROR(S19/R19-1,"")) | T21: =IF(OR(T19="",S19=""),"",IFERROR(T19/S19-1,"")) | U21: =IF(OR(U19="",T19=""),"",IFERROR(U19/T19-1,"")) | V21: =IF(OR(V19="",U19=""),"",IFERROR(V19/U19-1,"")) | W21: =IF(OR(W19="",V19=""),"",IFERROR(W19/V19-1,"")) | ... AC21: =IF(OR(AC19="",AB19=""),"",IFERROR(AC19/AB19-1,""))
A22: 비용의 성격별 분류 | B22: 참고 데이터
A23: 총 판관비 | O23: =IF(O17="","",O17) | P23: =IF(P17="","",P17) | Q23: =IF(Q17="","",Q17) | R23: =IF(R17="","",R17) | S23: =IF(S17="","",S17) | T23: =IF(T17="","",T17) | U23: =IF(U17="","",U17) | V23: =IF(V17="","",V17) | ... X23: =IF(X17="","",X17)
A24: 급여 | B24: 고정비 | O24: 58.048 | P24: 95.965 | Q24: 135.916
A25: % of Sales | O25: =IF(OR(O24="",O4=""),"",IFERROR(O24/O4,"")) | P25: =IF(OR(P24="",P4=""),"",IFERROR(P24/P4,"")) | Q25: =IF(OR(Q24="",Q4=""),"",IFERROR(Q24/Q4,"")) | R25: =IF(OR(R24="",R4=""),"",IFERROR(R24/R4,"")) | S25: =IF(OR(S24="",S4=""),"",IFERROR(S24/S4,"")) | T25: =IF(OR(T24="",T4=""),"",IFERROR(T24/T4,"")) | U25: =IF(OR(U24="",U4=""),"",IFERROR(U24/U4,"")) | V25: =IF(OR(V24="",V4=""),"",IFERROR(V24/V4,"")) | ... X25: =IF(OR(X24="",X4=""),"",IFERROR(X24/X4,""))
A26: 감가상각비 | B26: 고정비
A27: % of Sales | O27: =IF(OR(O26="",O4=""),"",IFERROR(O26/O4,"")) | P27: =IF(OR(P26="",P4=""),"",IFERROR(P26/P4,"")) | Q27: =IF(OR(Q26="",Q4=""),"",IFERROR(Q26/Q4,"")) | R27: =IF(OR(R26="",R4=""),"",IFERROR(R26/R4,"")) | S27: =IF(OR(S26="",S4=""),"",IFERROR(S26/S4,"")) | T27: =IF(OR(T26="",T4=""),"",IFERROR(T26/T4,"")) | U27: =IF(OR(U26="",U4=""),"",IFERROR(U26/U4,"")) | V27: =IF(OR(V26="",V4=""),"",IFERROR(V26/V4,"")) | ... X27: =IF(OR(X26="",X4=""),"",IFERROR(X26/X4,""))
A28: 지급수수료 | B28: 고정비
A29: % of Sales | O29: =IF(OR(O28="",O4=""),"",IFERROR(O28/O4,"")) | P29: =IF(OR(P28="",P4=""),"",IFERROR(P28/P4,"")) | Q29: =IF(OR(Q28="",Q4=""),"",IFERROR(Q28/Q4,"")) | R29: =IF(OR(R28="",R4=""),"",IFERROR(R28/R4,"")) | S29: =IF(OR(S28="",S4=""),"",IFERROR(S28/S4,"")) | T29: =IF(OR(T28="",T4=""),"",IFERROR(T28/T4,"")) | U29: =IF(OR(U28="",U4=""),"",IFERROR(U28/U4,"")) | V29: =IF(OR(V28="",V4=""),"",IFERROR(V28/V4,"")) | ... X29: =IF(OR(X28="",X4=""),"",IFERROR(X28/X4,""))
A30: 연구개발비 | B30: 변동비
A31: % of Sales | O31: =IF(OR(O30="",O4=""),"",IFERROR(O30/O4,"")) | P31: =IF(OR(P30="",P4=""),"",IFERROR(P30/P4,"")) | Q31: =IF(OR(Q30="",Q4=""),"",IFERROR(Q30/Q4,"")) | R31: =IF(OR(R30="",R4=""),"",IFERROR(R30/R4,"")) | S31: =IF(OR(S30="",S4=""),"",IFERROR(S30/S4,"")) | T31: =IF(OR(T30="",T4=""),"",IFERROR(T30/T4,"")) | U31: =IF(OR(U30="",U4=""),"",IFERROR(U30/U4,"")) | V31: =IF(OR(V30="",V4=""),"",IFERROR(V30/V4,"")) | ... X31: =IF(OR(X30="",X4=""),"",IFERROR(X30/X4,""))
A32: 기타비용 | B32: 변동비 | O32: =IF(OR(O23="",O24="",O26="",O28="",O30=""),"",IFERROR(O23-O24-O26-O28-O30,"")) | P32: =IF(OR(P23="",P24="",P26="",P28="",P30=""),"",IFERROR(P23-P24-P26-P28-P30,"")) | Q32: =IF(OR(Q23="",Q24="",Q26="",Q28="",Q30=""),"",IFERROR(Q23-Q24-Q26-Q28-Q30,"")) | R32: =IF(OR(R23="",R24="",R26="",R28="",R30=""),"",IFERROR(R23-R24-R26-R28-R30,"")) | S32: =IF(OR(S23="",S24="",S26="",S28="",S30=""),"",IFERROR(S23-S24-S26-S28-S30,"")) | T32: =IF(OR(T23="",T24="",T26="",T28="",T30=""),"",IFERROR(T23-T24-T26-T28-T30,"")) | U32: =IF(OR(U23="",U24="",U26="",U28="",U30=""),"",IFERROR(U23-U24-U26-U28-U30,"")) | V32: =IF(OR(V23="",V24="",V26="",V28="",V30=""),"",IFERROR(V23-V24-V26-V28-V30,"")) | ... X32: =IF(OR(X23="",X24="",X26="",X28="",X30=""),"",IFERROR(X23-X24-X26-X28-X30,""))
A33: % of Sales | O33: =IF(OR(O32="",O4=""),"",IFERROR(O32/O4,"")) | P33: =IF(OR(P32="",P4=""),"",IFERROR(P32/P4,"")) | Q33: =IF(OR(Q32="",Q4=""),"",IFERROR(Q32/Q4,"")) | R33: =IF(OR(R32="",R4=""),"",IFERROR(R32/R4,"")) | S33: =IF(OR(S32="",S4=""),"",IFERROR(S32/S4,"")) | T33: =IF(OR(T32="",T4=""),"",IFERROR(T32/T4,"")) | U33: =IF(OR(U32="",U4=""),"",IFERROR(U32/U4,"")) | V33: =IF(OR(V32="",V4=""),"",IFERROR(V32/V4,"")) | ... X33: =IF(OR(X32="",X4=""),"",IFERROR(X32/X4,""))
A34: 당기순이익 추정
A35: 특별이익 | C35: 0 | J35: 0 | N35: 0 | R35: 0 | S35: 0.15 | T35: 0 | U35: 21.525 | V35: 0 | Y35: =IF(OR(Y4="",Y36=""),"",IFERROR(Y4*Y36,"")) | Z35: =IF(OR(Z4="",Z36=""),"",IFERROR(Z4*Z36,"")) | AA35: =IF(OR(AA4="",AA36=""),"",IFERROR(AA4*AA36,"")) | AB35: =IF(OR(AB4="",AB36=""),"",IFERROR(AB4*AB36,"")) | AC35: =IF(OR(AC4="",AC36=""),"",IFERROR(AC4*AC36,""))
A36: % of Sales | B36: MW = 최근 3년 평균 | C36: =IF(OR(C35="",C4=""),"",IFERROR(C35/C4,"")) | D36: =IF(OR(D35="",D4=""),"",IFERROR(D35/D4,"")) | E36: =IF(OR(E35="",E4=""),"",IFERROR(E35/E4,"")) | F36: =IF(OR(F35="",F4=""),"",IFERROR(F35/F4,"")) | G36: =IF(OR(G35="",G4=""),"",IFERROR(G35/G4,"")) | H36: =IF(OR(H35="",H4=""),"",IFERROR(H35/H4,"")) | I36: =IF(OR(I35="",I4=""),"",IFERROR(I35/I4,"")) | J36: =IF(OR(J35="",J4=""),"",IFERROR(J35/J4,"")) | ... X36: =IF(OR(X35="",X4=""),"",IFERROR(X35/X4,"")) | Y36: =IFERROR(AVERAGE(V36,W36,X36),"") | Z36: =Y36 | AA36: =Z36 | AB36: =AA36 | AC36: =AB36
A37: 특별손실 | J37: 0 | K37: 0 | N37: 0 | Q37: 0 | R37: 100.991 | S37: 33.328 | T37: 73.933 | U37: 0 | V37: 0 | W37: 2.516 | X37: 0 | Y37: =IF(OR(Y4="",Y38=""),"",IFERROR(Y4*Y38,"")) | Z37: =IF(OR(Z4="",Z38=""),"",IFERROR(Z4*Z38,"")) | AA37: =IF(OR(AA4="",AA38=""),"",IFERROR(AA4*AA38,"")) | AB37: =IF(OR(AB4="",AB38=""),"",IFERROR(AB4*AB38,"")) | AC37: =IF(OR(AC4="",AC38=""),"",IFERROR(AC4*AC38,""))
A38: % of Sales | C38: =IF(OR(C37="",C4=""),"",IFERROR(C37/C4,"")) | D38: =IF(OR(D37="",D4=""),"",IFERROR(D37/D4,"")) | E38: =IF(OR(E37="",E4=""),"",IFERROR(E37/E4,"")) | F38: =IF(OR(F37="",F4=""),"",IFERROR(F37/F4,"")) | G38: =IF(OR(G37="",G4=""),"",IFERROR(G37/G4,"")) | H38: =IF(OR(H37="",H4=""),"",IFERROR(H37/H4,"")) | I38: =IF(OR(I37="",I4=""),"",IFERROR(I37/I4,"")) | J38: =IF(OR(J37="",J4=""),"",IFERROR(J37/J4,"")) | ... X38: =IF(OR(X37="",X4=""),"",IFERROR(X37/X4,"")) | Y38: =IFERROR(AVERAGE(V38,W38,X38),"") | Z38: =Y38 | AA38: =Z38 | AB38: =AA38 | AC38: =AB38
A39: 영업외수익 | C39: 0.198 | D39: 0.396 | E39: 2.478 | F39: 26.597 | G39: 2.974 | H39: 6.177 | I39: 10.584 | J39: 0.82 | K39: 2.874 | L39: 14.838 | M39: 7.619 | N39: 7.664 | O39: 27.905 | P39: 16.2 | Q39: 1.15 | R39: 3.391 | S39: 2.374 | T39: 3.409 | U39: 52.092 | V39: 3.808 | W39: 32.445 | X39: 20.455 | Y39: =IF(OR(Y4="",Y40=""),"",IFERROR(Y4*Y40,"")) | Z39: =IF(OR(Z4="",Z40=""),"",IFERROR(Z4*Z40,"")) | AA39: =IF(OR(AA4="",AA40=""),"",IFERROR(AA4*AA40,"")) | AB39: =IF(OR(AB4="",AB40=""),"",IFERROR(AB4*AB40,"")) | AC39: =IF(OR(AC4="",AC40=""),"",IFERROR(AC4*AC40,""))
A40: % of Sales | C40: =IF(OR(C39="",C4=""),"",IFERROR(C39/C4,"")) | D40: =IF(OR(D39="",D4=""),"",IFERROR(D39/D4,"")) | E40: =IF(OR(E39="",E4=""),"",IFERROR(E39/E4,"")) | F40: =IF(OR(F39="",F4=""),"",IFERROR(F39/F4,"")) | G40: =IF(OR(G39="",G4=""),"",IFERROR(G39/G4,"")) | H40: =IF(OR(H39="",H4=""),"",IFERROR(H39/H4,"")) | I40: =IF(OR(I39="",I4=""),"",IFERROR(I39/I4,"")) | J40: =IF(OR(J39="",J4=""),"",IFERROR(J39/J4,"")) | ... X40: =IF(OR(X39="",X4=""),"",IFERROR(X39/X4,"")) | Y40: =IFERROR(AVERAGE(V40,W40,X40),"") | Z40: =Y40 | AA40: =Z40 | AB40: =AA40 | AC40: =AB40
...

Sheet 재무상태표
A1: 필컴퍼니 재무상태표
A2: 재무비율은 기말 잔액 기준 · 분기 손익은 최근 4분기 합산(TTM) | B2: (단위: 백만엔)
A3: 항목 | B3: 참고 | C3: 2025.3Q | D3: 2025.4Q | E3: 2026.1Q | F3: 2026.2Q | G3: 2026.3Q | H3: 2021 | I3: 2022 | J3: 2023 | K3: 2024 | L3: 2025
A4: 자산
A5: 유동자산 | C5: 7352.005 | D5: 8728.144 | E5: 7499.756 | F5: 7990.829 | G5: 7798.13 | H5: 4575.914 | I5: 3886.695 | J5: 4433.676 | K5: 6616.406 | L5: 8728.144
A6: 현금및현금성자산 | C6: 3970.53 | D6: 5044.657 | E6: 3529.309 | F6: 2989.969 | G6: 3393.185 | H6: 4193.33 | I6: 2250.657 | J6: 2456.383 | K6: 4822.267 | L6: 5044.657
A7: 단기금융상품 | C7: 398.97 | D7: 399.276 | E7: 500.293 | F7: 400.206 | G7: 500.008 | K7: 0 | L7: 399.276
A8: 매출채권 | C8: 283.911 | D8: 132.036 | E8: 146.647 | F8: 243.89 | G8: 115.483 | H8: 5.127 | I8: 43.826 | J8: 65.461 | K8: 211.149 | L8: 132.036
A9: 재고자산 | C9: 71.357 | D9: 802.073 | E9: 414.21 | F9: 482.064 | G9: 1265.245 | H9: 168.903 | I9: 616.347 | J9: 836.026 | K9: 246.578 | L9: 802.073
A10: 기타유동자산 | B10: 총계 − 위 항목 | C10: =IF(OR(C5=""),"",IFERROR(C5-SUM(C6,C7,C8,C9),"")) | D10: =IF(OR(D5=""),"",IFERROR(D5-SUM(D6,D7,D8,D9),"")) | E10: =IF(OR(E5=""),"",IFERROR(E5-SUM(E6,E7,E8,E9),"")) | F10: =IF(OR(F5=""),"",IFERROR(F5-SUM(F6,F7,F8,F9),"")) | G10: =IF(OR(G5=""),"",IFERROR(G5-SUM(G6,G7,G8,G9),"")) | H10: =IF(OR(H5=""),"",IFERROR(H5-SUM(H6,H7,H8,H9),"")) | I10: =IF(OR(I5=""),"",IFERROR(I5-SUM(I6,I7,I8,I9),"")) | J10: =IF(OR(J5=""),"",IFERROR(J5-SUM(J6,J7,J8,J9),"")) | ... L10: =IF(OR(L5=""),"",IFERROR(L5-SUM(L6,L7,L8,L9),""))
A11: 비유동자산 | C11: 1108.247 | D11: 1211.99 | E11: 1196.803 | F11: 1110.499 | G11: 959.13 | H11: 874.397 | I11: 863.352 | J11: 1017.098 | K11: 879.933 | L11: 1211.99
A12: 유형자산 | C12: 477.24 | D12: 477.785 | E12: 471.492 | F12: 468.801 | G12: 581.622 | H12: 329.756 | I12: 301.477 | J12: 504.647 | K12: 482.18 | L12: 477.785
A13: 무형자산 | C13: 81.589 | D13: 73.17 | E13: 65.707 | F13: 57.248 | G13: 48.788 | H13: 168.771 | I13: 144.384 | J13: 141.881 | K13: 106.847 | L13: 73.17
A14: 투자부동산
A15: 기타비유동자산 | B15: 총계 − 위 항목 | C15: =IF(OR(C11=""),"",IFERROR(C11-SUM(C12,C13,C14),"")) | D15: =IF(OR(D11=""),"",IFERROR(D11-SUM(D12,D13,D14),"")) | E15: =IF(OR(E11=""),"",IFERROR(E11-SUM(E12,E13,E14),"")) | F15: =IF(OR(F11=""),"",IFERROR(F11-SUM(F12,F13,F14),"")) | G15: =IF(OR(G11=""),"",IFERROR(G11-SUM(G12,G13,G14),"")) | H15: =IF(OR(H11=""),"",IFERROR(H11-SUM(H12,H13,H14),"")) | I15: =IF(OR(I11=""),"",IFERROR(I11-SUM(I12,I13,I14),"")) | J15: =IF(OR(J11=""),"",IFERROR(J11-SUM(J12,J13,J14),"")) | ... L15: =IF(OR(L11=""),"",IFERROR(L11-SUM(L12,L13,L14),""))
A16: 자산총계 | C16: 8460.252 | D16: 9940.134 | E16: 8696.56 | F16: 9101.328 | G16: 8757.26 | H16: 5450.312 | I16: 4750.048 | J16: 5450.775 | K16: 7496.339 | L16: 9940.134
A17: 부채
A18: 유동부채 | C18: 4408.618 | D18: 4794.001 | E18: 3318.047 | F18: 3922.868 | G18: 3710.393 | H18: 2128.446 | I18: 1528.719 | J18: 1621.062 | K18: 3267.672 | L18: 4794.001
A19: 매입채무 | C19: 587.268 | D19: 733.454 | E19: 479.54 | F19: 429.078 | G19: 526.376 | H19: 168.205 | I19: 458.167 | J19: 389.72 | K19: 870.523 | L19: 733.454
A20: 단기차입금 | C20: 934.858 | D20: 920 | E20: 810 | F20: 810 | G20: 474.25 | H20: 0 | I20: 0 | J20: 437.5 | K20: 424.08 | L20: 920
A21: 유동성장기부채 | C21: 867.533 | D21: 696.081 | E21: 436.081 | F21: 1384.081 | G21: 1055.063 | H21: 37.28 | I21: 70.236 | J21: 83.092 | K21: 230.984 | L21: 696.081
A22: 기타유동부채 | B22: 총계 − 위 항목 | C22: =IF(OR(C18=""),"",IFERROR(C18-SUM(C19,C20,C21),"")) | D22: =IF(OR(D18=""),"",IFERROR(D18-SUM(D19,D20,D21),"")) | E22: =IF(OR(E18=""),"",IFERROR(E18-SUM(E19,E20,E21),"")) | F22: =IF(OR(F18=""),"",IFERROR(F18-SUM(F19,F20,F21),"")) | G22: =IF(OR(G18=""),"",IFERROR(G18-SUM(G19,G20,G21),"")) | H22: =IF(OR(H18=""),"",IFERROR(H18-SUM(H19,H20,H21),"")) | I22: =IF(OR(I18=""),"",IFERROR(I18-SUM(I19,I20,I21),"")) | J22: =IF(OR(J18=""),"",IFERROR(J18-SUM(J19,J20,J21),"")) | ... L22: =IF(OR(L18=""),"",IFERROR(L18-SUM(L19,L20,L21),""))
A23: 비유동부채 | C23: 954.548 | D23: 1801.621 | E23: 2124.642 | F23: 1862.854 | G23: 1481.482 | H23: 547.75 | I23: 777.593 | J23: 1099.247 | K23: 1247.623 | L23: 1801.621
A24: 장기차입금 | C24: 529.563 | D24: 1342.968 | E24: 1663.702 | F24: 1505.436 | G24: 1114.5 | H24: 202.792 | I24: 439.22 | J24: 683.986 | K24: 826.13 | L24: 1342.968
A25: 사채
A26: 기타비유동부채 | B26: 총계 − 위 항목 | C26: =IF(OR(C23=""),"",IFERROR(C23-SUM(C24,C25),"")) | D26: =IF(OR(D23=""),"",IFERROR(D23-SUM(D24,D25),"")) | E26: =IF(OR(E23=""),"",IFERROR(E23-SUM(E24,E25),"")) | F26: =IF(OR(F23=""),"",IFERROR(F23-SUM(F24,F25),"")) | G26: =IF(OR(G23=""),"",IFERROR(G23-SUM(G24,G25),"")) | H26: =IF(OR(H23=""),"",IFERROR(H23-SUM(H24,H25),"")) | I26: =IF(OR(I23=""),"",IFERROR(I23-SUM(I24,I25),"")) | J26: =IF(OR(J23=""),"",IFERROR(J23-SUM(J24,J25),"")) | ... L26: =IF(OR(L23=""),"",IFERROR(L23-SUM(L24,L25),""))
A27: 부채총계 | C27: 5363.166 | D27: 6595.622 | E27: 5442.689 | F27: 5785.722 | G27: 5191.876 | H27: 2676.197 | I27: 2306.313 | J27: 2720.309 | K27: 4515.296 | L27: 6595.622
A28: 총차입금 | B28: 단기+유동성장기+장기+사채 | C28: =SUM(C20,C21,C24,C25) | D28: =SUM(D20,D21,D24,D25) | E28: =SUM(E20,E21,E24,E25) | F28: =SUM(F20,F21,F24,F25) | G28: =SUM(G20,G21,G24,G25) | H28: =SUM(H20,H21,H24,H25) | I28: =SUM(I20,I21,I24,I25) | J28: =SUM(J20,J21,J24,J25) | ... L28: =SUM(L20,L21,L24,L25)
A29: 순차입금 | B29: 음수 = 순현금 | C29: =C28-C6-N(C7) | D29: =D28-D6-N(D7) | E29: =E28-E6-N(E7) | F29: =F28-F6-N(F7) | G29: =G28-G6-N(G7) | H29: =H28-H6-N(H7) | I29: =I28-I6-N(I7) | J29: =J28-J6-N(J7) | ... L29: =L28-L6-N(L7)
A30: 자본
A31: 지배주주지분 | C31: 3062.181 | D31: 3305.325 | E31: 3208.575 | F31: 3264.202 | G31: 3511.362 | H31: 2770.989 | I31: 2438.869 | J31: 2726.491 | K31: 2961.303 | L31: 3305.325
A32: 자본금 | C32: 789.647 | D32: 789.647 | E32: 789.647 | F32: 789.647 | G32: 789.647 | H32: 789.647 | I32: 789.647 | J32: 789.647 | K32: 789.647 | L32: 789.647
A33: 이익잉여금 | C33: 2183.866 | D33: 2427.011 | E33: 2330.262 | F33: 2299.353 | G33: 2546.513 | H33: 1801.442 | I33: 1936.076 | J33: 1848.148 | K33: 2082.987 | L33: 2427.011
A34: 비지배지분 | H34: 0.977 | I34: 0.892 | J34: 0
A35: 자본총계 | C35: 3097.085 | D35: 3344.511 | E35: 3253.87 | F35: 3315.606 | G35: 3565.384 | H35: 2774.114 | I35: 2443.735 | J35: 2730.465 | K35: 2981.043 | L35: 3344.511
A36: 현금흐름 요약 | B36: 분기 = TTM (있을 때만)
A37: 영업활동현금흐름 | D37: -442.819 | F37: -2537.163 | H37: 3291.115 | I37: -1663.383 | J37: -541.35 | K37: 2076.091 | L37: -442.819
A38: CAPEX (유·무형 취득) | B38: 양수로 입력 | D38: 39.728 | F38: 123.148 | H38: 8.336 | I38: 7.203 | J38: 131.961 | K38: 17.683 | L38: 39.728
A39: FCF | C39: =IF(OR(C37="",C38=""),"",IFERROR(C37-C38,"")) | D39: =IF(OR(D37="",D38=""),"",IFERROR(D37-D38,"")) | E39: =IF(OR(E37="",E38=""),"",IFERROR(E37-E38,"")) | F39: =IF(OR(F37="",F38=""),"",IFERROR(F37-F38,"")) | G39: =IF(OR(G37="",G38=""),"",IFERROR(G37-G38,"")) | H39: =IF(OR(H37="",H38=""),"",IFERROR(H37-H38,"")) | I39: =IF(OR(I37="",I38=""),"",IFERROR(I37-I38,"")) | J39: =IF(OR(J37="",J38=""),"",IFERROR(J37-J38,"")) | ... L39: =IF(OR(L37="",L38=""),"",IFERROR(L37-L38,""))
A40: 배당금 지급 | B40: 양수로 입력 | D40: 53.9 | F40: 107.626 | H40: 0.055 | I40: 56.284 | J40: 0.023 | K40: 26.94 | L40: 53.9
...

Sheet 섹터 데이터
A1: 필컴퍼니 섹터·사업 데이터
A2: 2단계 보고서를 만들 때 모은 자료 · 월차 · 출처는 맨 오른쪽
A4: this quarter · q single
A5: 항목 | B5: 값 | L5: 출처
A6: 매출 | B6: 28.4 | L6: 2단계 보고서 자료(회사 설명회 자료·공시)
A7: gp | B7: 8.3
A8: 매출총이익률 % | B8: 29.1
A9: sga | B9: 4.4
A10: 영업이익 | B10: 3.9
A11: ord | B11: 3.7
A12: 순이익 | B12: 2.5
A13: EPS approx | B13: 46.02
A15: this quarter · q single ly
A16: 항목 | B16: 값 | L16: 출처
A17: 매출 | B17: 16.8 | L17: 2단계 보고서 자료(회사 설명회 자료·공시)
A18: gp | B18: 4.7
A19: 매출총이익률 % | B19: 27.8
A20: 영업이익 | B20: 0.6
A21: 순이익 | B21: 0.3
A23: this quarter · ytd 9m
A24: 항목 | B24: 값 | L24: 출처
A25: 매출 | B25: 60.96 | L25: 2단계 보고서 자료(회사 설명회 자료·공시)
A26: 매출 YoY % | B26: 8.3
A27: gp | B27: 15.65
A28: 매출총이익률 % | B28: 25.7
A29: sga | B29: 12.95
A30: 영업이익 | B30: 2.7
A31: 영업이익 YoY % | B31: 3.4
A32: ord | B32: 2.34
A33: ord YoY % | B33: -8.9
A34: 순이익 | B34: 2.28
A35: 순이익 YoY % | B35: 46.9
A36: EPS | B36: 42.38
A38: this quarter · ytd 9m ly
A39: 항목 | B39: 값 | L39: 출처
A40: 매출 | B40: 56.29 | L40: 2단계 보고서 자료(회사 설명회 자료·공시)
A41: gp | B41: 14.11
A42: 매출총이익률 % | B42: 25.1
A43: sga | B43: 11.5
A44: 영업이익 | B44: 2.61
...

Sheet 출처
A1: 출처 · 쓴 결산단신
A3: 공시일 | B3: 문서 | C3: PDF
A4: 2026-10-13 | B4: 2026년 11월 결산기 ３분기 결산단신 | C4: https://www2.jpx.co.jp/disc/32670/140120261012549072.pdf
A5: 2026-07-14 | B5: 2026년 11월 결산기 ２분기 결산단신 | C5: https://www2.jpx.co.jp/disc/32670/140120260701586068.pdf
A6: 2026-04-14 | B6: 2026년 11월 결산기 １분기 결산단신 | C6: https://www2.jpx.co.jp/disc/32670/140120260413503112.pdf
A7: 2026-01-14 | B7: 2025년 11월 결산기 연간 결산단신 | C7: https://www2.jpx.co.jp/disc/32670/140120260113533027.pdf
A8: 2025-10-10 | B8: 2025년 11월 결산기 ３분기 결산단신 | C8: https://www2.jpx.co.jp/disc/32670/140120251010571624.pdf
A9: 2025-07-11 | B9: 2025년 11월 결산기 ２분기 결산단신 | C9: https://www2.jpx.co.jp/disc/32670/140120250710512001.pdf
A10: 2025-04-11 | B10: 2025년 11월 결산기 １분기 결산단신 | C10: https://www2.jpx.co.jp/disc/32670/140120250411513226.pdf
A11: 2025-01-10 | B11: 2024년 11월 결산기 연간 결산단신 | C11: https://www2.jpx.co.jp/disc/32670/140120250109548694.pdf
A12: 2024-10-10 | B12: 2024년 11월 결산기 ３분기 결산단신 | C12: https://www2.jpx.co.jp/disc/32670/140120241009595868.pdf
A13: 2024-07-11 | B13: 2024년 11월 결산기 ２분기 결산단신 | C13: https://www2.jpx.co.jp/disc/32670/140120240710547101.pdf
A14: 2024-04-11 | B14: 2024년 11월 결산기 １분기 결산단신 | C14: https://www2.jpx.co.jp/disc/32670/140120240410568387.pdf
... A24: 2018-01-12 | B24: 연간 결산단신 | C24: https://www2.jpx.co.jp/disc/32670/140120180112449908.pdf
