Workbook

Sheet 연간
A1: 4299 Model
A2: 모를 땐 보수적으로 | B2: (단위: 백만엔) | C2: 3월 결산 · 일본 기준 · 2027.1Q = 2027년 3월 결산기 1분기 | Y2: (추정: 파란 글씨 = 직접 입력)
A3: 항목 | B3: 참고 | C3: 2024.2Q | D3: 2024.3Q | E3: 2024.4Q | F3: 2025.1Q | G3: 2025.2Q | H3: 2025.3Q | I3: 2025.4Q | J3: 2026.1Q | K3: 2026.2Q | L3: 2026.3Q | M3: 2026.4Q | N3: 2027.1Q | O3: 2017 | P3: 2018 | Q3: 2019 | R3: 2020 | S3: 2021 | T3: 2022 | U3: 2023 | V3: 2024 | W3: 2025 | X3: 2026 | Y3: 2027(MW) | Z3: 2028(MW) | AA3: 2029(MW) | AB3: 2030(MW) | AC3: 2031(MW)
A4: 매출액 | B4: MW 직접 입력 | C4: 4333 | D4: 4336 | E4: 4353 | F4: 4327 | G4: 4489 | H4: 4510 | I4: 4740 | J4: 4454 | K4: 4495 | L4: 4522 | M4: 4745 | N4: 5124 | O4: 12485 | P4: 13493 | Q4: 14834 | R4: 15342 | S4: 15431 | T4: 16681 | U4: 17331 | V4: 17357 | W4: 18066 | X4: 18216 | Y4: =IF(COUNT(Y7)=0,"",SUM(Y7)) | Z4: =IF(COUNT(Z7)=0,"",SUM(Z7)) | AA4: =IF(COUNT(AA7)=0,"",SUM(AA7)) | AB4: =IF(COUNT(AB7)=0,"",SUM(AB7)) | AC4: =IF(COUNT(AC7)=0,"",SUM(AC7))
A5: YoY | G5: =IF(OR(G4="",C4=""),"",IFERROR(G4/C4-1,"")) | H5: =IF(OR(H4="",D4=""),"",IFERROR(H4/D4-1,"")) | I5: =IF(OR(I4="",E4=""),"",IFERROR(I4/E4-1,"")) | J5: =IF(OR(J4="",F4=""),"",IFERROR(J4/F4-1,"")) | K5: =IF(OR(K4="",G4=""),"",IFERROR(K4/G4-1,"")) | L5: =IF(OR(L4="",H4=""),"",IFERROR(L4/H4-1,"")) | M5: =IF(OR(M4="",I4=""),"",IFERROR(M4/I4-1,"")) | N5: =IF(OR(N4="",J4=""),"",IFERROR(N4/J4-1,"")) | P5: =IF(OR(P4="",O4=""),"",IFERROR(P4/O4-1,"")) | Q5: =IF(OR(Q4="",P4=""),"",IFERROR(Q4/P4-1,"")) | R5: =IF(OR(R4="",Q4=""),"",IFERROR(R4/Q4-1,"")) | S5: =IF(OR(S4="",R4=""),"",IFERROR(S4/R4-1,"")) | T5: =IF(OR(T4="",S4=""),"",IFERROR(T4/S4-1,"")) | U5: =IF(OR(U4="",T4=""),"",IFERROR(U4/T4-1,"")) | V5: =IF(OR(V4="",U4=""),"",IFERROR(V4/U4-1,"")) | W5: =IF(OR(W4="",V4=""),"",IFERROR(W4/V4-1,"")) | ... AC5: =IF(OR(AC4="",AB4=""),"",IFERROR(AC4/AB4-1,""))
A6: 제품별 매출 분류 | B6: 사업보고서 매출실적
A7: (제품별 매출 미공시 — 직접 입력)
A8: 비중 | C8: =IF(OR(C7="",C4=""),"",IFERROR(C7/C4,"")) | D8: =IF(OR(D7="",D4=""),"",IFERROR(D7/D4,"")) | E8: =IF(OR(E7="",E4=""),"",IFERROR(E7/E4,"")) | F8: =IF(OR(F7="",F4=""),"",IFERROR(F7/F4,"")) | G8: =IF(OR(G7="",G4=""),"",IFERROR(G7/G4,"")) | H8: =IF(OR(H7="",H4=""),"",IFERROR(H7/H4,"")) | I8: =IF(OR(I7="",I4=""),"",IFERROR(I7/I4,"")) | J8: =IF(OR(J7="",J4=""),"",IFERROR(J7/J4,"")) | ... AC8: =IF(OR(AC7="",AC4=""),"",IFERROR(AC7/AC4,""))
A9: YoY | G9: =IF(OR(G7="",C7=""),"",IFERROR(G7/C7-1,"")) | H9: =IF(OR(H7="",D7=""),"",IFERROR(H7/D7-1,"")) | I9: =IF(OR(I7="",E7=""),"",IFERROR(I7/E7-1,"")) | J9: =IF(OR(J7="",F7=""),"",IFERROR(J7/F7-1,"")) | K9: =IF(OR(K7="",G7=""),"",IFERROR(K7/G7-1,"")) | L9: =IF(OR(L7="",H7=""),"",IFERROR(L7/H7-1,"")) | M9: =IF(OR(M7="",I7=""),"",IFERROR(M7/I7-1,"")) | N9: =IF(OR(N7="",J7=""),"",IFERROR(N7/J7-1,"")) | P9: =IF(OR(P7="",O7=""),"",IFERROR(P7/O7-1,"")) | Q9: =IF(OR(Q7="",P7=""),"",IFERROR(Q7/P7-1,"")) | R9: =IF(OR(R7="",Q7=""),"",IFERROR(R7/Q7-1,"")) | S9: =IF(OR(S7="",R7=""),"",IFERROR(S7/R7-1,"")) | T9: =IF(OR(T7="",S7=""),"",IFERROR(T7/S7-1,"")) | U9: =IF(OR(U7="",T7=""),"",IFERROR(U7/T7-1,"")) | V9: =IF(OR(V7="",U7=""),"",IFERROR(V7/U7-1,"")) | W9: =IF(OR(W7="",V7=""),"",IFERROR(W7/V7-1,"")) | ... AC9: =IF(OR(AC7="",AB7=""),"",IFERROR(AC7/AB7-1,""))
A10: 매출원가
A11: 전체 매출원가 | C11: 3504 | D11: 3449 | E11: 3418 | F11: 3413 | G11: 3598 | H11: 3596 | I11: 3816 | J11: 3573 | K11: 3642 | L11: 3660 | M11: 3809 | N11: 4074 | O11: 10130 | P11: 11034 | Q11: 12123 | R11: 12563 | S11: 12450 | T11: 13374 | U11: 13860 | V11: 13819 | W11: 14423 | X11: 14684
A12: YoY | G12: =IF(OR(G11="",C11=""),"",IF(C11<=0,"",IFERROR(G11/C11-1,""))) | H12: =IF(OR(H11="",D11=""),"",IF(D11<=0,"",IFERROR(H11/D11-1,""))) | I12: =IF(OR(I11="",E11=""),"",IF(E11<=0,"",IFERROR(I11/E11-1,""))) | J12: =IF(OR(J11="",F11=""),"",IF(F11<=0,"",IFERROR(J11/F11-1,""))) | K12: =IF(OR(K11="",G11=""),"",IF(G11<=0,"",IFERROR(K11/G11-1,""))) | L12: =IF(OR(L11="",H11=""),"",IF(H11<=0,"",IFERROR(L11/H11-1,""))) | M12: =IF(OR(M11="",I11=""),"",IF(I11<=0,"",IFERROR(M11/I11-1,""))) | N12: =IF(OR(N11="",J11=""),"",IF(J11<=0,"",IFERROR(N11/J11-1,""))) | P12: =IF(OR(P11="",O11=""),"",IF(O11<=0,"",IFERROR(P11/O11-1,""))) | Q12: =IF(OR(Q11="",P11=""),"",IF(P11<=0,"",IFERROR(Q11/P11-1,""))) | R12: =IF(OR(R11="",Q11=""),"",IF(Q11<=0,"",IFERROR(R11/Q11-1,""))) | S12: =IF(OR(S11="",R11=""),"",IF(R11<=0,"",IFERROR(S11/R11-1,""))) | T12: =IF(OR(T11="",S11=""),"",IF(S11<=0,"",IFERROR(T11/S11-1,""))) | U12: =IF(OR(U11="",T11=""),"",IF(T11<=0,"",IFERROR(U11/T11-1,""))) | V12: =IF(OR(V11="",U11=""),"",IF(U11<=0,"",IFERROR(V11/U11-1,""))) | W12: =IF(OR(W11="",V11=""),"",IF(V11<=0,"",IFERROR(W11/V11-1,""))) | ... AC12: =IF(OR(AC11="",AB11=""),"",IF(AB11<=0,"",IFERROR(AC11/AB11-1,"")))
A13: 매출총이익 | C13: =IF(OR(C4="",C11=""),"",IFERROR(C4-C11,"")) | D13: =IF(OR(D4="",D11=""),"",IFERROR(D4-D11,"")) | E13: =IF(OR(E4="",E11=""),"",IFERROR(E4-E11,"")) | F13: =IF(OR(F4="",F11=""),"",IFERROR(F4-F11,"")) | G13: =IF(OR(G4="",G11=""),"",IFERROR(G4-G11,"")) | H13: =IF(OR(H4="",H11=""),"",IFERROR(H4-H11,"")) | I13: =IF(OR(I4="",I11=""),"",IFERROR(I4-I11,"")) | J13: =IF(OR(J4="",J11=""),"",IFERROR(J4-J11,"")) | ... X13: =IF(OR(X4="",X11=""),"",IFERROR(X4-X11,""))
A14: GPM | C14: =IF(OR(C13="",C4=""),"",IFERROR(C13/C4,"")) | D14: =IF(OR(D13="",D4=""),"",IFERROR(D13/D4,"")) | E14: =IF(OR(E13="",E4=""),"",IFERROR(E13/E4,"")) | F14: =IF(OR(F13="",F4=""),"",IFERROR(F13/F4,"")) | G14: =IF(OR(G13="",G4=""),"",IFERROR(G13/G4,"")) | H14: =IF(OR(H13="",H4=""),"",IFERROR(H13/H4,"")) | I14: =IF(OR(I13="",I4=""),"",IFERROR(I13/I4,"")) | J14: =IF(OR(J13="",J4=""),"",IFERROR(J13/J4,"")) | ... AC14: =IF(OR(AC13="",AC4=""),"",IFERROR(AC13/AC4,""))
A15: YoY | G15: =IF(OR(G13="",C13=""),"",IF(C13<=0,"",IFERROR(G13/C13-1,""))) | H15: =IF(OR(H13="",D13=""),"",IF(D13<=0,"",IFERROR(H13/D13-1,""))) | I15: =IF(OR(I13="",E13=""),"",IF(E13<=0,"",IFERROR(I13/E13-1,""))) | J15: =IF(OR(J13="",F13=""),"",IF(F13<=0,"",IFERROR(J13/F13-1,""))) | K15: =IF(OR(K13="",G13=""),"",IF(G13<=0,"",IFERROR(K13/G13-1,""))) | L15: =IF(OR(L13="",H13=""),"",IF(H13<=0,"",IFERROR(L13/H13-1,""))) | M15: =IF(OR(M13="",I13=""),"",IF(I13<=0,"",IFERROR(M13/I13-1,""))) | N15: =IF(OR(N13="",J13=""),"",IF(J13<=0,"",IFERROR(N13/J13-1,""))) | P15: =IF(OR(P13="",O13=""),"",IF(O13<=0,"",IFERROR(P13/O13-1,""))) | Q15: =IF(OR(Q13="",P13=""),"",IF(P13<=0,"",IFERROR(Q13/P13-1,""))) | R15: =IF(OR(R13="",Q13=""),"",IF(Q13<=0,"",IFERROR(R13/Q13-1,""))) | S15: =IF(OR(S13="",R13=""),"",IF(R13<=0,"",IFERROR(S13/R13-1,""))) | T15: =IF(OR(T13="",S13=""),"",IF(S13<=0,"",IFERROR(T13/S13-1,""))) | U15: =IF(OR(U13="",T13=""),"",IF(T13<=0,"",IFERROR(U13/T13-1,""))) | V15: =IF(OR(V13="",U13=""),"",IF(U13<=0,"",IFERROR(V13/U13-1,""))) | W15: =IF(OR(W13="",V13=""),"",IF(V13<=0,"",IFERROR(W13/V13-1,""))) | ... AC15: =IF(OR(AC13="",AB13=""),"",IF(AB13<=0,"",IFERROR(AC13/AB13-1,"")))
A16: 판매관리비
A17: 전체 판관비 | C17: 410 | D17: 394 | E17: 412 | F17: 614 | G17: 388 | H17: 406 | I17: 429 | J17: 646 | K17: 406 | L17: 417 | M17: 501 | N17: 817 | O17: 1394 | P17: 1478 | Q17: 1725 | R17: 1768 | S17: 1615 | T17: 1590 | U17: 1638 | V17: 1818 | W17: 1837 | X17: 1970
A18: YoY | G18: =IF(OR(G17="",C17=""),"",IF(C17<=0,"",IFERROR(G17/C17-1,""))) | H18: =IF(OR(H17="",D17=""),"",IF(D17<=0,"",IFERROR(H17/D17-1,""))) | I18: =IF(OR(I17="",E17=""),"",IF(E17<=0,"",IFERROR(I17/E17-1,""))) | J18: =IF(OR(J17="",F17=""),"",IF(F17<=0,"",IFERROR(J17/F17-1,""))) | K18: =IF(OR(K17="",G17=""),"",IF(G17<=0,"",IFERROR(K17/G17-1,""))) | L18: =IF(OR(L17="",H17=""),"",IF(H17<=0,"",IFERROR(L17/H17-1,""))) | M18: =IF(OR(M17="",I17=""),"",IF(I17<=0,"",IFERROR(M17/I17-1,""))) | N18: =IF(OR(N17="",J17=""),"",IF(J17<=0,"",IFERROR(N17/J17-1,""))) | P18: =IF(OR(P17="",O17=""),"",IF(O17<=0,"",IFERROR(P17/O17-1,""))) | Q18: =IF(OR(Q17="",P17=""),"",IF(P17<=0,"",IFERROR(Q17/P17-1,""))) | R18: =IF(OR(R17="",Q17=""),"",IF(Q17<=0,"",IFERROR(R17/Q17-1,""))) | S18: =IF(OR(S17="",R17=""),"",IF(R17<=0,"",IFERROR(S17/R17-1,""))) | T18: =IF(OR(T17="",S17=""),"",IF(S17<=0,"",IFERROR(T17/S17-1,""))) | U18: =IF(OR(U17="",T17=""),"",IF(T17<=0,"",IFERROR(U17/T17-1,""))) | V18: =IF(OR(V17="",U17=""),"",IF(U17<=0,"",IFERROR(V17/U17-1,""))) | W18: =IF(OR(W17="",V17=""),"",IF(V17<=0,"",IFERROR(W17/V17-1,""))) | ... AC18: =IF(OR(AC17="",AB17=""),"",IF(AB17<=0,"",IFERROR(AC17/AB17-1,"")))
A19: 영업이익 | B19: MW = 매출 × OPM | C19: 418 | D19: 494 | E19: 522 | F19: 301 | G19: 503 | H19: 507 | I19: 496 | J19: 235 | K19: 447 | L19: 445 | M19: 435 | N19: 232 | O19: 961 | P19: 981 | Q19: 986 | R19: 1012 | S19: 1367 | T19: 1716 | U19: 1833 | V19: 1719 | W19: 1807 | X19: 1562 | Y19: =IF(OR(Y4="",Y20=""),"",IFERROR(Y4*Y20,"")) | Z19: =IF(OR(Z4="",Z20=""),"",IFERROR(Z4*Z20,"")) | AA19: =IF(OR(AA4="",AA20=""),"",IFERROR(AA4*AA20,"")) | AB19: =IF(OR(AB4="",AB20=""),"",IFERROR(AB4*AB20,"")) | AC19: =IF(OR(AC4="",AC20=""),"",IFERROR(AC4*AC20,""))
A20: OPM | B20: MW 입력 | C20: =IF(OR(C19="",C4=""),"",IFERROR(C19/C4,"")) | D20: =IF(OR(D19="",D4=""),"",IFERROR(D19/D4,"")) | E20: =IF(OR(E19="",E4=""),"",IFERROR(E19/E4,"")) | F20: =IF(OR(F19="",F4=""),"",IFERROR(F19/F4,"")) | G20: =IF(OR(G19="",G4=""),"",IFERROR(G19/G4,"")) | H20: =IF(OR(H19="",H4=""),"",IFERROR(H19/H4,"")) | I20: =IF(OR(I19="",I4=""),"",IFERROR(I19/I4,"")) | J20: =IF(OR(J19="",J4=""),"",IFERROR(J19/J4,"")) | ... X20: =IF(OR(X19="",X4=""),"",IFERROR(X19/X4,""))
A21: 증가율 | G21: =IF(OR(G19="",C19=""),"",IFERROR(G19/C19-1,"")) | H21: =IF(OR(H19="",D19=""),"",IFERROR(H19/D19-1,"")) | I21: =IF(OR(I19="",E19=""),"",IFERROR(I19/E19-1,"")) | J21: =IF(OR(J19="",F19=""),"",IFERROR(J19/F19-1,"")) | K21: =IF(OR(K19="",G19=""),"",IFERROR(K19/G19-1,"")) | L21: =IF(OR(L19="",H19=""),"",IFERROR(L19/H19-1,"")) | M21: =IF(OR(M19="",I19=""),"",IFERROR(M19/I19-1,"")) | N21: =IF(OR(N19="",J19=""),"",IFERROR(N19/J19-1,"")) | P21: =IF(OR(P19="",O19=""),"",IFERROR(P19/O19-1,"")) | Q21: =IF(OR(Q19="",P19=""),"",IFERROR(Q19/P19-1,"")) | R21: =IF(OR(R19="",Q19=""),"",IFERROR(R19/Q19-1,"")) | S21: =IF(OR(S19="",R19=""),"",IFERROR(S19/R19-1,"")) | T21: =IF(OR(T19="",S19=""),"",IFERROR(T19/S19-1,"")) | U21: =IF(OR(U19="",T19=""),"",IFERROR(U19/T19-1,"")) | V21: =IF(OR(V19="",U19=""),"",IFERROR(V19/U19-1,"")) | W21: =IF(OR(W19="",V19=""),"",IFERROR(W19/V19-1,"")) | ... AC21: =IF(OR(AC19="",AB19=""),"",IFERROR(AC19/AB19-1,""))
A22: 비용의 성격별 분류 | B22: 참고 데이터
A23: 총 판관비 | O23: =IF(O17="","",O17) | P23: =IF(P17="","",P17) | Q23: =IF(Q17="","",Q17) | R23: =IF(R17="","",R17) | S23: =IF(S17="","",S17) | T23: =IF(T17="","",T17) | U23: =IF(U17="","",U17) | V23: =IF(V17="","",V17) | ... X23: =IF(X17="","",X17)
A24: 급여 | B24: 고정비
A25: % of Sales | O25: =IF(OR(O24="",O4=""),"",IFERROR(O24/O4,"")) | P25: =IF(OR(P24="",P4=""),"",IFERROR(P24/P4,"")) | Q25: =IF(OR(Q24="",Q4=""),"",IFERROR(Q24/Q4,"")) | R25: =IF(OR(R24="",R4=""),"",IFERROR(R24/R4,"")) | S25: =IF(OR(S24="",S4=""),"",IFERROR(S24/S4,"")) | T25: =IF(OR(T24="",T4=""),"",IFERROR(T24/T4,"")) | U25: =IF(OR(U24="",U4=""),"",IFERROR(U24/U4,"")) | V25: =IF(OR(V24="",V4=""),"",IFERROR(V24/V4,"")) | ... X25: =IF(OR(X24="",X4=""),"",IFERROR(X24/X4,""))
A26: 감가상각비 | B26: 고정비
A27: % of Sales | O27: =IF(OR(O26="",O4=""),"",IFERROR(O26/O4,"")) | P27: =IF(OR(P26="",P4=""),"",IFERROR(P26/P4,"")) | Q27: =IF(OR(Q26="",Q4=""),"",IFERROR(Q26/Q4,"")) | R27: =IF(OR(R26="",R4=""),"",IFERROR(R26/R4,"")) | S27: =IF(OR(S26="",S4=""),"",IFERROR(S26/S4,"")) | T27: =IF(OR(T26="",T4=""),"",IFERROR(T26/T4,"")) | U27: =IF(OR(U26="",U4=""),"",IFERROR(U26/U4,"")) | V27: =IF(OR(V26="",V4=""),"",IFERROR(V26/V4,"")) | ... X27: =IF(OR(X26="",X4=""),"",IFERROR(X26/X4,""))
A28: 지급수수료 | B28: 고정비
A29: % of Sales | O29: =IF(OR(O28="",O4=""),"",IFERROR(O28/O4,"")) | P29: =IF(OR(P28="",P4=""),"",IFERROR(P28/P4,"")) | Q29: =IF(OR(Q28="",Q4=""),"",IFERROR(Q28/Q4,"")) | R29: =IF(OR(R28="",R4=""),"",IFERROR(R28/R4,"")) | S29: =IF(OR(S28="",S4=""),"",IFERROR(S28/S4,"")) | T29: =IF(OR(T28="",T4=""),"",IFERROR(T28/T4,"")) | U29: =IF(OR(U28="",U4=""),"",IFERROR(U28/U4,"")) | V29: =IF(OR(V28="",V4=""),"",IFERROR(V28/V4,"")) | ... X29: =IF(OR(X28="",X4=""),"",IFERROR(X28/X4,""))
A30: 연구개발비 | B30: 변동비
A31: % of Sales | O31: =IF(OR(O30="",O4=""),"",IFERROR(O30/O4,"")) | P31: =IF(OR(P30="",P4=""),"",IFERROR(P30/P4,"")) | Q31: =IF(OR(Q30="",Q4=""),"",IFERROR(Q30/Q4,"")) | R31: =IF(OR(R30="",R4=""),"",IFERROR(R30/R4,"")) | S31: =IF(OR(S30="",S4=""),"",IFERROR(S30/S4,"")) | T31: =IF(OR(T30="",T4=""),"",IFERROR(T30/T4,"")) | U31: =IF(OR(U30="",U4=""),"",IFERROR(U30/U4,"")) | V31: =IF(OR(V30="",V4=""),"",IFERROR(V30/V4,"")) | ... X31: =IF(OR(X30="",X4=""),"",IFERROR(X30/X4,""))
A32: 기타비용 | B32: 변동비 | O32: =IF(OR(O23="",O24="",O26="",O28="",O30=""),"",IFERROR(O23-O24-O26-O28-O30,"")) | P32: =IF(OR(P23="",P24="",P26="",P28="",P30=""),"",IFERROR(P23-P24-P26-P28-P30,"")) | Q32: =IF(OR(Q23="",Q24="",Q26="",Q28="",Q30=""),"",IFERROR(Q23-Q24-Q26-Q28-Q30,"")) | R32: =IF(OR(R23="",R24="",R26="",R28="",R30=""),"",IFERROR(R23-R24-R26-R28-R30,"")) | S32: =IF(OR(S23="",S24="",S26="",S28="",S30=""),"",IFERROR(S23-S24-S26-S28-S30,"")) | T32: =IF(OR(T23="",T24="",T26="",T28="",T30=""),"",IFERROR(T23-T24-T26-T28-T30,"")) | U32: =IF(OR(U23="",U24="",U26="",U28="",U30=""),"",IFERROR(U23-U24-U26-U28-U30,"")) | V32: =IF(OR(V23="",V24="",V26="",V28="",V30=""),"",IFERROR(V23-V24-V26-V28-V30,"")) | ... X32: =IF(OR(X23="",X24="",X26="",X28="",X30=""),"",IFERROR(X23-X24-X26-X28-X30,""))
A33: % of Sales | O33: =IF(OR(O32="",O4=""),"",IFERROR(O32/O4,"")) | P33: =IF(OR(P32="",P4=""),"",IFERROR(P32/P4,"")) | Q33: =IF(OR(Q32="",Q4=""),"",IFERROR(Q32/Q4,"")) | R33: =IF(OR(R32="",R4=""),"",IFERROR(R32/R4,"")) | S33: =IF(OR(S32="",S4=""),"",IFERROR(S32/S4,"")) | T33: =IF(OR(T32="",T4=""),"",IFERROR(T32/T4,"")) | U33: =IF(OR(U32="",U4=""),"",IFERROR(U32/U4,"")) | V33: =IF(OR(V32="",V4=""),"",IFERROR(V32/V4,"")) | ... X33: =IF(OR(X32="",X4=""),"",IFERROR(X32/X4,""))
A34: 당기순이익 추정
A35: 특별이익 | O35: 15 | P35: 0 | Y35: =IF(OR(Y4="",Y36=""),"",IFERROR(Y4*Y36,"")) | Z35: =IF(OR(Z4="",Z36=""),"",IFERROR(Z4*Z36,"")) | AA35: =IF(OR(AA4="",AA36=""),"",IFERROR(AA4*AA36,"")) | AB35: =IF(OR(AB4="",AB36=""),"",IFERROR(AB4*AB36,"")) | AC35: =IF(OR(AC4="",AC36=""),"",IFERROR(AC4*AC36,""))
A36: % of Sales | B36: MW = 최근 3년 평균 | C36: =IF(OR(C35="",C4=""),"",IFERROR(C35/C4,"")) | D36: =IF(OR(D35="",D4=""),"",IFERROR(D35/D4,"")) | E36: =IF(OR(E35="",E4=""),"",IFERROR(E35/E4,"")) | F36: =IF(OR(F35="",F4=""),"",IFERROR(F35/F4,"")) | G36: =IF(OR(G35="",G4=""),"",IFERROR(G35/G4,"")) | H36: =IF(OR(H35="",H4=""),"",IFERROR(H35/H4,"")) | I36: =IF(OR(I35="",I4=""),"",IFERROR(I35/I4,"")) | J36: =IF(OR(J35="",J4=""),"",IFERROR(J35/J4,"")) | ... X36: =IF(OR(X35="",X4=""),"",IFERROR(X35/X4,"")) | Y36: =IFERROR(AVERAGE(V36,W36,X36),"") | Z36: =Y36 | AA36: =Z36 | AB36: =AA36 | AC36: =AB36
A37: 특별손실 | Y37: =IF(OR(Y4="",Y38=""),"",IFERROR(Y4*Y38,"")) | Z37: =IF(OR(Z4="",Z38=""),"",IFERROR(Z4*Z38,"")) | AA37: =IF(OR(AA4="",AA38=""),"",IFERROR(AA4*AA38,"")) | AB37: =IF(OR(AB4="",AB38=""),"",IFERROR(AB4*AB38,"")) | AC37: =IF(OR(AC4="",AC38=""),"",IFERROR(AC4*AC38,""))
A38: % of Sales | C38: =IF(OR(C37="",C4=""),"",IFERROR(C37/C4,"")) | D38: =IF(OR(D37="",D4=""),"",IFERROR(D37/D4,"")) | E38: =IF(OR(E37="",E4=""),"",IFERROR(E37/E4,"")) | F38: =IF(OR(F37="",F4=""),"",IFERROR(F37/F4,"")) | G38: =IF(OR(G37="",G4=""),"",IFERROR(G37/G4,"")) | H38: =IF(OR(H37="",H4=""),"",IFERROR(H37/H4,"")) | I38: =IF(OR(I37="",I4=""),"",IFERROR(I37/I4,"")) | J38: =IF(OR(J37="",J4=""),"",IFERROR(J37/J4,"")) | ... X38: =IF(OR(X37="",X4=""),"",IFERROR(X37/X4,"")) | Y38: =IFERROR(AVERAGE(V38,W38,X38),"") | Z38: =Y38 | AA38: =Z38 | AB38: =AA38 | AC38: =AB38
A39: 영업외수익 | C39: 2 | D39: 3 | E39: 7 | F39: 2 | G39: 5 | H39: 6 | I39: 2 | J39: 2 | K39: 15 | L39: 5 | M39: 3 | N39: 2 | O39: 9 | P39: 8 | Q39: 7 | R39: 7 | S39: 9 | T39: 7 | U39: 12 | V39: 14 | W39: 15 | X39: 25 | Y39: =IF(OR(Y4="",Y40=""),"",IFERROR(Y4*Y40,"")) | Z39: =IF(OR(Z4="",Z40=""),"",IFERROR(Z4*Z40,"")) | AA39: =IF(OR(AA4="",AA40=""),"",IFERROR(AA4*AA40,"")) | AB39: =IF(OR(AB4="",AB40=""),"",IFERROR(AB4*AB40,"")) | AC39: =IF(OR(AC4="",AC40=""),"",IFERROR(AC4*AC40,""))
A40: % of Sales | C40: =IF(OR(C39="",C4=""),"",IFERROR(C39/C4,"")) | D40: =IF(OR(D39="",D4=""),"",IFERROR(D39/D4,"")) | E40: =IF(OR(E39="",E4=""),"",IFERROR(E39/E4,"")) | F40: =IF(OR(F39="",F4=""),"",IFERROR(F39/F4,"")) | G40: =IF(OR(G39="",G4=""),"",IFERROR(G39/G4,"")) | H40: =IF(OR(H39="",H4=""),"",IFERROR(H39/H4,"")) | I40: =IF(OR(I39="",I4=""),"",IFERROR(I39/I4,"")) | J40: =IF(OR(J39="",J4=""),"",IFERROR(J39/J4,"")) | ... X40: =IF(OR(X39="",X4=""),"",IFERROR(X39/X4,"")) | Y40: =IFERROR(AVERAGE(V40,W40,X40),"") | Z40: =Y40 | AA40: =Z40 | AB40: =AA40 | AC40: =AB40
...

Sheet 재무상태표
A1: 4299 재무상태표
A2: 재무비율은 기말 잔액 기준 · 분기 손익은 최근 4분기 합산(TTM) | B2: (단위: 백만엔)
A3: 항목 | B3: 참고 | C3: 2026.1Q | D3: 2026.2Q | E3: 2026.3Q | F3: 2026.4Q | G3: 2027.1Q | H3: 2022 | I3: 2023 | J3: 2024 | K3: 2025 | L3: 2026
A4: 자산
A5: 유동자산 | C5: 12218 | D5: 12561 | E5: 11047 | F5: 11620 | G5: 10862 | H5: 10286 | I5: 10993 | J5: 12366 | K5: 12575 | L5: 11620
A6: 현금및현금성자산 | C6: 9624 | D6: 9885 | E6: 8263 | F6: 8818 | G6: 7808 | H6: 7386 | I6: 8474 | J6: 9846 | K6: 9469 | L6: 8818
A7: 단기금융상품
A8: 매출채권 | C8: 2367 | D8: 2445 | E8: 2556 | F8: 2544 | G8: 2697 | H8: 2485 | I8: 2323 | J8: 2430 | K8: 2766 | L8: 2544
A9: 재고자산 | C9: 47 | D9: 42 | E9: 73 | F9: 42 | G9: 68 | H9: 64 | I9: 33 | J9: 21 | K9: 14 | L9: 42
A10: 기타유동자산 | B10: 총계 − 위 항목 | C10: =IF(OR(C5=""),"",IFERROR(C5-SUM(C6,C7,C8,C9),"")) | D10: =IF(OR(D5=""),"",IFERROR(D5-SUM(D6,D7,D8,D9),"")) | E10: =IF(OR(E5=""),"",IFERROR(E5-SUM(E6,E7,E8,E9),"")) | F10: =IF(OR(F5=""),"",IFERROR(F5-SUM(F6,F7,F8,F9),"")) | G10: =IF(OR(G5=""),"",IFERROR(G5-SUM(G6,G7,G8,G9),"")) | H10: =IF(OR(H5=""),"",IFERROR(H5-SUM(H6,H7,H8,H9),"")) | I10: =IF(OR(I5=""),"",IFERROR(I5-SUM(I6,I7,I8,I9),"")) | J10: =IF(OR(J5=""),"",IFERROR(J5-SUM(J6,J7,J8,J9),"")) | ... L10: =IF(OR(L5=""),"",IFERROR(L5-SUM(L6,L7,L8,L9),""))
A11: 비유동자산 | C11: 1877 | D11: 1895 | E11: 1905 | F11: 1902 | G11: 2702 | H11: 1970 | I11: 1882 | J11: 1224 | K11: 1854 | L11: 1902
A12: 유형자산 | C12: 71 | D12: 67 | E12: 63 | F12: 56 | G12: 59 | H12: 129 | I12: 105 | J12: 87 | K12: 75 | L12: 56
A13: 무형자산 | C13: 45 | D13: 62 | E13: 72 | F13: 68 | G13: 848 | H13: 41 | I13: 21 | J13: 2 | K13: 22 | L13: 68
A14: 투자부동산
A15: 기타비유동자산 | B15: 총계 − 위 항목 | C15: =IF(OR(C11=""),"",IFERROR(C11-SUM(C12,C13,C14),"")) | D15: =IF(OR(D11=""),"",IFERROR(D11-SUM(D12,D13,D14),"")) | E15: =IF(OR(E11=""),"",IFERROR(E11-SUM(E12,E13,E14),"")) | F15: =IF(OR(F11=""),"",IFERROR(F11-SUM(F12,F13,F14),"")) | G15: =IF(OR(G11=""),"",IFERROR(G11-SUM(G12,G13,G14),"")) | H15: =IF(OR(H11=""),"",IFERROR(H11-SUM(H12,H13,H14),"")) | I15: =IF(OR(I11=""),"",IFERROR(I11-SUM(I12,I13,I14),"")) | J15: =IF(OR(J11=""),"",IFERROR(J11-SUM(J12,J13,J14),"")) | ... L15: =IF(OR(L11=""),"",IFERROR(L11-SUM(L12,L13,L14),""))
A16: 자산총계 | C16: 14095 | D16: 14456 | E16: 12952 | F16: 13522 | G16: 13564 | H16: 12257 | I16: 12875 | J16: 13590 | K16: 14430 | L16: 13522
A17: 부채
A18: 유동부채 | C18: 2184 | D18: 2204 | E18: 2119 | F18: 2326 | G18: 2444 | H18: 2436 | I18: 2221 | J18: 2332 | K18: 2402 | L18: 2326
A19: 매입채무 | C19: 732 | D19: 701 | E19: 724 | F19: 796 | G19: 850 | H19: 792 | I19: 708 | J19: 679 | K19: 764 | L19: 796
A20: 단기차입금
A21: 유동성장기부채
A22: 기타유동부채 | B22: 총계 − 위 항목 | C22: =IF(OR(C18=""),"",IFERROR(C18-SUM(C19,C20,C21),"")) | D22: =IF(OR(D18=""),"",IFERROR(D18-SUM(D19,D20,D21),"")) | E22: =IF(OR(E18=""),"",IFERROR(E18-SUM(E19,E20,E21),"")) | F22: =IF(OR(F18=""),"",IFERROR(F18-SUM(F19,F20,F21),"")) | G22: =IF(OR(G18=""),"",IFERROR(G18-SUM(G19,G20,G21),"")) | H22: =IF(OR(H18=""),"",IFERROR(H18-SUM(H19,H20,H21),"")) | I22: =IF(OR(I18=""),"",IFERROR(I18-SUM(I19,I20,I21),"")) | J22: =IF(OR(J18=""),"",IFERROR(J18-SUM(J19,J20,J21),"")) | ... L22: =IF(OR(L18=""),"",IFERROR(L18-SUM(L19,L20,L21),""))
A23: 비유동부채 | C23: 246 | D23: 247 | E23: 247 | F23: 291 | G23: 296 | H23: 311 | I23: 342 | J23: 323 | K23: 246 | L23: 291
A24: 장기차입금
A25: 사채
A26: 기타비유동부채 | B26: 총계 − 위 항목 | C26: =IF(OR(C23=""),"",IFERROR(C23-SUM(C24,C25),"")) | D26: =IF(OR(D23=""),"",IFERROR(D23-SUM(D24,D25),"")) | E26: =IF(OR(E23=""),"",IFERROR(E23-SUM(E24,E25),"")) | F26: =IF(OR(F23=""),"",IFERROR(F23-SUM(F24,F25),"")) | G26: =IF(OR(G23=""),"",IFERROR(G23-SUM(G24,G25),"")) | H26: =IF(OR(H23=""),"",IFERROR(H23-SUM(H24,H25),"")) | I26: =IF(OR(I23=""),"",IFERROR(I23-SUM(I24,I25),"")) | J26: =IF(OR(J23=""),"",IFERROR(J23-SUM(J24,J25),"")) | ... L26: =IF(OR(L23=""),"",IFERROR(L23-SUM(L24,L25),""))
A27: 부채총계 | C27: 2430 | D27: 2451 | E27: 2366 | F27: 2617 | G27: 2740 | H27: 2747 | I27: 2563 | J27: 2655 | K27: 2648 | L27: 2617
A28: 총차입금 | B28: 단기+유동성장기+장기+사채 | C28: =SUM(C20,C21,C24,C25) | D28: =SUM(D20,D21,D24,D25) | E28: =SUM(E20,E21,E24,E25) | F28: =SUM(F20,F21,F24,F25) | G28: =SUM(G20,G21,G24,G25) | H28: =SUM(H20,H21,H24,H25) | I28: =SUM(I20,I21,I24,I25) | J28: =SUM(J20,J21,J24,J25) | ... L28: =SUM(L20,L21,L24,L25)
A29: 순차입금 | B29: 음수 = 순현금 | C29: =C28-C6-N(C7) | D29: =D28-D6-N(D7) | E29: =E28-E6-N(E7) | F29: =F28-F6-N(F7) | G29: =G28-G6-N(G7) | H29: =H28-H6-N(H7) | I29: =I28-I6-N(I7) | J29: =J28-J6-N(J7) | ... L29: =L28-L6-N(L7)
A30: 자본
A31: 지배주주지분 | C31: 11665 | D31: 12005 | E31: 10587 | F31: 10904 | G31: 10823 | H31: 9510 | I31: 10313 | J31: 10935 | K31: 11782 | L31: 10904
A32: 자본금 | C32: 689 | D32: 689 | E32: 689 | F32: 689 | G32: 689 | H32: 689 | I32: 689 | J32: 689 | K32: 689 | L32: 689
A33: 이익잉여금 | C33: 10569 | D33: 10881 | E33: 10919 | F33: 10113 | G33: 10023 | H33: 8427 | I33: 9215 | J33: 9892 | K33: 10675 | L33: 10113
A34: 비지배지분
A35: 자본총계 | C35: 11665 | D35: 12005 | E35: 10587 | F35: 10904 | G35: 10823 | H35: 9510 | I35: 10313 | J35: 10935 | K35: 11782 | L35: 10904
A36: 현금흐름 요약 | B36: 분기 = TTM (있을 때만)
A37: 영업활동현금흐름 | C37: 1294 | D37: 1291 | E37: 1186 | F37: 1389 | H37: 948 | I37: 1579 | J37: 1389 | K37: 766 | L37: 1389
A38: CAPEX (유·무형 취득) | B38: 양수로 입력
A39: FCF | C39: =IF(OR(C37="",C38=""),"",IFERROR(C37-C38,"")) | D39: =IF(OR(D37="",D38=""),"",IFERROR(D37-D38,"")) | E39: =IF(OR(E37="",E38=""),"",IFERROR(E37-E38,"")) | F39: =IF(OR(F37="",F38=""),"",IFERROR(F37-F38,"")) | G39: =IF(OR(G37="",G38=""),"",IFERROR(G37-G38,"")) | H39: =IF(OR(H37="",H38=""),"",IFERROR(H37-H38,"")) | I39: =IF(OR(I37="",I38=""),"",IFERROR(I37-I38,"")) | J39: =IF(OR(J37="",J38=""),"",IFERROR(J37-J38,"")) | ... L39: =IF(OR(L37="",L38=""),"",IFERROR(L37-L38,""))
A40: 배당금 지급 | B40: 양수로 입력 | C40: 522 | D40: 522 | E40: 534 | F40: 534 | H40: 348 | I40: 506 | J40: 507 | K40: 509 | L40: 534
...

Sheet 섹터 데이터
A1: 4299 섹터·사업 데이터
A2: 2단계 보고서를 만들 때 모은 자료 · 월차 · 출처는 맨 오른쪽
A4: revision 2026 10 30 · 상반기 직전
A5: 항목 | B5: 값 | C5: 출처
A6: 매출 | B6: 98.1 | C6: 2단계 보고서 자료(회사 설명회 자료·공시)
A7: 영업이익 | B7: 3.8
A8: ord | B8: 3.95
A9: 순이익 | B9: 2.2
A10: EPS | B10: 21.07
A12: revision 2026 10 30 · 상반기 new
A13: 항목 | B13: 값 | C13: 출처
A14: 매출 | B14: 103 | C14: 2단계 보고서 자료(회사 설명회 자료·공시)
A15: 영업이익 | B15: 6.3
A16: ord | B16: 6.55
A17: 순이익 | B17: 4.2
A18: EPS | B18: 40.23
A20: revision 2026 10 30 · 상반기 change %
A21: 항목 | B21: 값 | C21: 출처
A22: 매출 | B22: 5 | C22: 2단계 보고서 자료(회사 설명회 자료·공시)
A23: 영업이익 | B23: 65.8
A24: ord | B24: 65.8
A25: 순이익 | B25: 90.9
A27: revision 2026 10 30 · 상반기 last year
A28: 항목 | B28: 값 | C28: 출처
A29: 매출 | B29: 89.49 | C29: 2단계 보고서 자료(회사 설명회 자료·공시)
A30: 영업이익 | B30: 6.82
A31: ord | B31: 6.97
A32: 순이익 | B32: 4.72
A33: EPS | B33: 40.7
A35: revision 2026 10 30 · FY 직전
A36: 항목 | B36: 값 | C36: 출처
A37: 매출 | B37: 200 | C37: 2단계 보고서 자료(회사 설명회 자료·공시)
A38: 영업이익 | B38: 12
A39: ord | B39: 12.2
A40: 순이익 | B40: 7.8
A41: EPS | B41: 74.51
A43: revision 2026 10 30 · FY new
A44: 항목 | B44: 값 | C44: 출처
A45: 매출 | B45: 210 | C45: 2단계 보고서 자료(회사 설명회 자료·공시)
A46: 영업이익 | B46: 14.5
...

Sheet 출처
A1: 출처 · 쓴 결산단신
A3: 공시일 | B3: 문서 | C3: PDF
A4: 2026-08-14 | B4: 2027년 3월 결산기 １분기 결산단신 | C4: https://www2.jpx.co.jp/disc/42990/140120260813519687.pdf
A5: 2026-05-13 | B5: 2026년 3월 결산기 연간 결산단신 | C5: https://www2.jpx.co.jp/disc/42990/140120260512526607.pdf
A6: 2026-01-30 | B6: 2026년 3월 결산기 ３분기 결산단신 | C6: https://www2.jpx.co.jp/disc/42990/140120260129541387.pdf
A7: 2025-10-31 | B7: 2026년 3월 결산기 ２분기 결산단신 | C7: https://www2.jpx.co.jp/disc/42990/140120251030582380.pdf
A8: 2025-07-31 | B8: 2026년 3월 결산기 １분기 결산단신 | C8: https://www2.jpx.co.jp/disc/42990/140120250730523369.pdf
A9: 2025-05-13 | B9: 2025년 3월 결산기 연간 결산단신 | C9: https://www2.jpx.co.jp/disc/42990/140120250512539969.pdf
A10: 2025-01-31 | B10: 2025년 3월 결산기 ３분기 결산단신 | C10: https://www2.jpx.co.jp/disc/42990/140120250130558817.pdf
A11: 2024-10-31 | B11: 2025년 3월 결산기 ２분기 결산단신 | C11: https://www2.jpx.co.jp/disc/42990/140120241031507275.pdf
A12: 2024-07-31 | B12: 2025년 3월 결산기 １분기 결산단신 | C12: https://www2.jpx.co.jp/disc/42990/140120240731558690.pdf
A13: 2024-05-14 | B13: 2024년 3월 결산기 연간 결산단신 | C13: https://www2.jpx.co.jp/disc/42990/140120240514595292.pdf
A14: 2024-01-31 | B14: 2024년 3월 결산기 ３분기 결산단신 | C14: https://www2.jpx.co.jp/disc/42990/140120240131522942.pdf
... A24: 2018-05-10 | B24: 연간 결산단신 | C24: https://www2.jpx.co.jp/disc/42990/140120180509431734.pdf

Sheet 재무제표 한눈에 보기
A1: 4299 재무제표 한눈에 보기 — 최근 40개 분기(달력 분기, 3Q26 = 26.7~9) · 단위 억 엔
A2: 출처: 매출·영업이익 결산단신 XBRL · 재무상태표 등 결산단신 XBRL 36건(2017-10-31~2026-08-14). 부문·지역·수주·수출은 있을 때만(출처는 줄 끝). 총 차입금 = 이자 붙는 부채 전부(단기·장기 차입금, CP, 사채·전환사채, 리스부채)
A4: 항목 | B4: 3Q16 | C4: 4Q16 | D4: 1Q17 | E4: 2Q17 | F4: 3Q17 | G4: 4Q17 | H4: 1Q18 | I4: 2Q18 | J4: 3Q18 | K4: 4Q18 | L4: 1Q19 | M4: 2Q19 | N4: 3Q19 | O4: 4Q19 | P4: 1Q20 | Q4: 2Q20 | R4: 3Q20 | S4: 4Q20 | T4: 1Q21 | U4: 2Q21 | V4: 3Q21 | W4: 4Q21 | X4: 1Q22 | Y4: 2Q22 | Z4: 3Q22 | AA4: 4Q22 | AB4: 1Q23 | AC4: 2Q23 | AD4: 3Q23 | AE4: 4Q23 | AF4: 1Q24 | AG4: 2Q24 | AH4: 3Q24 | AI4: 4Q24 | AJ4: 1Q25 | AK4: 2Q25 | AL4: 3Q25 | AM4: 4Q25 | AN4: 1Q26 | AO4: 2Q26 | AP4: 출처
A5: 매출액 | C5: 30.3 | D5: 32.6 | E5: 30.5 | F5: 34 | G5: 33.9 | H5: 36.5 | I5: 33.6 | J5: 38 | K5: 38.8 | L5: 37.9 | M5: 36.7 | N5: 40.4 | O5: 36.6 | P5: 39.7 | Q5: 37.8 | R5: 38.1 | S5: 38.3 | T5: 40.2 | U5: 37.8 | V5: 41.2 | W5: 43 | X5: 44.8 | Y5: 44.4 | Z5: 43.6 | AA5: 42.3 | AB5: 43.1 | AC5: 43.4 | AD5: 43.3 | AE5: 43.4 | AF5: 43.5 | AG5: 43.3 | AH5: 44.9 | AI5: 45.1 | AJ5: 47.4 | AK5: 44.5 | AL5: 45 | AM5: 45.2 | AN5: 47.5 | AO5: 51.2
A6: 매출액 YoY | G6: 11.9 | H6: 12 | I6: 10.2 | J6: 11.8 | K6: 14.5 | L6: 3.8 | M6: 9.2 | N6: 6.3 | O6: -5.7 | P6: 4.7 | Q6: 3 | R6: -5.7 | S6: 4.6 | T6: 1.3 | U6: 0 | V6: 8.1 | W6: 12.3 | X6: 11.4 | Y6: 17.5 | Z6: 5.8 | AA6: -1.6 | AB6: -3.8 | AC6: -2.3 | AD6: -0.7 | AE6: 2.6 | AF6: 0.9 | AG6: -0.2 | AH6: 3.7 | AI6: 3.9 | AJ6: 9 | AK6: 2.8 | AL6: 0.2 | AM6: 0.2 | AN6: 0.2 | AO6: 15.1
A7: 영업이익 | C7: 3.3 | D7: 1.8 | E7: 1.2 | F7: 2.8 | G7: 3 | H7: 2.8 | I7: 1.7 | J7: 2.5 | K7: 3.3 | L7: 2.3 | M7: 2 | N7: 1 | O7: 3.4 | P7: 3.7 | Q7: 2.9 | R7: 3.7 | S7: 3.6 | T7: 3.5 | U7: 2.9 | V7: 4.6 | W7: 5.6 | X7: 4 | Y7: 4 | Z7: 4.7 | AA7: 4.8 | AB7: 4.8 | AC7: 2.9 | AD7: 4.2 | AE7: 4.9 | AF7: 5.2 | AG7: 3 | AH7: 5 | AI7: 5.1 | AJ7: 5 | AK7: 2.4 | AL7: 4.5 | AM7: 4.5 | AN7: 4.3 | AO7: 2.3
A8: 영업이익률 | C8: 10.9 | D8: 5.5 | E8: 3.9 | F8: 8.2 | G8: 8.8 | H8: 7.7 | I8: 5.1 | J8: 6.6 | K8: 8.5 | L8: 6.1 | M8: 5.4 | N8: 2.5 | O8: 9.3 | P8: 9.3 | Q8: 7.7 | R8: 9.7 | S8: 9.4 | T8: 8.7 | U8: 7.7 | V8: 11.2 | W8: 13 | X8: 8.9 | Y8: 9 | Z8: 10.8 | AA8: 11.3 | AB8: 11.1 | AC8: 6.7 | AD8: 9.7 | AE8: 11.3 | AF8: 12 | AG8: 6.9 | AH8: 11.1 | AI8: 11.3 | AJ8: 10.5 | AK8: 5.4 | AL8: 10 | AM8: 10 | AN8: 9.1 | AO8: 4.5
A9: 영업이익 YoY | G9: -9.1 | H9: 55.6 | I9: 41.7 | J9: -10.7 | K9: 10 | L9: -17.9 | M9: 17.6 | N9: -60 | O9: 3 | P9: 60.9 | Q9: 45 | R9: 270 | S9: 5.9 | T9: -5.4 | U9: 0 | V9: 24.3 | W9: 55.6 | X9: 14.3 | Y9: 37.9 | Z9: 2.2 | AA9: -14.3 | AB9: 20 | AC9: -27.5 | AD9: -10.6 | AE9: 2.1 | AF9: 8.3 | AG9: 3.4 | AH9: 19 | AI9: 4.1 | AJ9: -3.8 | AK9: -20 | AL9: -10 | AM9: -11.8 | AN9: -14 | AO9: -4.2
A10: 유동자산 | D10: 66.8 | F10: 67.8 | G10: 67.2 | H10: 69.8 | I10: 67.5 | J10: 71.7 | K10: 71.3 | L10: 77.4 | M10: 75.8 | N10: 75.4 | O10: 74.5 | P10: 79.5 | Q10: 80.2 | R10: 84.6 | S10: 82.6 | T10: 87.9 | U10: 86.5 | V10: 94.4 | W10: 95.6 | X10: 102.9 | Y10: 101.2 | Z10: 104.8 | AA10: 104.9 | AB10: 109.9 | AC10: 107.9 | AD10: 113.7 | AE10: 110.2 | AF10: 123.7 | AG10: 120.8 | AH10: 125.5 | AI10: 126.2 | AJ10: 125.8 | AK10: 122.2 | AL10: 125.6 | AM10: 110.5 | AN10: 116.2 | AO10: 108.6
A11: 유동부채 | D11: 17.9 | F11: 17.3 | G11: 15.9 | H11: 19.3 | I11: 17.2 | J11: 19.4 | K11: 17.8 | L11: 22.4 | M11: 20.1 | N11: 19.3 | O11: 17.2 | P11: 19 | Q11: 18.5 | R11: 20.8 | S11: 19.8 | T11: 23.1 | U11: 19.1 | V11: 20.7 | W11: 20 | X11: 24.4 | Y11: 22.4 | Z11: 22.3 | AA11: 20.1 | AB11: 22.2 | AC11: 20.5 | AD11: 22.9 | AE11: 19.6 | AF11: 23.3 | AG11: 20.9 | AH11: 21.8 | AI11: 21.7 | AJ11: 24 | AK11: 21.8 | AL11: 22 | AM11: 21.2 | AN11: 23.3 | AO11: 24.4
A12: 부채총계 | D12: 21.5 | F12: 21.1 | G12: 19.7 | H12: 23.6 | I12: 21 | J12: 23.4 | K12: 21.9 | L12: 26.1 | M12: 23.8 | N12: 23 | O12: 20.9 | P12: 22.2 | Q12: 21.7 | R12: 24.1 | S12: 23.1 | T12: 26 | U12: 22 | V12: 23.7 | W12: 23.1 | X12: 27.5 | Y12: 25.5 | Z12: 25.4 | AA12: 23.3 | AB12: 25.6 | AC12: 24 | AD12: 26.3 | AE12: 23.1 | AF12: 26.6 | AG12: 24.2 | AH12: 25 | AI12: 24.9 | AJ12: 26.5 | AK12: 24.3 | AL12: 24.5 | AM12: 23.7 | AN12: 26.2 | AO12: 27.4
A13: 자기자본 | D13: 66.5 | F13: 68.4 | G13: 69.5 | H13: 70.9 | I13: 71.1 | J13: 72.8 | K13: 73.9 | L13: 76.2 | M13: 76.3 | N13: 77 | O13: 78 | P13: 80.9 | Q13: 81.5 | R13: 84.3 | S13: 83.5 | T13: 86.2 | U13: 86.6 | V13: 90.2 | W13: 91.9 | X13: 95.1 | Y13: 95.2 | Z13: 98.8 | AA13: 99.7 | AB13: 103.1 | AC13: 102.6 | AD13: 105.9 | AE13: 105.5 | AF13: 109.3 | AG13: 108.8 | AH13: 112.7 | AI13: 113.6 | AJ13: 117.8 | AK13: 116.7 | AL13: 120 | AM13: 105.9 | AN13: 109 | AO13: 108.2
A14: 유동비율 | D14: 373.2 | F14: 391.9 | G14: 422.6 | H14: 361.7 | I14: 392.4 | J14: 369.6 | K14: 400.6 | L14: 345.5 | M14: 377.1 | N14: 390.7 | O14: 433.1 | P14: 418.4 | Q14: 433.5 | R14: 406.7 | S14: 417.2 | T14: 380.5 | U14: 452.9 | V14: 456 | W14: 478 | X14: 421.7 | Y14: 451.8 | Z14: 470 | AA14: 521.9 | AB14: 495 | AC14: 526.3 | AD14: 496.5 | AE14: 562.2 | AF14: 530.9 | AG14: 578 | AH14: 575.7 | AI14: 581.6 | AJ14: 524.2 | AK14: 560.6 | AL14: 570.9 | AM14: 521.2 | AN14: 498.7 | AO14: 445.1
A15: 부채비율 | D15: 32.3 | F15: 30.8 | G15: 28.3 | H15: 33.3 | I15: 29.5 | J15: 32.1 | K15: 29.6 | L15: 34.3 | M15: 31.2 | N15: 29.9 | O15: 26.8 | P15: 27.4 | Q15: 26.6 | R15: 28.6 | S15: 27.7 | T15: 30.2 | U15: 25.4 | V15: 26.3 | W15: 25.1 | X15: 28.9 | Y15: 26.8 | Z15: 25.7 | AA15: 23.4 | AB15: 24.8 | AC15: 23.4 | AD15: 24.8 | AE15: 21.9 | AF15: 24.3 | AG15: 22.2 | AH15: 22.2 | AI15: 21.9 | AJ15: 22.5 | AK15: 20.8 | AL15: 20.4 | AM15: 22.4 | AN15: 24 | AO15: 25.3
A16: 순차입금/자기자본 | D16: -63.8 | F16: -64.3 | G16: -62.6 | H16: -65.3 | I16: -63.7 | J16: -66.6 | K16: -65.1 | L16: -73.1 | M16: -69.5 | N16: -70.6 | O16: -67.9 | P16: -71.2 | Q16: -69.6 | R16: -69.3 | S16: -69.9 | T16: -73.8 | U16: -74.1 | V16: -77.5 | W16: -74.4 | X16: -77.7 | Y16: -76.5 | Z16: -79 | AA16: -79.6 | AB16: -82.2 | AC16: -79.9 | AD16: -82.2 | AE16: -80.5 | AF16: -90.1 | AG16: -87.4 | AH16: -86.9 | AI16: -85.7 | AJ16: -80.4 | AK16: -82.4 | AL16: -82.3 | AM16: -78 | AN16: -80.9 | AO16: -72.2
A17: 재고자산 | D17: 0.7 | F17: 1.4 | G17: 1.7 | H17: 0.5 | I17: 2.1 | J17: 1 | K17: 0.8 | L17: 0.9 | M17: 2.8 | N17: 0.5 | O17: 1.1 | P17: 0.5 | Q17: 1.3 | R17: 1.1 | S17: 1.1 | T17: 0.2 | U17: 1.2 | V17: 0.4 | W17: 0.9 | X17: 0.6 | Y17: 0.9 | Z17: 0.7 | AA17: 0.7 | AB17: 0.3 | AC17: 0.5 | AD17: 1 | AE17: 0.7 | AF17: 0.2 | AG17: 0.6 | AH17: 0.7 | AI17: 1.1 | AJ17: 0.1 | AK17: 0.5 | AL17: 0.4 | AM17: 0.7 | AN17: 0.4 | AO17: 0.7
A18: 재고자산 회전일수 | D18: 2 | F18: 5 | G18: 6 | H18: 2 | I18: 7 | J18: 3 | K18: 2 | L18: 3 | M18: 9 | N18: 1 | O18: 3 | P18: 1 | Q18: 4 | R18: 3 | S18: 3 | T18: 1 | U18: 4 | V18: 1 | W18: 2 | X18: 1 | Y18: 2 | Z18: 2 | AA18: 2 | AB18: 1 | AC18: 1 | AD18: 3 | AE18: 2 | AF18: 1 | AG18: 2 | AH18: 2 | AI18: 3 | AJ18: 0 | AK18: 1 | AL18: 1 | AM18: 2 | AN18: 1 | AO18: 2
A19: 매출채권 회전일수 | D19: 58 | F19: 52 | G19: 51 | H19: 56 | I19: 52 | J19: 51 | K19: 51 | L19: 48 | M19: 47 | N19: 44 | O19: 49 | P19: 48 | Q19: 51 | R19: 58 | S19: 53 | T19: 53 | U19: 0 | V19: 0 | W19: 0 | X19: 51 | Y19: 51 | Z19: 50 | AA19: 49 | AB19: 49 | AC19: 50 | AD19: 50 | AE19: 49 | AF19: 51 | AG19: 50 | AH19: 50 | AI19: 48 | AJ19: 53 | AK19: 48 | AL19: 49 | AM19: 52 | AN19: 49 | AO19: 48
A20: 매입채무 회전일수 | D20: 16 | F20: 16 | G20: 19 | H20: 17 | I20: 20 | J20: 17 | K20: 19 | L20: 19 | M20: 21 | N20: 16 | O20: 20 | P20: 18 | Q20: 20 | R20: 19 | S20: 18 | T20: 18 | U20: 19 | V20: 18 | W20: 19 | X20: 20 | Y20: 21 | Z20: 19 | AA20: 19 | AB20: 19 | AC20: 20 | AD20: 18 | AE20: 18 | AF20: 18 | AG20: 19 | AH20: 18 | AI20: 19 | AJ20: 18 | AK20: 19 | AL20: 18 | AM20: 18 | AN20: 19 | AO20: 19
A21: 현금전환주기(CCC) | D21: 44 | F21: 41 | G21: 38 | H21: 41 | I21: 39 | J21: 37 | K21: 34 | L21: 32 | M21: 35 | N21: 29 | O21: 32 | P21: 31 | Q21: 35 | R21: 42 | S21: 38 | T21: 36 | U21: -15 | V21: -17 | W21: -17 | X21: 32 | Y21: 32 | Z21: 33 | AA21: 32 | AB21: 31 | AC21: 31 | AD21: 35 | AE21: 33 | AF21: 34 | AG21: 33 | AH21: 34 | AI21: 32 | AJ21: 35 | AK21: 30 | AL21: 32 | AM21: 36 | AN21: 31 | AO21: 31
... A23: 현금 | D23: 42.4 | F23: 44 | G23: 43.5 | H23: 46.3 | I23: 45.3 | J23: 48.5 | K23: 48.1 | L23: 55.7 | M23: 53 | N23: 54.4 | O23: 53 | P23: 57.6 | Q23: 56.7 | R23: 58.4 | S23: 58.4 | T23: 63.6 | U23: 64.2 | V23: 69.9 | W23: 68.4 | X23: 73.9 | Y23: 72.8 | Z23: 78.1 | AA23: 79.4 | AB23: 84.7 | AC23: 82 | AD23: 87 | AE23: 84.9 | AF23: 98.5 | AG23: 95.1 | AH23: 97.9 | AI23: 97.3 | AJ23: 94.7 | AK23: 96.2 | AL23: 98.8 | AM23: 82.6 | AN23: 88.2 | AO23: 78.1
