Workbook

Sheet 연간
A1: 4307 Model
A2: 모를 땐 보수적으로 | B2: (단위: 백만엔) | C2: 3월 결산 · IFRS · 2026.4Q = 2026년 3월 결산기 4분기 | Y2: (추정: 파란 글씨 = 직접 입력)
A3: 항목 | B3: 참고 | C3: 2024.1Q | D3: 2024.2Q | E3: 2024.3Q | F3: 2024.4Q | G3: 2025.1Q | H3: 2025.2Q | I3: 2025.3Q | J3: 2025.4Q | K3: 2026.1Q | L3: 2026.2Q | M3: 2026.3Q | N3: 2026.4Q | O3: 2017 | P3: 2018 | Q3: 2019 | R3: 2020 | S3: 2021 | T3: 2022 | U3: 2023 | V3: 2024 | W3: 2025 | X3: 2026 | Y3: 2027(MW) | Z3: 2028(MW) | AA3: 2029(MW) | AB3: 2030(MW) | AC3: 2031(MW)
A4: 매출액 | B4: MW = 제품 합계 | O4: 424548 | P4: 471488 | Q4: 501243 | R4: 528873 | S4: 550337 | T4: 611634 | U4: 692165 | V4: 736556 | W4: 764813 | X4: 814708 | Y4: =IF(COUNT(Y7,Y10,Y13,Y16)=0,"",SUM(Y7,Y10,Y13,Y16)) | Z4: =IF(COUNT(Z7,Z10,Z13,Z16)=0,"",SUM(Z7,Z10,Z13,Z16)) | AA4: =IF(COUNT(AA7,AA10,AA13,AA16)=0,"",SUM(AA7,AA10,AA13,AA16)) | AB4: =IF(COUNT(AB7,AB10,AB13,AB16)=0,"",SUM(AB7,AB10,AB13,AB16)) | AC4: =IF(COUNT(AC7,AC10,AC13,AC16)=0,"",SUM(AC7,AC10,AC13,AC16))
A5: YoY | G5: =IF(OR(G4="",C4=""),"",IFERROR(G4/C4-1,"")) | H5: =IF(OR(H4="",D4=""),"",IFERROR(H4/D4-1,"")) | I5: =IF(OR(I4="",E4=""),"",IFERROR(I4/E4-1,"")) | J5: =IF(OR(J4="",F4=""),"",IFERROR(J4/F4-1,"")) | K5: =IF(OR(K4="",G4=""),"",IFERROR(K4/G4-1,"")) | L5: =IF(OR(L4="",H4=""),"",IFERROR(L4/H4-1,"")) | M5: =IF(OR(M4="",I4=""),"",IFERROR(M4/I4-1,"")) | N5: =IF(OR(N4="",J4=""),"",IFERROR(N4/J4-1,"")) | P5: =IF(OR(P4="",O4=""),"",IFERROR(P4/O4-1,"")) | Q5: =IF(OR(Q4="",P4=""),"",IFERROR(Q4/P4-1,"")) | R5: =IF(OR(R4="",Q4=""),"",IFERROR(R4/Q4-1,"")) | S5: =IF(OR(S4="",R4=""),"",IFERROR(S4/R4-1,"")) | T5: =IF(OR(T4="",S4=""),"",IFERROR(T4/S4-1,"")) | U5: =IF(OR(U4="",T4=""),"",IFERROR(U4/T4-1,"")) | V5: =IF(OR(V4="",U4=""),"",IFERROR(V4/U4-1,"")) | W5: =IF(OR(W4="",V4=""),"",IFERROR(W4/V4-1,"")) | ... AC5: =IF(OR(AC4="",AB4=""),"",IFERROR(AC4/AB4-1,""))
A6: 제품별 매출 분류 | B6: 사업보고서 매출실적
A7: Consulting | C7: 10655 | D7: 13092 | E7: 13609 | F7: 14603 | G7: 12579 | H7: 14866 | I7: 16189 | J7: 16699 | K7: 13404 | L7: 15917 | M7: 17154 | N7: 17081 | V7: 51959 | W7: 60333 | X7: 63556
A8: 비중 | C8: =IF(OR(C7="",C4=""),"",IFERROR(C7/C4,"")) | D8: =IF(OR(D7="",D4=""),"",IFERROR(D7/D4,"")) | E8: =IF(OR(E7="",E4=""),"",IFERROR(E7/E4,"")) | F8: =IF(OR(F7="",F4=""),"",IFERROR(F7/F4,"")) | G8: =IF(OR(G7="",G4=""),"",IFERROR(G7/G4,"")) | H8: =IF(OR(H7="",H4=""),"",IFERROR(H7/H4,"")) | I8: =IF(OR(I7="",I4=""),"",IFERROR(I7/I4,"")) | J8: =IF(OR(J7="",J4=""),"",IFERROR(J7/J4,"")) | ... AC8: =IF(OR(AC7="",AC4=""),"",IFERROR(AC7/AC4,""))
A9: YoY | G9: =IF(OR(G7="",C7=""),"",IFERROR(G7/C7-1,"")) | H9: =IF(OR(H7="",D7=""),"",IFERROR(H7/D7-1,"")) | I9: =IF(OR(I7="",E7=""),"",IFERROR(I7/E7-1,"")) | J9: =IF(OR(J7="",F7=""),"",IFERROR(J7/F7-1,"")) | K9: =IF(OR(K7="",G7=""),"",IFERROR(K7/G7-1,"")) | L9: =IF(OR(L7="",H7=""),"",IFERROR(L7/H7-1,"")) | M9: =IF(OR(M7="",I7=""),"",IFERROR(M7/I7-1,"")) | N9: =IF(OR(N7="",J7=""),"",IFERROR(N7/J7-1,"")) | P9: =IF(OR(P7="",O7=""),"",IFERROR(P7/O7-1,"")) | Q9: =IF(OR(Q7="",P7=""),"",IFERROR(Q7/P7-1,"")) | R9: =IF(OR(R7="",Q7=""),"",IFERROR(R7/Q7-1,"")) | S9: =IF(OR(S7="",R7=""),"",IFERROR(S7/R7-1,"")) | T9: =IF(OR(T7="",S7=""),"",IFERROR(T7/S7-1,"")) | U9: =IF(OR(U7="",T7=""),"",IFERROR(U7/T7-1,"")) | V9: =IF(OR(V7="",U7=""),"",IFERROR(V7/U7-1,"")) | W9: =IF(OR(W7="",V7=""),"",IFERROR(W7/V7-1,"")) | ... AC9: =IF(OR(AC7="",AB7=""),"",IFERROR(AC7/AB7-1,""))
A10: Financial ITSolutions | C10: 83408 | D10: 87511 | E10: 89458 | F10: 89495 | G10: 89313 | H10: 90639 | I10: 93066 | J10: 93587 | K10: 109443 | L10: 84104 | M10: 101903 | N10: 104342 | V10: 349872 | W10: 366605 | X10: 399792
A11: 비중 | C11: =IF(OR(C10="",C4=""),"",IFERROR(C10/C4,"")) | D11: =IF(OR(D10="",D4=""),"",IFERROR(D10/D4,"")) | E11: =IF(OR(E10="",E4=""),"",IFERROR(E10/E4,"")) | F11: =IF(OR(F10="",F4=""),"",IFERROR(F10/F4,"")) | G11: =IF(OR(G10="",G4=""),"",IFERROR(G10/G4,"")) | H11: =IF(OR(H10="",H4=""),"",IFERROR(H10/H4,"")) | I11: =IF(OR(I10="",I4=""),"",IFERROR(I10/I4,"")) | J11: =IF(OR(J10="",J4=""),"",IFERROR(J10/J4,"")) | ... AC11: =IF(OR(AC10="",AC4=""),"",IFERROR(AC10/AC4,""))
A12: YoY | G12: =IF(OR(G10="",C10=""),"",IFERROR(G10/C10-1,"")) | H12: =IF(OR(H10="",D10=""),"",IFERROR(H10/D10-1,"")) | I12: =IF(OR(I10="",E10=""),"",IFERROR(I10/E10-1,"")) | J12: =IF(OR(J10="",F10=""),"",IFERROR(J10/F10-1,"")) | K12: =IF(OR(K10="",G10=""),"",IFERROR(K10/G10-1,"")) | L12: =IF(OR(L10="",H10=""),"",IFERROR(L10/H10-1,"")) | M12: =IF(OR(M10="",I10=""),"",IFERROR(M10/I10-1,"")) | N12: =IF(OR(N10="",J10=""),"",IFERROR(N10/J10-1,"")) | P12: =IF(OR(P10="",O10=""),"",IFERROR(P10/O10-1,"")) | Q12: =IF(OR(Q10="",P10=""),"",IFERROR(Q10/P10-1,"")) | R12: =IF(OR(R10="",Q10=""),"",IFERROR(R10/Q10-1,"")) | S12: =IF(OR(S10="",R10=""),"",IFERROR(S10/R10-1,"")) | T12: =IF(OR(T10="",S10=""),"",IFERROR(T10/S10-1,"")) | U12: =IF(OR(U10="",T10=""),"",IFERROR(U10/T10-1,"")) | V12: =IF(OR(V10="",U10=""),"",IFERROR(V10/U10-1,"")) | W12: =IF(OR(W10="",V10=""),"",IFERROR(W10/V10-1,"")) | ... AC12: =IF(OR(AC10="",AB10=""),"",IFERROR(AC10/AB10-1,""))
A13: Industrial ITSolutions | C13: 69426 | D13: 70631 | E13: 69295 | F13: 66571 | G13: 70599 | H13: 67175 | I13: 64674 | J13: 65039 | K13: 54550 | L13: 82486 | M13: 66210 | N13: 67995 | V13: 275923 | W13: 267487 | X13: 271241
A14: 비중 | C14: =IF(OR(C13="",C4=""),"",IFERROR(C13/C4,"")) | D14: =IF(OR(D13="",D4=""),"",IFERROR(D13/D4,"")) | E14: =IF(OR(E13="",E4=""),"",IFERROR(E13/E4,"")) | F14: =IF(OR(F13="",F4=""),"",IFERROR(F13/F4,"")) | G14: =IF(OR(G13="",G4=""),"",IFERROR(G13/G4,"")) | H14: =IF(OR(H13="",H4=""),"",IFERROR(H13/H4,"")) | I14: =IF(OR(I13="",I4=""),"",IFERROR(I13/I4,"")) | J14: =IF(OR(J13="",J4=""),"",IFERROR(J13/J4,"")) | ... AC14: =IF(OR(AC13="",AC4=""),"",IFERROR(AC13/AC4,""))
A15: YoY | G15: =IF(OR(G13="",C13=""),"",IFERROR(G13/C13-1,"")) | H15: =IF(OR(H13="",D13=""),"",IFERROR(H13/D13-1,"")) | I15: =IF(OR(I13="",E13=""),"",IFERROR(I13/E13-1,"")) | J15: =IF(OR(J13="",F13=""),"",IFERROR(J13/F13-1,"")) | K15: =IF(OR(K13="",G13=""),"",IFERROR(K13/G13-1,"")) | L15: =IF(OR(L13="",H13=""),"",IFERROR(L13/H13-1,"")) | M15: =IF(OR(M13="",I13=""),"",IFERROR(M13/I13-1,"")) | N15: =IF(OR(N13="",J13=""),"",IFERROR(N13/J13-1,"")) | P15: =IF(OR(P13="",O13=""),"",IFERROR(P13/O13-1,"")) | Q15: =IF(OR(Q13="",P13=""),"",IFERROR(Q13/P13-1,"")) | R15: =IF(OR(R13="",Q13=""),"",IFERROR(R13/Q13-1,"")) | S15: =IF(OR(S13="",R13=""),"",IFERROR(S13/R13-1,"")) | T15: =IF(OR(T13="",S13=""),"",IFERROR(T13/S13-1,"")) | U15: =IF(OR(U13="",T13=""),"",IFERROR(U13/T13-1,"")) | V15: =IF(OR(V13="",U13=""),"",IFERROR(V13/U13-1,"")) | W15: =IF(OR(W13="",V13=""),"",IFERROR(W13/V13-1,"")) | ... AC15: =IF(OR(AC13="",AB13=""),"",IFERROR(AC13/AB13-1,""))
A16: ITPlatform Services | C16: 12489 | D16: 13339 | E16: 14805 | F16: 14995 | G16: 14745 | H16: 15147 | I16: 16725 | J16: 20424 | K16: 17648 | L16: 18037 | M16: 19216 | N16: 22138 | V16: 55628 | W16: 67041 | X16: 77039
A17: 비중 | C17: =IF(OR(C16="",C4=""),"",IFERROR(C16/C4,"")) | D17: =IF(OR(D16="",D4=""),"",IFERROR(D16/D4,"")) | E17: =IF(OR(E16="",E4=""),"",IFERROR(E16/E4,"")) | F17: =IF(OR(F16="",F4=""),"",IFERROR(F16/F4,"")) | G17: =IF(OR(G16="",G4=""),"",IFERROR(G16/G4,"")) | H17: =IF(OR(H16="",H4=""),"",IFERROR(H16/H4,"")) | I17: =IF(OR(I16="",I4=""),"",IFERROR(I16/I4,"")) | J17: =IF(OR(J16="",J4=""),"",IFERROR(J16/J4,"")) | ... AC17: =IF(OR(AC16="",AC4=""),"",IFERROR(AC16/AC4,""))
A18: YoY | G18: =IF(OR(G16="",C16=""),"",IFERROR(G16/C16-1,"")) | H18: =IF(OR(H16="",D16=""),"",IFERROR(H16/D16-1,"")) | I18: =IF(OR(I16="",E16=""),"",IFERROR(I16/E16-1,"")) | J18: =IF(OR(J16="",F16=""),"",IFERROR(J16/F16-1,"")) | K18: =IF(OR(K16="",G16=""),"",IFERROR(K16/G16-1,"")) | L18: =IF(OR(L16="",H16=""),"",IFERROR(L16/H16-1,"")) | M18: =IF(OR(M16="",I16=""),"",IFERROR(M16/I16-1,"")) | N18: =IF(OR(N16="",J16=""),"",IFERROR(N16/J16-1,"")) | P18: =IF(OR(P16="",O16=""),"",IFERROR(P16/O16-1,"")) | Q18: =IF(OR(Q16="",P16=""),"",IFERROR(Q16/P16-1,"")) | R18: =IF(OR(R16="",Q16=""),"",IFERROR(R16/Q16-1,"")) | S18: =IF(OR(S16="",R16=""),"",IFERROR(S16/R16-1,"")) | T18: =IF(OR(T16="",S16=""),"",IFERROR(T16/S16-1,"")) | U18: =IF(OR(U16="",T16=""),"",IFERROR(U16/T16-1,"")) | V18: =IF(OR(V16="",U16=""),"",IFERROR(V16/U16-1,"")) | W18: =IF(OR(W16="",V16=""),"",IFERROR(W16/V16-1,"")) | ... AC18: =IF(OR(AC16="",AB16=""),"",IFERROR(AC16/AB16-1,""))
A19: 매출원가
A20: 전체 매출원가 | O20: 280761 | P20: 311868 | Q20: 336508 | R20: 348006 | S20: 364539 | T20: 395562 | U20: 452336 | V20: 475549 | W20: 489517 | X20: 514556
A21: YoY | G21: =IF(OR(G20="",C20=""),"",IF(C20<=0,"",IFERROR(G20/C20-1,""))) | H21: =IF(OR(H20="",D20=""),"",IF(D20<=0,"",IFERROR(H20/D20-1,""))) | I21: =IF(OR(I20="",E20=""),"",IF(E20<=0,"",IFERROR(I20/E20-1,""))) | J21: =IF(OR(J20="",F20=""),"",IF(F20<=0,"",IFERROR(J20/F20-1,""))) | K21: =IF(OR(K20="",G20=""),"",IF(G20<=0,"",IFERROR(K20/G20-1,""))) | L21: =IF(OR(L20="",H20=""),"",IF(H20<=0,"",IFERROR(L20/H20-1,""))) | M21: =IF(OR(M20="",I20=""),"",IF(I20<=0,"",IFERROR(M20/I20-1,""))) | N21: =IF(OR(N20="",J20=""),"",IF(J20<=0,"",IFERROR(N20/J20-1,""))) | P21: =IF(OR(P20="",O20=""),"",IF(O20<=0,"",IFERROR(P20/O20-1,""))) | Q21: =IF(OR(Q20="",P20=""),"",IF(P20<=0,"",IFERROR(Q20/P20-1,""))) | R21: =IF(OR(R20="",Q20=""),"",IF(Q20<=0,"",IFERROR(R20/Q20-1,""))) | S21: =IF(OR(S20="",R20=""),"",IF(R20<=0,"",IFERROR(S20/R20-1,""))) | T21: =IF(OR(T20="",S20=""),"",IF(S20<=0,"",IFERROR(T20/S20-1,""))) | U21: =IF(OR(U20="",T20=""),"",IF(T20<=0,"",IFERROR(U20/T20-1,""))) | V21: =IF(OR(V20="",U20=""),"",IF(U20<=0,"",IFERROR(V20/U20-1,""))) | W21: =IF(OR(W20="",V20=""),"",IF(V20<=0,"",IFERROR(W20/V20-1,""))) | ... AC21: =IF(OR(AC20="",AB20=""),"",IF(AB20<=0,"",IFERROR(AC20/AB20-1,"")))
A22: 매출총이익 | C22: =IF(OR(C4="",C20=""),"",IFERROR(C4-C20,"")) | D22: =IF(OR(D4="",D20=""),"",IFERROR(D4-D20,"")) | E22: =IF(OR(E4="",E20=""),"",IFERROR(E4-E20,"")) | F22: =IF(OR(F4="",F20=""),"",IFERROR(F4-F20,"")) | G22: =IF(OR(G4="",G20=""),"",IFERROR(G4-G20,"")) | H22: =IF(OR(H4="",H20=""),"",IFERROR(H4-H20,"")) | I22: =IF(OR(I4="",I20=""),"",IFERROR(I4-I20,"")) | J22: =IF(OR(J4="",J20=""),"",IFERROR(J4-J20,"")) | ... X22: =IF(OR(X4="",X20=""),"",IFERROR(X4-X20,""))
A23: GPM | C23: =IF(OR(C22="",C4=""),"",IFERROR(C22/C4,"")) | D23: =IF(OR(D22="",D4=""),"",IFERROR(D22/D4,"")) | E23: =IF(OR(E22="",E4=""),"",IFERROR(E22/E4,"")) | F23: =IF(OR(F22="",F4=""),"",IFERROR(F22/F4,"")) | G23: =IF(OR(G22="",G4=""),"",IFERROR(G22/G4,"")) | H23: =IF(OR(H22="",H4=""),"",IFERROR(H22/H4,"")) | I23: =IF(OR(I22="",I4=""),"",IFERROR(I22/I4,"")) | J23: =IF(OR(J22="",J4=""),"",IFERROR(J22/J4,"")) | ... AC23: =IF(OR(AC22="",AC4=""),"",IFERROR(AC22/AC4,""))
A24: YoY | G24: =IF(OR(G22="",C22=""),"",IF(C22<=0,"",IFERROR(G22/C22-1,""))) | H24: =IF(OR(H22="",D22=""),"",IF(D22<=0,"",IFERROR(H22/D22-1,""))) | I24: =IF(OR(I22="",E22=""),"",IF(E22<=0,"",IFERROR(I22/E22-1,""))) | J24: =IF(OR(J22="",F22=""),"",IF(F22<=0,"",IFERROR(J22/F22-1,""))) | K24: =IF(OR(K22="",G22=""),"",IF(G22<=0,"",IFERROR(K22/G22-1,""))) | L24: =IF(OR(L22="",H22=""),"",IF(H22<=0,"",IFERROR(L22/H22-1,""))) | M24: =IF(OR(M22="",I22=""),"",IF(I22<=0,"",IFERROR(M22/I22-1,""))) | N24: =IF(OR(N22="",J22=""),"",IF(J22<=0,"",IFERROR(N22/J22-1,""))) | P24: =IF(OR(P22="",O22=""),"",IF(O22<=0,"",IFERROR(P22/O22-1,""))) | Q24: =IF(OR(Q22="",P22=""),"",IF(P22<=0,"",IFERROR(Q22/P22-1,""))) | R24: =IF(OR(R22="",Q22=""),"",IF(Q22<=0,"",IFERROR(R22/Q22-1,""))) | S24: =IF(OR(S22="",R22=""),"",IF(R22<=0,"",IFERROR(S22/R22-1,""))) | T24: =IF(OR(T22="",S22=""),"",IF(S22<=0,"",IFERROR(T22/S22-1,""))) | U24: =IF(OR(U22="",T22=""),"",IF(T22<=0,"",IFERROR(U22/T22-1,""))) | V24: =IF(OR(V22="",U22=""),"",IF(U22<=0,"",IFERROR(V22/U22-1,""))) | W24: =IF(OR(W22="",V22=""),"",IF(V22<=0,"",IFERROR(W22/V22-1,""))) | ... AC24: =IF(OR(AC22="",AB22=""),"",IF(AB22<=0,"",IFERROR(AC22/AB22-1,"")))
A25: 판매관리비
A26: 전체 판관비 | O26: 85272 | P26: 94481 | Q26: 93293 | R26: 97688 | S26: 98366 | T26: 113536 | U26: 131580 | V26: 142353 | W26: 144071 | X26: 145642
A27: YoY | G27: =IF(OR(G26="",C26=""),"",IF(C26<=0,"",IFERROR(G26/C26-1,""))) | H27: =IF(OR(H26="",D26=""),"",IF(D26<=0,"",IFERROR(H26/D26-1,""))) | I27: =IF(OR(I26="",E26=""),"",IF(E26<=0,"",IFERROR(I26/E26-1,""))) | J27: =IF(OR(J26="",F26=""),"",IF(F26<=0,"",IFERROR(J26/F26-1,""))) | K27: =IF(OR(K26="",G26=""),"",IF(G26<=0,"",IFERROR(K26/G26-1,""))) | L27: =IF(OR(L26="",H26=""),"",IF(H26<=0,"",IFERROR(L26/H26-1,""))) | M27: =IF(OR(M26="",I26=""),"",IF(I26<=0,"",IFERROR(M26/I26-1,""))) | N27: =IF(OR(N26="",J26=""),"",IF(J26<=0,"",IFERROR(N26/J26-1,""))) | P27: =IF(OR(P26="",O26=""),"",IF(O26<=0,"",IFERROR(P26/O26-1,""))) | Q27: =IF(OR(Q26="",P26=""),"",IF(P26<=0,"",IFERROR(Q26/P26-1,""))) | R27: =IF(OR(R26="",Q26=""),"",IF(Q26<=0,"",IFERROR(R26/Q26-1,""))) | S27: =IF(OR(S26="",R26=""),"",IF(R26<=0,"",IFERROR(S26/R26-1,""))) | T27: =IF(OR(T26="",S26=""),"",IF(S26<=0,"",IFERROR(T26/S26-1,""))) | U27: =IF(OR(U26="",T26=""),"",IF(T26<=0,"",IFERROR(U26/T26-1,""))) | V27: =IF(OR(V26="",U26=""),"",IF(U26<=0,"",IFERROR(V26/U26-1,""))) | W27: =IF(OR(W26="",V26=""),"",IF(V26<=0,"",IFERROR(W26/V26-1,""))) | ... AC27: =IF(OR(AC26="",AB26=""),"",IF(AB26<=0,"",IFERROR(AC26/AB26-1,"")))
A28: 영업이익 | B28: MW = 매출 × OPM | O28: 58514 | P28: 65138 | Q28: 71442 | R28: 83178 | S28: 80748 | T28: 106218 | U28: 111832 | V28: 120411 | W28: 134907 | X28: 58273 | Y28: =IF(OR(Y4="",Y29=""),"",IFERROR(Y4*Y29,"")) | Z28: =IF(OR(Z4="",Z29=""),"",IFERROR(Z4*Z29,"")) | AA28: =IF(OR(AA4="",AA29=""),"",IFERROR(AA4*AA29,"")) | AB28: =IF(OR(AB4="",AB29=""),"",IFERROR(AB4*AB29,"")) | AC28: =IF(OR(AC4="",AC29=""),"",IFERROR(AC4*AC29,""))
A29: OPM | B29: MW 입력 | C29: =IF(OR(C28="",C4=""),"",IFERROR(C28/C4,"")) | D29: =IF(OR(D28="",D4=""),"",IFERROR(D28/D4,"")) | E29: =IF(OR(E28="",E4=""),"",IFERROR(E28/E4,"")) | F29: =IF(OR(F28="",F4=""),"",IFERROR(F28/F4,"")) | G29: =IF(OR(G28="",G4=""),"",IFERROR(G28/G4,"")) | H29: =IF(OR(H28="",H4=""),"",IFERROR(H28/H4,"")) | I29: =IF(OR(I28="",I4=""),"",IFERROR(I28/I4,"")) | J29: =IF(OR(J28="",J4=""),"",IFERROR(J28/J4,"")) | ... X29: =IF(OR(X28="",X4=""),"",IFERROR(X28/X4,""))
A30: 증가율 | G30: =IF(OR(G28="",C28=""),"",IFERROR(G28/C28-1,"")) | H30: =IF(OR(H28="",D28=""),"",IFERROR(H28/D28-1,"")) | I30: =IF(OR(I28="",E28=""),"",IFERROR(I28/E28-1,"")) | J30: =IF(OR(J28="",F28=""),"",IFERROR(J28/F28-1,"")) | K30: =IF(OR(K28="",G28=""),"",IFERROR(K28/G28-1,"")) | L30: =IF(OR(L28="",H28=""),"",IFERROR(L28/H28-1,"")) | M30: =IF(OR(M28="",I28=""),"",IFERROR(M28/I28-1,"")) | N30: =IF(OR(N28="",J28=""),"",IFERROR(N28/J28-1,"")) | P30: =IF(OR(P28="",O28=""),"",IFERROR(P28/O28-1,"")) | Q30: =IF(OR(Q28="",P28=""),"",IFERROR(Q28/P28-1,"")) | R30: =IF(OR(R28="",Q28=""),"",IFERROR(R28/Q28-1,"")) | S30: =IF(OR(S28="",R28=""),"",IFERROR(S28/R28-1,"")) | T30: =IF(OR(T28="",S28=""),"",IFERROR(T28/S28-1,"")) | U30: =IF(OR(U28="",T28=""),"",IFERROR(U28/T28-1,"")) | V30: =IF(OR(V28="",U28=""),"",IFERROR(V28/U28-1,"")) | W30: =IF(OR(W28="",V28=""),"",IFERROR(W28/V28-1,"")) | ... AC30: =IF(OR(AC28="",AB28=""),"",IFERROR(AC28/AB28-1,""))
A31: 비용의 성격별 분류 | B31: 참고 데이터
A32: 총 판관비 | O32: =IF(O26="","",O26) | P32: =IF(P26="","",P26) | Q32: =IF(Q26="","",Q26) | R32: =IF(R26="","",R26) | S32: =IF(S26="","",S26) | T32: =IF(T26="","",T26) | U32: =IF(U26="","",U26) | V32: =IF(V26="","",V26) | ... X32: =IF(X26="","",X26)
A33: 급여 | B33: 고정비
A34: % of Sales | O34: =IF(OR(O33="",O4=""),"",IFERROR(O33/O4,"")) | P34: =IF(OR(P33="",P4=""),"",IFERROR(P33/P4,"")) | Q34: =IF(OR(Q33="",Q4=""),"",IFERROR(Q33/Q4,"")) | R34: =IF(OR(R33="",R4=""),"",IFERROR(R33/R4,"")) | S34: =IF(OR(S33="",S4=""),"",IFERROR(S33/S4,"")) | T34: =IF(OR(T33="",T4=""),"",IFERROR(T33/T4,"")) | U34: =IF(OR(U33="",U4=""),"",IFERROR(U33/U4,"")) | V34: =IF(OR(V33="",V4=""),"",IFERROR(V33/V4,"")) | ... X34: =IF(OR(X33="",X4=""),"",IFERROR(X33/X4,""))
A35: 감가상각비 | B35: 고정비
A36: % of Sales | O36: =IF(OR(O35="",O4=""),"",IFERROR(O35/O4,"")) | P36: =IF(OR(P35="",P4=""),"",IFERROR(P35/P4,"")) | Q36: =IF(OR(Q35="",Q4=""),"",IFERROR(Q35/Q4,"")) | R36: =IF(OR(R35="",R4=""),"",IFERROR(R35/R4,"")) | S36: =IF(OR(S35="",S4=""),"",IFERROR(S35/S4,"")) | T36: =IF(OR(T35="",T4=""),"",IFERROR(T35/T4,"")) | U36: =IF(OR(U35="",U4=""),"",IFERROR(U35/U4,"")) | V36: =IF(OR(V35="",V4=""),"",IFERROR(V35/V4,"")) | ... X36: =IF(OR(X35="",X4=""),"",IFERROR(X35/X4,""))
A37: 지급수수료 | B37: 고정비
A38: % of Sales | O38: =IF(OR(O37="",O4=""),"",IFERROR(O37/O4,"")) | P38: =IF(OR(P37="",P4=""),"",IFERROR(P37/P4,"")) | Q38: =IF(OR(Q37="",Q4=""),"",IFERROR(Q37/Q4,"")) | R38: =IF(OR(R37="",R4=""),"",IFERROR(R37/R4,"")) | S38: =IF(OR(S37="",S4=""),"",IFERROR(S37/S4,"")) | T38: =IF(OR(T37="",T4=""),"",IFERROR(T37/T4,"")) | U38: =IF(OR(U37="",U4=""),"",IFERROR(U37/U4,"")) | V38: =IF(OR(V37="",V4=""),"",IFERROR(V37/V4,"")) | ... X38: =IF(OR(X37="",X4=""),"",IFERROR(X37/X4,""))
A39: 연구개발비 | B39: 변동비
A40: % of Sales | O40: =IF(OR(O39="",O4=""),"",IFERROR(O39/O4,"")) | P40: =IF(OR(P39="",P4=""),"",IFERROR(P39/P4,"")) | Q40: =IF(OR(Q39="",Q4=""),"",IFERROR(Q39/Q4,"")) | R40: =IF(OR(R39="",R4=""),"",IFERROR(R39/R4,"")) | S40: =IF(OR(S39="",S4=""),"",IFERROR(S39/S4,"")) | T40: =IF(OR(T39="",T4=""),"",IFERROR(T39/T4,"")) | U40: =IF(OR(U39="",U4=""),"",IFERROR(U39/U4,"")) | V40: =IF(OR(V39="",V4=""),"",IFERROR(V39/V4,"")) | ... X40: =IF(OR(X39="",X4=""),"",IFERROR(X39/X4,""))
...

Sheet 재무상태표
A1: 4307 재무상태표
A2: 재무비율은 기말 잔액 기준 · 분기 손익은 최근 4분기 합산(TTM) | B2: (단위: 백만엔)
A3: 항목 | B3: 참고 | C3: 2026.1Q | D3: 2026.2Q | E3: 2026.3Q | F3: 2026.4Q | G3: 2027.1Q | H3: 2022 | I3: 2023 | J3: 2024 | K3: 2025 | L3: 2026
A4: 자산
A5: 유동자산 | C5: 413613 | D5: 466465 | E5: 401200 | F5: 501060 | G5: 444936 | H5: 333645 | I5: 349102 | J5: 405178 | K5: 419424 | L5: 501060
A6: 현금및현금성자산 | C6: 176277 | D6: 152852 | E6: 108663 | F6: 132620 | G6: 131784 | H6: 115610 | I6: 129257 | J6: 173935 | K6: 168597 | L6: 132620
A7: 단기금융상품 | C7: 20058 | D7: 44412 | E7: 57966 | F7: 61975 | G7: 14964 | H7: 14015 | I7: 14201 | J7: 13982 | K7: 15622 | L7: 61975
A8: 매출채권 | C8: 117324 | D8: 155666 | E8: 110112 | F8: 146189 | G8: 88879 | H8: 135678 | I8: 131592 | J8: 141870 | K8: 158295 | L8: 146189
A9: 재고자산
A10: 기타유동자산 | B10: 총계 − 위 항목 | C10: =IF(OR(C5=""),"",IFERROR(C5-SUM(C6,C7,C8,C9),"")) | D10: =IF(OR(D5=""),"",IFERROR(D5-SUM(D6,D7,D8,D9),"")) | E10: =IF(OR(E5=""),"",IFERROR(E5-SUM(E6,E7,E8,E9),"")) | F10: =IF(OR(F5=""),"",IFERROR(F5-SUM(F6,F7,F8,F9),"")) | G10: =IF(OR(G5=""),"",IFERROR(G5-SUM(G6,G7,G8,G9),"")) | H10: =IF(OR(H5=""),"",IFERROR(H5-SUM(H6,H7,H8,H9),"")) | I10: =IF(OR(I5=""),"",IFERROR(I5-SUM(I6,I7,I8,I9),"")) | J10: =IF(OR(J5=""),"",IFERROR(J5-SUM(J6,J7,J8,J9),"")) | ... L10: =IF(OR(L5=""),"",IFERROR(L5-SUM(L6,L7,L8,L9),""))
A11: 비유동자산 | C11: 512587 | D11: 528048 | E11: 547339 | F11: 458733 | G11: 461453 | H11: 456010 | I11: 489122 | J11: 517595 | K11: 509077 | L11: 458733
A12: 유형자산 | C12: 37244 | D12: 36900 | E12: 38341 | F12: 46748 | G12: 45807 | H12: 37482 | I12: 42114 | J12: 40245 | K12: 38032 | L12: 46748
A13: 무형자산
A14: 투자부동산
A15: 기타비유동자산 | B15: 총계 − 위 항목 | C15: =IF(OR(C11=""),"",IFERROR(C11-SUM(C12,C13,C14),"")) | D15: =IF(OR(D11=""),"",IFERROR(D11-SUM(D12,D13,D14),"")) | E15: =IF(OR(E11=""),"",IFERROR(E11-SUM(E12,E13,E14),"")) | F15: =IF(OR(F11=""),"",IFERROR(F11-SUM(F12,F13,F14),"")) | G15: =IF(OR(G11=""),"",IFERROR(G11-SUM(G12,G13,G14),"")) | H15: =IF(OR(H11=""),"",IFERROR(H11-SUM(H12,H13,H14),"")) | I15: =IF(OR(I11=""),"",IFERROR(I11-SUM(I12,I13,I14),"")) | J15: =IF(OR(J11=""),"",IFERROR(J11-SUM(J12,J13,J14),"")) | ... L15: =IF(OR(L11=""),"",IFERROR(L11-SUM(L12,L13,L14),""))
A16: 자산총계 | C16: 926201 | D16: 994514 | E16: 948539 | F16: 959794 | G16: 906390 | H16: 789655 | I16: 838224 | J16: 922773 | K16: 928501 | L16: 959794
A17: 부채
A18: 유동부채 | C18: 224650 | D18: 270664 | E18: 192746 | F18: 273021 | G18: 275000 | H18: 298342 | I18: 198247 | J18: 214642 | K18: 239482 | L18: 273021
A19: 매입채무 | C19: 63800 | D19: 79896 | E19: 53776 | F19: 36911 | G19: 30939 | H19: 53800 | I19: 52129 | J19: 53038 | K19: 58146 | L19: 36911
A20: 단기차입금
A21: 유동성장기부채
A22: 기타유동부채 | B22: 총계 − 위 항목 | C22: =IF(OR(C18=""),"",IFERROR(C18-SUM(C19,C20,C21),"")) | D22: =IF(OR(D18=""),"",IFERROR(D18-SUM(D19,D20,D21),"")) | E22: =IF(OR(E18=""),"",IFERROR(E18-SUM(E19,E20,E21),"")) | F22: =IF(OR(F18=""),"",IFERROR(F18-SUM(F19,F20,F21),"")) | G22: =IF(OR(G18=""),"",IFERROR(G18-SUM(G19,G20,G21),"")) | H22: =IF(OR(H18=""),"",IFERROR(H18-SUM(H19,H20,H21),"")) | I22: =IF(OR(I18=""),"",IFERROR(I18-SUM(I19,I20,I21),"")) | J22: =IF(OR(J18=""),"",IFERROR(J18-SUM(J19,J20,J21),"")) | ... L22: =IF(OR(L18=""),"",IFERROR(L18-SUM(L19,L20,L21),""))
A23: 비유동부채 | C23: 254324 | D23: 242710 | E23: 250227 | F23: 248770 | G23: 254189 | H23: 148826 | I23: 237570 | J23: 305109 | K23: 251059 | L23: 248770
A24: 장기차입금
A25: 사채 | C25: 208418 | D25: 190089 | E25: 191378 | F25: 192245 | G25: 192471 | H25: 91275 | I25: 182725 | J25: 253864 | K25: 208654 | L25: 192245
A26: 기타비유동부채 | B26: 총계 − 위 항목 | C26: =IF(OR(C23=""),"",IFERROR(C23-SUM(C24,C25),"")) | D26: =IF(OR(D23=""),"",IFERROR(D23-SUM(D24,D25),"")) | E26: =IF(OR(E23=""),"",IFERROR(E23-SUM(E24,E25),"")) | F26: =IF(OR(F23=""),"",IFERROR(F23-SUM(F24,F25),"")) | G26: =IF(OR(G23=""),"",IFERROR(G23-SUM(G24,G25),"")) | H26: =IF(OR(H23=""),"",IFERROR(H23-SUM(H24,H25),"")) | I26: =IF(OR(I23=""),"",IFERROR(I23-SUM(I24,I25),"")) | J26: =IF(OR(J23=""),"",IFERROR(J23-SUM(J24,J25),"")) | ... L26: =IF(OR(L23=""),"",IFERROR(L23-SUM(L24,L25),""))
A27: 부채총계 | C27: 478974 | D27: 513374 | E27: 442974 | F27: 521791 | G27: 529189 | H27: 447168 | I27: 435817 | J27: 519752 | K27: 490542 | L27: 521791
A28: 총차입금 | B28: 단기+유동성장기+장기+사채 | C28: =SUM(C20,C21,C24,C25) | D28: =SUM(D20,D21,D24,D25) | E28: =SUM(E20,E21,E24,E25) | F28: =SUM(F20,F21,F24,F25) | G28: =SUM(G20,G21,G24,G25) | H28: =SUM(H20,H21,H24,H25) | I28: =SUM(I20,I21,I24,I25) | J28: =SUM(J20,J21,J24,J25) | ... L28: =SUM(L20,L21,L24,L25)
A29: 순차입금 | B29: 음수 = 순현금 | C29: =C28-C6-N(C7) | D29: =D28-D6-N(D7) | E29: =E28-E6-N(E7) | F29: =F28-F6-N(F7) | G29: =G28-G6-N(G7) | H29: =H28-H6-N(H7) | I29: =I28-I6-N(I7) | J29: =J28-J6-N(J7) | ... L29: =L28-L6-N(L7)
A30: 자본
A31: 지배주주지분 | C31: 443603 | D31: 477384 | E31: 501656 | F31: 433905 | G31: 373424 | H31: 339360 | I31: 399006 | J31: 399532 | K31: 434040 | L31: 433905
A32: 자본금 | C32: 25655 | D32: 25655 | E32: 25655 | F32: 25655 | G32: 25655 | H32: 22414 | I32: 23644 | J32: 24701 | K32: 25655 | L32: 25655
A33: 이익잉여금 | C33: 385184 | D33: 412742 | E33: 422302 | F33: 354056 | G33: 265808 | H33: 328830 | I33: 321676 | J33: 320320 | K33: 378659 | L33: 354056
A34: 비지배지분 | C34: 3622 | D34: 3754 | E34: 3908 | F34: 4097 | G34: 3775 | H34: 3126 | I34: 3399 | J34: 3489 | K34: 3918 | L34: 4097
A35: 자본총계 | C35: 447226 | D35: 481139 | E35: 505565 | F35: 438002 | G35: 377200 | H35: 342486 | I35: 402406 | J35: 403021 | K35: 437959 | L35: 438002
A36: 현금흐름 요약 | B36: 분기 = TTM (있을 때만)
A37: 영업활동현금흐름 | C37: 147245 | D37: 145208 | E37: 143423 | F37: 147641 | G37: 160201 | H37: 98137 | I37: 118899 | J37: 142277 | K37: 130196 | L37: 147641
A38: CAPEX (유·무형 취득) | B38: 양수로 입력 | C38: 50179 | D38: 50383 | E38: 48208 | F38: 46311 | G38: 45330 | H38: 42977 | I38: 54701 | J38: 49797 | K38: 49602 | L38: 46311
A39: FCF | C39: =IF(OR(C37="",C38=""),"",IFERROR(C37-C38,"")) | D39: =IF(OR(D37="",D38=""),"",IFERROR(D37-D38,"")) | E39: =IF(OR(E37="",E38=""),"",IFERROR(E37-E38,"")) | F39: =IF(OR(F37="",F38=""),"",IFERROR(F37-F38,"")) | G39: =IF(OR(G37="",G38=""),"",IFERROR(G37-G38,"")) | H39: =IF(OR(H37="",H38=""),"",IFERROR(H37-H38,"")) | I39: =IF(OR(I37="",I38=""),"",IFERROR(I37-I38,"")) | J39: =IF(OR(J37="",J38=""),"",IFERROR(J37-J38,"")) | ... L39: =IF(OR(L37="",L38=""),"",IFERROR(L37-L38,""))
A40: 배당금 지급 | B40: 양수로 입력 | C40: 36057 | D40: 36053 | E40: 39519 | F40: 39516 | G40: 44182 | H40: 22647 | I40: 25372 | J40: 27583 | K40: 33313 | L40: 39516
...

Sheet 출처
A1: 출처 · 쓴 결산단신
A3: 공시일 | B3: 문서 | C3: PDF
A4: 2026-07-30 | B4: 2027년 3월 결산기 1분기 결산단신 | C4: https://www2.jpx.co.jp/disc/43070/140120260729501398.pdf
A5: 2026-04-24 | B5: 2026년 3월 결산기 연간 결산단신 | C5: https://www2.jpx.co.jp/disc/43070/140120260423509100.pdf
A6: 2026-01-29 | B6: 2026년 3월 결산기 3분기 결산단신 | C6: https://www2.jpx.co.jp/disc/43070/140120260126538339.pdf
A7: 2025-10-30 | B7: 2026년 3월 결산기 2분기 결산단신 | C7: https://www2.jpx.co.jp/disc/43070/140120251027579313.pdf
A8: 2025-07-28 | B8: 2026년 3월 결산기 1분기 결산단신 | C8: https://www2.jpx.co.jp/disc/43070/140120250724519337.pdf
A9: 2025-04-24 | B9: 2025년 3월 결산기 연간 결산단신 | C9: https://www2.jpx.co.jp/disc/43070/140120250422519942.pdf
A10: 2025-01-30 | B10: 2025년 3월 결산기 3분기 결산단신 | C10: https://www2.jpx.co.jp/disc/43070/140120250127555598.pdf
A11: 2024-10-30 | B11: 2025년 3월 결산기 2분기 결산단신 | C11: https://www2.jpx.co.jp/disc/43070/140120241028504098.pdf
A12: 2024-07-25 | B12: 2025년 3월 결산기 1분기 결산단신 | C12: https://www2.jpx.co.jp/disc/43070/140120240723552972.pdf
A13: 2024-04-25 | B13: 2024년 3월 결산기 연간 결산단신 | C13: https://www2.jpx.co.jp/disc/43070/140120240422573620.pdf
A14: 2024-01-31 | B14: 2024년 3월 결산기 3분기 결산단신 | C14: https://www2.jpx.co.jp/disc/43070/140120240129520393.pdf
... A24: 2018-04-26 | B24: 연간 결산단신 | C24: https://www2.jpx.co.jp/disc/43070/140120180426421152.pdf
