Workbook

Sheet 연간
A1: 5257 Model
A2: 모를 땐 보수적으로 | B2: (단위: 백만엔) | C2: 12월 결산 · 일본 기준 · 2026.3Q = 2026년 12월 결산기 3분기 | Y2: (추정: 파란 글씨 = 직접 입력)
A3: 항목 | B3: 참고 | C3: 2023.4Q | D3: 2024.1Q | E3: 2024.2Q | F3: 2024.3Q | G3: 2024.4Q | H3: 2025.1Q | I3: 2025.2Q | J3: 2025.3Q | K3: 2025.4Q | L3: 2026.1Q | M3: 2026.2Q | N3: 2026.3Q | O3: 2016 | P3: 2017 | Q3: 2018 | R3: 2019 | S3: 2020 | T3: 2021 | U3: 2022 | V3: 2023 | W3: 2024 | X3: 2025 | Y3: 2026(MW) | Z3: 2027(MW) | AA3: 2028(MW) | AB3: 2029(MW) | AC3: 2030(MW)
A4: 매출액 | B4: MW 직접 입력 | C4: 1426.668 | D4: 1584.021 | E4: 1511.883 | F4: 1648.352 | G4: 1717.573 | H4: 1676.977 | I4: 1617.122 | J4: 1690.535 | K4: 1731.555 | L4: 1718.008 | M4: 1797.601 | N4: 1859.032 | U4: 4626.211 | V4: 5422.716 | W4: 6461.829 | X4: 6716.189 | Y4: =IF(COUNT(Y7)=0,"",SUM(Y7)) | Z4: =IF(COUNT(Z7)=0,"",SUM(Z7)) | AA4: =IF(COUNT(AA7)=0,"",SUM(AA7)) | AB4: =IF(COUNT(AB7)=0,"",SUM(AB7)) | AC4: =IF(COUNT(AC7)=0,"",SUM(AC7))
A5: YoY | G5: =IF(OR(G4="",C4=""),"",IFERROR(G4/C4-1,"")) | H5: =IF(OR(H4="",D4=""),"",IFERROR(H4/D4-1,"")) | I5: =IF(OR(I4="",E4=""),"",IFERROR(I4/E4-1,"")) | J5: =IF(OR(J4="",F4=""),"",IFERROR(J4/F4-1,"")) | K5: =IF(OR(K4="",G4=""),"",IFERROR(K4/G4-1,"")) | L5: =IF(OR(L4="",H4=""),"",IFERROR(L4/H4-1,"")) | M5: =IF(OR(M4="",I4=""),"",IFERROR(M4/I4-1,"")) | N5: =IF(OR(N4="",J4=""),"",IFERROR(N4/J4-1,"")) | P5: =IF(OR(P4="",O4=""),"",IFERROR(P4/O4-1,"")) | Q5: =IF(OR(Q4="",P4=""),"",IFERROR(Q4/P4-1,"")) | R5: =IF(OR(R4="",Q4=""),"",IFERROR(R4/Q4-1,"")) | S5: =IF(OR(S4="",R4=""),"",IFERROR(S4/R4-1,"")) | T5: =IF(OR(T4="",S4=""),"",IFERROR(T4/S4-1,"")) | U5: =IF(OR(U4="",T4=""),"",IFERROR(U4/T4-1,"")) | V5: =IF(OR(V4="",U4=""),"",IFERROR(V4/U4-1,"")) | W5: =IF(OR(W4="",V4=""),"",IFERROR(W4/V4-1,"")) | ... AC5: =IF(OR(AC4="",AB4=""),"",IFERROR(AC4/AB4-1,""))
A6: 제품별 매출 분류 | B6: 사업보고서 매출실적
A7: (제품별 매출 미공시 — 직접 입력)
A8: 비중 | C8: =IF(OR(C7="",C4=""),"",IFERROR(C7/C4,"")) | D8: =IF(OR(D7="",D4=""),"",IFERROR(D7/D4,"")) | E8: =IF(OR(E7="",E4=""),"",IFERROR(E7/E4,"")) | F8: =IF(OR(F7="",F4=""),"",IFERROR(F7/F4,"")) | G8: =IF(OR(G7="",G4=""),"",IFERROR(G7/G4,"")) | H8: =IF(OR(H7="",H4=""),"",IFERROR(H7/H4,"")) | I8: =IF(OR(I7="",I4=""),"",IFERROR(I7/I4,"")) | J8: =IF(OR(J7="",J4=""),"",IFERROR(J7/J4,"")) | ... AC8: =IF(OR(AC7="",AC4=""),"",IFERROR(AC7/AC4,""))
A9: YoY | G9: =IF(OR(G7="",C7=""),"",IFERROR(G7/C7-1,"")) | H9: =IF(OR(H7="",D7=""),"",IFERROR(H7/D7-1,"")) | I9: =IF(OR(I7="",E7=""),"",IFERROR(I7/E7-1,"")) | J9: =IF(OR(J7="",F7=""),"",IFERROR(J7/F7-1,"")) | K9: =IF(OR(K7="",G7=""),"",IFERROR(K7/G7-1,"")) | L9: =IF(OR(L7="",H7=""),"",IFERROR(L7/H7-1,"")) | M9: =IF(OR(M7="",I7=""),"",IFERROR(M7/I7-1,"")) | N9: =IF(OR(N7="",J7=""),"",IFERROR(N7/J7-1,"")) | P9: =IF(OR(P7="",O7=""),"",IFERROR(P7/O7-1,"")) | Q9: =IF(OR(Q7="",P7=""),"",IFERROR(Q7/P7-1,"")) | R9: =IF(OR(R7="",Q7=""),"",IFERROR(R7/Q7-1,"")) | S9: =IF(OR(S7="",R7=""),"",IFERROR(S7/R7-1,"")) | T9: =IF(OR(T7="",S7=""),"",IFERROR(T7/S7-1,"")) | U9: =IF(OR(U7="",T7=""),"",IFERROR(U7/T7-1,"")) | V9: =IF(OR(V7="",U7=""),"",IFERROR(V7/U7-1,"")) | W9: =IF(OR(W7="",V7=""),"",IFERROR(W7/V7-1,"")) | ... AC9: =IF(OR(AC7="",AB7=""),"",IFERROR(AC7/AB7-1,""))
A10: 매출원가
A11: 전체 매출원가 | C11: 1109.397 | D11: 1213.005 | E11: 1202.67 | F11: 1316.258 | G11: 1305.314 | H11: 1355.062 | I11: 1343.012 | J11: 1396.342 | K11: 1324.905 | L11: 1342.983 | M11: 1336.124 | N11: 1429.576 | U11: 3598.047 | V11: 4088.889 | W11: 5037.247 | X11: 5419.321
A12: YoY | G12: =IF(OR(G11="",C11=""),"",IF(C11<=0,"",IFERROR(G11/C11-1,""))) | H12: =IF(OR(H11="",D11=""),"",IF(D11<=0,"",IFERROR(H11/D11-1,""))) | I12: =IF(OR(I11="",E11=""),"",IF(E11<=0,"",IFERROR(I11/E11-1,""))) | J12: =IF(OR(J11="",F11=""),"",IF(F11<=0,"",IFERROR(J11/F11-1,""))) | K12: =IF(OR(K11="",G11=""),"",IF(G11<=0,"",IFERROR(K11/G11-1,""))) | L12: =IF(OR(L11="",H11=""),"",IF(H11<=0,"",IFERROR(L11/H11-1,""))) | M12: =IF(OR(M11="",I11=""),"",IF(I11<=0,"",IFERROR(M11/I11-1,""))) | N12: =IF(OR(N11="",J11=""),"",IF(J11<=0,"",IFERROR(N11/J11-1,""))) | P12: =IF(OR(P11="",O11=""),"",IF(O11<=0,"",IFERROR(P11/O11-1,""))) | Q12: =IF(OR(Q11="",P11=""),"",IF(P11<=0,"",IFERROR(Q11/P11-1,""))) | R12: =IF(OR(R11="",Q11=""),"",IF(Q11<=0,"",IFERROR(R11/Q11-1,""))) | S12: =IF(OR(S11="",R11=""),"",IF(R11<=0,"",IFERROR(S11/R11-1,""))) | T12: =IF(OR(T11="",S11=""),"",IF(S11<=0,"",IFERROR(T11/S11-1,""))) | U12: =IF(OR(U11="",T11=""),"",IF(T11<=0,"",IFERROR(U11/T11-1,""))) | V12: =IF(OR(V11="",U11=""),"",IF(U11<=0,"",IFERROR(V11/U11-1,""))) | W12: =IF(OR(W11="",V11=""),"",IF(V11<=0,"",IFERROR(W11/V11-1,""))) | ... AC12: =IF(OR(AC11="",AB11=""),"",IF(AB11<=0,"",IFERROR(AC11/AB11-1,"")))
A13: 매출총이익 | C13: =IF(OR(C4="",C11=""),"",IFERROR(C4-C11,"")) | D13: =IF(OR(D4="",D11=""),"",IFERROR(D4-D11,"")) | E13: =IF(OR(E4="",E11=""),"",IFERROR(E4-E11,"")) | F13: =IF(OR(F4="",F11=""),"",IFERROR(F4-F11,"")) | G13: =IF(OR(G4="",G11=""),"",IFERROR(G4-G11,"")) | H13: =IF(OR(H4="",H11=""),"",IFERROR(H4-H11,"")) | I13: =IF(OR(I4="",I11=""),"",IFERROR(I4-I11,"")) | J13: =IF(OR(J4="",J11=""),"",IFERROR(J4-J11,"")) | ... X13: =IF(OR(X4="",X11=""),"",IFERROR(X4-X11,""))
A14: GPM | C14: =IF(OR(C13="",C4=""),"",IFERROR(C13/C4,"")) | D14: =IF(OR(D13="",D4=""),"",IFERROR(D13/D4,"")) | E14: =IF(OR(E13="",E4=""),"",IFERROR(E13/E4,"")) | F14: =IF(OR(F13="",F4=""),"",IFERROR(F13/F4,"")) | G14: =IF(OR(G13="",G4=""),"",IFERROR(G13/G4,"")) | H14: =IF(OR(H13="",H4=""),"",IFERROR(H13/H4,"")) | I14: =IF(OR(I13="",I4=""),"",IFERROR(I13/I4,"")) | J14: =IF(OR(J13="",J4=""),"",IFERROR(J13/J4,"")) | ... AC14: =IF(OR(AC13="",AC4=""),"",IFERROR(AC13/AC4,""))
A15: YoY | G15: =IF(OR(G13="",C13=""),"",IF(C13<=0,"",IFERROR(G13/C13-1,""))) | H15: =IF(OR(H13="",D13=""),"",IF(D13<=0,"",IFERROR(H13/D13-1,""))) | I15: =IF(OR(I13="",E13=""),"",IF(E13<=0,"",IFERROR(I13/E13-1,""))) | J15: =IF(OR(J13="",F13=""),"",IF(F13<=0,"",IFERROR(J13/F13-1,""))) | K15: =IF(OR(K13="",G13=""),"",IF(G13<=0,"",IFERROR(K13/G13-1,""))) | L15: =IF(OR(L13="",H13=""),"",IF(H13<=0,"",IFERROR(L13/H13-1,""))) | M15: =IF(OR(M13="",I13=""),"",IF(I13<=0,"",IFERROR(M13/I13-1,""))) | N15: =IF(OR(N13="",J13=""),"",IF(J13<=0,"",IFERROR(N13/J13-1,""))) | P15: =IF(OR(P13="",O13=""),"",IF(O13<=0,"",IFERROR(P13/O13-1,""))) | Q15: =IF(OR(Q13="",P13=""),"",IF(P13<=0,"",IFERROR(Q13/P13-1,""))) | R15: =IF(OR(R13="",Q13=""),"",IF(Q13<=0,"",IFERROR(R13/Q13-1,""))) | S15: =IF(OR(S13="",R13=""),"",IF(R13<=0,"",IFERROR(S13/R13-1,""))) | T15: =IF(OR(T13="",S13=""),"",IF(S13<=0,"",IFERROR(T13/S13-1,""))) | U15: =IF(OR(U13="",T13=""),"",IF(T13<=0,"",IFERROR(U13/T13-1,""))) | V15: =IF(OR(V13="",U13=""),"",IF(U13<=0,"",IFERROR(V13/U13-1,""))) | W15: =IF(OR(W13="",V13=""),"",IF(V13<=0,"",IFERROR(W13/V13-1,""))) | ... AC15: =IF(OR(AC13="",AB13=""),"",IF(AB13<=0,"",IFERROR(AC13/AB13-1,"")))
A16: 판매관리비
A17: 전체 판관비 | C17: 221.552 | D17: 212.357 | E17: 260.958 | F17: 209.522 | G17: 213.559 | H17: 226.234 | I17: 281.883 | J17: 221.582 | K17: 242.406 | L17: 253.926 | M17: 308.434 | N17: 269.497 | U17: 698.094 | V17: 843.051 | W17: 896.396 | X17: 972.105
A18: YoY | G18: =IF(OR(G17="",C17=""),"",IF(C17<=0,"",IFERROR(G17/C17-1,""))) | H18: =IF(OR(H17="",D17=""),"",IF(D17<=0,"",IFERROR(H17/D17-1,""))) | I18: =IF(OR(I17="",E17=""),"",IF(E17<=0,"",IFERROR(I17/E17-1,""))) | J18: =IF(OR(J17="",F17=""),"",IF(F17<=0,"",IFERROR(J17/F17-1,""))) | K18: =IF(OR(K17="",G17=""),"",IF(G17<=0,"",IFERROR(K17/G17-1,""))) | L18: =IF(OR(L17="",H17=""),"",IF(H17<=0,"",IFERROR(L17/H17-1,""))) | M18: =IF(OR(M17="",I17=""),"",IF(I17<=0,"",IFERROR(M17/I17-1,""))) | N18: =IF(OR(N17="",J17=""),"",IF(J17<=0,"",IFERROR(N17/J17-1,""))) | P18: =IF(OR(P17="",O17=""),"",IF(O17<=0,"",IFERROR(P17/O17-1,""))) | Q18: =IF(OR(Q17="",P17=""),"",IF(P17<=0,"",IFERROR(Q17/P17-1,""))) | R18: =IF(OR(R17="",Q17=""),"",IF(Q17<=0,"",IFERROR(R17/Q17-1,""))) | S18: =IF(OR(S17="",R17=""),"",IF(R17<=0,"",IFERROR(S17/R17-1,""))) | T18: =IF(OR(T17="",S17=""),"",IF(S17<=0,"",IFERROR(T17/S17-1,""))) | U18: =IF(OR(U17="",T17=""),"",IF(T17<=0,"",IFERROR(U17/T17-1,""))) | V18: =IF(OR(V17="",U17=""),"",IF(U17<=0,"",IFERROR(V17/U17-1,""))) | W18: =IF(OR(W17="",V17=""),"",IF(V17<=0,"",IFERROR(W17/V17-1,""))) | ... AC18: =IF(OR(AC17="",AB17=""),"",IF(AB17<=0,"",IFERROR(AC17/AB17-1,"")))
A19: 영업이익 | B19: MW = 매출 × OPM | C19: 95.72 | D19: 158.657 | E19: 48.256 | F19: 122.573 | G19: 198.7 | H19: 95.68 | I19: -7.773 | J19: 72.611 | K19: 164.244 | L19: 121.098 | M19: 153.043 | N19: 159.96 | U19: 330.07 | V19: 490.776 | W19: 528.186 | X19: 324.762 | Y19: =IF(OR(Y4="",Y20=""),"",IFERROR(Y4*Y20,"")) | Z19: =IF(OR(Z4="",Z20=""),"",IFERROR(Z4*Z20,"")) | AA19: =IF(OR(AA4="",AA20=""),"",IFERROR(AA4*AA20,"")) | AB19: =IF(OR(AB4="",AB20=""),"",IFERROR(AB4*AB20,"")) | AC19: =IF(OR(AC4="",AC20=""),"",IFERROR(AC4*AC20,""))
A20: OPM | B20: MW 입력 | C20: =IF(OR(C19="",C4=""),"",IFERROR(C19/C4,"")) | D20: =IF(OR(D19="",D4=""),"",IFERROR(D19/D4,"")) | E20: =IF(OR(E19="",E4=""),"",IFERROR(E19/E4,"")) | F20: =IF(OR(F19="",F4=""),"",IFERROR(F19/F4,"")) | G20: =IF(OR(G19="",G4=""),"",IFERROR(G19/G4,"")) | H20: =IF(OR(H19="",H4=""),"",IFERROR(H19/H4,"")) | I20: =IF(OR(I19="",I4=""),"",IFERROR(I19/I4,"")) | J20: =IF(OR(J19="",J4=""),"",IFERROR(J19/J4,"")) | ... X20: =IF(OR(X19="",X4=""),"",IFERROR(X19/X4,""))
A21: 증가율 | G21: =IF(OR(G19="",C19=""),"",IFERROR(G19/C19-1,"")) | H21: =IF(OR(H19="",D19=""),"",IFERROR(H19/D19-1,"")) | I21: =IF(OR(I19="",E19=""),"",IFERROR(I19/E19-1,"")) | J21: =IF(OR(J19="",F19=""),"",IFERROR(J19/F19-1,"")) | K21: =IF(OR(K19="",G19=""),"",IFERROR(K19/G19-1,"")) | L21: =IF(OR(L19="",H19=""),"",IFERROR(L19/H19-1,"")) | M21: =IF(OR(M19="",I19=""),"",IFERROR(M19/I19-1,"")) | N21: =IF(OR(N19="",J19=""),"",IFERROR(N19/J19-1,"")) | P21: =IF(OR(P19="",O19=""),"",IFERROR(P19/O19-1,"")) | Q21: =IF(OR(Q19="",P19=""),"",IFERROR(Q19/P19-1,"")) | R21: =IF(OR(R19="",Q19=""),"",IFERROR(R19/Q19-1,"")) | S21: =IF(OR(S19="",R19=""),"",IFERROR(S19/R19-1,"")) | T21: =IF(OR(T19="",S19=""),"",IFERROR(T19/S19-1,"")) | U21: =IF(OR(U19="",T19=""),"",IFERROR(U19/T19-1,"")) | V21: =IF(OR(V19="",U19=""),"",IFERROR(V19/U19-1,"")) | W21: =IF(OR(W19="",V19=""),"",IFERROR(W19/V19-1,"")) | ... AC21: =IF(OR(AC19="",AB19=""),"",IFERROR(AC19/AB19-1,""))
A22: 비용의 성격별 분류 | B22: 참고 데이터
A23: 총 판관비 | O23: =IF(O17="","",O17) | P23: =IF(P17="","",P17) | Q23: =IF(Q17="","",Q17) | R23: =IF(R17="","",R17) | S23: =IF(S17="","",S17) | T23: =IF(T17="","",T17) | U23: =IF(U17="","",U17) | V23: =IF(V17="","",V17) | ... X23: =IF(X17="","",X17)
A24: 급여 | B24: 고정비
A25: % of Sales | O25: =IF(OR(O24="",O4=""),"",IFERROR(O24/O4,"")) | P25: =IF(OR(P24="",P4=""),"",IFERROR(P24/P4,"")) | Q25: =IF(OR(Q24="",Q4=""),"",IFERROR(Q24/Q4,"")) | R25: =IF(OR(R24="",R4=""),"",IFERROR(R24/R4,"")) | S25: =IF(OR(S24="",S4=""),"",IFERROR(S24/S4,"")) | T25: =IF(OR(T24="",T4=""),"",IFERROR(T24/T4,"")) | U25: =IF(OR(U24="",U4=""),"",IFERROR(U24/U4,"")) | V25: =IF(OR(V24="",V4=""),"",IFERROR(V24/V4,"")) | ... X25: =IF(OR(X24="",X4=""),"",IFERROR(X24/X4,""))
A26: 감가상각비 | B26: 고정비
A27: % of Sales | O27: =IF(OR(O26="",O4=""),"",IFERROR(O26/O4,"")) | P27: =IF(OR(P26="",P4=""),"",IFERROR(P26/P4,"")) | Q27: =IF(OR(Q26="",Q4=""),"",IFERROR(Q26/Q4,"")) | R27: =IF(OR(R26="",R4=""),"",IFERROR(R26/R4,"")) | S27: =IF(OR(S26="",S4=""),"",IFERROR(S26/S4,"")) | T27: =IF(OR(T26="",T4=""),"",IFERROR(T26/T4,"")) | U27: =IF(OR(U26="",U4=""),"",IFERROR(U26/U4,"")) | V27: =IF(OR(V26="",V4=""),"",IFERROR(V26/V4,"")) | ... X27: =IF(OR(X26="",X4=""),"",IFERROR(X26/X4,""))
A28: 지급수수료 | B28: 고정비
A29: % of Sales | O29: =IF(OR(O28="",O4=""),"",IFERROR(O28/O4,"")) | P29: =IF(OR(P28="",P4=""),"",IFERROR(P28/P4,"")) | Q29: =IF(OR(Q28="",Q4=""),"",IFERROR(Q28/Q4,"")) | R29: =IF(OR(R28="",R4=""),"",IFERROR(R28/R4,"")) | S29: =IF(OR(S28="",S4=""),"",IFERROR(S28/S4,"")) | T29: =IF(OR(T28="",T4=""),"",IFERROR(T28/T4,"")) | U29: =IF(OR(U28="",U4=""),"",IFERROR(U28/U4,"")) | V29: =IF(OR(V28="",V4=""),"",IFERROR(V28/V4,"")) | ... X29: =IF(OR(X28="",X4=""),"",IFERROR(X28/X4,""))
A30: 연구개발비 | B30: 변동비
A31: % of Sales | O31: =IF(OR(O30="",O4=""),"",IFERROR(O30/O4,"")) | P31: =IF(OR(P30="",P4=""),"",IFERROR(P30/P4,"")) | Q31: =IF(OR(Q30="",Q4=""),"",IFERROR(Q30/Q4,"")) | R31: =IF(OR(R30="",R4=""),"",IFERROR(R30/R4,"")) | S31: =IF(OR(S30="",S4=""),"",IFERROR(S30/S4,"")) | T31: =IF(OR(T30="",T4=""),"",IFERROR(T30/T4,"")) | U31: =IF(OR(U30="",U4=""),"",IFERROR(U30/U4,"")) | V31: =IF(OR(V30="",V4=""),"",IFERROR(V30/V4,"")) | ... X31: =IF(OR(X30="",X4=""),"",IFERROR(X30/X4,""))
A32: 기타비용 | B32: 변동비 | O32: =IF(OR(O23="",O24="",O26="",O28="",O30=""),"",IFERROR(O23-O24-O26-O28-O30,"")) | P32: =IF(OR(P23="",P24="",P26="",P28="",P30=""),"",IFERROR(P23-P24-P26-P28-P30,"")) | Q32: =IF(OR(Q23="",Q24="",Q26="",Q28="",Q30=""),"",IFERROR(Q23-Q24-Q26-Q28-Q30,"")) | R32: =IF(OR(R23="",R24="",R26="",R28="",R30=""),"",IFERROR(R23-R24-R26-R28-R30,"")) | S32: =IF(OR(S23="",S24="",S26="",S28="",S30=""),"",IFERROR(S23-S24-S26-S28-S30,"")) | T32: =IF(OR(T23="",T24="",T26="",T28="",T30=""),"",IFERROR(T23-T24-T26-T28-T30,"")) | U32: =IF(OR(U23="",U24="",U26="",U28="",U30=""),"",IFERROR(U23-U24-U26-U28-U30,"")) | V32: =IF(OR(V23="",V24="",V26="",V28="",V30=""),"",IFERROR(V23-V24-V26-V28-V30,"")) | ... X32: =IF(OR(X23="",X24="",X26="",X28="",X30=""),"",IFERROR(X23-X24-X26-X28-X30,""))
A33: % of Sales | O33: =IF(OR(O32="",O4=""),"",IFERROR(O32/O4,"")) | P33: =IF(OR(P32="",P4=""),"",IFERROR(P32/P4,"")) | Q33: =IF(OR(Q32="",Q4=""),"",IFERROR(Q32/Q4,"")) | R33: =IF(OR(R32="",R4=""),"",IFERROR(R32/R4,"")) | S33: =IF(OR(S32="",S4=""),"",IFERROR(S32/S4,"")) | T33: =IF(OR(T32="",T4=""),"",IFERROR(T32/T4,"")) | U33: =IF(OR(U32="",U4=""),"",IFERROR(U32/U4,"")) | V33: =IF(OR(V32="",V4=""),"",IFERROR(V32/V4,"")) | ... X33: =IF(OR(X32="",X4=""),"",IFERROR(X32/X4,""))
A34: 당기순이익 추정
A35: 특별이익 | F35: 0 | G35: 0.909 | H35: 0 | I35: 0.378 | J35: 0 | K35: 0 | L35: 1.174 | M35: 0 | N35: 0 | U35: 0 | V35: 3.997 | W35: 0.909 | X35: 0.378 | Y35: =IF(OR(Y4="",Y36=""),"",IFERROR(Y4*Y36,"")) | Z35: =IF(OR(Z4="",Z36=""),"",IFERROR(Z4*Z36,"")) | AA35: =IF(OR(AA4="",AA36=""),"",IFERROR(AA4*AA36,"")) | AB35: =IF(OR(AB4="",AB36=""),"",IFERROR(AB4*AB36,"")) | AC35: =IF(OR(AC4="",AC36=""),"",IFERROR(AC4*AC36,""))
A36: % of Sales | B36: MW = 최근 3년 평균 | C36: =IF(OR(C35="",C4=""),"",IFERROR(C35/C4,"")) | D36: =IF(OR(D35="",D4=""),"",IFERROR(D35/D4,"")) | E36: =IF(OR(E35="",E4=""),"",IFERROR(E35/E4,"")) | F36: =IF(OR(F35="",F4=""),"",IFERROR(F35/F4,"")) | G36: =IF(OR(G35="",G4=""),"",IFERROR(G35/G4,"")) | H36: =IF(OR(H35="",H4=""),"",IFERROR(H35/H4,"")) | I36: =IF(OR(I35="",I4=""),"",IFERROR(I35/I4,"")) | J36: =IF(OR(J35="",J4=""),"",IFERROR(J35/J4,"")) | ... X36: =IF(OR(X35="",X4=""),"",IFERROR(X35/X4,"")) | Y36: =IFERROR(AVERAGE(V36,W36,X36),"") | Z36: =Y36 | AA36: =Z36 | AB36: =AA36 | AC36: =AB36
A37: 특별손실 | C37: 1.268 | H37: 0 | I37: 0 | J37: 0 | K37: 16.288 | L37: 22.5 | M37: 1.111 | N37: 4.282 | U37: 2.618 | V37: 1.268 | W37: 12.952 | X37: 16.288 | Y37: =IF(OR(Y4="",Y38=""),"",IFERROR(Y4*Y38,"")) | Z37: =IF(OR(Z4="",Z38=""),"",IFERROR(Z4*Z38,"")) | AA37: =IF(OR(AA4="",AA38=""),"",IFERROR(AA4*AA38,"")) | AB37: =IF(OR(AB4="",AB38=""),"",IFERROR(AB4*AB38,"")) | AC37: =IF(OR(AC4="",AC38=""),"",IFERROR(AC4*AC38,""))
A38: % of Sales | C38: =IF(OR(C37="",C4=""),"",IFERROR(C37/C4,"")) | D38: =IF(OR(D37="",D4=""),"",IFERROR(D37/D4,"")) | E38: =IF(OR(E37="",E4=""),"",IFERROR(E37/E4,"")) | F38: =IF(OR(F37="",F4=""),"",IFERROR(F37/F4,"")) | G38: =IF(OR(G37="",G4=""),"",IFERROR(G37/G4,"")) | H38: =IF(OR(H37="",H4=""),"",IFERROR(H37/H4,"")) | I38: =IF(OR(I37="",I4=""),"",IFERROR(I37/I4,"")) | J38: =IF(OR(J37="",J4=""),"",IFERROR(J37/J4,"")) | ... X38: =IF(OR(X37="",X4=""),"",IFERROR(X37/X4,"")) | Y38: =IFERROR(AVERAGE(V38,W38,X38),"") | Z38: =Y38 | AA38: =Z38 | AB38: =AA38 | AC38: =AB38
A39: 영업외수익 | C39: 5.814 | D39: 2.777 | E39: 7.217 | F39: 3.467 | G39: 14.365 | H39: 12.953 | I39: 7.225 | J39: 4.921 | K39: 25.524 | L39: 5.009 | M39: 8.797 | N39: 11.329 | U39: 18.577 | V39: 18.128 | W39: 27.826 | X39: 50.623 | Y39: =IF(OR(Y4="",Y40=""),"",IFERROR(Y4*Y40,"")) | Z39: =IF(OR(Z4="",Z40=""),"",IFERROR(Z4*Z40,"")) | AA39: =IF(OR(AA4="",AA40=""),"",IFERROR(AA4*AA40,"")) | AB39: =IF(OR(AB4="",AB40=""),"",IFERROR(AB4*AB40,"")) | AC39: =IF(OR(AC4="",AC40=""),"",IFERROR(AC4*AC40,""))
A40: % of Sales | C40: =IF(OR(C39="",C4=""),"",IFERROR(C39/C4,"")) | D40: =IF(OR(D39="",D4=""),"",IFERROR(D39/D4,"")) | E40: =IF(OR(E39="",E4=""),"",IFERROR(E39/E4,"")) | F40: =IF(OR(F39="",F4=""),"",IFERROR(F39/F4,"")) | G40: =IF(OR(G39="",G4=""),"",IFERROR(G39/G4,"")) | H40: =IF(OR(H39="",H4=""),"",IFERROR(H39/H4,"")) | I40: =IF(OR(I39="",I4=""),"",IFERROR(I39/I4,"")) | J40: =IF(OR(J39="",J4=""),"",IFERROR(J39/J4,"")) | ... X40: =IF(OR(X39="",X4=""),"",IFERROR(X39/X4,"")) | Y40: =IFERROR(AVERAGE(V40,W40,X40),"") | Z40: =Y40 | AA40: =Z40 | AB40: =AA40 | AC40: =AB40
...

Sheet 재무상태표
A1: 5257 재무상태표
A2: 재무비율은 기말 잔액 기준 · 분기 손익은 최근 4분기 합산(TTM) | B2: (단위: 백만엔)
A3: 항목 | B3: 참고 | C3: 2025.3Q | D3: 2025.4Q | E3: 2026.1Q | F3: 2026.2Q | G3: 2026.3Q | H3: 2022 | I3: 2023 | J3: 2024 | K3: 2025
A4: 자산
A5: 유동자산 | C5: 1929.203 | D5: 1994.664 | E5: 2229.164 | F5: 2053.709 | G5: 2025.228 | H5: 1487.786 | I5: 1981.817 | J5: 2189.405 | K5: 1994.664
A6: 현금및현금성자산 | C6: 721.249 | D6: 732.866 | E6: 1110.658 | F6: 896.554 | G6: 737.719 | H6: 633.554 | I6: 898.688 | J6: 758.979 | K6: 732.866
A7: 단기금융상품
A8: 매출채권 | C8: 1127.434 | D8: 1198.613 | E8: 1052.535 | F8: 1078.045 | G8: 1188.498 | H8: 782.733 | I8: 1016.396 | J8: 1374.371 | K8: 1198.613
A9: 재고자산 | C9: 15.878 | D9: 21.071 | E9: 25.046 | F9: 26.11 | G9: 26.536 | H9: 38.918 | I9: 28.185 | J9: 14.743 | K9: 21.071
A10: 기타유동자산 | B10: 총계 − 위 항목 | C10: =IF(OR(C5=""),"",IFERROR(C5-SUM(C6,C7,C8,C9),"")) | D10: =IF(OR(D5=""),"",IFERROR(D5-SUM(D6,D7,D8,D9),"")) | E10: =IF(OR(E5=""),"",IFERROR(E5-SUM(E6,E7,E8,E9),"")) | F10: =IF(OR(F5=""),"",IFERROR(F5-SUM(F6,F7,F8,F9),"")) | G10: =IF(OR(G5=""),"",IFERROR(G5-SUM(G6,G7,G8,G9),"")) | H10: =IF(OR(H5=""),"",IFERROR(H5-SUM(H6,H7,H8,H9),"")) | I10: =IF(OR(I5=""),"",IFERROR(I5-SUM(I6,I7,I8,I9),"")) | J10: =IF(OR(J5=""),"",IFERROR(J5-SUM(J6,J7,J8,J9),"")) | K10: =IF(OR(K5=""),"",IFERROR(K5-SUM(K6,K7,K8,K9),""))
A11: 비유동자산 | C11: 2056.76 | D11: 2093.009 | E11: 2005.244 | F11: 2124.31 | G11: 2174.179 | H11: 1299.173 | I11: 1400.702 | J11: 1541.072 | K11: 2093.009
A12: 유형자산 | C12: 1352.109 | D12: 1353.908 | E12: 1459.674 | F12: 1461.624 | G12: 1441.524 | H12: 863.192 | I12: 1003.389 | J12: 966.751 | K12: 1353.908
A13: 무형자산 | C13: 7.252 | D13: 6.532 | E13: 5.839 | F13: 5.197 | G13: 4.556 | H13: 19.218 | I13: 15.733 | J13: 10.574 | K13: 6.532
A14: 투자부동산
A15: 기타비유동자산 | B15: 총계 − 위 항목 | C15: =IF(OR(C11=""),"",IFERROR(C11-SUM(C12,C13,C14),"")) | D15: =IF(OR(D11=""),"",IFERROR(D11-SUM(D12,D13,D14),"")) | E15: =IF(OR(E11=""),"",IFERROR(E11-SUM(E12,E13,E14),"")) | F15: =IF(OR(F11=""),"",IFERROR(F11-SUM(F12,F13,F14),"")) | G15: =IF(OR(G11=""),"",IFERROR(G11-SUM(G12,G13,G14),"")) | H15: =IF(OR(H11=""),"",IFERROR(H11-SUM(H12,H13,H14),"")) | I15: =IF(OR(I11=""),"",IFERROR(I11-SUM(I12,I13,I14),"")) | J15: =IF(OR(J11=""),"",IFERROR(J11-SUM(J12,J13,J14),"")) | K15: =IF(OR(K11=""),"",IFERROR(K11-SUM(K12,K13,K14),""))
A16: 자산총계 | C16: 3985.963 | D16: 4087.674 | E16: 4234.409 | F16: 4178.02 | G16: 4199.407 | H16: 2786.959 | I16: 3382.52 | J16: 3730.478 | K16: 4087.674
A17: 부채
A18: 유동부채 | C18: 1058.283 | D18: 1042.954 | E18: 1233.554 | F18: 1140.273 | G18: 1198.055 | H18: 1059.296 | I18: 980.647 | J18: 1043.657 | K18: 1042.954
A19: 매입채무 | C19: 192.584 | D19: 193.018 | E19: 182.861 | F19: 192.448 | G19: 207.13 | H19: 117.475 | I19: 157.643 | J19: 211.777 | K19: 193.018
A20: 단기차입금
A21: 유동성장기부채 | C21: 400.232 | D21: 376.923 | E21: 521.318 | F21: 494.573 | G21: 465.079 | H21: 465.292 | I21: 411.946 | J21: 308.202 | K21: 376.923
A22: 기타유동부채 | B22: 총계 − 위 항목 | C22: =IF(OR(C18=""),"",IFERROR(C18-SUM(C19,C20,C21),"")) | D22: =IF(OR(D18=""),"",IFERROR(D18-SUM(D19,D20,D21),"")) | E22: =IF(OR(E18=""),"",IFERROR(E18-SUM(E19,E20,E21),"")) | F22: =IF(OR(F18=""),"",IFERROR(F18-SUM(F19,F20,F21),"")) | G22: =IF(OR(G18=""),"",IFERROR(G18-SUM(G19,G20,G21),"")) | H22: =IF(OR(H18=""),"",IFERROR(H18-SUM(H19,H20,H21),"")) | I22: =IF(OR(I18=""),"",IFERROR(I18-SUM(I19,I20,I21),"")) | J22: =IF(OR(J18=""),"",IFERROR(J18-SUM(J19,J20,J21),"")) | K22: =IF(OR(K18=""),"",IFERROR(K18-SUM(K19,K20,K21),""))
A23: 비유동부채 | C23: 518.229 | D23: 492.787 | E23: 653.538 | F23: 603.102 | G23: 478.229 | H23: 564.641 | I23: 604.7 | J23: 452.836 | K23: 492.787
A24: 장기차입금 | C24: 390.97 | D24: 307.026 | E24: 539.209 | F24: 432.571 | G24: 328.682 | H24: 387.359 | I24: 482.124 | J24: 320.032 | K24: 307.026
A25: 사채 | H25: 50 | I25: 0
A26: 기타비유동부채 | B26: 총계 − 위 항목 | C26: =IF(OR(C23=""),"",IFERROR(C23-SUM(C24,C25),"")) | D26: =IF(OR(D23=""),"",IFERROR(D23-SUM(D24,D25),"")) | E26: =IF(OR(E23=""),"",IFERROR(E23-SUM(E24,E25),"")) | F26: =IF(OR(F23=""),"",IFERROR(F23-SUM(F24,F25),"")) | G26: =IF(OR(G23=""),"",IFERROR(G23-SUM(G24,G25),"")) | H26: =IF(OR(H23=""),"",IFERROR(H23-SUM(H24,H25),"")) | I26: =IF(OR(I23=""),"",IFERROR(I23-SUM(I24,I25),"")) | J26: =IF(OR(J23=""),"",IFERROR(J23-SUM(J24,J25),"")) | K26: =IF(OR(K23=""),"",IFERROR(K23-SUM(K24,K25),""))
A27: 부채총계 | C27: 1576.513 | D27: 1535.742 | E27: 1887.093 | F27: 1743.375 | G27: 1676.285 | H27: 1623.937 | I27: 1585.347 | J27: 1496.493 | K27: 1535.742
A28: 총차입금 | B28: 단기+유동성장기+장기+사채 | C28: =SUM(C20,C21,C24,C25) | D28: =SUM(D20,D21,D24,D25) | E28: =SUM(E20,E21,E24,E25) | F28: =SUM(F20,F21,F24,F25) | G28: =SUM(G20,G21,G24,G25) | H28: =SUM(H20,H21,H24,H25) | I28: =SUM(I20,I21,I24,I25) | J28: =SUM(J20,J21,J24,J25) | K28: =SUM(K20,K21,K24,K25)
A29: 순차입금 | B29: 음수 = 순현금 | C29: =C28-C6-N(C7) | D29: =D28-D6-N(D7) | E29: =E28-E6-N(E7) | F29: =F28-F6-N(F7) | G29: =G28-G6-N(G7) | H29: =H28-H6-N(H7) | I29: =I28-I6-N(I7) | J29: =J28-J6-N(J7) | K29: =K28-K6-N(K7)
A30: 자본
A31: 지배주주지분 | C31: 2409.45 | D31: 2551.931 | E31: 2347.315 | F31: 2434.644 | G31: 2523.122 | H31: 1163.022 | I31: 1797.172 | J31: 2233.984 | K31: 2551.931
A32: 자본금 | C32: 298.105 | D32: 298.105 | E32: 298.105 | F32: 298.105 | G32: 298.105 | H32: 139.75 | I32: 298.105 | J32: 298.105 | K32: 298.105
A33: 이익잉여금 | C33: 1559.008 | D33: 1661.604 | E33: 1584.359 | F33: 1689.896 | G33: 1791.997 | H33: 702.498 | I33: 1044.734 | J33: 1439.41 | K33: 1661.604
A34: 비지배지분
A35: 자본총계 | C35: 2409.45 | D35: 2551.931 | E35: 2347.315 | F35: 2434.644 | G35: 2523.122 | H35: 1163.022 | I35: 1797.172 | J35: 2233.984 | K35: 2551.931
A36: 현금흐름 요약 | B36: 분기 = TTM (있을 때만)
A37: 영업활동현금흐름 | D37: 401.199 | F37: 690.335 | H37: 80.143 | I37: 145.01 | J37: 253.242 | K37: 401.199
A38: CAPEX (유·무형 취득) | B38: 양수로 입력 | D38: 440.458 | F38: 130.117 | H38: 390.63 | I38: 211.208 | J38: 18.511 | K38: 440.458
A39: FCF | C39: =IF(OR(C37="",C38=""),"",IFERROR(C37-C38,"")) | D39: =IF(OR(D37="",D38=""),"",IFERROR(D37-D38,"")) | E39: =IF(OR(E37="",E38=""),"",IFERROR(E37-E38,"")) | F39: =IF(OR(F37="",F38=""),"",IFERROR(F37-F38,"")) | G39: =IF(OR(G37="",G38=""),"",IFERROR(G37-G38,"")) | H39: =IF(OR(H37="",H38=""),"",IFERROR(H37-H38,"")) | I39: =IF(OR(I37="",I38=""),"",IFERROR(I37-I38,"")) | J39: =IF(OR(J37="",J38=""),"",IFERROR(J37-J38,"")) | K39: =IF(OR(K37="",K38=""),"",IFERROR(K37-K38,""))
A40: 배당금 지급 | B40: 양수로 입력
...

Sheet 섹터 데이터
A1: 5257 섹터·사업 데이터
A2: 2단계 보고서를 만들 때 모은 자료 · 월차 · 출처는 맨 오른쪽
A4: this_results · q3_standalone_억엔
A5: 항목 | B5: 값 | N5: 출처
A6: 매출 | B6: 18.59 | N6: 2단계 보고서 자료(회사 설명회 자료·공시)
A7: 영업이익 | B7: 1.6
A8: 경상이익 | B8: 1.67
A9: 순이익 | B9: 1.12
A10: EPS_엔 | B10: 80.96
A11: OPM_% | B11: 8.6
A12: YoY_매출_% | B12: 10
A14: this_results · ytd_9m_백만엔
A15: 항목 | B15: 값 | N15: 출처
A16: 매출 | B16: 5374.6 | N16: 2단계 보고서 자료(회사 설명회 자료·공시)
A17: YoY | B17: 7.8
A18: SI매출 | B18: 5285.2
A19: SI YoY | B19: 7.8
A20: 클라우드매출 | B20: 89.5
A21: 클라우드_YoY | B21: 6.7
A22: 매출원가 | B22: 4108.7
A23: 매출총이익 | B23: 1266
A24: GP YoY | B24: 42.2
A25: 판관비 | B25: 831.9
A26: 판관비_YoY | B26: 14
A27: 영업이익 | B27: 434.1
A28: 영업이익 YoY | B28: 170.4
... A36: 감가상각비 | B36: 61.5
A38: this_results · ytd_prev_9m_백만엔
A39: 항목 | B39: 값 | N39: 출처
A40: 매출 | B40: 4984.6 | N40: 2단계 보고서 자료(회사 설명회 자료·공시)
A41: 매출원가 | B41: 4094.4
A42: 매출총이익 | B42: 890.2
A43: 판관비 | B43: 729.7
A44: 영업이익 | B44: 160.5
A45: 경상이익 | B45: 179.9
A46: 특별이익 | B46: 0.4
A47: 세전 | B47: 180.3
A48: 법인세등 | B48: 60.2
A49: 순이익 | B49: 120.1
A51: this_results · guidance_FY26_백만엔
...

Sheet 출처
A1: 출처 · 쓴 결산단신
A3: 공시일 | B3: 문서 | C3: PDF
A4: 2026-10-30 | B4: 2026년 12월 결산기 ３분기 결산단신 | C4: https://www2.jpx.co.jp/disc/52570/140120261029558756.pdf
A5: 2026-07-31 | B5: 2026년 12월 결산기 ２분기 결산단신 | C5: https://www2.jpx.co.jp/disc/52570/140120260731504310.pdf
A6: 2026-04-30 | B6: 2026년 12월 결산기 １분기 결산단신 | C6: https://www2.jpx.co.jp/disc/52570/140120260428513795.pdf
A7: 2026-02-13 | B7: 2025년 12월 결산기 연간 결산단신 | C7: https://www2.jpx.co.jp/disc/52570/140120260213559062.pdf
A8: 2025-10-31 | B8: 2025년 12월 결산기 ３분기 결산단신 | C8: https://www2.jpx.co.jp/disc/52570/140120251030582916.pdf
A9: 2025-07-31 | B9: 2025년 12월 결산기 ２분기 결산단신 | C9: https://www2.jpx.co.jp/disc/52570/140120250730524474.pdf
A10: 2025-05-02 | B10: 2025년 12월 결산기 １분기 결산단신 | C10: https://www2.jpx.co.jp/disc/52570/140120250501529021.pdf
A11: 2025-04-30 | B11: 2025년 12월 결산기 １분기 결산단신 | C11: https://www2.jpx.co.jp/disc/52570/140120250425524884.pdf
A12: 2025-02-13 | B12: 2024년 12월 결산기 연간 결산단신 | C12: https://www2.jpx.co.jp/disc/52570/140120250213572288.pdf
A13: 2024-10-31 | B13: 2024년 12월 결산기 ３분기 결산단신 | C13: https://www2.jpx.co.jp/disc/52570/140120241030506335.pdf
A14: 2024-07-31 | B14: 2024년 12월 결산기 ２분기 결산단신 | C14: https://www2.jpx.co.jp/disc/52570/140120240730557856.pdf
... A19: 2023-04-28 | B19: 2023년 12월 결산기 １분기 결산단신 | C19: https://www2.jpx.co.jp/disc/52570/140120230426553659.pdf

Sheet 재무제표 한눈에 보기
A1: 5257 재무제표 한눈에 보기 — 최근 40개 분기(달력 분기, 3Q26 = 26.7~9) · 단위 억 엔
A2: 출처: 매출·영업이익 결산단신 XBRL · 재무상태표 등 결산단신 XBRL 16건(2023-04-28~2026-10-30). 부문·지역·수주·수출은 있을 때만(출처는 줄 끝). 총 차입금 = 이자 붙는 부채 전부(단기·장기 차입금, CP, 사채·전환사채, 리스부채)
A4: 항목 | B4: 4Q16 | C4: 1Q17 | D4: 2Q17 | E4: 3Q17 | F4: 4Q17 | G4: 1Q18 | H4: 2Q18 | I4: 3Q18 | J4: 4Q18 | K4: 1Q19 | L4: 2Q19 | M4: 3Q19 | N4: 4Q19 | O4: 1Q20 | P4: 2Q20 | Q4: 3Q20 | R4: 4Q20 | S4: 1Q21 | T4: 2Q21 | U4: 3Q21 | V4: 4Q21 | W4: 1Q22 | X4: 2Q22 | Y4: 3Q22 | Z4: 4Q22 | AA4: 1Q23 | AB4: 2Q23 | AC4: 3Q23 | AD4: 4Q23 | AE4: 1Q24 | AF4: 2Q24 | AG4: 3Q24 | AH4: 4Q24 | AI4: 1Q25 | AJ4: 2Q25 | AK4: 3Q25 | AL4: 4Q25 | AM4: 1Q26 | AN4: 2Q26 | AO4: 3Q26 | AP4: 출처
A5: 매출액 | Z5: 12.8 | AA5: 13.3 | AB5: 12.6 | AC5: 14.1 | AD5: 14.3 | AE5: 15.8 | AF5: 15.1 | AG5: 16.5 | AH5: 17.2 | AI5: 16.8 | AJ5: 16.2 | AK5: 16.9 | AL5: 17.3 | AM5: 17.2 | AN5: 18 | AO5: 18.6
A6: 매출액 YoY | AD6: 11.7 | AE6: 18.8 | AF6: 19.8 | AG6: 17 | AH6: 20.3 | AI6: 6.3 | AJ6: 7.3 | AK6: 2.4 | AL6: 0.6 | AM6: 2.4 | AN6: 11.1 | AO6: 10.1
A7: 영업이익 | Z7: 1.4 | AA7: 1.7 | AB7: 0.7 | AC7: 1.6 | AD7: 1 | AE7: 1.6 | AF7: 0.5 | AG7: 1.2 | AH7: 2 | AI7: 1 | AJ7: -0.1 | AK7: 0.7 | AL7: 1.6 | AM7: 1.2 | AN7: 1.5 | AO7: 1.6
A8: 영업이익률 | Z8: 10.9 | AA8: 12.8 | AB8: 5.6 | AC8: 11.3 | AD8: 7 | AE8: 10.1 | AF8: 3.3 | AG8: 7.3 | AH8: 11.6 | AI8: 6 | AJ8: -0.6 | AK8: 4.1 | AL8: 9.2 | AM8: 7 | AN8: 8.3 | AO8: 8.6
A9: 영업이익 YoY | AD9: -28.6 | AE9: -5.9 | AF9: -28.6 | AG9: -25 | AH9: 100 | AI9: -37.5 | AJ9: -120 | AK9: -41.7 | AL9: -20 | AM9: 20 | AO9: 128.6
A10: 유동자산 | Z10: 14.9 | AA10: 19.5 | AB10: 18.4 | AC10: 19.3 | AD10: 19.8 | AE10: 22.4 | AF10: 21.8 | AG10: 21.2 | AH10: 21.9 | AI10: 24.5 | AJ10: 19.8 | AK10: 19.3 | AL10: 19.9 | AM10: 22.3 | AN10: 20.5 | AO10: 20.3
A11: 유동부채 | Z11: 10.6 | AA11: 9.9 | AB11: 8.8 | AC11: 10 | AD11: 9.8 | AE11: 11 | AF11: 10.5 | AG11: 9.9 | AH11: 10.4 | AI11: 11.1 | AJ11: 10.3 | AK11: 10.6 | AL11: 10.4 | AM11: 12.3 | AN11: 11.4 | AO11: 12
A12: 부채총계 | Z12: 16.2 | AA12: 18.4 | AB12: 16.8 | AC12: 16.6 | AD12: 15.9 | AE12: 17.3 | AF12: 16.1 | AG12: 14.7 | AH12: 15 | AI12: 17.3 | AJ12: 16.8 | AK12: 15.8 | AL12: 15.4 | AM12: 18.9 | AN12: 17.4 | AO12: 16.8
A13: 자기자본 | Z13: 11.6 | AA13: 15 | AB13: 16.4 | AC13: 17.3 | AD13: 18 | AE13: 19.2 | AF13: 19.4 | AG13: 20.6 | AH13: 22.3 | AI13: 23.1 | AJ13: 23.6 | AK13: 24.1 | AL13: 25.5 | AM13: 23.5 | AN13: 24.3 | AO13: 25.2
A14: 유동비율 | Z14: 140.6 | AA14: 197 | AB14: 209.1 | AC14: 193 | AD14: 202 | AE14: 203.6 | AF14: 207.6 | AG14: 214.1 | AH14: 210.6 | AI14: 220.7 | AJ14: 192.2 | AK14: 182.1 | AL14: 191.3 | AM14: 181.3 | AN14: 179.8 | AO14: 169.2
A15: 부채비율 | Z15: 139.7 | AA15: 122.7 | AB15: 102.4 | AC15: 96 | AD15: 88.3 | AE15: 90.1 | AF15: 83 | AG15: 71.4 | AH15: 67.3 | AI15: 74.9 | AJ15: 71.2 | AK15: 65.6 | AL15: 60.4 | AM15: 80.4 | AN15: 71.6 | AO15: 66.7
A16: 순차입금/자기자본 | Z16: 23.3 | AA16: 8 | AB16: 10.4 | AC16: 4 | AD16: -0.6 | AE16: -2.6 | AF16: -4.6 | AG16: -7.8 | AH16: -5.8 | AI16: -14.7 | AJ16: 13.6 | AK16: 2.9 | AL16: -1.6 | AM16: -2.1 | AN16: 0.8 | AO16: 2.4
A17: 재고자산 | Z17: 0.4 | AA17: 0.3 | AB17: 0.4 | AC17: 0.4 | AD17: 0.3 | AE17: 0.3 | AF17: 0.2 | AG17: 0.2 | AH17: 0.1 | AI17: 0.1 | AJ17: 0.1 | AK17: 0.2 | AL17: 0.2 | AM17: 0.3 | AN17: 0.3 | AO17: 0.3
A18: 재고자산 회전일수 | Z18: 4 | AA18: 3 | AB18: 4 | AC18: 3 | AD18: 2 | AE18: 2 | AF18: 2 | AG18: 1 | AH18: 1 | AI18: 1 | AJ18: 1 | AK18: 1 | AL18: 1 | AM18: 2 | AN18: 2 | AO18: 2
A19: 매출채권 회전일수 | Z19: 55 | AA19: 55 | AB19: 61 | AC19: 61 | AD19: 65 | AE19: 69 | AF19: 72 | AG19: 67 | AH19: 72 | AI19: 61 | AJ19: 75 | AK19: 61 | AL19: 63 | AM19: 56 | AN19: 55 | AO19: 58
A20: 매입채무 회전일수 | Z20: 11 | AA20: 13 | AB20: 12 | AC20: 12 | AD20: 13 | AE20: 17 | AF20: 15 | AG20: 14 | AH20: 15 | AI20: 14 | AJ20: 15 | AK20: 12 | AL20: 13 | AM20: 12 | AN20: 13 | AO20: 13
A21: 현금전환주기(CCC) | Z21: 48 | AA21: 45 | AB21: 53 | AC21: 52 | AD21: 54 | AE21: 54 | AF21: 59 | AG21: 54 | AH21: 58 | AI21: 48 | AJ21: 61 | AK21: 50 | AL21: 51 | AM21: 46 | AN21: 44 | AO21: 47
... A23: 현금 | Z23: 6.3 | AA23: 10.7 | AB23: 9.3 | AC23: 9.2 | AD23: 9 | AE23: 10 | AF23: 9.3 | AG23: 8.7 | AH23: 7.6 | AI23: 12.6 | AJ23: 5.9 | AK23: 7.2 | AL23: 7.3 | AM23: 11.1 | AN23: 9 | AO23: 7.4
