Workbook

Sheet 연간
A1: JRC Model
A2: 모를 땐 보수적으로 | B2: (단위: 백만엔) | C2: 2월 결산 · 일본 기준 · 2027.2Q = 2027년 2월 결산기 2분기 | Y2: (추정: 파란 글씨 = 직접 입력)
A3: 항목 | B3: 참고 | C3: 2024.3Q | D3: 2024.4Q | E3: 2025.1Q | F3: 2025.2Q | G3: 2025.3Q | H3: 2025.4Q | I3: 2026.1Q | J3: 2026.2Q | K3: 2026.3Q | L3: 2026.4Q | M3: 2027.1Q | N3: 2027.2Q | O3: 2017 | P3: 2018 | Q3: 2019 | R3: 2020 | S3: 2021 | T3: 2022 | U3: 2023 | V3: 2024 | W3: 2025 | X3: 2026 | Y3: 2027(MW) | Z3: 2028(MW) | AA3: 2029(MW) | AB3: 2030(MW) | AC3: 2031(MW)
A4: 매출액 | B4: MW = 제품 합계 | C4: 2574.757 | D4: 2508.214 | E4: 2355.733 | F4: 2593.327 | G4: 2968.985 | H4: 3146.526 | I4: 3394.745 | J4: 2931.382 | K4: 3383.595 | L4: 4037.163 | M4: 3538.826 | N4: 3243.321 | U4: 8961.165 | V4: 9473.293 | W4: 11064.571 | X4: 13746.885 | Y4: =IF(COUNT(Y7,Y10,Y13,Y16,Y19)=0,"",SUM(Y7,Y10,Y13,Y16,Y19)) | Z4: =IF(COUNT(Z7,Z10,Z13,Z16,Z19)=0,"",SUM(Z7,Z10,Z13,Z16,Z19)) | AA4: =IF(COUNT(AA7,AA10,AA13,AA16,AA19)=0,"",SUM(AA7,AA10,AA13,AA16,AA19)) | AB4: =IF(COUNT(AB7,AB10,AB13,AB16,AB19)=0,"",SUM(AB7,AB10,AB13,AB16,AB19)) | AC4: =IF(COUNT(AC7,AC10,AC13,AC16,AC19)=0,"",SUM(AC7,AC10,AC13,AC16,AC19))
A5: YoY | G5: =IF(OR(G4="",C4=""),"",IFERROR(G4/C4-1,"")) | H5: =IF(OR(H4="",D4=""),"",IFERROR(H4/D4-1,"")) | I5: =IF(OR(I4="",E4=""),"",IFERROR(I4/E4-1,"")) | J5: =IF(OR(J4="",F4=""),"",IFERROR(J4/F4-1,"")) | K5: =IF(OR(K4="",G4=""),"",IFERROR(K4/G4-1,"")) | L5: =IF(OR(L4="",H4=""),"",IFERROR(L4/H4-1,"")) | M5: =IF(OR(M4="",I4=""),"",IFERROR(M4/I4-1,"")) | N5: =IF(OR(N4="",J4=""),"",IFERROR(N4/J4-1,"")) | P5: =IF(OR(P4="",O4=""),"",IFERROR(P4/O4-1,"")) | Q5: =IF(OR(Q4="",P4=""),"",IFERROR(Q4/P4-1,"")) | R5: =IF(OR(R4="",Q4=""),"",IFERROR(R4/Q4-1,"")) | S5: =IF(OR(S4="",R4=""),"",IFERROR(S4/R4-1,"")) | T5: =IF(OR(T4="",S4=""),"",IFERROR(T4/S4-1,"")) | U5: =IF(OR(U4="",T4=""),"",IFERROR(U4/T4-1,"")) | V5: =IF(OR(V4="",U4=""),"",IFERROR(V4/U4-1,"")) | W5: =IF(OR(W4="",V4=""),"",IFERROR(W4/V4-1,"")) | ... AC5: =IF(OR(AC4="",AB4=""),"",IFERROR(AC4/AB4-1,""))
A6: 제품별 매출 분류 | B6: 사업보고서 매출실적
A7: ConveyorBusinessReportableSegmentMember | C7: 2268.64 | D7: 762.045 | E7: 1922.353 | F7: 1973.113 | G7: 1936.651 | H7: 2085.113 | I7: 1876.581 | J7: 1815.066 | K7: 3348.889 | L7: 3145.449 | M7: 1935.52 | N7: 1931.534 | V7: 7233.097 | W7: 7917.23 | X7: 10185.985
A8: 비중 | C8: =IF(OR(C7="",C4=""),"",IFERROR(C7/C4,"")) | D8: =IF(OR(D7="",D4=""),"",IFERROR(D7/D4,"")) | E8: =IF(OR(E7="",E4=""),"",IFERROR(E7/E4,"")) | F8: =IF(OR(F7="",F4=""),"",IFERROR(F7/F4,"")) | G8: =IF(OR(G7="",G4=""),"",IFERROR(G7/G4,"")) | H8: =IF(OR(H7="",H4=""),"",IFERROR(H7/H4,"")) | I8: =IF(OR(I7="",I4=""),"",IFERROR(I7/I4,"")) | J8: =IF(OR(J7="",J4=""),"",IFERROR(J7/J4,"")) | ... AC8: =IF(OR(AC7="",AC4=""),"",IFERROR(AC7/AC4,""))
A9: YoY | G9: =IF(OR(G7="",C7=""),"",IFERROR(G7/C7-1,"")) | H9: =IF(OR(H7="",D7=""),"",IFERROR(H7/D7-1,"")) | I9: =IF(OR(I7="",E7=""),"",IFERROR(I7/E7-1,"")) | J9: =IF(OR(J7="",F7=""),"",IFERROR(J7/F7-1,"")) | K9: =IF(OR(K7="",G7=""),"",IFERROR(K7/G7-1,"")) | L9: =IF(OR(L7="",H7=""),"",IFERROR(L7/H7-1,"")) | M9: =IF(OR(M7="",I7=""),"",IFERROR(M7/I7-1,"")) | N9: =IF(OR(N7="",J7=""),"",IFERROR(N7/J7-1,"")) | P9: =IF(OR(P7="",O7=""),"",IFERROR(P7/O7-1,"")) | Q9: =IF(OR(Q7="",P7=""),"",IFERROR(Q7/P7-1,"")) | R9: =IF(OR(R7="",Q7=""),"",IFERROR(R7/Q7-1,"")) | S9: =IF(OR(S7="",R7=""),"",IFERROR(S7/R7-1,"")) | T9: =IF(OR(T7="",S7=""),"",IFERROR(T7/S7-1,"")) | U9: =IF(OR(U7="",T7=""),"",IFERROR(U7/T7-1,"")) | V9: =IF(OR(V7="",U7=""),"",IFERROR(V7/U7-1,"")) | W9: =IF(OR(W7="",V7=""),"",IFERROR(W7/V7-1,"")) | ... AC9: =IF(OR(AC7="",AB7=""),"",IFERROR(AC7/AB7-1,""))
A10: EnvironmentalPlantsReportableSegmentMember | E10: 402.409 | F10: 544.112 | G10: 569.69 | H10: 633.831 | I10: 468.442 | J10: 526.745 | K10: 523.651 | L10: 622.241 | V10: 1523.323 | W10: 2150.042 | X10: 2141.079
A11: 비중 | C11: =IF(OR(C10="",C4=""),"",IFERROR(C10/C4,"")) | D11: =IF(OR(D10="",D4=""),"",IFERROR(D10/D4,"")) | E11: =IF(OR(E10="",E4=""),"",IFERROR(E10/E4,"")) | F11: =IF(OR(F10="",F4=""),"",IFERROR(F10/F4,"")) | G11: =IF(OR(G10="",G4=""),"",IFERROR(G10/G4,"")) | H11: =IF(OR(H10="",H4=""),"",IFERROR(H10/H4,"")) | I11: =IF(OR(I10="",I4=""),"",IFERROR(I10/I4,"")) | J11: =IF(OR(J10="",J4=""),"",IFERROR(J10/J4,"")) | ... AC11: =IF(OR(AC10="",AC4=""),"",IFERROR(AC10/AC4,""))
A12: YoY | G12: =IF(OR(G10="",C10=""),"",IFERROR(G10/C10-1,"")) | H12: =IF(OR(H10="",D10=""),"",IFERROR(H10/D10-1,"")) | I12: =IF(OR(I10="",E10=""),"",IFERROR(I10/E10-1,"")) | J12: =IF(OR(J10="",F10=""),"",IFERROR(J10/F10-1,"")) | K12: =IF(OR(K10="",G10=""),"",IFERROR(K10/G10-1,"")) | L12: =IF(OR(L10="",H10=""),"",IFERROR(L10/H10-1,"")) | M12: =IF(OR(M10="",I10=""),"",IFERROR(M10/I10-1,"")) | N12: =IF(OR(N10="",J10=""),"",IFERROR(N10/J10-1,"")) | P12: =IF(OR(P10="",O10=""),"",IFERROR(P10/O10-1,"")) | Q12: =IF(OR(Q10="",P10=""),"",IFERROR(Q10/P10-1,"")) | R12: =IF(OR(R10="",Q10=""),"",IFERROR(R10/Q10-1,"")) | S12: =IF(OR(S10="",R10=""),"",IFERROR(S10/R10-1,"")) | T12: =IF(OR(T10="",S10=""),"",IFERROR(T10/S10-1,"")) | U12: =IF(OR(U10="",T10=""),"",IFERROR(U10/T10-1,"")) | V12: =IF(OR(V10="",U10=""),"",IFERROR(V10/U10-1,"")) | W12: =IF(OR(W10="",V10=""),"",IFERROR(W10/V10-1,"")) | ... AC12: =IF(OR(AC10="",AB10=""),"",IFERROR(AC10/AB10-1,""))
A13: EnvironmentalEnergyBusinessReportableSegmentMember | I13: 1151.335 | J13: 806.705 | M13: 1173.001 | N13: 1127.693
A14: 비중 | C14: =IF(OR(C13="",C4=""),"",IFERROR(C13/C4,"")) | D14: =IF(OR(D13="",D4=""),"",IFERROR(D13/D4,"")) | E14: =IF(OR(E13="",E4=""),"",IFERROR(E13/E4,"")) | F14: =IF(OR(F13="",F4=""),"",IFERROR(F13/F4,"")) | G14: =IF(OR(G13="",G4=""),"",IFERROR(G13/G4,"")) | H14: =IF(OR(H13="",H4=""),"",IFERROR(H13/H4,"")) | I14: =IF(OR(I13="",I4=""),"",IFERROR(I13/I4,"")) | J14: =IF(OR(J13="",J4=""),"",IFERROR(J13/J4,"")) | ... AC14: =IF(OR(AC13="",AC4=""),"",IFERROR(AC13/AC4,""))
A15: YoY | G15: =IF(OR(G13="",C13=""),"",IFERROR(G13/C13-1,"")) | H15: =IF(OR(H13="",D13=""),"",IFERROR(H13/D13-1,"")) | I15: =IF(OR(I13="",E13=""),"",IFERROR(I13/E13-1,"")) | J15: =IF(OR(J13="",F13=""),"",IFERROR(J13/F13-1,"")) | K15: =IF(OR(K13="",G13=""),"",IFERROR(K13/G13-1,"")) | L15: =IF(OR(L13="",H13=""),"",IFERROR(L13/H13-1,"")) | M15: =IF(OR(M13="",I13=""),"",IFERROR(M13/I13-1,"")) | N15: =IF(OR(N13="",J13=""),"",IFERROR(N13/J13-1,"")) | P15: =IF(OR(P13="",O13=""),"",IFERROR(P13/O13-1,"")) | Q15: =IF(OR(Q13="",P13=""),"",IFERROR(Q13/P13-1,"")) | R15: =IF(OR(R13="",Q13=""),"",IFERROR(R13/Q13-1,"")) | S15: =IF(OR(S13="",R13=""),"",IFERROR(S13/R13-1,"")) | T15: =IF(OR(T13="",S13=""),"",IFERROR(T13/S13-1,"")) | U15: =IF(OR(U13="",T13=""),"",IFERROR(U13/T13-1,"")) | V15: =IF(OR(V13="",U13=""),"",IFERROR(V13/U13-1,"")) | W15: =IF(OR(W13="",V13=""),"",IFERROR(W13/V13-1,"")) | ... AC15: =IF(OR(AC13="",AB13=""),"",IFERROR(AC13/AB13-1,""))
A16: RobotSIBusinessReportableSegmentMember | C16: 306.116 | D16: 222.845 | E16: 30.97 | F16: 76.102 | G16: 462.644 | H16: 427.582 | I16: 366.829 | J16: 309.61 | K16: 473.908 | L16: 269.473 | M16: 430.304 | N16: 184.095 | V16: 716.871 | W16: 997.298 | X16: 1419.82
A17: 비중 | C17: =IF(OR(C16="",C4=""),"",IFERROR(C16/C4,"")) | D17: =IF(OR(D16="",D4=""),"",IFERROR(D16/D4,"")) | E17: =IF(OR(E16="",E4=""),"",IFERROR(E16/E4,"")) | F17: =IF(OR(F16="",F4=""),"",IFERROR(F16/F4,"")) | G17: =IF(OR(G16="",G4=""),"",IFERROR(G16/G4,"")) | H17: =IF(OR(H16="",H4=""),"",IFERROR(H16/H4,"")) | I17: =IF(OR(I16="",I4=""),"",IFERROR(I16/I4,"")) | J17: =IF(OR(J16="",J4=""),"",IFERROR(J16/J4,"")) | ... AC17: =IF(OR(AC16="",AC4=""),"",IFERROR(AC16/AC4,""))
A18: YoY | G18: =IF(OR(G16="",C16=""),"",IFERROR(G16/C16-1,"")) | H18: =IF(OR(H16="",D16=""),"",IFERROR(H16/D16-1,"")) | I18: =IF(OR(I16="",E16=""),"",IFERROR(I16/E16-1,"")) | J18: =IF(OR(J16="",F16=""),"",IFERROR(J16/F16-1,"")) | K18: =IF(OR(K16="",G16=""),"",IFERROR(K16/G16-1,"")) | L18: =IF(OR(L16="",H16=""),"",IFERROR(L16/H16-1,"")) | M18: =IF(OR(M16="",I16=""),"",IFERROR(M16/I16-1,"")) | N18: =IF(OR(N16="",J16=""),"",IFERROR(N16/J16-1,"")) | P18: =IF(OR(P16="",O16=""),"",IFERROR(P16/O16-1,"")) | Q18: =IF(OR(Q16="",P16=""),"",IFERROR(Q16/P16-1,"")) | R18: =IF(OR(R16="",Q16=""),"",IFERROR(R16/Q16-1,"")) | S18: =IF(OR(S16="",R16=""),"",IFERROR(S16/R16-1,"")) | T18: =IF(OR(T16="",S16=""),"",IFERROR(T16/S16-1,"")) | U18: =IF(OR(U16="",T16=""),"",IFERROR(U16/T16-1,"")) | V18: =IF(OR(V16="",U16=""),"",IFERROR(V16/U16-1,"")) | W18: =IF(OR(W16="",V16=""),"",IFERROR(W16/V16-1,"")) | ... AC18: =IF(OR(AC16="",AB16=""),"",IFERROR(AC16/AB16-1,""))
A19: EntityTotalMember | I19: 3394.745 | M19: 3538.826
A20: 비중 | C20: =IF(OR(C19="",C4=""),"",IFERROR(C19/C4,"")) | D20: =IF(OR(D19="",D4=""),"",IFERROR(D19/D4,"")) | E20: =IF(OR(E19="",E4=""),"",IFERROR(E19/E4,"")) | F20: =IF(OR(F19="",F4=""),"",IFERROR(F19/F4,"")) | G20: =IF(OR(G19="",G4=""),"",IFERROR(G19/G4,"")) | H20: =IF(OR(H19="",H4=""),"",IFERROR(H19/H4,"")) | I20: =IF(OR(I19="",I4=""),"",IFERROR(I19/I4,"")) | J20: =IF(OR(J19="",J4=""),"",IFERROR(J19/J4,"")) | ... AC20: =IF(OR(AC19="",AC4=""),"",IFERROR(AC19/AC4,""))
A21: YoY | G21: =IF(OR(G19="",C19=""),"",IFERROR(G19/C19-1,"")) | H21: =IF(OR(H19="",D19=""),"",IFERROR(H19/D19-1,"")) | I21: =IF(OR(I19="",E19=""),"",IFERROR(I19/E19-1,"")) | J21: =IF(OR(J19="",F19=""),"",IFERROR(J19/F19-1,"")) | K21: =IF(OR(K19="",G19=""),"",IFERROR(K19/G19-1,"")) | L21: =IF(OR(L19="",H19=""),"",IFERROR(L19/H19-1,"")) | M21: =IF(OR(M19="",I19=""),"",IFERROR(M19/I19-1,"")) | N21: =IF(OR(N19="",J19=""),"",IFERROR(N19/J19-1,"")) | P21: =IF(OR(P19="",O19=""),"",IFERROR(P19/O19-1,"")) | Q21: =IF(OR(Q19="",P19=""),"",IFERROR(Q19/P19-1,"")) | R21: =IF(OR(R19="",Q19=""),"",IFERROR(R19/Q19-1,"")) | S21: =IF(OR(S19="",R19=""),"",IFERROR(S19/R19-1,"")) | T21: =IF(OR(T19="",S19=""),"",IFERROR(T19/S19-1,"")) | U21: =IF(OR(U19="",T19=""),"",IFERROR(U19/T19-1,"")) | V21: =IF(OR(V19="",U19=""),"",IFERROR(V19/U19-1,"")) | W21: =IF(OR(W19="",V19=""),"",IFERROR(W19/V19-1,"")) | ... AC21: =IF(OR(AC19="",AB19=""),"",IFERROR(AC19/AB19-1,""))
A22: 매출원가
A23: 전체 매출원가 | C23: 1665.436 | D23: 1640.376 | E23: 1526.53 | F23: 1636.043 | G23: 1842.031 | H23: 2060.932 | I23: 1993.365 | J23: 2036.489 | K23: 2238.87 | L23: 2599.101 | M23: 2358.907 | N23: 1990.296 | U23: 5937.793 | V23: 6259.998 | W23: 7065.536 | X23: 8867.825
A24: YoY | G24: =IF(OR(G23="",C23=""),"",IF(C23<=0,"",IFERROR(G23/C23-1,""))) | H24: =IF(OR(H23="",D23=""),"",IF(D23<=0,"",IFERROR(H23/D23-1,""))) | I24: =IF(OR(I23="",E23=""),"",IF(E23<=0,"",IFERROR(I23/E23-1,""))) | J24: =IF(OR(J23="",F23=""),"",IF(F23<=0,"",IFERROR(J23/F23-1,""))) | K24: =IF(OR(K23="",G23=""),"",IF(G23<=0,"",IFERROR(K23/G23-1,""))) | L24: =IF(OR(L23="",H23=""),"",IF(H23<=0,"",IFERROR(L23/H23-1,""))) | M24: =IF(OR(M23="",I23=""),"",IF(I23<=0,"",IFERROR(M23/I23-1,""))) | N24: =IF(OR(N23="",J23=""),"",IF(J23<=0,"",IFERROR(N23/J23-1,""))) | P24: =IF(OR(P23="",O23=""),"",IF(O23<=0,"",IFERROR(P23/O23-1,""))) | Q24: =IF(OR(Q23="",P23=""),"",IF(P23<=0,"",IFERROR(Q23/P23-1,""))) | R24: =IF(OR(R23="",Q23=""),"",IF(Q23<=0,"",IFERROR(R23/Q23-1,""))) | S24: =IF(OR(S23="",R23=""),"",IF(R23<=0,"",IFERROR(S23/R23-1,""))) | T24: =IF(OR(T23="",S23=""),"",IF(S23<=0,"",IFERROR(T23/S23-1,""))) | U24: =IF(OR(U23="",T23=""),"",IF(T23<=0,"",IFERROR(U23/T23-1,""))) | V24: =IF(OR(V23="",U23=""),"",IF(U23<=0,"",IFERROR(V23/U23-1,""))) | W24: =IF(OR(W23="",V23=""),"",IF(V23<=0,"",IFERROR(W23/V23-1,""))) | ... AC24: =IF(OR(AC23="",AB23=""),"",IF(AB23<=0,"",IFERROR(AC23/AB23-1,"")))
A25: 매출총이익 | C25: =IF(OR(C4="",C23=""),"",IFERROR(C4-C23,"")) | D25: =IF(OR(D4="",D23=""),"",IFERROR(D4-D23,"")) | E25: =IF(OR(E4="",E23=""),"",IFERROR(E4-E23,"")) | F25: =IF(OR(F4="",F23=""),"",IFERROR(F4-F23,"")) | G25: =IF(OR(G4="",G23=""),"",IFERROR(G4-G23,"")) | H25: =IF(OR(H4="",H23=""),"",IFERROR(H4-H23,"")) | I25: =IF(OR(I4="",I23=""),"",IFERROR(I4-I23,"")) | J25: =IF(OR(J4="",J23=""),"",IFERROR(J4-J23,"")) | ... X25: =IF(OR(X4="",X23=""),"",IFERROR(X4-X23,""))
A26: GPM | C26: =IF(OR(C25="",C4=""),"",IFERROR(C25/C4,"")) | D26: =IF(OR(D25="",D4=""),"",IFERROR(D25/D4,"")) | E26: =IF(OR(E25="",E4=""),"",IFERROR(E25/E4,"")) | F26: =IF(OR(F25="",F4=""),"",IFERROR(F25/F4,"")) | G26: =IF(OR(G25="",G4=""),"",IFERROR(G25/G4,"")) | H26: =IF(OR(H25="",H4=""),"",IFERROR(H25/H4,"")) | I26: =IF(OR(I25="",I4=""),"",IFERROR(I25/I4,"")) | J26: =IF(OR(J25="",J4=""),"",IFERROR(J25/J4,"")) | ... AC26: =IF(OR(AC25="",AC4=""),"",IFERROR(AC25/AC4,""))
A27: YoY | G27: =IF(OR(G25="",C25=""),"",IF(C25<=0,"",IFERROR(G25/C25-1,""))) | H27: =IF(OR(H25="",D25=""),"",IF(D25<=0,"",IFERROR(H25/D25-1,""))) | I27: =IF(OR(I25="",E25=""),"",IF(E25<=0,"",IFERROR(I25/E25-1,""))) | J27: =IF(OR(J25="",F25=""),"",IF(F25<=0,"",IFERROR(J25/F25-1,""))) | K27: =IF(OR(K25="",G25=""),"",IF(G25<=0,"",IFERROR(K25/G25-1,""))) | L27: =IF(OR(L25="",H25=""),"",IF(H25<=0,"",IFERROR(L25/H25-1,""))) | M27: =IF(OR(M25="",I25=""),"",IF(I25<=0,"",IFERROR(M25/I25-1,""))) | N27: =IF(OR(N25="",J25=""),"",IF(J25<=0,"",IFERROR(N25/J25-1,""))) | P27: =IF(OR(P25="",O25=""),"",IF(O25<=0,"",IFERROR(P25/O25-1,""))) | Q27: =IF(OR(Q25="",P25=""),"",IF(P25<=0,"",IFERROR(Q25/P25-1,""))) | R27: =IF(OR(R25="",Q25=""),"",IF(Q25<=0,"",IFERROR(R25/Q25-1,""))) | S27: =IF(OR(S25="",R25=""),"",IF(R25<=0,"",IFERROR(S25/R25-1,""))) | T27: =IF(OR(T25="",S25=""),"",IF(S25<=0,"",IFERROR(T25/S25-1,""))) | U27: =IF(OR(U25="",T25=""),"",IF(T25<=0,"",IFERROR(U25/T25-1,""))) | V27: =IF(OR(V25="",U25=""),"",IF(U25<=0,"",IFERROR(V25/U25-1,""))) | W27: =IF(OR(W25="",V25=""),"",IF(V25<=0,"",IFERROR(W25/V25-1,""))) | ... AC27: =IF(OR(AC25="",AB25=""),"",IF(AB25<=0,"",IFERROR(AC25/AB25-1,"")))
A28: 판매관리비
A29: 전체 판관비 | C29: 497.051 | D29: 507.193 | E29: 574.902 | F29: 560.385 | G29: 766.741 | H29: 721.298 | I29: 703.346 | J29: 688.722 | K29: 736.259 | L29: 786.669 | M29: 739.95 | N29: 689.49 | U29: 1771.044 | V29: 1942.403 | W29: 2623.326 | X29: 2914.996
A30: YoY | G30: =IF(OR(G29="",C29=""),"",IF(C29<=0,"",IFERROR(G29/C29-1,""))) | H30: =IF(OR(H29="",D29=""),"",IF(D29<=0,"",IFERROR(H29/D29-1,""))) | I30: =IF(OR(I29="",E29=""),"",IF(E29<=0,"",IFERROR(I29/E29-1,""))) | J30: =IF(OR(J29="",F29=""),"",IF(F29<=0,"",IFERROR(J29/F29-1,""))) | K30: =IF(OR(K29="",G29=""),"",IF(G29<=0,"",IFERROR(K29/G29-1,""))) | L30: =IF(OR(L29="",H29=""),"",IF(H29<=0,"",IFERROR(L29/H29-1,""))) | M30: =IF(OR(M29="",I29=""),"",IF(I29<=0,"",IFERROR(M29/I29-1,""))) | N30: =IF(OR(N29="",J29=""),"",IF(J29<=0,"",IFERROR(N29/J29-1,""))) | P30: =IF(OR(P29="",O29=""),"",IF(O29<=0,"",IFERROR(P29/O29-1,""))) | Q30: =IF(OR(Q29="",P29=""),"",IF(P29<=0,"",IFERROR(Q29/P29-1,""))) | R30: =IF(OR(R29="",Q29=""),"",IF(Q29<=0,"",IFERROR(R29/Q29-1,""))) | S30: =IF(OR(S29="",R29=""),"",IF(R29<=0,"",IFERROR(S29/R29-1,""))) | T30: =IF(OR(T29="",S29=""),"",IF(S29<=0,"",IFERROR(T29/S29-1,""))) | U30: =IF(OR(U29="",T29=""),"",IF(T29<=0,"",IFERROR(U29/T29-1,""))) | V30: =IF(OR(V29="",U29=""),"",IF(U29<=0,"",IFERROR(V29/U29-1,""))) | W30: =IF(OR(W29="",V29=""),"",IF(V29<=0,"",IFERROR(W29/V29-1,""))) | ... AC30: =IF(OR(AC29="",AB29=""),"",IF(AB29<=0,"",IFERROR(AC29/AB29-1,"")))
A31: 영업이익 | B31: MW = 매출 × OPM | C31: 412.27 | D31: 360.646 | E31: 254.3 | F31: 396.899 | G31: 360.212 | H31: 364.298 | I31: 698.033 | J31: 206.17 | K31: 408.467 | L31: 651.393 | M31: 439.968 | N31: 563.535 | U31: 1252.327 | V31: 1270.892 | W31: 1375.709 | X31: 1964.063 | Y31: =IF(OR(Y4="",Y32=""),"",IFERROR(Y4*Y32,"")) | Z31: =IF(OR(Z4="",Z32=""),"",IFERROR(Z4*Z32,"")) | AA31: =IF(OR(AA4="",AA32=""),"",IFERROR(AA4*AA32,"")) | AB31: =IF(OR(AB4="",AB32=""),"",IFERROR(AB4*AB32,"")) | AC31: =IF(OR(AC4="",AC32=""),"",IFERROR(AC4*AC32,""))
A32: OPM | B32: MW 입력 | C32: =IF(OR(C31="",C4=""),"",IFERROR(C31/C4,"")) | D32: =IF(OR(D31="",D4=""),"",IFERROR(D31/D4,"")) | E32: =IF(OR(E31="",E4=""),"",IFERROR(E31/E4,"")) | F32: =IF(OR(F31="",F4=""),"",IFERROR(F31/F4,"")) | G32: =IF(OR(G31="",G4=""),"",IFERROR(G31/G4,"")) | H32: =IF(OR(H31="",H4=""),"",IFERROR(H31/H4,"")) | I32: =IF(OR(I31="",I4=""),"",IFERROR(I31/I4,"")) | J32: =IF(OR(J31="",J4=""),"",IFERROR(J31/J4,"")) | ... X32: =IF(OR(X31="",X4=""),"",IFERROR(X31/X4,""))
A33: 증가율 | G33: =IF(OR(G31="",C31=""),"",IFERROR(G31/C31-1,"")) | H33: =IF(OR(H31="",D31=""),"",IFERROR(H31/D31-1,"")) | I33: =IF(OR(I31="",E31=""),"",IFERROR(I31/E31-1,"")) | J33: =IF(OR(J31="",F31=""),"",IFERROR(J31/F31-1,"")) | K33: =IF(OR(K31="",G31=""),"",IFERROR(K31/G31-1,"")) | L33: =IF(OR(L31="",H31=""),"",IFERROR(L31/H31-1,"")) | M33: =IF(OR(M31="",I31=""),"",IFERROR(M31/I31-1,"")) | N33: =IF(OR(N31="",J31=""),"",IFERROR(N31/J31-1,"")) | P33: =IF(OR(P31="",O31=""),"",IFERROR(P31/O31-1,"")) | Q33: =IF(OR(Q31="",P31=""),"",IFERROR(Q31/P31-1,"")) | R33: =IF(OR(R31="",Q31=""),"",IFERROR(R31/Q31-1,"")) | S33: =IF(OR(S31="",R31=""),"",IFERROR(S31/R31-1,"")) | T33: =IF(OR(T31="",S31=""),"",IFERROR(T31/S31-1,"")) | U33: =IF(OR(U31="",T31=""),"",IFERROR(U31/T31-1,"")) | V33: =IF(OR(V31="",U31=""),"",IFERROR(V31/U31-1,"")) | W33: =IF(OR(W31="",V31=""),"",IFERROR(W31/V31-1,"")) | ... AC33: =IF(OR(AC31="",AB31=""),"",IFERROR(AC31/AB31-1,""))
A34: 비용의 성격별 분류 | B34: 참고 데이터
A35: 총 판관비 | O35: =IF(O29="","",O29) | P35: =IF(P29="","",P29) | Q35: =IF(Q29="","",Q29) | R35: =IF(R29="","",R29) | S35: =IF(S29="","",S29) | T35: =IF(T29="","",T29) | U35: =IF(U29="","",U29) | V35: =IF(V29="","",V29) | ... X35: =IF(X29="","",X29)
A36: 급여 | B36: 고정비
A37: % of Sales | O37: =IF(OR(O36="",O4=""),"",IFERROR(O36/O4,"")) | P37: =IF(OR(P36="",P4=""),"",IFERROR(P36/P4,"")) | Q37: =IF(OR(Q36="",Q4=""),"",IFERROR(Q36/Q4,"")) | R37: =IF(OR(R36="",R4=""),"",IFERROR(R36/R4,"")) | S37: =IF(OR(S36="",S4=""),"",IFERROR(S36/S4,"")) | T37: =IF(OR(T36="",T4=""),"",IFERROR(T36/T4,"")) | U37: =IF(OR(U36="",U4=""),"",IFERROR(U36/U4,"")) | V37: =IF(OR(V36="",V4=""),"",IFERROR(V36/V4,"")) | ... X37: =IF(OR(X36="",X4=""),"",IFERROR(X36/X4,""))
A38: 감가상각비 | B38: 고정비
A39: % of Sales | O39: =IF(OR(O38="",O4=""),"",IFERROR(O38/O4,"")) | P39: =IF(OR(P38="",P4=""),"",IFERROR(P38/P4,"")) | Q39: =IF(OR(Q38="",Q4=""),"",IFERROR(Q38/Q4,"")) | R39: =IF(OR(R38="",R4=""),"",IFERROR(R38/R4,"")) | S39: =IF(OR(S38="",S4=""),"",IFERROR(S38/S4,"")) | T39: =IF(OR(T38="",T4=""),"",IFERROR(T38/T4,"")) | U39: =IF(OR(U38="",U4=""),"",IFERROR(U38/U4,"")) | V39: =IF(OR(V38="",V4=""),"",IFERROR(V38/V4,"")) | ... X39: =IF(OR(X38="",X4=""),"",IFERROR(X38/X4,""))
A40: 지급수수료 | B40: 고정비
...

Sheet 재무상태표
A1: JRC 재무상태표
A2: 재무비율은 기말 잔액 기준 · 분기 손익은 최근 4분기 합산(TTM) | B2: (단위: 백만엔)
A3: 항목 | B3: 참고 | C3: 2026.2Q | D3: 2026.3Q | E3: 2026.4Q | F3: 2027.1Q | G3: 2027.2Q | H3: 2023 | I3: 2024 | J3: 2025 | K3: 2026
A4: 자산
A5: 유동자산 | C5: 8524.744 | D5: 7781.556 | E5: 8076.244 | F5: 7920.312 | G5: 9246.473 | H5: 5939.914 | I5: 6332.272 | J5: 7455.58 | K5: 8076.244
A6: 현금및현금성자산 | C6: 3490.925 | D6: 2503.11 | E6: 2585.441 | F6: 2615.56 | G6: 3992.872 | H6: 1640.16 | I6: 1452.334 | J6: 2431.302 | K6: 2585.441
A7: 단기금융상품
A8: 매출채권 | C8: 1535.028 | D8: 1912.332 | E8: 1947.797 | F8: 1736.543 | G8: 1669.569 | H8: 1316.414 | I8: 1700.152 | J8: 1631.052 | K8: 1947.797
A9: 재고자산 | C9: 1602.244 | D9: 1435.551 | E9: 1501.549 | F9: 1463.152 | G9: 1672.885 | H9: 1120.821 | I9: 1160.758 | J9: 1403.762 | K9: 1501.549
A10: 기타유동자산 | B10: 총계 − 위 항목 | C10: =IF(OR(C5=""),"",IFERROR(C5-SUM(C6,C7,C8,C9),"")) | D10: =IF(OR(D5=""),"",IFERROR(D5-SUM(D6,D7,D8,D9),"")) | E10: =IF(OR(E5=""),"",IFERROR(E5-SUM(E6,E7,E8,E9),"")) | F10: =IF(OR(F5=""),"",IFERROR(F5-SUM(F6,F7,F8,F9),"")) | G10: =IF(OR(G5=""),"",IFERROR(G5-SUM(G6,G7,G8,G9),"")) | H10: =IF(OR(H5=""),"",IFERROR(H5-SUM(H6,H7,H8,H9),"")) | I10: =IF(OR(I5=""),"",IFERROR(I5-SUM(I6,I7,I8,I9),"")) | J10: =IF(OR(J5=""),"",IFERROR(J5-SUM(J6,J7,J8,J9),"")) | K10: =IF(OR(K5=""),"",IFERROR(K5-SUM(K6,K7,K8,K9),""))
A11: 비유동자산 | C11: 5075.602 | D11: 5298.01 | E11: 5234.132 | F11: 5146.187 | G11: 4981.268 | H11: 4022.378 | I11: 3722.839 | J11: 5646.152 | K11: 5234.132
A12: 유형자산 | C12: 3528.067 | D12: 3535.928 | E12: 3592.733 | F12: 3557.432 | G12: 3499.899 | H12: 3069.965 | I12: 2971.439 | J12: 3547.303 | K12: 3592.733
A13: 무형자산 | C13: 768.483 | D13: 886.276 | E13: 860.303 | F13: 831.968 | G13: 799.912 | H13: 49.995 | I13: 151.657 | J13: 798.616 | K13: 860.303
A14: 투자부동산
A15: 기타비유동자산 | B15: 총계 − 위 항목 | C15: =IF(OR(C11=""),"",IFERROR(C11-SUM(C12,C13,C14),"")) | D15: =IF(OR(D11=""),"",IFERROR(D11-SUM(D12,D13,D14),"")) | E15: =IF(OR(E11=""),"",IFERROR(E11-SUM(E12,E13,E14),"")) | F15: =IF(OR(F11=""),"",IFERROR(F11-SUM(F12,F13,F14),"")) | G15: =IF(OR(G11=""),"",IFERROR(G11-SUM(G12,G13,G14),"")) | H15: =IF(OR(H11=""),"",IFERROR(H11-SUM(H12,H13,H14),"")) | I15: =IF(OR(I11=""),"",IFERROR(I11-SUM(I12,I13,I14),"")) | J15: =IF(OR(J11=""),"",IFERROR(J11-SUM(J12,J13,J14),"")) | K15: =IF(OR(K11=""),"",IFERROR(K11-SUM(K12,K13,K14),""))
A16: 자산총계 | C16: 13600.347 | D16: 13079.567 | E16: 13310.376 | F16: 13066.499 | G16: 14227.741 | H16: 9962.292 | I16: 10055.111 | J16: 13101.732 | K16: 13310.376
A17: 부채
A18: 유동부채 | C18: 5877.376 | D18: 4421.018 | E18: 3773 | F18: 3709.487 | G18: 3989.318 | H18: 2967.909 | I18: 2914.029 | J18: 5657.748 | K18: 3773
A19: 매입채무 | C19: 1332.152 | D19: 1317.172 | E19: 999.029 | F19: 439.387 | G19: 339.557 | H19: 1584.963 | I19: 1639.051 | J19: 1479.95 | K19: 999.029
A20: 단기차입금 | C20: 2500 | D20: 850 | E20: 250 | F20: 500 | G20: 950 | H20: 0 | I20: 182.2 | J20: 1800 | K20: 250
A21: 유동성장기부채 | C21: 472.142 | D21: 644.142 | E21: 785.022 | F21: 782.16 | G21: 942.36 | H21: 426 | I21: 470 | J21: 472.142 | K21: 785.022
A22: 기타유동부채 | B22: 총계 − 위 항목 | C22: =IF(OR(C18=""),"",IFERROR(C18-SUM(C19,C20,C21),"")) | D22: =IF(OR(D18=""),"",IFERROR(D18-SUM(D19,D20,D21),"")) | E22: =IF(OR(E18=""),"",IFERROR(E18-SUM(E19,E20,E21),"")) | F22: =IF(OR(F18=""),"",IFERROR(F18-SUM(F19,F20,F21),"")) | G22: =IF(OR(G18=""),"",IFERROR(G18-SUM(G19,G20,G21),"")) | H22: =IF(OR(H18=""),"",IFERROR(H18-SUM(H19,H20,H21),"")) | I22: =IF(OR(I18=""),"",IFERROR(I18-SUM(I19,I20,I21),"")) | J22: =IF(OR(J18=""),"",IFERROR(J18-SUM(J19,J20,J21),"")) | K22: =IF(OR(K18=""),"",IFERROR(K18-SUM(K19,K20,K21),""))
A23: 비유동부채 | C23: 2477.585 | D23: 3345.532 | E23: 3698.566 | F23: 3450.149 | G23: 3851.346 | H23: 3544.298 | I23: 3343.734 | J23: 2829.952 | K23: 3698.566
A24: 장기차입금 | C24: 2120.714 | D24: 2987.678 | E24: 3350.365 | F24: 3151.26 | G24: 3555.47 | H24: 3296 | I24: 3010.158 | J24: 2356.785 | K24: 3350.365
A25: 사채
A26: 기타비유동부채 | B26: 총계 − 위 항목 | C26: =IF(OR(C23=""),"",IFERROR(C23-SUM(C24,C25),"")) | D26: =IF(OR(D23=""),"",IFERROR(D23-SUM(D24,D25),"")) | E26: =IF(OR(E23=""),"",IFERROR(E23-SUM(E24,E25),"")) | F26: =IF(OR(F23=""),"",IFERROR(F23-SUM(F24,F25),"")) | G26: =IF(OR(G23=""),"",IFERROR(G23-SUM(G24,G25),"")) | H26: =IF(OR(H23=""),"",IFERROR(H23-SUM(H24,H25),"")) | I26: =IF(OR(I23=""),"",IFERROR(I23-SUM(I24,I25),"")) | J26: =IF(OR(J23=""),"",IFERROR(J23-SUM(J24,J25),"")) | K26: =IF(OR(K23=""),"",IFERROR(K23-SUM(K24,K25),""))
A27: 부채총계 | C27: 8354.961 | D27: 7766.55 | E27: 7471.566 | F27: 7159.636 | G27: 7840.664 | H27: 6512.208 | I27: 6257.764 | J27: 8487.7 | K27: 7471.566
A28: 총차입금 | B28: 단기+유동성장기+장기+사채 | C28: =SUM(C20,C21,C24,C25) | D28: =SUM(D20,D21,D24,D25) | E28: =SUM(E20,E21,E24,E25) | F28: =SUM(F20,F21,F24,F25) | G28: =SUM(G20,G21,G24,G25) | H28: =SUM(H20,H21,H24,H25) | I28: =SUM(I20,I21,I24,I25) | J28: =SUM(J20,J21,J24,J25) | K28: =SUM(K20,K21,K24,K25)
A29: 순차입금 | B29: 음수 = 순현금 | C29: =C28-C6-N(C7) | D29: =D28-D6-N(D7) | E29: =E28-E6-N(E7) | F29: =F28-F6-N(F7) | G29: =G28-G6-N(G7) | H29: =H28-H6-N(H7) | I29: =I28-I6-N(I7) | J29: =J28-J6-N(J7) | K29: =K28-K6-N(K7)
A30: 자본
A31: 지배주주지분 | C31: 5244.921 | D31: 5312.553 | E31: 5838.356 | F31: 5906.41 | G31: 6386.681 | H31: 3449.622 | I31: 3796.367 | J31: 4613.16 | K31: 5838.356
A32: 자본금 | C32: 167.944 | D32: 174.918 | E32: 182.65 | F32: 184.503 | G32: 220.016 | H32: 80 | I32: 131.415 | J32: 131.415 | K32: 182.65
A33: 이익잉여금 | C33: 5079.281 | D33: 5189.145 | E33: 5712.741 | F33: 5760.624 | G33: 6132.011 | H33: 3489.538 | I33: 4236.995 | J33: 4691.581 | K33: 5712.741
A34: 비지배지분
A35: 자본총계 | C35: 5245.385 | D35: 5313.016 | E35: 5838.809 | F35: 5906.863 | G35: 6387.077 | H35: 3450.084 | I35: 3797.347 | J35: 4614.032 | K35: 5838.809
A36: 현금흐름 요약 | B36: 분기 = TTM (있을 때만)
A37: 영업활동현금흐름 | C37: 1055.579 | E37: 824.671 | G37: 907.927 | H37: 1030.628 | I37: 576.365 | J37: 1676.503 | K37: 824.671
A38: CAPEX (유·무형 취득) | B38: 양수로 입력 | C38: 583.51 | E38: 612.608 | G38: 260.552 | H38: 106.506 | I38: 165.984 | J38: 310.188 | K38: 612.608
A39: FCF | C39: =IF(OR(C37="",C38=""),"",IFERROR(C37-C38,"")) | D39: =IF(OR(D37="",D38=""),"",IFERROR(D37-D38,"")) | E39: =IF(OR(E37="",E38=""),"",IFERROR(E37-E38,"")) | F39: =IF(OR(F37="",F38=""),"",IFERROR(F37-F38,"")) | G39: =IF(OR(G37="",G38=""),"",IFERROR(G37-G38,"")) | H39: =IF(OR(H37="",H38=""),"",IFERROR(H37-H38,"")) | I39: =IF(OR(I37="",I38=""),"",IFERROR(I37-I38,"")) | J39: =IF(OR(J37="",J38=""),"",IFERROR(J37-J38,"")) | K39: =IF(OR(K37="",K38=""),"",IFERROR(K37-K38,""))
A40: 배당금 지급 | B40: 양수로 입력 | C40: 321.977 | E40: 341.944 | G40: 425.238 | H40: 100 | I40: 100 | J40: 413.791 | K40: 341.944
...

Sheet 출처
A1: 출처 · 쓴 결산단신
A3: 공시일 | B3: 문서 | C3: PDF
A4: 2026-10-15 | B4: 2027년 2월 결산기 ２분기 결산단신 | C4: https://www2.jpx.co.jp/disc/62240/140120261014550149.pdf
A5: 2026-07-15 | B5: 2027년 2월 결산기 １분기 결산단신 | C5: https://www2.jpx.co.jp/disc/62240/140120260715594254.pdf
A6: 2026-04-14 | B6: 2026년 2월 결산기 연간 결산단신 | C6: https://www2.jpx.co.jp/disc/62240/140120260413503143.pdf
A7: 2026-01-14 | B7: 2026년 2월 결산기 ３분기 결산단신 | C7: https://www2.jpx.co.jp/disc/62240/140120260113532987.pdf
A8: 2025-10-15 | B8: 2026년 2월 결산기 ２분기 결산단신 | C8: https://www2.jpx.co.jp/disc/62240/140120251010571763.pdf
A9: 2025-07-15 | B9: 2026년 2월 결산기 １분기 결산단신 | C9: https://www2.jpx.co.jp/disc/62240/140120250714514097.pdf
A10: 2025-04-14 | B10: 2025년 2월 결산기 연간 결산단신 | C10: https://www2.jpx.co.jp/disc/62240/140120250414514702.pdf
A11: 2025-01-14 | B11: 2025년 2월 결산기 ３분기 결산단신 | C11: https://www2.jpx.co.jp/disc/62240/140120250114549920.pdf
A12: 2024-10-11 | B12: 2025년 2월 결산기 ２분기 결산단신 | C12: https://www2.jpx.co.jp/disc/62240/140120241009595879.pdf
A13: 2024-07-12 | B13: 2025년 2월 결산기 １분기 결산단신 | C13: https://www2.jpx.co.jp/disc/62240/140120240710546620.pdf
A14: 2024-04-12 | B14: 2024년 2월 결산기 연간 결산단신 | C14: https://www2.jpx.co.jp/disc/62240/140120240411569055.pdf
... A16: 2023-10-13 | B16: 2024년 2월 결산기 ２분기 결산단신 | C16: https://www2.jpx.co.jp/disc/62240/140120231013566440.pdf
