Workbook

Sheet 연간
A1: 6663 Model
A2: 모를 땐 보수적으로 | B2: (단위: 백만엔) | C2: 11월 결산 · 일본 기준 · 2026.4Q = 2026년 11월 결산기 4분기 | Y2: (추정: 파란 글씨 = 직접 입력)
A3: 항목 | B3: 참고 | C3: 2024.1Q | D3: 2024.2Q | E3: 2024.3Q | F3: 2024.4Q | G3: 2025.1Q | H3: 2025.2Q | I3: 2025.3Q | J3: 2025.4Q | K3: 2026.1Q | L3: 2026.2Q | M3: 2026.3Q | N3: 2026.4Q | O3: 2017 | P3: 2018 | Q3: 2019 | R3: 2020 | S3: 2021 | T3: 2022 | U3: 2023 | V3: 2024 | W3: 2025 | X3: 2026 | Y3: 2027(MW) | Z3: 2028(MW) | AA3: 2029(MW) | AB3: 2030(MW) | AC3: 2031(MW)
A4: 매출액 | B4: MW = 제품 합계 | C4: 865.849 | D4: 894.376 | E4: 997.932 | F4: 653.308 | G4: 783.899 | H4: 823.261 | I4: 1011.058 | J4: 901.082 | K4: 820.764 | L4: 961.948 | O4: 4979.906 | P4: 4238.765 | Q4: 4582.357 | R4: 3896.341 | S4: 3175.189 | T4: 3917.94 | U4: 3625.517 | V4: 3411.465 | W4: 3519.3 | X4: 3751.667 | Y4: =IF(COUNT(Y7,Y10,Y13,Y16)=0,"",SUM(Y7,Y10,Y13,Y16)) | Z4: =IF(COUNT(Z7,Z10,Z13,Z16)=0,"",SUM(Z7,Z10,Z13,Z16)) | AA4: =IF(COUNT(AA7,AA10,AA13,AA16)=0,"",SUM(AA7,AA10,AA13,AA16)) | AB4: =IF(COUNT(AB7,AB10,AB13,AB16)=0,"",SUM(AB7,AB10,AB13,AB16)) | AC4: =IF(COUNT(AC7,AC10,AC13,AC16)=0,"",SUM(AC7,AC10,AC13,AC16))
A5: YoY | G5: =IF(OR(G4="",C4=""),"",IFERROR(G4/C4-1,"")) | H5: =IF(OR(H4="",D4=""),"",IFERROR(H4/D4-1,"")) | I5: =IF(OR(I4="",E4=""),"",IFERROR(I4/E4-1,"")) | J5: =IF(OR(J4="",F4=""),"",IFERROR(J4/F4-1,"")) | K5: =IF(OR(K4="",G4=""),"",IFERROR(K4/G4-1,"")) | L5: =IF(OR(L4="",H4=""),"",IFERROR(L4/H4-1,"")) | M5: =IF(OR(M4="",I4=""),"",IFERROR(M4/I4-1,"")) | N5: =IF(OR(N4="",J4=""),"",IFERROR(N4/J4-1,"")) | P5: =IF(OR(P4="",O4=""),"",IFERROR(P4/O4-1,"")) | Q5: =IF(OR(Q4="",P4=""),"",IFERROR(Q4/P4-1,"")) | R5: =IF(OR(R4="",Q4=""),"",IFERROR(R4/Q4-1,"")) | S5: =IF(OR(S4="",R4=""),"",IFERROR(S4/R4-1,"")) | T5: =IF(OR(T4="",S4=""),"",IFERROR(T4/S4-1,"")) | U5: =IF(OR(U4="",T4=""),"",IFERROR(U4/T4-1,"")) | V5: =IF(OR(V4="",U4=""),"",IFERROR(V4/U4-1,"")) | W5: =IF(OR(W4="",V4=""),"",IFERROR(W4/V4-1,"")) | ... AC5: =IF(OR(AC4="",AB4=""),"",IFERROR(AC4/AB4-1,""))
A6: 제품별 매출 분류 | B6: 사업보고서 매출실적
A7: 부문 | C7: 572.255 | D7: 580.651 | E7: 564.595 | F7: 701.874 | G7: 574.353 | H7: 584.717 | I7: 548.37 | J7: 559.268 | K7: 649.97 | L7: 673.094 | V7: 2419.375 | W7: 2266.708 | X7: 2409.323
A8: 비중 | C8: =IF(OR(C7="",C4=""),"",IFERROR(C7/C4,"")) | D8: =IF(OR(D7="",D4=""),"",IFERROR(D7/D4,"")) | E8: =IF(OR(E7="",E4=""),"",IFERROR(E7/E4,"")) | F8: =IF(OR(F7="",F4=""),"",IFERROR(F7/F4,"")) | G8: =IF(OR(G7="",G4=""),"",IFERROR(G7/G4,"")) | H8: =IF(OR(H7="",H4=""),"",IFERROR(H7/H4,"")) | I8: =IF(OR(I7="",I4=""),"",IFERROR(I7/I4,"")) | J8: =IF(OR(J7="",J4=""),"",IFERROR(J7/J4,"")) | ... AC8: =IF(OR(AC7="",AC4=""),"",IFERROR(AC7/AC4,""))
A9: YoY | G9: =IF(OR(G7="",C7=""),"",IFERROR(G7/C7-1,"")) | H9: =IF(OR(H7="",D7=""),"",IFERROR(H7/D7-1,"")) | I9: =IF(OR(I7="",E7=""),"",IFERROR(I7/E7-1,"")) | J9: =IF(OR(J7="",F7=""),"",IFERROR(J7/F7-1,"")) | K9: =IF(OR(K7="",G7=""),"",IFERROR(K7/G7-1,"")) | L9: =IF(OR(L7="",H7=""),"",IFERROR(L7/H7-1,"")) | M9: =IF(OR(M7="",I7=""),"",IFERROR(M7/I7-1,"")) | N9: =IF(OR(N7="",J7=""),"",IFERROR(N7/J7-1,"")) | P9: =IF(OR(P7="",O7=""),"",IFERROR(P7/O7-1,"")) | Q9: =IF(OR(Q7="",P7=""),"",IFERROR(Q7/P7-1,"")) | R9: =IF(OR(R7="",Q7=""),"",IFERROR(R7/Q7-1,"")) | S9: =IF(OR(S7="",R7=""),"",IFERROR(S7/R7-1,"")) | T9: =IF(OR(T7="",S7=""),"",IFERROR(T7/S7-1,"")) | U9: =IF(OR(U7="",T7=""),"",IFERROR(U7/T7-1,"")) | V9: =IF(OR(V7="",U7=""),"",IFERROR(V7/U7-1,"")) | W9: =IF(OR(W7="",V7=""),"",IFERROR(W7/V7-1,"")) | ... AC9: =IF(OR(AC7="",AB7=""),"",IFERROR(AC7/AB7-1,""))
A10: 부문 | C10: 175.585 | D10: 173.913 | E10: 243.186 | F10: -171.931 | G10: 77.954 | H10: 61.254 | I10: 80.823 | J10: 477.705 | K10: 76.842 | L10: 116.365 | V10: 420.753 | W10: 697.736 | X10: 450.982
A11: 비중 | C11: =IF(OR(C10="",C4=""),"",IFERROR(C10/C4,"")) | D11: =IF(OR(D10="",D4=""),"",IFERROR(D10/D4,"")) | E11: =IF(OR(E10="",E4=""),"",IFERROR(E10/E4,"")) | F11: =IF(OR(F10="",F4=""),"",IFERROR(F10/F4,"")) | G11: =IF(OR(G10="",G4=""),"",IFERROR(G10/G4,"")) | H11: =IF(OR(H10="",H4=""),"",IFERROR(H10/H4,"")) | I11: =IF(OR(I10="",I4=""),"",IFERROR(I10/I4,"")) | J11: =IF(OR(J10="",J4=""),"",IFERROR(J10/J4,"")) | ... AC11: =IF(OR(AC10="",AC4=""),"",IFERROR(AC10/AC4,""))
A12: YoY | G12: =IF(OR(G10="",C10=""),"",IFERROR(G10/C10-1,"")) | H12: =IF(OR(H10="",D10=""),"",IFERROR(H10/D10-1,"")) | I12: =IF(OR(I10="",E10=""),"",IFERROR(I10/E10-1,"")) | J12: =IF(OR(J10="",F10=""),"",IFERROR(J10/F10-1,"")) | K12: =IF(OR(K10="",G10=""),"",IFERROR(K10/G10-1,"")) | L12: =IF(OR(L10="",H10=""),"",IFERROR(L10/H10-1,"")) | M12: =IF(OR(M10="",I10=""),"",IFERROR(M10/I10-1,"")) | N12: =IF(OR(N10="",J10=""),"",IFERROR(N10/J10-1,"")) | P12: =IF(OR(P10="",O10=""),"",IFERROR(P10/O10-1,"")) | Q12: =IF(OR(Q10="",P10=""),"",IFERROR(Q10/P10-1,"")) | R12: =IF(OR(R10="",Q10=""),"",IFERROR(R10/Q10-1,"")) | S12: =IF(OR(S10="",R10=""),"",IFERROR(S10/R10-1,"")) | T12: =IF(OR(T10="",S10=""),"",IFERROR(T10/S10-1,"")) | U12: =IF(OR(U10="",T10=""),"",IFERROR(U10/T10-1,"")) | V12: =IF(OR(V10="",U10=""),"",IFERROR(V10/U10-1,"")) | W12: =IF(OR(W10="",V10=""),"",IFERROR(W10/V10-1,"")) | ... AC12: =IF(OR(AC10="",AB10=""),"",IFERROR(AC10/AB10-1,""))
A13: 부문 | C13: 102.012 | D13: 90.459 | E13: 134.637 | F13: 69.611 | G13: 119.334 | H13: 97.19 | I13: 104.111 | J13: 101.201 | K13: 65.52 | L13: 133.173 | V13: 396.719 | W13: 421.836 | X13: 445.667
A14: 비중 | C14: =IF(OR(C13="",C4=""),"",IFERROR(C13/C4,"")) | D14: =IF(OR(D13="",D4=""),"",IFERROR(D13/D4,"")) | E14: =IF(OR(E13="",E4=""),"",IFERROR(E13/E4,"")) | F14: =IF(OR(F13="",F4=""),"",IFERROR(F13/F4,"")) | G14: =IF(OR(G13="",G4=""),"",IFERROR(G13/G4,"")) | H14: =IF(OR(H13="",H4=""),"",IFERROR(H13/H4,"")) | I14: =IF(OR(I13="",I4=""),"",IFERROR(I13/I4,"")) | J14: =IF(OR(J13="",J4=""),"",IFERROR(J13/J4,"")) | ... AC14: =IF(OR(AC13="",AC4=""),"",IFERROR(AC13/AC4,""))
A15: YoY | G15: =IF(OR(G13="",C13=""),"",IFERROR(G13/C13-1,"")) | H15: =IF(OR(H13="",D13=""),"",IFERROR(H13/D13-1,"")) | I15: =IF(OR(I13="",E13=""),"",IFERROR(I13/E13-1,"")) | J15: =IF(OR(J13="",F13=""),"",IFERROR(J13/F13-1,"")) | K15: =IF(OR(K13="",G13=""),"",IFERROR(K13/G13-1,"")) | L15: =IF(OR(L13="",H13=""),"",IFERROR(L13/H13-1,"")) | M15: =IF(OR(M13="",I13=""),"",IFERROR(M13/I13-1,"")) | N15: =IF(OR(N13="",J13=""),"",IFERROR(N13/J13-1,"")) | P15: =IF(OR(P13="",O13=""),"",IFERROR(P13/O13-1,"")) | Q15: =IF(OR(Q13="",P13=""),"",IFERROR(Q13/P13-1,"")) | R15: =IF(OR(R13="",Q13=""),"",IFERROR(R13/Q13-1,"")) | S15: =IF(OR(S13="",R13=""),"",IFERROR(S13/R13-1,"")) | T15: =IF(OR(T13="",S13=""),"",IFERROR(T13/S13-1,"")) | U15: =IF(OR(U13="",T13=""),"",IFERROR(U13/T13-1,"")) | V15: =IF(OR(V13="",U13=""),"",IFERROR(V13/U13-1,"")) | W15: =IF(OR(W13="",V13=""),"",IFERROR(W13/V13-1,"")) | ... AC15: =IF(OR(AC13="",AB13=""),"",IFERROR(AC13/AB13-1,""))
A16: 부문 | C16: 15.995 | D16: 49.354 | E16: 55.512 | F16: 53.756 | G16: 12.257 | H16: 80.099 | I16: 277.755 | J16: -237.092 | K16: 28.43 | L16: 39.316 | V16: 174.617 | W16: 133.019 | X16: 445.693
A17: 비중 | C17: =IF(OR(C16="",C4=""),"",IFERROR(C16/C4,"")) | D17: =IF(OR(D16="",D4=""),"",IFERROR(D16/D4,"")) | E17: =IF(OR(E16="",E4=""),"",IFERROR(E16/E4,"")) | F17: =IF(OR(F16="",F4=""),"",IFERROR(F16/F4,"")) | G17: =IF(OR(G16="",G4=""),"",IFERROR(G16/G4,"")) | H17: =IF(OR(H16="",H4=""),"",IFERROR(H16/H4,"")) | I17: =IF(OR(I16="",I4=""),"",IFERROR(I16/I4,"")) | J17: =IF(OR(J16="",J4=""),"",IFERROR(J16/J4,"")) | ... AC17: =IF(OR(AC16="",AC4=""),"",IFERROR(AC16/AC4,""))
A18: YoY | G18: =IF(OR(G16="",C16=""),"",IFERROR(G16/C16-1,"")) | H18: =IF(OR(H16="",D16=""),"",IFERROR(H16/D16-1,"")) | I18: =IF(OR(I16="",E16=""),"",IFERROR(I16/E16-1,"")) | J18: =IF(OR(J16="",F16=""),"",IFERROR(J16/F16-1,"")) | K18: =IF(OR(K16="",G16=""),"",IFERROR(K16/G16-1,"")) | L18: =IF(OR(L16="",H16=""),"",IFERROR(L16/H16-1,"")) | M18: =IF(OR(M16="",I16=""),"",IFERROR(M16/I16-1,"")) | N18: =IF(OR(N16="",J16=""),"",IFERROR(N16/J16-1,"")) | P18: =IF(OR(P16="",O16=""),"",IFERROR(P16/O16-1,"")) | Q18: =IF(OR(Q16="",P16=""),"",IFERROR(Q16/P16-1,"")) | R18: =IF(OR(R16="",Q16=""),"",IFERROR(R16/Q16-1,"")) | S18: =IF(OR(S16="",R16=""),"",IFERROR(S16/R16-1,"")) | T18: =IF(OR(T16="",S16=""),"",IFERROR(T16/S16-1,"")) | U18: =IF(OR(U16="",T16=""),"",IFERROR(U16/T16-1,"")) | V18: =IF(OR(V16="",U16=""),"",IFERROR(V16/U16-1,"")) | W18: =IF(OR(W16="",V16=""),"",IFERROR(W16/V16-1,"")) | ... AC18: =IF(OR(AC16="",AB16=""),"",IFERROR(AC16/AB16-1,""))
A19: 매출원가
A20: 전체 매출원가 | C20: 593.605 | D20: 670.452 | E20: 697.359 | F20: 505.74 | G20: 562.78 | H20: 583.814 | I20: 759.414 | J20: 603.213 | K20: 546.983 | L20: 652.153 | O20: 3747.426 | P20: 3095.518 | Q20: 3263.75 | R20: 2834.274 | S20: 2540.878 | T20: 2726.187 | U20: 2583.747 | V20: 2467.156 | W20: 2509.221 | X20: 2627.606
A21: 매출총이익 | C21: =IF(OR(C4="",C20=""),"",IFERROR(C4-C20,"")) | D21: =IF(OR(D4="",D20=""),"",IFERROR(D4-D20,"")) | E21: =IF(OR(E4="",E20=""),"",IFERROR(E4-E20,"")) | F21: =IF(OR(F4="",F20=""),"",IFERROR(F4-F20,"")) | G21: =IF(OR(G4="",G20=""),"",IFERROR(G4-G20,"")) | H21: =IF(OR(H4="",H20=""),"",IFERROR(H4-H20,"")) | I21: =IF(OR(I4="",I20=""),"",IFERROR(I4-I20,"")) | J21: =IF(OR(J4="",J20=""),"",IFERROR(J4-J20,"")) | ... X21: =IF(OR(X4="",X20=""),"",IFERROR(X4-X20,""))
A22: GPM | C22: =IF(OR(C21="",C4=""),"",IFERROR(C21/C4,"")) | D22: =IF(OR(D21="",D4=""),"",IFERROR(D21/D4,"")) | E22: =IF(OR(E21="",E4=""),"",IFERROR(E21/E4,"")) | F22: =IF(OR(F21="",F4=""),"",IFERROR(F21/F4,"")) | G22: =IF(OR(G21="",G4=""),"",IFERROR(G21/G4,"")) | H22: =IF(OR(H21="",H4=""),"",IFERROR(H21/H4,"")) | I22: =IF(OR(I21="",I4=""),"",IFERROR(I21/I4,"")) | J22: =IF(OR(J21="",J4=""),"",IFERROR(J21/J4,"")) | ... AC22: =IF(OR(AC21="",AC4=""),"",IFERROR(AC21/AC4,""))
A23: 판매관리비
A24: 전체 판관비 | C24: 270.476 | D24: 260.157 | E24: 269.416 | F24: 286.133 | G24: 280.648 | H24: 237.353 | I24: 227.358 | J24: 318.807 | K24: 249.62 | L24: 250.577 | O24: 1175.282 | P24: 1173.203 | Q24: 1196.519 | R24: 1175.836 | S24: 1060.003 | T24: 1070.503 | U24: 1069.554 | V24: 1086.182 | W24: 1064.166 | X24: 981.488
A25: 영업이익 | B25: MW = 매출 × OPM | C25: 1.767 | D25: -36.232 | E25: 31.156 | F25: -138.564 | G25: -59.528 | H25: 2.093 | I25: 24.286 | J25: -20.939 | K25: 24.16 | L25: 59.218 | O25: 57.197 | P25: -29.956 | Q25: 122.086 | R25: -113.769 | S25: -425.693 | T25: 121.249 | U25: -27.783 | V25: -141.873 | W25: -54.088 | X25: 142.572 | Y25: =IF(OR(Y4="",Y26=""),"",IFERROR(Y4*Y26,"")) | Z25: =IF(OR(Z4="",Z26=""),"",IFERROR(Z4*Z26,"")) | AA25: =IF(OR(AA4="",AA26=""),"",IFERROR(AA4*AA26,"")) | AB25: =IF(OR(AB4="",AB26=""),"",IFERROR(AB4*AB26,"")) | AC25: =IF(OR(AC4="",AC26=""),"",IFERROR(AC4*AC26,""))
A26: OPM | B26: MW 입력 | C26: =IF(OR(C25="",C4=""),"",IFERROR(C25/C4,"")) | D26: =IF(OR(D25="",D4=""),"",IFERROR(D25/D4,"")) | E26: =IF(OR(E25="",E4=""),"",IFERROR(E25/E4,"")) | F26: =IF(OR(F25="",F4=""),"",IFERROR(F25/F4,"")) | G26: =IF(OR(G25="",G4=""),"",IFERROR(G25/G4,"")) | H26: =IF(OR(H25="",H4=""),"",IFERROR(H25/H4,"")) | I26: =IF(OR(I25="",I4=""),"",IFERROR(I25/I4,"")) | J26: =IF(OR(J25="",J4=""),"",IFERROR(J25/J4,"")) | ... X26: =IF(OR(X25="",X4=""),"",IFERROR(X25/X4,""))
A27: 증가율 | G27: =IF(OR(G25="",C25=""),"",IFERROR(G25/C25-1,"")) | H27: =IF(OR(H25="",D25=""),"",IFERROR(H25/D25-1,"")) | I27: =IF(OR(I25="",E25=""),"",IFERROR(I25/E25-1,"")) | J27: =IF(OR(J25="",F25=""),"",IFERROR(J25/F25-1,"")) | K27: =IF(OR(K25="",G25=""),"",IFERROR(K25/G25-1,"")) | L27: =IF(OR(L25="",H25=""),"",IFERROR(L25/H25-1,"")) | M27: =IF(OR(M25="",I25=""),"",IFERROR(M25/I25-1,"")) | N27: =IF(OR(N25="",J25=""),"",IFERROR(N25/J25-1,"")) | P27: =IF(OR(P25="",O25=""),"",IFERROR(P25/O25-1,"")) | Q27: =IF(OR(Q25="",P25=""),"",IFERROR(Q25/P25-1,"")) | R27: =IF(OR(R25="",Q25=""),"",IFERROR(R25/Q25-1,"")) | S27: =IF(OR(S25="",R25=""),"",IFERROR(S25/R25-1,"")) | T27: =IF(OR(T25="",S25=""),"",IFERROR(T25/S25-1,"")) | U27: =IF(OR(U25="",T25=""),"",IFERROR(U25/T25-1,"")) | V27: =IF(OR(V25="",U25=""),"",IFERROR(V25/U25-1,"")) | W27: =IF(OR(W25="",V25=""),"",IFERROR(W25/V25-1,"")) | ... AC27: =IF(OR(AC25="",AB25=""),"",IFERROR(AC25/AB25-1,""))
A28: 비용의 성격별 분류 | B28: 참고 데이터
A29: 총 판관비 | O29: =IF(O24="","",O24) | P29: =IF(P24="","",P24) | Q29: =IF(Q24="","",Q24) | R29: =IF(R24="","",R24) | S29: =IF(S24="","",S24) | T29: =IF(T24="","",T24) | U29: =IF(U24="","",U24) | V29: =IF(V24="","",V24) | ... X29: =IF(X24="","",X24)
A30: 급여 | B30: 고정비
A31: % of Sales | O31: =IF(OR(O30="",O4=""),"",IFERROR(O30/O4,"")) | P31: =IF(OR(P30="",P4=""),"",IFERROR(P30/P4,"")) | Q31: =IF(OR(Q30="",Q4=""),"",IFERROR(Q30/Q4,"")) | R31: =IF(OR(R30="",R4=""),"",IFERROR(R30/R4,"")) | S31: =IF(OR(S30="",S4=""),"",IFERROR(S30/S4,"")) | T31: =IF(OR(T30="",T4=""),"",IFERROR(T30/T4,"")) | U31: =IF(OR(U30="",U4=""),"",IFERROR(U30/U4,"")) | V31: =IF(OR(V30="",V4=""),"",IFERROR(V30/V4,"")) | ... X31: =IF(OR(X30="",X4=""),"",IFERROR(X30/X4,""))
A32: 감가상각비 | B32: 고정비
A33: % of Sales | O33: =IF(OR(O32="",O4=""),"",IFERROR(O32/O4,"")) | P33: =IF(OR(P32="",P4=""),"",IFERROR(P32/P4,"")) | Q33: =IF(OR(Q32="",Q4=""),"",IFERROR(Q32/Q4,"")) | R33: =IF(OR(R32="",R4=""),"",IFERROR(R32/R4,"")) | S33: =IF(OR(S32="",S4=""),"",IFERROR(S32/S4,"")) | T33: =IF(OR(T32="",T4=""),"",IFERROR(T32/T4,"")) | U33: =IF(OR(U32="",U4=""),"",IFERROR(U32/U4,"")) | V33: =IF(OR(V32="",V4=""),"",IFERROR(V32/V4,"")) | ... X33: =IF(OR(X32="",X4=""),"",IFERROR(X32/X4,""))
A34: 지급수수료 | B34: 고정비
A35: % of Sales | O35: =IF(OR(O34="",O4=""),"",IFERROR(O34/O4,"")) | P35: =IF(OR(P34="",P4=""),"",IFERROR(P34/P4,"")) | Q35: =IF(OR(Q34="",Q4=""),"",IFERROR(Q34/Q4,"")) | R35: =IF(OR(R34="",R4=""),"",IFERROR(R34/R4,"")) | S35: =IF(OR(S34="",S4=""),"",IFERROR(S34/S4,"")) | T35: =IF(OR(T34="",T4=""),"",IFERROR(T34/T4,"")) | U35: =IF(OR(U34="",U4=""),"",IFERROR(U34/U4,"")) | V35: =IF(OR(V34="",V4=""),"",IFERROR(V34/V4,"")) | ... X35: =IF(OR(X34="",X4=""),"",IFERROR(X34/X4,""))
A36: 연구개발비 | B36: 변동비
A37: % of Sales | O37: =IF(OR(O36="",O4=""),"",IFERROR(O36/O4,"")) | P37: =IF(OR(P36="",P4=""),"",IFERROR(P36/P4,"")) | Q37: =IF(OR(Q36="",Q4=""),"",IFERROR(Q36/Q4,"")) | R37: =IF(OR(R36="",R4=""),"",IFERROR(R36/R4,"")) | S37: =IF(OR(S36="",S4=""),"",IFERROR(S36/S4,"")) | T37: =IF(OR(T36="",T4=""),"",IFERROR(T36/T4,"")) | U37: =IF(OR(U36="",U4=""),"",IFERROR(U36/U4,"")) | V37: =IF(OR(V36="",V4=""),"",IFERROR(V36/V4,"")) | ... X37: =IF(OR(X36="",X4=""),"",IFERROR(X36/X4,""))
A38: 기타비용 | B38: 변동비 | O38: =IF(OR(O29="",O30="",O32="",O34="",O36=""),"",IFERROR(O29-O30-O32-O34-O36,"")) | P38: =IF(OR(P29="",P30="",P32="",P34="",P36=""),"",IFERROR(P29-P30-P32-P34-P36,"")) | Q38: =IF(OR(Q29="",Q30="",Q32="",Q34="",Q36=""),"",IFERROR(Q29-Q30-Q32-Q34-Q36,"")) | R38: =IF(OR(R29="",R30="",R32="",R34="",R36=""),"",IFERROR(R29-R30-R32-R34-R36,"")) | S38: =IF(OR(S29="",S30="",S32="",S34="",S36=""),"",IFERROR(S29-S30-S32-S34-S36,"")) | T38: =IF(OR(T29="",T30="",T32="",T34="",T36=""),"",IFERROR(T29-T30-T32-T34-T36,"")) | U38: =IF(OR(U29="",U30="",U32="",U34="",U36=""),"",IFERROR(U29-U30-U32-U34-U36,"")) | V38: =IF(OR(V29="",V30="",V32="",V34="",V36=""),"",IFERROR(V29-V30-V32-V34-V36,"")) | ... X38: =IF(OR(X29="",X30="",X32="",X34="",X36=""),"",IFERROR(X29-X30-X32-X34-X36,""))
A39: % of Sales | O39: =IF(OR(O38="",O4=""),"",IFERROR(O38/O4,"")) | P39: =IF(OR(P38="",P4=""),"",IFERROR(P38/P4,"")) | Q39: =IF(OR(Q38="",Q4=""),"",IFERROR(Q38/Q4,"")) | R39: =IF(OR(R38="",R4=""),"",IFERROR(R38/R4,"")) | S39: =IF(OR(S38="",S4=""),"",IFERROR(S38/S4,"")) | T39: =IF(OR(T38="",T4=""),"",IFERROR(T38/T4,"")) | U39: =IF(OR(U38="",U4=""),"",IFERROR(U38/U4,"")) | V39: =IF(OR(V38="",V4=""),"",IFERROR(V38/V4,"")) | ... X39: =IF(OR(X38="",X4=""),"",IFERROR(X38/X4,""))
A40: 당기순이익 추정
...

Sheet 재무상태표
A1: 6663 재무상태표
A2: 재무비율은 기말 잔액 기준 · 분기 손익은 최근 4분기 합산(TTM) | B2: (단위: 백만엔)
A3: 항목 | B3: 참고 | C3: 2025.3Q | D3: 2025.4Q | E3: 2026.1Q | F3: 2026.2Q | G3: 2026.3Q | H3: 2022 | I3: 2023 | J3: 2024 | K3: 2025
A4: 자산
A5: 유동자산 | C5: 2911.257 | D5: 2777.075 | E5: 2604.667 | F5: 2811.898 | G5: 2941.501 | H5: 3039.748 | I5: 2767.155 | J5: 2916.735 | K5: 2777.075
A6: 현금및현금성자산 | C6: 1872.416 | D6: 1650.048 | E6: 1257.565 | F6: 1707.71 | G6: 1942.751 | H6: 1758.992 | I6: 1665.094 | J6: 1769.981 | K6: 1650.048
A7: 단기금융상품 | C7: 0 | D7: 0 | E7: 0 | H7: 10 | I7: 0 | J7: 150 | K7: 0
A8: 매출채권 | C8: 584.847 | D8: 721.239 | E8: 1001.287 | F8: 701.593 | G8: 583.368 | H8: 686.654 | I8: 519.277 | J8: 580.887 | K8: 721.239
A9: 재고자산 | C9: 383.998 | D9: 376.169 | E9: 325.345 | F9: 389.142 | G9: 380.619 | H9: 532.542 | I9: 549.685 | J9: 379.4 | K9: 376.169
A10: 기타유동자산 | B10: 총계 − 위 항목 | C10: =IF(OR(C5=""),"",IFERROR(C5-SUM(C6,C7,C8,C9),"")) | D10: =IF(OR(D5=""),"",IFERROR(D5-SUM(D6,D7,D8,D9),"")) | E10: =IF(OR(E5=""),"",IFERROR(E5-SUM(E6,E7,E8,E9),"")) | F10: =IF(OR(F5=""),"",IFERROR(F5-SUM(F6,F7,F8,F9),"")) | G10: =IF(OR(G5=""),"",IFERROR(G5-SUM(G6,G7,G8,G9),"")) | H10: =IF(OR(H5=""),"",IFERROR(H5-SUM(H6,H7,H8,H9),"")) | I10: =IF(OR(I5=""),"",IFERROR(I5-SUM(I6,I7,I8,I9),"")) | J10: =IF(OR(J5=""),"",IFERROR(J5-SUM(J6,J7,J8,J9),"")) | K10: =IF(OR(K5=""),"",IFERROR(K5-SUM(K6,K7,K8,K9),""))
A11: 비유동자산 | C11: 1929.037 | D11: 1971.903 | E11: 1966.304 | F11: 2013.61 | G11: 2075.974 | H11: 2050.489 | I11: 2059.079 | J11: 2023.229 | K11: 1971.903
A12: 유형자산 | C12: 1381.958 | D12: 1380.279 | E12: 1356.225 | F12: 1335.302 | G12: 1332.055 | H12: 1418.311 | I12: 1412.807 | J12: 1439.542 | K12: 1380.279
A13: 무형자산 | C13: 51.158 | D13: 46.476 | E13: 41.841 | F13: 37.556 | G13: 33.567 | H13: 28.124 | I13: 63.814 | J13: 60.9 | K13: 46.476
A14: 투자부동산
A15: 기타비유동자산 | B15: 총계 − 위 항목 | C15: =IF(OR(C11=""),"",IFERROR(C11-SUM(C12,C13,C14),"")) | D15: =IF(OR(D11=""),"",IFERROR(D11-SUM(D12,D13,D14),"")) | E15: =IF(OR(E11=""),"",IFERROR(E11-SUM(E12,E13,E14),"")) | F15: =IF(OR(F11=""),"",IFERROR(F11-SUM(F12,F13,F14),"")) | G15: =IF(OR(G11=""),"",IFERROR(G11-SUM(G12,G13,G14),"")) | H15: =IF(OR(H11=""),"",IFERROR(H11-SUM(H12,H13,H14),"")) | I15: =IF(OR(I11=""),"",IFERROR(I11-SUM(I12,I13,I14),"")) | J15: =IF(OR(J11=""),"",IFERROR(J11-SUM(J12,J13,J14),"")) | K15: =IF(OR(K11=""),"",IFERROR(K11-SUM(K12,K13,K14),""))
A16: 자산총계 | C16: 4840.294 | D16: 4748.978 | E16: 4570.972 | F16: 4825.509 | G16: 5017.476 | H16: 5090.238 | I16: 4826.234 | J16: 4939.964 | K16: 4748.978
A17: 부채
A18: 유동부채 | C18: 1215.539 | D18: 1107.225 | E18: 784.061 | F18: 1021.765 | G18: 1024.752 | H18: 1157.769 | I18: 1051.918 | J18: 1144.982 | K18: 1107.225
A19: 매입채무 | C19: 100.747 | D19: 183.237 | E19: 135.614 | F19: 124.486 | G19: 127.169 | H19: 167.151 | I19: 97.028 | J19: 143.291 | K19: 183.237
A20: 단기차입금 | C20: 574.192 | D20: 562.165 | E20: 290.668 | F20: 510.689 | G20: 510.959 | H20: 599.197 | I20: 571.416 | J20: 598.676 | K20: 562.165
A21: 유동성장기부채
A22: 기타유동부채 | B22: 총계 − 위 항목 | C22: =IF(OR(C18=""),"",IFERROR(C18-SUM(C19,C20,C21),"")) | D22: =IF(OR(D18=""),"",IFERROR(D18-SUM(D19,D20,D21),"")) | E22: =IF(OR(E18=""),"",IFERROR(E18-SUM(E19,E20,E21),"")) | F22: =IF(OR(F18=""),"",IFERROR(F18-SUM(F19,F20,F21),"")) | G22: =IF(OR(G18=""),"",IFERROR(G18-SUM(G19,G20,G21),"")) | H22: =IF(OR(H18=""),"",IFERROR(H18-SUM(H19,H20,H21),"")) | I22: =IF(OR(I18=""),"",IFERROR(I18-SUM(I19,I20,I21),"")) | J22: =IF(OR(J18=""),"",IFERROR(J18-SUM(J19,J20,J21),"")) | K22: =IF(OR(K18=""),"",IFERROR(K18-SUM(K19,K20,K21),""))
A23: 비유동부채 | C23: 1180.433 | D23: 1137.966 | E23: 1088.5 | F23: 1088.554 | G23: 1173.526 | H23: 1302.884 | I23: 1234.38 | J23: 1225.434 | K23: 1137.966
A24: 장기차입금 | C24: 384.038 | D24: 331.575 | E24: 280.582 | F24: 268.76 | G24: 321.414 | H24: 517.808 | I24: 479.739 | J24: 394.737 | K24: 331.575
A25: 사채
A26: 기타비유동부채 | B26: 총계 − 위 항목 | C26: =IF(OR(C23=""),"",IFERROR(C23-SUM(C24,C25),"")) | D26: =IF(OR(D23=""),"",IFERROR(D23-SUM(D24,D25),"")) | E26: =IF(OR(E23=""),"",IFERROR(E23-SUM(E24,E25),"")) | F26: =IF(OR(F23=""),"",IFERROR(F23-SUM(F24,F25),"")) | G26: =IF(OR(G23=""),"",IFERROR(G23-SUM(G24,G25),"")) | H26: =IF(OR(H23=""),"",IFERROR(H23-SUM(H24,H25),"")) | I26: =IF(OR(I23=""),"",IFERROR(I23-SUM(I24,I25),"")) | J26: =IF(OR(J23=""),"",IFERROR(J23-SUM(J24,J25),"")) | K26: =IF(OR(K23=""),"",IFERROR(K23-SUM(K24,K25),""))
A27: 부채총계 | C27: 2395.973 | D27: 2245.191 | E27: 1872.562 | F27: 2110.319 | G27: 2198.279 | H27: 2460.654 | I27: 2286.298 | J27: 2370.417 | K27: 2245.191
A28: 총차입금 | B28: 단기+유동성장기+장기+사채 | C28: =SUM(C20,C21,C24,C25) | D28: =SUM(D20,D21,D24,D25) | E28: =SUM(E20,E21,E24,E25) | F28: =SUM(F20,F21,F24,F25) | G28: =SUM(G20,G21,G24,G25) | H28: =SUM(H20,H21,H24,H25) | I28: =SUM(I20,I21,I24,I25) | J28: =SUM(J20,J21,J24,J25) | K28: =SUM(K20,K21,K24,K25)
A29: 순차입금 | B29: 음수 = 순현금 | C29: =C28-C6-N(C7) | D29: =D28-D6-N(D7) | E29: =E28-E6-N(E7) | F29: =F28-F6-N(F7) | G29: =G28-G6-N(G7) | H29: =H28-H6-N(H7) | I29: =I28-I6-N(I7) | J29: =J28-J6-N(J7) | K29: =K28-K6-N(K7)
A30: 자본
A31: 지배주주지분 | C31: 2416.627 | D31: 2474.671 | E31: 2669.024 | F31: 2684.008 | G31: 2786.58 | H31: 2597.579 | I31: 2509.989 | J31: 2536.942 | K31: 2474.671
A32: 자본금 | C32: 822.195 | D32: 822.195 | E32: 822.195 | F32: 822.195 | G32: 833.535 | H32: 815.198 | I32: 815.198 | J32: 822.195 | K32: 822.195
A33: 이익잉여금 | C33: 476.169 | D33: 511.788 | E33: 678.098 | F33: 644.294 | G33: 681.306 | H33: 757.509 | I33: 648.872 | J33: 633.359 | K33: 511.788
A34: 비지배지분 | C34: 27.694 | D34: 29.115 | E34: 29.386 | F34: 31.181 | G34: 32.616 | H34: 32.005 | I34: 29.947 | J34: 32.605 | K34: 29.115
A35: 자본총계 | C35: 2444.321 | D35: 2503.786 | E35: 2698.41 | F35: 2715.189 | G35: 2819.196 | H35: 2629.584 | I35: 2539.936 | J35: 2569.547 | K35: 2503.786
A36: 현금흐름 요약 | B36: 분기 = TTM (있을 때만)
A37: 영업활동현금흐름 | D37: 248.699 | F37: 616.404 | H37: 165.18 | I37: 233.127 | J37: -27.472 | K37: 248.699
A38: CAPEX (유·무형 취득) | B38: 양수로 입력 | D38: 36.467 | F38: 24.074 | H38: 18.797 | I38: 87.276 | J38: 175.808 | K38: 36.467
A39: FCF | C39: =IF(OR(C37="",C38=""),"",IFERROR(C37-C38,"")) | D39: =IF(OR(D37="",D38=""),"",IFERROR(D37-D38,"")) | E39: =IF(OR(E37="",E38=""),"",IFERROR(E37-E38,"")) | F39: =IF(OR(F37="",F38=""),"",IFERROR(F37-F38,"")) | G39: =IF(OR(G37="",G38=""),"",IFERROR(G37-G38,"")) | H39: =IF(OR(H37="",H38=""),"",IFERROR(H37-H38,"")) | I39: =IF(OR(I37="",I38=""),"",IFERROR(I37-I38,"")) | J39: =IF(OR(J37="",J38=""),"",IFERROR(J37-J38,"")) | K39: =IF(OR(K37="",K38=""),"",IFERROR(K37-K38,""))
A40: 배당금 지급 | B40: 양수로 입력 | D40: 17.836 | F40: 35.795 | H40: 17.724 | I40: 29.519 | J40: 17.836 | K40: 17.836
...

Sheet 출처
A1: 출처 · 쓴 결산단신
A3: 공시일 | B3: 문서 | C3: PDF
A4: 2026-07-30 | B4: 2026년 12월 결산기 2분기 결산단신 | C4: https://www2.jpx.co.jp/disc/66630/140120260713592535.pdf
A5: 2026-04-24 | B5: 2026년 12월 결산기 1분기 결산단신 | C5: https://www2.jpx.co.jp/disc/66630/140120260406598632.pdf
A6: 2026-01-30 | B6: 2025년 12월 결산기 연간 결산단신 | C6: https://www2.jpx.co.jp/disc/66630/140120260115534361.pdf
A7: 2025-10-24 | B7: 2025년 12월 결산기 3분기 결산단신 | C7: https://www2.jpx.co.jp/disc/66630/140120251007569636.pdf
A8: 2025-07-30 | B8: 2025년 12월 결산기 2분기 결산단신 | C8: https://www2.jpx.co.jp/disc/66630/140120250618592901.pdf
A9: 2025-04-25 | B9: 2025년 12월 결산기 1분기 결산단신 | C9: https://www2.jpx.co.jp/disc/66630/140120250404509322.pdf
A10: 2025-01-31 | B10: 2024년 12월 결산기 연간 결산단신 | C10: https://www2.jpx.co.jp/disc/66630/140120241218540676.pdf
A11: 2024-10-25 | B11: 2024년 12월 결산기 3분기 결산단신 | C11: https://www2.jpx.co.jp/disc/66630/140120240912583995.pdf
A12: 2024-07-30 | B12: 2024년 12월 결산기 2분기 결산단신 | C12: https://www2.jpx.co.jp/disc/66630/140120240722552383.pdf
A13: 2024-04-26 | B13: 2024년 12월 결산기 1분기 결산단신 | C13: https://www2.jpx.co.jp/disc/66630/140120240401564224.pdf
A14: 2024-01-30 | B14: 2023년 12월 결산기 연간 결산단신 | C14: https://www2.jpx.co.jp/disc/66630/140120231221506600.pdf
... A24: 2018-01-30 | B24: 연간 결산단신 | C24: https://www2.jpx.co.jp/disc/66630/140120171227443538.pdf
