Workbook

Sheet 연간
A1: 미라이공업 Model
A2: 모를 땐 보수적으로 | B2: (단위: 백만엔) | C2: 2월 결산 · 일본 기준 · 2027.4Q = 2027년 2월 결산기 4분기 | Y2: (추정: 파란 글씨 = 직접 입력)
A3: 항목 | B3: 참고 | C3: 2025.1Q | D3: 2025.2Q | E3: 2025.3Q | F3: 2025.4Q | G3: 2026.1Q | H3: 2026.2Q | I3: 2026.3Q | J3: 2026.4Q | K3: 2027.1Q | L3: 2027.2Q | M3: 2027.3Q | N3: 2027.4Q | O3: 2018 | P3: 2019 | Q3: 2020 | R3: 2021 | S3: 2022 | T3: 2023 | U3: 2024 | V3: 2025 | W3: 2026 | X3: 2027 | Y3: 2028(MW) | Z3: 2029(MW) | AA3: 2030(MW) | AB3: 2031(MW) | AC3: 2032(MW)
A4: 매출액 | B4: MW = 제품 합계 | C4: 11142 | D4: 11221 | E4: 12606 | F4: 9122 | G4: 11677 | H4: 11269 | I4: 12432 | J4: 9735 | K4: 12764 | L4: 12097 | P4: 35175 | Q4: 36035 | R4: 37573 | S4: 36069 | T4: 36905 | U4: 39568 | V4: 44091 | W4: 45113 | X4: 45673 | Y4: =IF(COUNT(Y7,Y10,Y13)=0,"",SUM(Y7,Y10,Y13)) | Z4: =IF(COUNT(Z7,Z10,Z13)=0,"",SUM(Z7,Z10,Z13)) | AA4: =IF(COUNT(AA7,AA10,AA13)=0,"",SUM(AA7,AA10,AA13)) | AB4: =IF(COUNT(AB7,AB10,AB13)=0,"",SUM(AB7,AB10,AB13)) | AC4: =IF(COUNT(AC7,AC10,AC13)=0,"",SUM(AC7,AC10,AC13))
A5: YoY | G5: =IF(OR(G4="",C4=""),"",IFERROR(G4/C4-1,"")) | H5: =IF(OR(H4="",D4=""),"",IFERROR(H4/D4-1,"")) | I5: =IF(OR(I4="",E4=""),"",IFERROR(I4/E4-1,"")) | J5: =IF(OR(J4="",F4=""),"",IFERROR(J4/F4-1,"")) | K5: =IF(OR(K4="",G4=""),"",IFERROR(K4/G4-1,"")) | L5: =IF(OR(L4="",H4=""),"",IFERROR(L4/H4-1,"")) | M5: =IF(OR(M4="",I4=""),"",IFERROR(M4/I4-1,"")) | N5: =IF(OR(N4="",J4=""),"",IFERROR(N4/J4-1,"")) | P5: =IF(OR(P4="",O4=""),"",IFERROR(P4/O4-1,"")) | Q5: =IF(OR(Q4="",P4=""),"",IFERROR(Q4/P4-1,"")) | R5: =IF(OR(R4="",Q4=""),"",IFERROR(R4/Q4-1,"")) | S5: =IF(OR(S4="",R4=""),"",IFERROR(S4/R4-1,"")) | T5: =IF(OR(T4="",S4=""),"",IFERROR(T4/S4-1,"")) | U5: =IF(OR(U4="",T4=""),"",IFERROR(U4/T4-1,"")) | V5: =IF(OR(V4="",U4=""),"",IFERROR(V4/U4-1,"")) | W5: =IF(OR(W4="",V4=""),"",IFERROR(W4/V4-1,"")) | ... AC5: =IF(OR(AC4="",AB4=""),"",IFERROR(AC4/AB4-1,""))
A6: 제품별 매출 분류 | B6: 사업보고서 매출실적
A7: 전기자재 및 관재 | C7: 8649 | D7: 8708 | E7: 9766 | F7: 6997 | G7: 9019 | H7: 8540 | I7: 9492 | J7: 7733 | K7: 9883 | L7: 9150 | V7: 34120 | W7: 34784 | X7: 34733
A8: 비중 | C8: =IF(OR(C7="",C4=""),"",IFERROR(C7/C4,"")) | D8: =IF(OR(D7="",D4=""),"",IFERROR(D7/D4,"")) | E8: =IF(OR(E7="",E4=""),"",IFERROR(E7/E4,"")) | F8: =IF(OR(F7="",F4=""),"",IFERROR(F7/F4,"")) | G8: =IF(OR(G7="",G4=""),"",IFERROR(G7/G4,"")) | H8: =IF(OR(H7="",H4=""),"",IFERROR(H7/H4,"")) | I8: =IF(OR(I7="",I4=""),"",IFERROR(I7/I4,"")) | J8: =IF(OR(J7="",J4=""),"",IFERROR(J7/J4,"")) | ... AC8: =IF(OR(AC7="",AC4=""),"",IFERROR(AC7/AC4,""))
A9: YoY | G9: =IF(OR(G7="",C7=""),"",IFERROR(G7/C7-1,"")) | H9: =IF(OR(H7="",D7=""),"",IFERROR(H7/D7-1,"")) | I9: =IF(OR(I7="",E7=""),"",IFERROR(I7/E7-1,"")) | J9: =IF(OR(J7="",F7=""),"",IFERROR(J7/F7-1,"")) | K9: =IF(OR(K7="",G7=""),"",IFERROR(K7/G7-1,"")) | L9: =IF(OR(L7="",H7=""),"",IFERROR(L7/H7-1,"")) | M9: =IF(OR(M7="",I7=""),"",IFERROR(M7/I7-1,"")) | N9: =IF(OR(N7="",J7=""),"",IFERROR(N7/J7-1,"")) | P9: =IF(OR(P7="",O7=""),"",IFERROR(P7/O7-1,"")) | Q9: =IF(OR(Q7="",P7=""),"",IFERROR(Q7/P7-1,"")) | R9: =IF(OR(R7="",Q7=""),"",IFERROR(R7/Q7-1,"")) | S9: =IF(OR(S7="",R7=""),"",IFERROR(S7/R7-1,"")) | T9: =IF(OR(T7="",S7=""),"",IFERROR(T7/S7-1,"")) | U9: =IF(OR(U7="",T7=""),"",IFERROR(U7/T7-1,"")) | V9: =IF(OR(V7="",U7=""),"",IFERROR(V7/U7-1,"")) | W9: =IF(OR(W7="",V7=""),"",IFERROR(W7/V7-1,"")) | ... AC9: =IF(OR(AC7="",AB7=""),"",IFERROR(AC7/AB7-1,""))
A10: 배선 기구 | C10: 1710 | D10: 1804 | E10: 2089 | F10: 1224 | G10: 1903 | H10: 1972 | I10: 2221 | J10: 1233 | K10: 2148 | L10: 2177 | V10: 6827 | W10: 7329 | X10: 8037
A11: 비중 | C11: =IF(OR(C10="",C4=""),"",IFERROR(C10/C4,"")) | D11: =IF(OR(D10="",D4=""),"",IFERROR(D10/D4,"")) | E11: =IF(OR(E10="",E4=""),"",IFERROR(E10/E4,"")) | F11: =IF(OR(F10="",F4=""),"",IFERROR(F10/F4,"")) | G11: =IF(OR(G10="",G4=""),"",IFERROR(G10/G4,"")) | H11: =IF(OR(H10="",H4=""),"",IFERROR(H10/H4,"")) | I11: =IF(OR(I10="",I4=""),"",IFERROR(I10/I4,"")) | J11: =IF(OR(J10="",J4=""),"",IFERROR(J10/J4,"")) | ... AC11: =IF(OR(AC10="",AC4=""),"",IFERROR(AC10/AC4,""))
A12: YoY | G12: =IF(OR(G10="",C10=""),"",IFERROR(G10/C10-1,"")) | H12: =IF(OR(H10="",D10=""),"",IFERROR(H10/D10-1,"")) | I12: =IF(OR(I10="",E10=""),"",IFERROR(I10/E10-1,"")) | J12: =IF(OR(J10="",F10=""),"",IFERROR(J10/F10-1,"")) | K12: =IF(OR(K10="",G10=""),"",IFERROR(K10/G10-1,"")) | L12: =IF(OR(L10="",H10=""),"",IFERROR(L10/H10-1,"")) | M12: =IF(OR(M10="",I10=""),"",IFERROR(M10/I10-1,"")) | N12: =IF(OR(N10="",J10=""),"",IFERROR(N10/J10-1,"")) | P12: =IF(OR(P10="",O10=""),"",IFERROR(P10/O10-1,"")) | Q12: =IF(OR(Q10="",P10=""),"",IFERROR(Q10/P10-1,"")) | R12: =IF(OR(R10="",Q10=""),"",IFERROR(R10/Q10-1,"")) | S12: =IF(OR(S10="",R10=""),"",IFERROR(S10/R10-1,"")) | T12: =IF(OR(T10="",S10=""),"",IFERROR(T10/S10-1,"")) | U12: =IF(OR(U10="",T10=""),"",IFERROR(U10/T10-1,"")) | V12: =IF(OR(V10="",U10=""),"",IFERROR(V10/U10-1,"")) | W12: =IF(OR(W10="",V10=""),"",IFERROR(W10/V10-1,"")) | ... AC12: =IF(OR(AC10="",AB10=""),"",IFERROR(AC10/AB10-1,""))
A13: 기타 | C13: 782 | D13: 709 | E13: 751 | F13: 901 | G13: 754 | H13: 757 | I13: 720 | J13: 768 | K13: 732 | L13: 769 | V13: 3143 | W13: 2999 | X13: 2902
A14: 비중 | C14: =IF(OR(C13="",C4=""),"",IFERROR(C13/C4,"")) | D14: =IF(OR(D13="",D4=""),"",IFERROR(D13/D4,"")) | E14: =IF(OR(E13="",E4=""),"",IFERROR(E13/E4,"")) | F14: =IF(OR(F13="",F4=""),"",IFERROR(F13/F4,"")) | G14: =IF(OR(G13="",G4=""),"",IFERROR(G13/G4,"")) | H14: =IF(OR(H13="",H4=""),"",IFERROR(H13/H4,"")) | I14: =IF(OR(I13="",I4=""),"",IFERROR(I13/I4,"")) | J14: =IF(OR(J13="",J4=""),"",IFERROR(J13/J4,"")) | ... AC14: =IF(OR(AC13="",AC4=""),"",IFERROR(AC13/AC4,""))
A15: YoY | G15: =IF(OR(G13="",C13=""),"",IFERROR(G13/C13-1,"")) | H15: =IF(OR(H13="",D13=""),"",IFERROR(H13/D13-1,"")) | I15: =IF(OR(I13="",E13=""),"",IFERROR(I13/E13-1,"")) | J15: =IF(OR(J13="",F13=""),"",IFERROR(J13/F13-1,"")) | K15: =IF(OR(K13="",G13=""),"",IFERROR(K13/G13-1,"")) | L15: =IF(OR(L13="",H13=""),"",IFERROR(L13/H13-1,"")) | M15: =IF(OR(M13="",I13=""),"",IFERROR(M13/I13-1,"")) | N15: =IF(OR(N13="",J13=""),"",IFERROR(N13/J13-1,"")) | P15: =IF(OR(P13="",O13=""),"",IFERROR(P13/O13-1,"")) | Q15: =IF(OR(Q13="",P13=""),"",IFERROR(Q13/P13-1,"")) | R15: =IF(OR(R13="",Q13=""),"",IFERROR(R13/Q13-1,"")) | S15: =IF(OR(S13="",R13=""),"",IFERROR(S13/R13-1,"")) | T15: =IF(OR(T13="",S13=""),"",IFERROR(T13/S13-1,"")) | U15: =IF(OR(U13="",T13=""),"",IFERROR(U13/T13-1,"")) | V15: =IF(OR(V13="",U13=""),"",IFERROR(V13/U13-1,"")) | W15: =IF(OR(W13="",V13=""),"",IFERROR(W13/V13-1,"")) | ... AC15: =IF(OR(AC13="",AB13=""),"",IFERROR(AC13/AB13-1,""))
A16: 매출원가
A17: 전체 매출원가 | C17: 6663 | D17: 6803 | E17: 7481 | F17: 5369 | G17: 7250 | H17: 6961 | I17: 7391 | J17: 5756 | K17: 7689 | L17: 7471 | P17: 21374 | Q17: 22417 | R17: 23238 | S17: 22118 | T17: 23111 | U17: 25606 | V17: 26316 | W17: 27358 | X17: 28012
A18: YoY | G18: =IF(OR(G17="",C17=""),"",IF(C17<=0,"",IFERROR(G17/C17-1,""))) | H18: =IF(OR(H17="",D17=""),"",IF(D17<=0,"",IFERROR(H17/D17-1,""))) | I18: =IF(OR(I17="",E17=""),"",IF(E17<=0,"",IFERROR(I17/E17-1,""))) | J18: =IF(OR(J17="",F17=""),"",IF(F17<=0,"",IFERROR(J17/F17-1,""))) | K18: =IF(OR(K17="",G17=""),"",IF(G17<=0,"",IFERROR(K17/G17-1,""))) | L18: =IF(OR(L17="",H17=""),"",IF(H17<=0,"",IFERROR(L17/H17-1,""))) | M18: =IF(OR(M17="",I17=""),"",IF(I17<=0,"",IFERROR(M17/I17-1,""))) | N18: =IF(OR(N17="",J17=""),"",IF(J17<=0,"",IFERROR(N17/J17-1,""))) | P18: =IF(OR(P17="",O17=""),"",IF(O17<=0,"",IFERROR(P17/O17-1,""))) | Q18: =IF(OR(Q17="",P17=""),"",IF(P17<=0,"",IFERROR(Q17/P17-1,""))) | R18: =IF(OR(R17="",Q17=""),"",IF(Q17<=0,"",IFERROR(R17/Q17-1,""))) | S18: =IF(OR(S17="",R17=""),"",IF(R17<=0,"",IFERROR(S17/R17-1,""))) | T18: =IF(OR(T17="",S17=""),"",IF(S17<=0,"",IFERROR(T17/S17-1,""))) | U18: =IF(OR(U17="",T17=""),"",IF(T17<=0,"",IFERROR(U17/T17-1,""))) | V18: =IF(OR(V17="",U17=""),"",IF(U17<=0,"",IFERROR(V17/U17-1,""))) | W18: =IF(OR(W17="",V17=""),"",IF(V17<=0,"",IFERROR(W17/V17-1,""))) | ... AC18: =IF(OR(AC17="",AB17=""),"",IF(AB17<=0,"",IFERROR(AC17/AB17-1,"")))
A19: 매출총이익 | C19: =IF(OR(C4="",C17=""),"",IFERROR(C4-C17,"")) | D19: =IF(OR(D4="",D17=""),"",IFERROR(D4-D17,"")) | E19: =IF(OR(E4="",E17=""),"",IFERROR(E4-E17,"")) | F19: =IF(OR(F4="",F17=""),"",IFERROR(F4-F17,"")) | G19: =IF(OR(G4="",G17=""),"",IFERROR(G4-G17,"")) | H19: =IF(OR(H4="",H17=""),"",IFERROR(H4-H17,"")) | I19: =IF(OR(I4="",I17=""),"",IFERROR(I4-I17,"")) | J19: =IF(OR(J4="",J17=""),"",IFERROR(J4-J17,"")) | ... X19: =IF(OR(X4="",X17=""),"",IFERROR(X4-X17,""))
A20: GPM | C20: =IF(OR(C19="",C4=""),"",IFERROR(C19/C4,"")) | D20: =IF(OR(D19="",D4=""),"",IFERROR(D19/D4,"")) | E20: =IF(OR(E19="",E4=""),"",IFERROR(E19/E4,"")) | F20: =IF(OR(F19="",F4=""),"",IFERROR(F19/F4,"")) | G20: =IF(OR(G19="",G4=""),"",IFERROR(G19/G4,"")) | H20: =IF(OR(H19="",H4=""),"",IFERROR(H19/H4,"")) | I20: =IF(OR(I19="",I4=""),"",IFERROR(I19/I4,"")) | J20: =IF(OR(J19="",J4=""),"",IFERROR(J19/J4,"")) | ... AC20: =IF(OR(AC19="",AC4=""),"",IFERROR(AC19/AC4,""))
A21: YoY | G21: =IF(OR(G19="",C19=""),"",IF(C19<=0,"",IFERROR(G19/C19-1,""))) | H21: =IF(OR(H19="",D19=""),"",IF(D19<=0,"",IFERROR(H19/D19-1,""))) | I21: =IF(OR(I19="",E19=""),"",IF(E19<=0,"",IFERROR(I19/E19-1,""))) | J21: =IF(OR(J19="",F19=""),"",IF(F19<=0,"",IFERROR(J19/F19-1,""))) | K21: =IF(OR(K19="",G19=""),"",IF(G19<=0,"",IFERROR(K19/G19-1,""))) | L21: =IF(OR(L19="",H19=""),"",IF(H19<=0,"",IFERROR(L19/H19-1,""))) | M21: =IF(OR(M19="",I19=""),"",IF(I19<=0,"",IFERROR(M19/I19-1,""))) | N21: =IF(OR(N19="",J19=""),"",IF(J19<=0,"",IFERROR(N19/J19-1,""))) | P21: =IF(OR(P19="",O19=""),"",IF(O19<=0,"",IFERROR(P19/O19-1,""))) | Q21: =IF(OR(Q19="",P19=""),"",IF(P19<=0,"",IFERROR(Q19/P19-1,""))) | R21: =IF(OR(R19="",Q19=""),"",IF(Q19<=0,"",IFERROR(R19/Q19-1,""))) | S21: =IF(OR(S19="",R19=""),"",IF(R19<=0,"",IFERROR(S19/R19-1,""))) | T21: =IF(OR(T19="",S19=""),"",IF(S19<=0,"",IFERROR(T19/S19-1,""))) | U21: =IF(OR(U19="",T19=""),"",IF(T19<=0,"",IFERROR(U19/T19-1,""))) | V21: =IF(OR(V19="",U19=""),"",IF(U19<=0,"",IFERROR(V19/U19-1,""))) | W21: =IF(OR(W19="",V19=""),"",IF(V19<=0,"",IFERROR(W19/V19-1,""))) | ... AC21: =IF(OR(AC19="",AB19=""),"",IF(AB19<=0,"",IFERROR(AC19/AB19-1,"")))
A22: 판매관리비
A23: 전체 판관비 | C23: 2847 | D23: 2580 | E23: 2900 | F23: 2114 | G23: 2947 | H23: 2628 | I23: 2733 | J23: 2549 | K23: 3128 | L23: 2780 | P23: 9601 | Q23: 9712 | R23: 10123 | S23: 9767 | T23: 9749 | U23: 9917 | V23: 10441 | W23: 10857 | X23: 10937
A24: YoY | G24: =IF(OR(G23="",C23=""),"",IF(C23<=0,"",IFERROR(G23/C23-1,""))) | H24: =IF(OR(H23="",D23=""),"",IF(D23<=0,"",IFERROR(H23/D23-1,""))) | I24: =IF(OR(I23="",E23=""),"",IF(E23<=0,"",IFERROR(I23/E23-1,""))) | J24: =IF(OR(J23="",F23=""),"",IF(F23<=0,"",IFERROR(J23/F23-1,""))) | K24: =IF(OR(K23="",G23=""),"",IF(G23<=0,"",IFERROR(K23/G23-1,""))) | L24: =IF(OR(L23="",H23=""),"",IF(H23<=0,"",IFERROR(L23/H23-1,""))) | M24: =IF(OR(M23="",I23=""),"",IF(I23<=0,"",IFERROR(M23/I23-1,""))) | N24: =IF(OR(N23="",J23=""),"",IF(J23<=0,"",IFERROR(N23/J23-1,""))) | P24: =IF(OR(P23="",O23=""),"",IF(O23<=0,"",IFERROR(P23/O23-1,""))) | Q24: =IF(OR(Q23="",P23=""),"",IF(P23<=0,"",IFERROR(Q23/P23-1,""))) | R24: =IF(OR(R23="",Q23=""),"",IF(Q23<=0,"",IFERROR(R23/Q23-1,""))) | S24: =IF(OR(S23="",R23=""),"",IF(R23<=0,"",IFERROR(S23/R23-1,""))) | T24: =IF(OR(T23="",S23=""),"",IF(S23<=0,"",IFERROR(T23/S23-1,""))) | U24: =IF(OR(U23="",T23=""),"",IF(T23<=0,"",IFERROR(U23/T23-1,""))) | V24: =IF(OR(V23="",U23=""),"",IF(U23<=0,"",IFERROR(V23/U23-1,""))) | W24: =IF(OR(W23="",V23=""),"",IF(V23<=0,"",IFERROR(W23/V23-1,""))) | ... AC24: =IF(OR(AC23="",AB23=""),"",IF(AB23<=0,"",IFERROR(AC23/AB23-1,"")))
A25: 영업이익 | B25: MW = 매출 × OPM | C25: 1631 | D25: 1837 | E25: 2225 | F25: 1639 | G25: 1479 | H25: 1680 | I25: 2309 | J25: 1429 | K25: 1945 | L25: 1847 | P25: 4198 | Q25: 3904 | R25: 4211 | S25: 4184 | T25: 4044 | U25: 4044 | V25: 7332 | W25: 6897 | X25: 6723 | Y25: =IF(OR(Y4="",Y26=""),"",IFERROR(Y4*Y26,"")) | Z25: =IF(OR(Z4="",Z26=""),"",IFERROR(Z4*Z26,"")) | AA25: =IF(OR(AA4="",AA26=""),"",IFERROR(AA4*AA26,"")) | AB25: =IF(OR(AB4="",AB26=""),"",IFERROR(AB4*AB26,"")) | AC25: =IF(OR(AC4="",AC26=""),"",IFERROR(AC4*AC26,""))
A26: OPM | B26: MW 입력 | C26: =IF(OR(C25="",C4=""),"",IFERROR(C25/C4,"")) | D26: =IF(OR(D25="",D4=""),"",IFERROR(D25/D4,"")) | E26: =IF(OR(E25="",E4=""),"",IFERROR(E25/E4,"")) | F26: =IF(OR(F25="",F4=""),"",IFERROR(F25/F4,"")) | G26: =IF(OR(G25="",G4=""),"",IFERROR(G25/G4,"")) | H26: =IF(OR(H25="",H4=""),"",IFERROR(H25/H4,"")) | I26: =IF(OR(I25="",I4=""),"",IFERROR(I25/I4,"")) | J26: =IF(OR(J25="",J4=""),"",IFERROR(J25/J4,"")) | ... X26: =IF(OR(X25="",X4=""),"",IFERROR(X25/X4,""))
A27: 증가율 | G27: =IF(OR(G25="",C25=""),"",IFERROR(G25/C25-1,"")) | H27: =IF(OR(H25="",D25=""),"",IFERROR(H25/D25-1,"")) | I27: =IF(OR(I25="",E25=""),"",IFERROR(I25/E25-1,"")) | J27: =IF(OR(J25="",F25=""),"",IFERROR(J25/F25-1,"")) | K27: =IF(OR(K25="",G25=""),"",IFERROR(K25/G25-1,"")) | L27: =IF(OR(L25="",H25=""),"",IFERROR(L25/H25-1,"")) | M27: =IF(OR(M25="",I25=""),"",IFERROR(M25/I25-1,"")) | N27: =IF(OR(N25="",J25=""),"",IFERROR(N25/J25-1,"")) | P27: =IF(OR(P25="",O25=""),"",IFERROR(P25/O25-1,"")) | Q27: =IF(OR(Q25="",P25=""),"",IFERROR(Q25/P25-1,"")) | R27: =IF(OR(R25="",Q25=""),"",IFERROR(R25/Q25-1,"")) | S27: =IF(OR(S25="",R25=""),"",IFERROR(S25/R25-1,"")) | T27: =IF(OR(T25="",S25=""),"",IFERROR(T25/S25-1,"")) | U27: =IF(OR(U25="",T25=""),"",IFERROR(U25/T25-1,"")) | V27: =IF(OR(V25="",U25=""),"",IFERROR(V25/U25-1,"")) | W27: =IF(OR(W25="",V25=""),"",IFERROR(W25/V25-1,"")) | ... AC27: =IF(OR(AC25="",AB25=""),"",IFERROR(AC25/AB25-1,""))
A28: 비용의 성격별 분류 | B28: 참고 데이터
A29: 총 판관비 | O29: =IF(O23="","",O23) | P29: =IF(P23="","",P23) | Q29: =IF(Q23="","",Q23) | R29: =IF(R23="","",R23) | S29: =IF(S23="","",S23) | T29: =IF(T23="","",T23) | U29: =IF(U23="","",U23) | V29: =IF(V23="","",V23) | ... X29: =IF(X23="","",X23)
A30: 급여 | B30: 고정비 | P30: 3379 | Q30: 3503 | R30: 3556 | S30: 3517 | T30: 3542 | U30: 3611 | V30: 3653 | W30: 3751 | X30: 3859
A31: % of Sales | O31: =IF(OR(O30="",O4=""),"",IFERROR(O30/O4,"")) | P31: =IF(OR(P30="",P4=""),"",IFERROR(P30/P4,"")) | Q31: =IF(OR(Q30="",Q4=""),"",IFERROR(Q30/Q4,"")) | R31: =IF(OR(R30="",R4=""),"",IFERROR(R30/R4,"")) | S31: =IF(OR(S30="",S4=""),"",IFERROR(S30/S4,"")) | T31: =IF(OR(T30="",T4=""),"",IFERROR(T30/T4,"")) | U31: =IF(OR(U30="",U4=""),"",IFERROR(U30/U4,"")) | V31: =IF(OR(V30="",V4=""),"",IFERROR(V30/V4,"")) | ... X31: =IF(OR(X30="",X4=""),"",IFERROR(X30/X4,""))
A32: 감가상각비 | B32: 고정비
A33: % of Sales | O33: =IF(OR(O32="",O4=""),"",IFERROR(O32/O4,"")) | P33: =IF(OR(P32="",P4=""),"",IFERROR(P32/P4,"")) | Q33: =IF(OR(Q32="",Q4=""),"",IFERROR(Q32/Q4,"")) | R33: =IF(OR(R32="",R4=""),"",IFERROR(R32/R4,"")) | S33: =IF(OR(S32="",S4=""),"",IFERROR(S32/S4,"")) | T33: =IF(OR(T32="",T4=""),"",IFERROR(T32/T4,"")) | U33: =IF(OR(U32="",U4=""),"",IFERROR(U32/U4,"")) | V33: =IF(OR(V32="",V4=""),"",IFERROR(V32/V4,"")) | ... X33: =IF(OR(X32="",X4=""),"",IFERROR(X32/X4,""))
A34: 지급수수료 | B34: 고정비
A35: % of Sales | O35: =IF(OR(O34="",O4=""),"",IFERROR(O34/O4,"")) | P35: =IF(OR(P34="",P4=""),"",IFERROR(P34/P4,"")) | Q35: =IF(OR(Q34="",Q4=""),"",IFERROR(Q34/Q4,"")) | R35: =IF(OR(R34="",R4=""),"",IFERROR(R34/R4,"")) | S35: =IF(OR(S34="",S4=""),"",IFERROR(S34/S4,"")) | T35: =IF(OR(T34="",T4=""),"",IFERROR(T34/T4,"")) | U35: =IF(OR(U34="",U4=""),"",IFERROR(U34/U4,"")) | V35: =IF(OR(V34="",V4=""),"",IFERROR(V34/V4,"")) | ... X35: =IF(OR(X34="",X4=""),"",IFERROR(X34/X4,""))
A36: 연구개발비 | B36: 변동비
A37: % of Sales | O37: =IF(OR(O36="",O4=""),"",IFERROR(O36/O4,"")) | P37: =IF(OR(P36="",P4=""),"",IFERROR(P36/P4,"")) | Q37: =IF(OR(Q36="",Q4=""),"",IFERROR(Q36/Q4,"")) | R37: =IF(OR(R36="",R4=""),"",IFERROR(R36/R4,"")) | S37: =IF(OR(S36="",S4=""),"",IFERROR(S36/S4,"")) | T37: =IF(OR(T36="",T4=""),"",IFERROR(T36/T4,"")) | U37: =IF(OR(U36="",U4=""),"",IFERROR(U36/U4,"")) | V37: =IF(OR(V36="",V4=""),"",IFERROR(V36/V4,"")) | ... X37: =IF(OR(X36="",X4=""),"",IFERROR(X36/X4,""))
A38: 기타비용 | B38: 변동비 | O38: =IF(OR(O29="",O30="",O32="",O34="",O36=""),"",IFERROR(O29-O30-O32-O34-O36,"")) | P38: =IF(OR(P29="",P30="",P32="",P34="",P36=""),"",IFERROR(P29-P30-P32-P34-P36,"")) | Q38: =IF(OR(Q29="",Q30="",Q32="",Q34="",Q36=""),"",IFERROR(Q29-Q30-Q32-Q34-Q36,"")) | R38: =IF(OR(R29="",R30="",R32="",R34="",R36=""),"",IFERROR(R29-R30-R32-R34-R36,"")) | S38: =IF(OR(S29="",S30="",S32="",S34="",S36=""),"",IFERROR(S29-S30-S32-S34-S36,"")) | T38: =IF(OR(T29="",T30="",T32="",T34="",T36=""),"",IFERROR(T29-T30-T32-T34-T36,"")) | U38: =IF(OR(U29="",U30="",U32="",U34="",U36=""),"",IFERROR(U29-U30-U32-U34-U36,"")) | V38: =IF(OR(V29="",V30="",V32="",V34="",V36=""),"",IFERROR(V29-V30-V32-V34-V36,"")) | ... X38: =IF(OR(X29="",X30="",X32="",X34="",X36=""),"",IFERROR(X29-X30-X32-X34-X36,""))
A39: % of Sales | O39: =IF(OR(O38="",O4=""),"",IFERROR(O38/O4,"")) | P39: =IF(OR(P38="",P4=""),"",IFERROR(P38/P4,"")) | Q39: =IF(OR(Q38="",Q4=""),"",IFERROR(Q38/Q4,"")) | R39: =IF(OR(R38="",R4=""),"",IFERROR(R38/R4,"")) | S39: =IF(OR(S38="",S4=""),"",IFERROR(S38/S4,"")) | T39: =IF(OR(T38="",T4=""),"",IFERROR(T38/T4,"")) | U39: =IF(OR(U38="",U4=""),"",IFERROR(U38/U4,"")) | V39: =IF(OR(V38="",V4=""),"",IFERROR(V38/V4,"")) | ... X39: =IF(OR(X38="",X4=""),"",IFERROR(X38/X4,""))
A40: 당기순이익 추정
...

Sheet 재무상태표
A1: 미라이공업 재무상태표
A2: 재무비율은 기말 잔액 기준 · 분기 손익은 최근 4분기 합산(TTM) | B2: (단위: 백만엔)
A3: 항목 | B3: 참고 | C3: 2026.3Q | D3: 2026.4Q | E3: 2027.1Q | F3: 2027.2Q | G3: 2027.3Q | H3: 2023 | I3: 2024 | J3: 2025 | K3: 2026
A4: 자산
A5: 유동자산 | C5: 42632 | D5: 42684 | E5: 42950 | F5: 43382 | G5: 44474 | H5: 41705 | I5: 39202 | J5: 41825 | K5: 42684
A6: 현금및현금성자산 | C6: 21234 | D6: 20458 | E6: 21728 | F6: 20761 | G6: 21024 | H6: 22115 | I6: 17787 | J6: 19010 | K6: 20458
A7: 단기금융상품 | C7: 1525 | D7: 1499 | E7: 1513 | F7: 1498 | G7: 1497 | K7: 1499
A8: 매출채권 | C8: 6979 | D8: 7510 | E8: 6548 | F8: 7235 | G8: 7298 | H8: 8184 | I8: 8941 | J8: 8154 | K8: 7510
A9: 재고자산 | C9: 6586 | D9: 6821 | E9: 6920 | F9: 7088 | G9: 7425 | H9: 5850 | I9: 6191 | J9: 6432 | K9: 6821
A10: 기타유동자산 | B10: 총계 − 위 항목 | C10: =IF(OR(C5=""),"",IFERROR(C5-SUM(C6,C7,C8,C9),"")) | D10: =IF(OR(D5=""),"",IFERROR(D5-SUM(D6,D7,D8,D9),"")) | E10: =IF(OR(E5=""),"",IFERROR(E5-SUM(E6,E7,E8,E9),"")) | F10: =IF(OR(F5=""),"",IFERROR(F5-SUM(F6,F7,F8,F9),"")) | G10: =IF(OR(G5=""),"",IFERROR(G5-SUM(G6,G7,G8,G9),"")) | H10: =IF(OR(H5=""),"",IFERROR(H5-SUM(H6,H7,H8,H9),"")) | I10: =IF(OR(I5=""),"",IFERROR(I5-SUM(I6,I7,I8,I9),"")) | J10: =IF(OR(J5=""),"",IFERROR(J5-SUM(J6,J7,J8,J9),"")) | K10: =IF(OR(K5=""),"",IFERROR(K5-SUM(K6,K7,K8,K9),""))
A11: 비유동자산 | C11: 24402 | D11: 24615 | E11: 25746 | F11: 25942 | G11: 26501 | H11: 21579 | I11: 22456 | J11: 23286 | K11: 24615
A12: 유형자산 | C12: 15020 | D12: 15229 | E12: 15544 | F12: 15617 | G12: 15849 | H12: 13875 | I12: 14172 | J12: 14416 | K12: 15229
A13: 무형자산 | C13: 184 | D13: 256 | E13: 340 | F13: 361 | G13: 367 | H13: 156 | I13: 129 | J13: 190 | K13: 256
A14: 투자부동산
A15: 기타비유동자산 | B15: 총계 − 위 항목 | C15: =IF(OR(C11=""),"",IFERROR(C11-SUM(C12,C13,C14),"")) | D15: =IF(OR(D11=""),"",IFERROR(D11-SUM(D12,D13,D14),"")) | E15: =IF(OR(E11=""),"",IFERROR(E11-SUM(E12,E13,E14),"")) | F15: =IF(OR(F11=""),"",IFERROR(F11-SUM(F12,F13,F14),"")) | G15: =IF(OR(G11=""),"",IFERROR(G11-SUM(G12,G13,G14),"")) | H15: =IF(OR(H11=""),"",IFERROR(H11-SUM(H12,H13,H14),"")) | I15: =IF(OR(I11=""),"",IFERROR(I11-SUM(I12,I13,I14),"")) | J15: =IF(OR(J11=""),"",IFERROR(J11-SUM(J12,J13,J14),"")) | K15: =IF(OR(K11=""),"",IFERROR(K11-SUM(K12,K13,K14),""))
A16: 자산총계 | C16: 67034 | D16: 67300 | E16: 68697 | F16: 69325 | G16: 70976 | H16: 63285 | I16: 61658 | J16: 65112 | K16: 67300
A17: 부채
A18: 유동부채 | C18: 10404 | D18: 9792 | E18: 9688 | F18: 10159 | G18: 10569 | H18: 11666 | I18: 9921 | J18: 10236 | K18: 9792
A19: 매입채무 | C19: 3055 | D19: 3215 | E19: 2592 | F19: 3465 | G19: 3344 | H19: 3491 | I19: 3111 | J19: 3411 | K19: 3215
A20: 단기차입금 | C20: 85 | D20: 267 | E20: 40 | F20: 85 | G20: 120 | H20: 225 | I20: 220 | J20: 237 | K20: 267
A21: 유동성장기부채 | C21: 202 | D21: 163 | E21: 124 | F21: 364 | G21: 311 | H21: 236 | I21: 171 | J21: 153 | K21: 163
A22: 기타유동부채 | B22: 총계 − 위 항목 | C22: =IF(OR(C18=""),"",IFERROR(C18-SUM(C19,C20,C21),"")) | D22: =IF(OR(D18=""),"",IFERROR(D18-SUM(D19,D20,D21),"")) | E22: =IF(OR(E18=""),"",IFERROR(E18-SUM(E19,E20,E21),"")) | F22: =IF(OR(F18=""),"",IFERROR(F18-SUM(F19,F20,F21),"")) | G22: =IF(OR(G18=""),"",IFERROR(G18-SUM(G19,G20,G21),"")) | H22: =IF(OR(H18=""),"",IFERROR(H18-SUM(H19,H20,H21),"")) | I22: =IF(OR(I18=""),"",IFERROR(I18-SUM(I19,I20,I21),"")) | J22: =IF(OR(J18=""),"",IFERROR(J18-SUM(J19,J20,J21),"")) | K22: =IF(OR(K18=""),"",IFERROR(K18-SUM(K19,K20,K21),""))
A23: 비유동부채 | C23: 2680 | D23: 2674 | E23: 2745 | F23: 2977 | G23: 2791 | H23: 2460 | I23: 2468 | J23: 2625 | K23: 2674
A24: 장기차입금 | C24: 48 | D24: 31 | E24: 14 | F24: 80 | G24: 26 | H24: 37 | I24: 0 | J24: 77 | K24: 31
A25: 사채
A26: 기타비유동부채 | B26: 총계 − 위 항목 | C26: =IF(OR(C23=""),"",IFERROR(C23-SUM(C24,C25),"")) | D26: =IF(OR(D23=""),"",IFERROR(D23-SUM(D24,D25),"")) | E26: =IF(OR(E23=""),"",IFERROR(E23-SUM(E24,E25),"")) | F26: =IF(OR(F23=""),"",IFERROR(F23-SUM(F24,F25),"")) | G26: =IF(OR(G23=""),"",IFERROR(G23-SUM(G24,G25),"")) | H26: =IF(OR(H23=""),"",IFERROR(H23-SUM(H24,H25),"")) | I26: =IF(OR(I23=""),"",IFERROR(I23-SUM(I24,I25),"")) | J26: =IF(OR(J23=""),"",IFERROR(J23-SUM(J24,J25),"")) | K26: =IF(OR(K23=""),"",IFERROR(K23-SUM(K24,K25),""))
A27: 부채총계 | C27: 13085 | D27: 12466 | E27: 12434 | F27: 13137 | G27: 13360 | H27: 14126 | I27: 12390 | J27: 12861 | K27: 12466
A28: 총차입금 | B28: 단기+유동성장기+장기+사채 | C28: =SUM(C20,C21,C24,C25) | D28: =SUM(D20,D21,D24,D25) | E28: =SUM(E20,E21,E24,E25) | F28: =SUM(F20,F21,F24,F25) | G28: =SUM(G20,G21,G24,G25) | H28: =SUM(H20,H21,H24,H25) | I28: =SUM(I20,I21,I24,I25) | J28: =SUM(J20,J21,J24,J25) | K28: =SUM(K20,K21,K24,K25)
A29: 순차입금 | B29: 음수 = 순현금 | C29: =C28-C6-N(C7) | D29: =D28-D6-N(D7) | E29: =E28-E6-N(E7) | F29: =F28-F6-N(F7) | G29: =G28-G6-N(G7) | H29: =H28-H6-N(H7) | I29: =I28-I6-N(I7) | J29: =J28-J6-N(J7) | K29: =K28-K6-N(K7)
A30: 자본
A31: 지배주주지분 | C31: 53176 | D31: 54040 | E31: 55450 | F31: 55354 | G31: 56763 | H31: 48598 | I31: 48631 | J31: 51544 | K31: 54040
A32: 자본금 | C32: 7067 | D32: 7067 | E32: 7067 | F32: 7067 | G32: 7067 | H32: 7067 | I32: 7067 | J32: 7067 | K32: 7067
A33: 이익잉여금 | C33: 55165 | D33: 55921 | E33: 56806 | F33: 56550 | G33: 57817 | H33: 48167 | I33: 51303 | J33: 53804 | K33: 55921
A34: 비지배지분 | C34: 773 | D34: 793 | E34: 812 | F34: 833 | G34: 852 | H34: 560 | I34: 637 | J34: 707 | K34: 793
A35: 자본총계 | C35: 53949 | D35: 54833 | E35: 56262 | F35: 56187 | G35: 57615 | H35: 49158 | I35: 49268 | J35: 52251 | K35: 54833
A36: 현금흐름 요약 | B36: 분기 = TTM (있을 때만)
A37: 영업활동현금흐름 | D37: 7531 | F37: 6652 | H37: 6036 | I37: 4000 | J37: 4675 | K37: 7531
A38: CAPEX (유·무형 취득) | B38: 양수로 입력 | D38: 2707 | F38: 2731 | H38: 1740 | I38: 1788 | J38: 2867 | K38: 2707
A39: FCF | C39: =IF(OR(C37="",C38=""),"",IFERROR(C37-C38,"")) | D39: =IF(OR(D37="",D38=""),"",IFERROR(D37-D38,"")) | E39: =IF(OR(E37="",E38=""),"",IFERROR(E37-E38,"")) | F39: =IF(OR(F37="",F38=""),"",IFERROR(F37-F38,"")) | G39: =IF(OR(G37="",G38=""),"",IFERROR(G37-G38,"")) | H39: =IF(OR(H37="",H38=""),"",IFERROR(H37-H38,"")) | I39: =IF(OR(I37="",I38=""),"",IFERROR(I37-I38,"")) | J39: =IF(OR(J37="",J38=""),"",IFERROR(J37-J38,"")) | K39: =IF(OR(K37="",K38=""),"",IFERROR(K37-K38,""))
A40: 배당금 지급 | B40: 양수로 입력 | D40: 2581 | F40: 2494 | H40: 810 | I40: 900 | J40: 1350 | K40: 2581
...

Sheet 섹터 데이터
A1: 미라이공업 섹터·사업 데이터
A2: 2단계 보고서를 만들 때 모은 자료 · 월차 · 출처는 맨 오른쪽
A4: G27
A5: 항목 | B5: 값 | H5: 출처
A6: 매출 | B6: 489.84 | H6: 2단계 보고서 자료(회사 설명회 자료·공시)
A7: 영업이익 | B7: 69.27
A8: ord | B8: 71.25
A9: 순이익 | B9: 47.55
A10: EPS | B10: 293.91
A11: dps | B11: 135
A13: G27 직전
A14: 항목 | B14: 값 | H14: 출처
A15: 매출 | B15: 485.3 | H15: 2단계 보고서 자료(회사 설명회 자료·공시)
A16: 영업이익 | B16: 62.32
A17: ord | B17: 63.98
A18: 순이익 | B18: 43.42
A19: EPS | B19: 268.54
A21: 상반기 계획
A22: 항목 | B22: 값 | H22: 출처
A23: 매출 | B23: 247.78 | H23: 2단계 보고서 자료(회사 설명회 자료·공시)
A24: 영업이익 | B24: 33.43
A26: band
A27: 항목 | B27: 값 | H27: 출처
A28: lo | B28: 11.8 | H28: 2단계 보고서 자료(회사 설명회 자료·공시)
A29: avg | B29: 13.8
A30: hi | B30: 19.6
A32: nap q
A33: 항목 | B33: 값 | H33: 출처
A34: 2024-Q3 | B34: 74.3 | H34: 2단계 보고서 자료(회사 설명회 자료·공시)
A35: 2024-Q4 | B35: 72.9
A36: 2025-Q1 | B36: 80.6
A37: 2025-Q2 | B37: 79
A38: 2025-Q3 | B38: 73
A39: 2025-Q4 | B39: 73.5
A40: 2026-Q1 | B40: 66.2
A41: 2026-Q2 | B41: 65.5
A42: 2026-Q3 | B42: 65.8
A43: 2026-Q4 | B43: 68.4
A44: 2027-Q1 | B44: 121.3
A45: 2027-Q2 | B45: 101.4
...

Sheet 출처
A1: 출처 · 쓴 결산단신
A3: 공시일 | B3: 문서 | C3: PDF
A4: 2026-10-23 | B4: 2027년 3월 결산기 ２분기 결산단신 | C4: https://www2.jpx.co.jp/disc/79310/140120261022554660.pdf
A5: 2026-07-23 | B5: 2027년 3월 결산기 １분기 결산단신 | C5: https://www2.jpx.co.jp/disc/79310/140120260722597572.pdf
A6: 2026-04-23 | B6: 2026년 3월 결산기 연간 결산단신 | C6: https://www2.jpx.co.jp/disc/79310/140120260422508231.pdf
A7: 2026-01-29 | B7: 2026년 3월 결산기 ３분기 결산단신 | C7: https://www2.jpx.co.jp/disc/79310/140120260128540246.pdf
A8: 2025-10-23 | B8: 2026년 3월 결산기 ２분기 결산단신 | C8: https://www2.jpx.co.jp/disc/79310/140120251022577052.pdf
A9: 2025-07-24 | B9: 2026년 3월 결산기 １분기 결산단신 | C9: https://www2.jpx.co.jp/disc/79310/140120250723518478.pdf
A10: 2025-04-24 | B10: 2025년 3월 결산기 연간 결산단신 | C10: https://www2.jpx.co.jp/disc/79310/140120250424521883.pdf
A11: 2025-01-28 | B11: 2025년 3월 결산기 ３분기 결산단신 | C11: https://www2.jpx.co.jp/disc/79310/140120250127555617.pdf
A12: 2024-10-24 | B12: 2025년 3월 결산기 ２분기 결산단신 | C12: https://www2.jpx.co.jp/disc/79310/140120241023501530.pdf
A13: 2024-07-24 | B13: 2025년 3월 결산기 １분기 결산단신 | C13: https://www2.jpx.co.jp/disc/79310/140120240723553317.pdf
A14: 2024-04-25 | B14: 2024년 3월 결산기 연간 결산단신 | C14: https://www2.jpx.co.jp/disc/79310/140120240424575835.pdf
... A23: 2019-04-26 | B23: 2019년 3월 결산기 연간 결산단신 | C23: https://www2.jpx.co.jp/disc/79310/140120190425411633.pdf
