Workbook

Sheet 연간
A1: 9950 Model
A2: 모를 땐 보수적으로 | B2: (단위: 백만엔) | C2: 2월 결산 · 일본 기준 · 2027.4Q = 2027년 2월 결산기 4분기 | Y2: (추정: 파란 글씨 = 직접 입력)
A3: 항목 | B3: 참고 | C3: 2025.1Q | D3: 2025.2Q | E3: 2025.3Q | F3: 2025.4Q | G3: 2026.1Q | H3: 2026.2Q | I3: 2026.3Q | J3: 2026.4Q | K3: 2027.1Q | L3: 2027.2Q | M3: 2027.3Q | N3: 2027.4Q | O3: 2018 | P3: 2019 | Q3: 2020 | R3: 2021 | S3: 2022 | T3: 2023 | U3: 2024 | V3: 2025 | W3: 2026 | X3: 2027 | Y3: 2028(MW) | Z3: 2029(MW) | AA3: 2030(MW) | AB3: 2031(MW) | AC3: 2032(MW)
A4: 매출액 | B4: MW = 제품 합계 | C4: 1864.782 | D4: 1983.858 | E4: 1785.445 | F4: 1207.226 | G4: 1862.071 | H4: 1984.798 | I4: 1935.544 | J4: 1595.276 | K4: 2008.744 | L4: 2115.126 | O4: 6748.559 | P4: 7068.409 | Q4: 7683.199 | R4: 7650.678 | S4: 5309.975 | T4: 5400.634 | U4: 6435.409 | V4: 6841.311 | W4: 7377.689 | X4: 7730.061 | Y4: =IF(COUNT(Y7,Y10,Y13,Y16,Y19,Y22)=0,"",SUM(Y7,Y10,Y13,Y16,Y19,Y22)) | Z4: =IF(COUNT(Z7,Z10,Z13,Z16,Z19,Z22)=0,"",SUM(Z7,Z10,Z13,Z16,Z19,Z22)) | AA4: =IF(COUNT(AA7,AA10,AA13,AA16,AA19,AA22)=0,"",SUM(AA7,AA10,AA13,AA16,AA19,AA22)) | AB4: =IF(COUNT(AB7,AB10,AB13,AB16,AB19,AB22)=0,"",SUM(AB7,AB10,AB13,AB16,AB19,AB22)) | AC4: =IF(COUNT(AC7,AC10,AC13,AC16,AC19,AC22)=0,"",SUM(AC7,AC10,AC13,AC16,AC19,AC22))
A5: YoY | G5: =IF(OR(G4="",C4=""),"",IFERROR(G4/C4-1,"")) | H5: =IF(OR(H4="",D4=""),"",IFERROR(H4/D4-1,"")) | I5: =IF(OR(I4="",E4=""),"",IFERROR(I4/E4-1,"")) | J5: =IF(OR(J4="",F4=""),"",IFERROR(J4/F4-1,"")) | K5: =IF(OR(K4="",G4=""),"",IFERROR(K4/G4-1,"")) | L5: =IF(OR(L4="",H4=""),"",IFERROR(L4/H4-1,"")) | M5: =IF(OR(M4="",I4=""),"",IFERROR(M4/I4-1,"")) | N5: =IF(OR(N4="",J4=""),"",IFERROR(N4/J4-1,"")) | P5: =IF(OR(P4="",O4=""),"",IFERROR(P4/O4-1,"")) | Q5: =IF(OR(Q4="",P4=""),"",IFERROR(Q4/P4-1,"")) | R5: =IF(OR(R4="",Q4=""),"",IFERROR(R4/Q4-1,"")) | S5: =IF(OR(S4="",R4=""),"",IFERROR(S4/R4-1,"")) | T5: =IF(OR(T4="",S4=""),"",IFERROR(T4/S4-1,"")) | U5: =IF(OR(U4="",T4=""),"",IFERROR(U4/T4-1,"")) | V5: =IF(OR(V4="",U4=""),"",IFERROR(V4/U4-1,"")) | W5: =IF(OR(W4="",V4=""),"",IFERROR(W4/V4-1,"")) | ... AC5: =IF(OR(AC4="",AB4=""),"",IFERROR(AC4/AB4-1,""))
A6: 제품별 매출 분류 | B6: 사업보고서 매출실적
A7: Restaurant Business Reportable Segments | E7: 1508 | F7: 1023.631 | I7: 1624.649 | J7: 1294.115 | V7: 5822.418 | W7: 6192.966 | X7: 6528.348
A8: 비중 | C8: =IF(OR(C7="",C4=""),"",IFERROR(C7/C4,"")) | D8: =IF(OR(D7="",D4=""),"",IFERROR(D7/D4,"")) | E8: =IF(OR(E7="",E4=""),"",IFERROR(E7/E4,"")) | F8: =IF(OR(F7="",F4=""),"",IFERROR(F7/F4,"")) | G8: =IF(OR(G7="",G4=""),"",IFERROR(G7/G4,"")) | H8: =IF(OR(H7="",H4=""),"",IFERROR(H7/H4,"")) | I8: =IF(OR(I7="",I4=""),"",IFERROR(I7/I4,"")) | J8: =IF(OR(J7="",J4=""),"",IFERROR(J7/J4,"")) | ... AC8: =IF(OR(AC7="",AC4=""),"",IFERROR(AC7/AC4,""))
A9: YoY | G9: =IF(OR(G7="",C7=""),"",IFERROR(G7/C7-1,"")) | H9: =IF(OR(H7="",D7=""),"",IFERROR(H7/D7-1,"")) | I9: =IF(OR(I7="",E7=""),"",IFERROR(I7/E7-1,"")) | J9: =IF(OR(J7="",F7=""),"",IFERROR(J7/F7-1,"")) | K9: =IF(OR(K7="",G7=""),"",IFERROR(K7/G7-1,"")) | L9: =IF(OR(L7="",H7=""),"",IFERROR(L7/H7-1,"")) | M9: =IF(OR(M7="",I7=""),"",IFERROR(M7/I7-1,"")) | N9: =IF(OR(N7="",J7=""),"",IFERROR(N7/J7-1,"")) | P9: =IF(OR(P7="",O7=""),"",IFERROR(P7/O7-1,"")) | Q9: =IF(OR(Q7="",P7=""),"",IFERROR(Q7/P7-1,"")) | R9: =IF(OR(R7="",Q7=""),"",IFERROR(R7/Q7-1,"")) | S9: =IF(OR(S7="",R7=""),"",IFERROR(S7/R7-1,"")) | T9: =IF(OR(T7="",S7=""),"",IFERROR(T7/S7-1,"")) | U9: =IF(OR(U7="",T7=""),"",IFERROR(U7/T7-1,"")) | V9: =IF(OR(V7="",U7=""),"",IFERROR(V7/U7-1,"")) | W9: =IF(OR(W7="",V7=""),"",IFERROR(W7/V7-1,"")) | ... AC9: =IF(OR(AC7="",AB7=""),"",IFERROR(AC7/AB7-1,""))
A10: Wholesale Business Reportable Segments | V10: 649.629 | W10: 603.208 | X10: 576.962
A11: 비중 | C11: =IF(OR(C10="",C4=""),"",IFERROR(C10/C4,"")) | D11: =IF(OR(D10="",D4=""),"",IFERROR(D10/D4,"")) | E11: =IF(OR(E10="",E4=""),"",IFERROR(E10/E4,"")) | F11: =IF(OR(F10="",F4=""),"",IFERROR(F10/F4,"")) | G11: =IF(OR(G10="",G4=""),"",IFERROR(G10/G4,"")) | H11: =IF(OR(H10="",H4=""),"",IFERROR(H10/H4,"")) | I11: =IF(OR(I10="",I4=""),"",IFERROR(I10/I4,"")) | J11: =IF(OR(J10="",J4=""),"",IFERROR(J10/J4,"")) | ... AC11: =IF(OR(AC10="",AC4=""),"",IFERROR(AC10/AC4,""))
A12: YoY | G12: =IF(OR(G10="",C10=""),"",IFERROR(G10/C10-1,"")) | H12: =IF(OR(H10="",D10=""),"",IFERROR(H10/D10-1,"")) | I12: =IF(OR(I10="",E10=""),"",IFERROR(I10/E10-1,"")) | J12: =IF(OR(J10="",F10=""),"",IFERROR(J10/F10-1,"")) | K12: =IF(OR(K10="",G10=""),"",IFERROR(K10/G10-1,"")) | L12: =IF(OR(L10="",H10=""),"",IFERROR(L10/H10-1,"")) | M12: =IF(OR(M10="",I10=""),"",IFERROR(M10/I10-1,"")) | N12: =IF(OR(N10="",J10=""),"",IFERROR(N10/J10-1,"")) | P12: =IF(OR(P10="",O10=""),"",IFERROR(P10/O10-1,"")) | Q12: =IF(OR(Q10="",P10=""),"",IFERROR(Q10/P10-1,"")) | R12: =IF(OR(R10="",Q10=""),"",IFERROR(R10/Q10-1,"")) | S12: =IF(OR(S10="",R10=""),"",IFERROR(S10/R10-1,"")) | T12: =IF(OR(T10="",S10=""),"",IFERROR(T10/S10-1,"")) | U12: =IF(OR(U10="",T10=""),"",IFERROR(U10/T10-1,"")) | V12: =IF(OR(V10="",U10=""),"",IFERROR(V10/U10-1,"")) | W12: =IF(OR(W10="",V10=""),"",IFERROR(W10/V10-1,"")) | ... AC12: =IF(OR(AC10="",AB10=""),"",IFERROR(AC10/AB10-1,""))
A13: Retail Sales Business Reportable Segments | E13: 141.72 | I13: 143.389
A14: 비중 | C14: =IF(OR(C13="",C4=""),"",IFERROR(C13/C4,"")) | D14: =IF(OR(D13="",D4=""),"",IFERROR(D13/D4,"")) | E14: =IF(OR(E13="",E4=""),"",IFERROR(E13/E4,"")) | F14: =IF(OR(F13="",F4=""),"",IFERROR(F13/F4,"")) | G14: =IF(OR(G13="",G4=""),"",IFERROR(G13/G4,"")) | H14: =IF(OR(H13="",H4=""),"",IFERROR(H13/H4,"")) | I14: =IF(OR(I13="",I4=""),"",IFERROR(I13/I4,"")) | J14: =IF(OR(J13="",J4=""),"",IFERROR(J13/J4,"")) | ... AC14: =IF(OR(AC13="",AC4=""),"",IFERROR(AC13/AC4,""))
A15: YoY | G15: =IF(OR(G13="",C13=""),"",IFERROR(G13/C13-1,"")) | H15: =IF(OR(H13="",D13=""),"",IFERROR(H13/D13-1,"")) | I15: =IF(OR(I13="",E13=""),"",IFERROR(I13/E13-1,"")) | J15: =IF(OR(J13="",F13=""),"",IFERROR(J13/F13-1,"")) | K15: =IF(OR(K13="",G13=""),"",IFERROR(K13/G13-1,"")) | L15: =IF(OR(L13="",H13=""),"",IFERROR(L13/H13-1,"")) | M15: =IF(OR(M13="",I13=""),"",IFERROR(M13/I13-1,"")) | N15: =IF(OR(N13="",J13=""),"",IFERROR(N13/J13-1,"")) | P15: =IF(OR(P13="",O13=""),"",IFERROR(P13/O13-1,"")) | Q15: =IF(OR(Q13="",P13=""),"",IFERROR(Q13/P13-1,"")) | R15: =IF(OR(R13="",Q13=""),"",IFERROR(R13/Q13-1,"")) | S15: =IF(OR(S13="",R13=""),"",IFERROR(S13/R13-1,"")) | T15: =IF(OR(T13="",S13=""),"",IFERROR(T13/S13-1,"")) | U15: =IF(OR(U13="",T13=""),"",IFERROR(U13/T13-1,"")) | V15: =IF(OR(V13="",U13=""),"",IFERROR(V13/U13-1,"")) | W15: =IF(OR(W13="",V13=""),"",IFERROR(W13/V13-1,"")) | ... AC15: =IF(OR(AC13="",AB13=""),"",IFERROR(AC13/AB13-1,""))
A16: 해외 사업 | C16: 310.514 | D16: 348.894 | E16: 342.352 | F16: 149.984 | G16: 354.933 | H16: 358.907 | I16: 386.478 | J16: 336.956 | K16: 409.98 | L16: 372.644 | V16: 1151.744 | W16: 1437.274 | X16: 1539.202
A17: 비중 | C17: =IF(OR(C16="",C4=""),"",IFERROR(C16/C4,"")) | D17: =IF(OR(D16="",D4=""),"",IFERROR(D16/D4,"")) | E17: =IF(OR(E16="",E4=""),"",IFERROR(E16/E4,"")) | F17: =IF(OR(F16="",F4=""),"",IFERROR(F16/F4,"")) | G17: =IF(OR(G16="",G4=""),"",IFERROR(G16/G4,"")) | H17: =IF(OR(H16="",H4=""),"",IFERROR(H16/H4,"")) | I17: =IF(OR(I16="",I4=""),"",IFERROR(I16/I4,"")) | J17: =IF(OR(J16="",J4=""),"",IFERROR(J16/J4,"")) | ... AC17: =IF(OR(AC16="",AC4=""),"",IFERROR(AC16/AC4,""))
A18: YoY | G18: =IF(OR(G16="",C16=""),"",IFERROR(G16/C16-1,"")) | H18: =IF(OR(H16="",D16=""),"",IFERROR(H16/D16-1,"")) | I18: =IF(OR(I16="",E16=""),"",IFERROR(I16/E16-1,"")) | J18: =IF(OR(J16="",F16=""),"",IFERROR(J16/F16-1,"")) | K18: =IF(OR(K16="",G16=""),"",IFERROR(K16/G16-1,"")) | L18: =IF(OR(L16="",H16=""),"",IFERROR(L16/H16-1,"")) | M18: =IF(OR(M16="",I16=""),"",IFERROR(M16/I16-1,"")) | N18: =IF(OR(N16="",J16=""),"",IFERROR(N16/J16-1,"")) | P18: =IF(OR(P16="",O16=""),"",IFERROR(P16/O16-1,"")) | Q18: =IF(OR(Q16="",P16=""),"",IFERROR(Q16/P16-1,"")) | R18: =IF(OR(R16="",Q16=""),"",IFERROR(R16/Q16-1,"")) | S18: =IF(OR(S16="",R16=""),"",IFERROR(S16/R16-1,"")) | T18: =IF(OR(T16="",S16=""),"",IFERROR(T16/S16-1,"")) | U18: =IF(OR(U16="",T16=""),"",IFERROR(U16/T16-1,"")) | V18: =IF(OR(V16="",U16=""),"",IFERROR(V16/U16-1,"")) | W18: =IF(OR(W16="",V16=""),"",IFERROR(W16/V16-1,"")) | ... AC18: =IF(OR(AC16="",AB16=""),"",IFERROR(AC16/AB16-1,""))
A19: Restaurant Business Segments | C19: 1611.648 | G19: 1583.721 | K19: 1706.824
A20: 비중 | C20: =IF(OR(C19="",C4=""),"",IFERROR(C19/C4,"")) | D20: =IF(OR(D19="",D4=""),"",IFERROR(D19/D4,"")) | E20: =IF(OR(E19="",E4=""),"",IFERROR(E19/E4,"")) | F20: =IF(OR(F19="",F4=""),"",IFERROR(F19/F4,"")) | G20: =IF(OR(G19="",G4=""),"",IFERROR(G19/G4,"")) | H20: =IF(OR(H19="",H4=""),"",IFERROR(H19/H4,"")) | I20: =IF(OR(I19="",I4=""),"",IFERROR(I19/I4,"")) | J20: =IF(OR(J19="",J4=""),"",IFERROR(J19/J4,"")) | ... AC20: =IF(OR(AC19="",AC4=""),"",IFERROR(AC19/AC4,""))
A21: YoY | G21: =IF(OR(G19="",C19=""),"",IFERROR(G19/C19-1,"")) | H21: =IF(OR(H19="",D19=""),"",IFERROR(H19/D19-1,"")) | I21: =IF(OR(I19="",E19=""),"",IFERROR(I19/E19-1,"")) | J21: =IF(OR(J19="",F19=""),"",IFERROR(J19/F19-1,"")) | K21: =IF(OR(K19="",G19=""),"",IFERROR(K19/G19-1,"")) | L21: =IF(OR(L19="",H19=""),"",IFERROR(L19/H19-1,"")) | M21: =IF(OR(M19="",I19=""),"",IFERROR(M19/I19-1,"")) | N21: =IF(OR(N19="",J19=""),"",IFERROR(N19/J19-1,"")) | P21: =IF(OR(P19="",O19=""),"",IFERROR(P19/O19-1,"")) | Q21: =IF(OR(Q19="",P19=""),"",IFERROR(Q19/P19-1,"")) | R21: =IF(OR(R19="",Q19=""),"",IFERROR(R19/Q19-1,"")) | S21: =IF(OR(S19="",R19=""),"",IFERROR(S19/R19-1,"")) | T21: =IF(OR(T19="",S19=""),"",IFERROR(T19/S19-1,"")) | U21: =IF(OR(U19="",T19=""),"",IFERROR(U19/T19-1,"")) | V21: =IF(OR(V19="",U19=""),"",IFERROR(V19/U19-1,"")) | W21: =IF(OR(W19="",V19=""),"",IFERROR(W19/V19-1,"")) | ... AC21: =IF(OR(AC19="",AB19=""),"",IFERROR(AC19/AB19-1,""))
A22: Retail Sales Business Segments | C22: 163.594 | G22: 142.07 | K22: 133.743
A23: 비중 | C23: =IF(OR(C22="",C4=""),"",IFERROR(C22/C4,"")) | D23: =IF(OR(D22="",D4=""),"",IFERROR(D22/D4,"")) | E23: =IF(OR(E22="",E4=""),"",IFERROR(E22/E4,"")) | F23: =IF(OR(F22="",F4=""),"",IFERROR(F22/F4,"")) | G23: =IF(OR(G22="",G4=""),"",IFERROR(G22/G4,"")) | H23: =IF(OR(H22="",H4=""),"",IFERROR(H22/H4,"")) | I23: =IF(OR(I22="",I4=""),"",IFERROR(I22/I4,"")) | J23: =IF(OR(J22="",J4=""),"",IFERROR(J22/J4,"")) | ... AC23: =IF(OR(AC22="",AC4=""),"",IFERROR(AC22/AC4,""))
A24: YoY | G24: =IF(OR(G22="",C22=""),"",IFERROR(G22/C22-1,"")) | H24: =IF(OR(H22="",D22=""),"",IFERROR(H22/D22-1,"")) | I24: =IF(OR(I22="",E22=""),"",IFERROR(I22/E22-1,"")) | J24: =IF(OR(J22="",F22=""),"",IFERROR(J22/F22-1,"")) | K24: =IF(OR(K22="",G22=""),"",IFERROR(K22/G22-1,"")) | L24: =IF(OR(L22="",H22=""),"",IFERROR(L22/H22-1,"")) | M24: =IF(OR(M22="",I22=""),"",IFERROR(M22/I22-1,"")) | N24: =IF(OR(N22="",J22=""),"",IFERROR(N22/J22-1,"")) | P24: =IF(OR(P22="",O22=""),"",IFERROR(P22/O22-1,"")) | Q24: =IF(OR(Q22="",P22=""),"",IFERROR(Q22/P22-1,"")) | R24: =IF(OR(R22="",Q22=""),"",IFERROR(R22/Q22-1,"")) | S24: =IF(OR(S22="",R22=""),"",IFERROR(S22/R22-1,"")) | T24: =IF(OR(T22="",S22=""),"",IFERROR(T22/S22-1,"")) | U24: =IF(OR(U22="",T22=""),"",IFERROR(U22/T22-1,"")) | V24: =IF(OR(V22="",U22=""),"",IFERROR(V22/U22-1,"")) | W24: =IF(OR(W22="",V22=""),"",IFERROR(W22/V22-1,"")) | ... AC24: =IF(OR(AC22="",AB22=""),"",IFERROR(AC22/AB22-1,""))
A25: 매출원가
A26: 전체 매출원가 | C26: 1119.078 | D26: 1164.358 | E26: 1079.498 | F26: 737.004 | G26: 1149.124 | H26: 1204.381 | I26: 1174.85 | J26: 961.347 | K26: 1183.909 | L26: 1244.835 | O26: 3448.092 | P26: 3702.345 | Q26: 4049.493 | R26: 4057.732 | S26: 3197.46 | T26: 3266.112 | U26: 3729.3 | V26: 4099.938 | W26: 4489.702 | X26: 4762.017
A27: YoY | G27: =IF(OR(G26="",C26=""),"",IF(C26<=0,"",IFERROR(G26/C26-1,""))) | H27: =IF(OR(H26="",D26=""),"",IF(D26<=0,"",IFERROR(H26/D26-1,""))) | I27: =IF(OR(I26="",E26=""),"",IF(E26<=0,"",IFERROR(I26/E26-1,""))) | J27: =IF(OR(J26="",F26=""),"",IF(F26<=0,"",IFERROR(J26/F26-1,""))) | K27: =IF(OR(K26="",G26=""),"",IF(G26<=0,"",IFERROR(K26/G26-1,""))) | L27: =IF(OR(L26="",H26=""),"",IF(H26<=0,"",IFERROR(L26/H26-1,""))) | M27: =IF(OR(M26="",I26=""),"",IF(I26<=0,"",IFERROR(M26/I26-1,""))) | N27: =IF(OR(N26="",J26=""),"",IF(J26<=0,"",IFERROR(N26/J26-1,""))) | P27: =IF(OR(P26="",O26=""),"",IF(O26<=0,"",IFERROR(P26/O26-1,""))) | Q27: =IF(OR(Q26="",P26=""),"",IF(P26<=0,"",IFERROR(Q26/P26-1,""))) | R27: =IF(OR(R26="",Q26=""),"",IF(Q26<=0,"",IFERROR(R26/Q26-1,""))) | S27: =IF(OR(S26="",R26=""),"",IF(R26<=0,"",IFERROR(S26/R26-1,""))) | T27: =IF(OR(T26="",S26=""),"",IF(S26<=0,"",IFERROR(T26/S26-1,""))) | U27: =IF(OR(U26="",T26=""),"",IF(T26<=0,"",IFERROR(U26/T26-1,""))) | V27: =IF(OR(V26="",U26=""),"",IF(U26<=0,"",IFERROR(V26/U26-1,""))) | W27: =IF(OR(W26="",V26=""),"",IF(V26<=0,"",IFERROR(W26/V26-1,""))) | ... AC27: =IF(OR(AC26="",AB26=""),"",IF(AB26<=0,"",IFERROR(AC26/AB26-1,"")))
A28: 매출총이익 | C28: =IF(OR(C4="",C26=""),"",IFERROR(C4-C26,"")) | D28: =IF(OR(D4="",D26=""),"",IFERROR(D4-D26,"")) | E28: =IF(OR(E4="",E26=""),"",IFERROR(E4-E26,"")) | F28: =IF(OR(F4="",F26=""),"",IFERROR(F4-F26,"")) | G28: =IF(OR(G4="",G26=""),"",IFERROR(G4-G26,"")) | H28: =IF(OR(H4="",H26=""),"",IFERROR(H4-H26,"")) | I28: =IF(OR(I4="",I26=""),"",IFERROR(I4-I26,"")) | J28: =IF(OR(J4="",J26=""),"",IFERROR(J4-J26,"")) | ... X28: =IF(OR(X4="",X26=""),"",IFERROR(X4-X26,""))
A29: GPM | C29: =IF(OR(C28="",C4=""),"",IFERROR(C28/C4,"")) | D29: =IF(OR(D28="",D4=""),"",IFERROR(D28/D4,"")) | E29: =IF(OR(E28="",E4=""),"",IFERROR(E28/E4,"")) | F29: =IF(OR(F28="",F4=""),"",IFERROR(F28/F4,"")) | G29: =IF(OR(G28="",G4=""),"",IFERROR(G28/G4,"")) | H29: =IF(OR(H28="",H4=""),"",IFERROR(H28/H4,"")) | I29: =IF(OR(I28="",I4=""),"",IFERROR(I28/I4,"")) | J29: =IF(OR(J28="",J4=""),"",IFERROR(J28/J4,"")) | ... AC29: =IF(OR(AC28="",AC4=""),"",IFERROR(AC28/AC4,""))
A30: YoY | G30: =IF(OR(G28="",C28=""),"",IF(C28<=0,"",IFERROR(G28/C28-1,""))) | H30: =IF(OR(H28="",D28=""),"",IF(D28<=0,"",IFERROR(H28/D28-1,""))) | I30: =IF(OR(I28="",E28=""),"",IF(E28<=0,"",IFERROR(I28/E28-1,""))) | J30: =IF(OR(J28="",F28=""),"",IF(F28<=0,"",IFERROR(J28/F28-1,""))) | K30: =IF(OR(K28="",G28=""),"",IF(G28<=0,"",IFERROR(K28/G28-1,""))) | L30: =IF(OR(L28="",H28=""),"",IF(H28<=0,"",IFERROR(L28/H28-1,""))) | M30: =IF(OR(M28="",I28=""),"",IF(I28<=0,"",IFERROR(M28/I28-1,""))) | N30: =IF(OR(N28="",J28=""),"",IF(J28<=0,"",IFERROR(N28/J28-1,""))) | P30: =IF(OR(P28="",O28=""),"",IF(O28<=0,"",IFERROR(P28/O28-1,""))) | Q30: =IF(OR(Q28="",P28=""),"",IF(P28<=0,"",IFERROR(Q28/P28-1,""))) | R30: =IF(OR(R28="",Q28=""),"",IF(Q28<=0,"",IFERROR(R28/Q28-1,""))) | S30: =IF(OR(S28="",R28=""),"",IF(R28<=0,"",IFERROR(S28/R28-1,""))) | T30: =IF(OR(T28="",S28=""),"",IF(S28<=0,"",IFERROR(T28/S28-1,""))) | U30: =IF(OR(U28="",T28=""),"",IF(T28<=0,"",IFERROR(U28/T28-1,""))) | V30: =IF(OR(V28="",U28=""),"",IF(U28<=0,"",IFERROR(V28/U28-1,""))) | W30: =IF(OR(W28="",V28=""),"",IF(V28<=0,"",IFERROR(W28/V28-1,""))) | ... AC30: =IF(OR(AC28="",AB28=""),"",IF(AB28<=0,"",IFERROR(AC28/AB28-1,"")))
A31: 판매관리비
A32: 전체 판관비 | C32: 874.853 | D32: 865.874 | E32: 861.318 | F32: 686.468 | G32: 919.844 | H32: 963.136 | I32: 1010.182 | J32: 586.15 | K32: 1061.502 | L32: 1021.989 | O32: 3437.404 | P32: 3650.976 | Q32: 3956.515 | R32: 4007.669 | S32: 3247.401 | T32: 2992.36 | U32: 3209.876 | V32: 3288.513 | W32: 3479.312 | X32: 3877.842
A33: YoY | G33: =IF(OR(G32="",C32=""),"",IF(C32<=0,"",IFERROR(G32/C32-1,""))) | H33: =IF(OR(H32="",D32=""),"",IF(D32<=0,"",IFERROR(H32/D32-1,""))) | I33: =IF(OR(I32="",E32=""),"",IF(E32<=0,"",IFERROR(I32/E32-1,""))) | J33: =IF(OR(J32="",F32=""),"",IF(F32<=0,"",IFERROR(J32/F32-1,""))) | K33: =IF(OR(K32="",G32=""),"",IF(G32<=0,"",IFERROR(K32/G32-1,""))) | L33: =IF(OR(L32="",H32=""),"",IF(H32<=0,"",IFERROR(L32/H32-1,""))) | M33: =IF(OR(M32="",I32=""),"",IF(I32<=0,"",IFERROR(M32/I32-1,""))) | N33: =IF(OR(N32="",J32=""),"",IF(J32<=0,"",IFERROR(N32/J32-1,""))) | P33: =IF(OR(P32="",O32=""),"",IF(O32<=0,"",IFERROR(P32/O32-1,""))) | Q33: =IF(OR(Q32="",P32=""),"",IF(P32<=0,"",IFERROR(Q32/P32-1,""))) | R33: =IF(OR(R32="",Q32=""),"",IF(Q32<=0,"",IFERROR(R32/Q32-1,""))) | S33: =IF(OR(S32="",R32=""),"",IF(R32<=0,"",IFERROR(S32/R32-1,""))) | T33: =IF(OR(T32="",S32=""),"",IF(S32<=0,"",IFERROR(T32/S32-1,""))) | U33: =IF(OR(U32="",T32=""),"",IF(T32<=0,"",IFERROR(U32/T32-1,""))) | V33: =IF(OR(V32="",U32=""),"",IF(U32<=0,"",IFERROR(V32/U32-1,""))) | W33: =IF(OR(W32="",V32=""),"",IF(V32<=0,"",IFERROR(W32/V32-1,""))) | ... AC33: =IF(OR(AC32="",AB32=""),"",IF(AB32<=0,"",IFERROR(AC32/AB32-1,"")))
A34: 영업이익 | B34: MW = 매출 × OPM | C34: 91.825 | D34: 177.684 | E34: 51.257 | F34: -85.425 | G34: 11.757 | H34: 58.616 | I34: -30.516 | J34: 224.578 | K34: 5.136 | L34: 95.965 | O34: 427.328 | P34: 297.236 | Q34: 285.435 | R34: 202.614 | S34: -647.451 | T34: -343.402 | U34: 168.106 | V34: 235.341 | W34: 264.435 | X34: 4.653 | Y34: =IF(OR(Y4="",Y35=""),"",IFERROR(Y4*Y35,"")) | Z34: =IF(OR(Z4="",Z35=""),"",IFERROR(Z4*Z35,"")) | AA34: =IF(OR(AA4="",AA35=""),"",IFERROR(AA4*AA35,"")) | AB34: =IF(OR(AB4="",AB35=""),"",IFERROR(AB4*AB35,"")) | AC34: =IF(OR(AC4="",AC35=""),"",IFERROR(AC4*AC35,""))
A35: OPM | B35: MW 입력 | C35: =IF(OR(C34="",C4=""),"",IFERROR(C34/C4,"")) | D35: =IF(OR(D34="",D4=""),"",IFERROR(D34/D4,"")) | E35: =IF(OR(E34="",E4=""),"",IFERROR(E34/E4,"")) | F35: =IF(OR(F34="",F4=""),"",IFERROR(F34/F4,"")) | G35: =IF(OR(G34="",G4=""),"",IFERROR(G34/G4,"")) | H35: =IF(OR(H34="",H4=""),"",IFERROR(H34/H4,"")) | I35: =IF(OR(I34="",I4=""),"",IFERROR(I34/I4,"")) | J35: =IF(OR(J34="",J4=""),"",IFERROR(J34/J4,"")) | ... X35: =IF(OR(X34="",X4=""),"",IFERROR(X34/X4,""))
A36: 증가율 | G36: =IF(OR(G34="",C34=""),"",IFERROR(G34/C34-1,"")) | H36: =IF(OR(H34="",D34=""),"",IFERROR(H34/D34-1,"")) | I36: =IF(OR(I34="",E34=""),"",IFERROR(I34/E34-1,"")) | J36: =IF(OR(J34="",F34=""),"",IFERROR(J34/F34-1,"")) | K36: =IF(OR(K34="",G34=""),"",IFERROR(K34/G34-1,"")) | L36: =IF(OR(L34="",H34=""),"",IFERROR(L34/H34-1,"")) | M36: =IF(OR(M34="",I34=""),"",IFERROR(M34/I34-1,"")) | N36: =IF(OR(N34="",J34=""),"",IFERROR(N34/J34-1,"")) | P36: =IF(OR(P34="",O34=""),"",IFERROR(P34/O34-1,"")) | Q36: =IF(OR(Q34="",P34=""),"",IFERROR(Q34/P34-1,"")) | R36: =IF(OR(R34="",Q34=""),"",IFERROR(R34/Q34-1,"")) | S36: =IF(OR(S34="",R34=""),"",IFERROR(S34/R34-1,"")) | T36: =IF(OR(T34="",S34=""),"",IFERROR(T34/S34-1,"")) | U36: =IF(OR(U34="",T34=""),"",IFERROR(U34/T34-1,"")) | V36: =IF(OR(V34="",U34=""),"",IFERROR(V34/U34-1,"")) | W36: =IF(OR(W34="",V34=""),"",IFERROR(W34/V34-1,"")) | ... AC36: =IF(OR(AC34="",AB34=""),"",IFERROR(AC34/AB34-1,""))
A37: 비용의 성격별 분류 | B37: 참고 데이터
A38: 총 판관비 | O38: =IF(O32="","",O32) | P38: =IF(P32="","",P32) | Q38: =IF(Q32="","",Q32) | R38: =IF(R32="","",R32) | S38: =IF(S32="","",S32) | T38: =IF(T32="","",T32) | U38: =IF(U32="","",U32) | V38: =IF(V32="","",V32) | ... X38: =IF(X32="","",X32)
A39: 급여 | B39: 고정비 | O39: 1294.209 | P39: 1430.946 | Q39: 1512.451 | R39: 1578.299 | S39: 1264.341 | T39: 1134.829 | U39: 1238.444 | V39: 1202.665 | W39: 1315.111 | X39: 1500.55
A40: % of Sales | O40: =IF(OR(O39="",O4=""),"",IFERROR(O39/O4,"")) | P40: =IF(OR(P39="",P4=""),"",IFERROR(P39/P4,"")) | Q40: =IF(OR(Q39="",Q4=""),"",IFERROR(Q39/Q4,"")) | R40: =IF(OR(R39="",R4=""),"",IFERROR(R39/R4,"")) | S40: =IF(OR(S39="",S4=""),"",IFERROR(S39/S4,"")) | T40: =IF(OR(T39="",T4=""),"",IFERROR(T39/T4,"")) | U40: =IF(OR(U39="",U4=""),"",IFERROR(U39/U4,"")) | V40: =IF(OR(V39="",V4=""),"",IFERROR(V39/V4,"")) | ... X40: =IF(OR(X39="",X4=""),"",IFERROR(X39/X4,""))
...

Sheet 재무상태표
A1: 9950 재무상태표
A2: 재무비율은 기말 잔액 기준 · 분기 손익은 최근 4분기 합산(TTM) | B2: (단위: 백만엔)
A3: 항목 | B3: 참고 | C3: 2026.3Q | D3: 2026.4Q | E3: 2027.1Q | F3: 2027.2Q | G3: 2027.3Q | H3: 2023 | I3: 2024 | J3: 2025 | K3: 2026
A4: 자산
A5: 유동자산 | C5: 2126.837 | D5: 1914.112 | E5: 1799.529 | F5: 2200.944 | G5: 3118.64 | H5: 1959.853 | I5: 2026.813 | J5: 2162.267 | K5: 1914.112
A6: 현금및현금성자산 | C6: 883.839 | D6: 587.071 | E6: 682.082 | F6: 890.502 | G6: 1812.83 | H6: 870.986 | I6: 870.99 | J6: 913.121 | K6: 587.071
A7: 단기금융상품
A8: 매출채권 | C8: 837.08 | D8: 969.287 | E8: 795.849 | F8: 950.146 | G8: 908.975 | H8: 679.814 | I8: 720.665 | J8: 796.159 | K8: 969.287
A9: 재고자산 | C9: 216.072 | D9: 233.651 | E9: 220.091 | F9: 237.832 | G9: 261.269 | H9: 210.771 | I9: 242.75 | J9: 239.671 | K9: 233.651
A10: 기타유동자산 | B10: 총계 − 위 항목 | C10: =IF(OR(C5=""),"",IFERROR(C5-SUM(C6,C7,C8,C9),"")) | D10: =IF(OR(D5=""),"",IFERROR(D5-SUM(D6,D7,D8,D9),"")) | E10: =IF(OR(E5=""),"",IFERROR(E5-SUM(E6,E7,E8,E9),"")) | F10: =IF(OR(F5=""),"",IFERROR(F5-SUM(F6,F7,F8,F9),"")) | G10: =IF(OR(G5=""),"",IFERROR(G5-SUM(G6,G7,G8,G9),"")) | H10: =IF(OR(H5=""),"",IFERROR(H5-SUM(H6,H7,H8,H9),"")) | I10: =IF(OR(I5=""),"",IFERROR(I5-SUM(I6,I7,I8,I9),"")) | J10: =IF(OR(J5=""),"",IFERROR(J5-SUM(J6,J7,J8,J9),"")) | K10: =IF(OR(K5=""),"",IFERROR(K5-SUM(K6,K7,K8,K9),""))
A11: 비유동자산 | C11: 3561.266 | D11: 3736.07 | E11: 3809.081 | F11: 3832.592 | G11: 3920.724 | H11: 2955.748 | I11: 2857.97 | J11: 3449.38 | K11: 3736.07
A12: 유형자산 | C12: 2471.529 | D12: 2577.731 | E12: 2576.257 | F12: 2578.398 | G12: 2644.875 | H12: 2011.932 | I12: 2028.016 | J12: 2455.704 | K12: 2577.731
A13: 무형자산 | C13: 247.804 | D13: 277.574 | E13: 289.923 | F13: 293.405 | G13: 274.286 | H13: 71.482 | I13: 50.96 | J13: 210.124 | K13: 277.574
A14: 투자부동산
A15: 기타비유동자산 | B15: 총계 − 위 항목 | C15: =IF(OR(C11=""),"",IFERROR(C11-SUM(C12,C13,C14),"")) | D15: =IF(OR(D11=""),"",IFERROR(D11-SUM(D12,D13,D14),"")) | E15: =IF(OR(E11=""),"",IFERROR(E11-SUM(E12,E13,E14),"")) | F15: =IF(OR(F11=""),"",IFERROR(F11-SUM(F12,F13,F14),"")) | G15: =IF(OR(G11=""),"",IFERROR(G11-SUM(G12,G13,G14),"")) | H15: =IF(OR(H11=""),"",IFERROR(H11-SUM(H12,H13,H14),"")) | I15: =IF(OR(I11=""),"",IFERROR(I11-SUM(I12,I13,I14),"")) | J15: =IF(OR(J11=""),"",IFERROR(J11-SUM(J12,J13,J14),"")) | K15: =IF(OR(K11=""),"",IFERROR(K11-SUM(K12,K13,K14),""))
A16: 자산총계 | C16: 5688.103 | D16: 5650.182 | E16: 5608.61 | F16: 6033.536 | G16: 7039.364 | H16: 4915.602 | I16: 4884.783 | J16: 5611.648 | K16: 5650.182
A17: 부채
A18: 유동부채 | C18: 1184.975 | D18: 1169.505 | E18: 1156.746 | F18: 1543.49 | G18: 1510.935 | H18: 1127.503 | I18: 1007.068 | J18: 1141.948 | K18: 1169.505
A19: 매입채무 | C19: 420.452 | D19: 489.369 | E19: 429.872 | F19: 432.553 | G19: 461.559 | H19: 379.585 | I19: 400.595 | J19: 391.965 | K19: 489.369
A20: 단기차입금 | C20: 150.014 | D20: 149.984 | E20: 149.984 | F20: 449.984 | G20: 389.576 | H20: 210.084 | I20: 110.084 | J20: 222.551 | K20: 149.984
A21: 유동성장기부채
A22: 기타유동부채 | B22: 총계 − 위 항목 | C22: =IF(OR(C18=""),"",IFERROR(C18-SUM(C19,C20,C21),"")) | D22: =IF(OR(D18=""),"",IFERROR(D18-SUM(D19,D20,D21),"")) | E22: =IF(OR(E18=""),"",IFERROR(E18-SUM(E19,E20,E21),"")) | F22: =IF(OR(F18=""),"",IFERROR(F18-SUM(F19,F20,F21),"")) | G22: =IF(OR(G18=""),"",IFERROR(G18-SUM(G19,G20,G21),"")) | H22: =IF(OR(H18=""),"",IFERROR(H18-SUM(H19,H20,H21),"")) | I22: =IF(OR(I18=""),"",IFERROR(I18-SUM(I19,I20,I21),"")) | J22: =IF(OR(J18=""),"",IFERROR(J18-SUM(J19,J20,J21),"")) | K22: =IF(OR(K18=""),"",IFERROR(K18-SUM(K19,K20,K21),""))
A23: 비유동부채 | C23: 695.761 | D23: 667.795 | E23: 643.907 | F23: 613.529 | G23: 1522.948 | H23: 509.436 | I23: 434.206 | J23: 732.284 | K23: 667.795
A24: 장기차입금 | C24: 390.034 | D24: 352.538 | E24: 315.042 | F24: 277.546 | G24: 1200.458 | H24: 191.969 | I24: 81.885 | J24: 454.343 | K24: 352.538
A25: 사채
A26: 기타비유동부채 | B26: 총계 − 위 항목 | C26: =IF(OR(C23=""),"",IFERROR(C23-SUM(C24,C25),"")) | D26: =IF(OR(D23=""),"",IFERROR(D23-SUM(D24,D25),"")) | E26: =IF(OR(E23=""),"",IFERROR(E23-SUM(E24,E25),"")) | F26: =IF(OR(F23=""),"",IFERROR(F23-SUM(F24,F25),"")) | G26: =IF(OR(G23=""),"",IFERROR(G23-SUM(G24,G25),"")) | H26: =IF(OR(H23=""),"",IFERROR(H23-SUM(H24,H25),"")) | I26: =IF(OR(I23=""),"",IFERROR(I23-SUM(I24,I25),"")) | J26: =IF(OR(J23=""),"",IFERROR(J23-SUM(J24,J25),"")) | K26: =IF(OR(K23=""),"",IFERROR(K23-SUM(K24,K25),""))
A27: 부채총계 | C27: 1880.737 | D27: 1837.301 | E27: 1800.653 | F27: 2157.02 | G27: 3033.883 | H27: 1636.939 | I27: 1441.274 | J27: 1874.232 | K27: 1837.301
A28: 총차입금 | B28: 단기+유동성장기+장기+사채 | C28: =SUM(C20,C21,C24,C25) | D28: =SUM(D20,D21,D24,D25) | E28: =SUM(E20,E21,E24,E25) | F28: =SUM(F20,F21,F24,F25) | G28: =SUM(G20,G21,G24,G25) | H28: =SUM(H20,H21,H24,H25) | I28: =SUM(I20,I21,I24,I25) | J28: =SUM(J20,J21,J24,J25) | K28: =SUM(K20,K21,K24,K25)
A29: 순차입금 | B29: 음수 = 순현금 | C29: =C28-C6-N(C7) | D29: =D28-D6-N(D7) | E29: =E28-E6-N(E7) | F29: =F28-F6-N(F7) | G29: =G28-G6-N(G7) | H29: =H28-H6-N(H7) | I29: =I28-I6-N(I7) | J29: =J28-J6-N(J7) | K29: =K28-K6-N(K7)
A30: 자본
A31: 지배주주지분 | C31: 3807.361 | D31: 3812.876 | E31: 3807.95 | F31: 3876.511 | G31: 4005.475 | H31: 3278.659 | I31: 3443.505 | J31: 3737.412 | K31: 3812.876
A32: 자본금 | C32: 1518.454 | D32: 1518.454 | E32: 1518.454 | F32: 1518.454 | G32: 1518.454 | H32: 1518.454 | I32: 1518.454 | J32: 1518.454 | K32: 1518.454
A33: 이익잉여금 | C33: 1408.465 | D33: 1362.619 | E33: 1287.932 | F33: 1352.773 | G33: 1403.025 | H33: 1082.338 | I33: 1183.141 | J33: 1387.057 | K33: 1362.619
A34: 비지배지분 | C34: 0.005 | D34: 0.005 | E34: 0.006 | F34: 0.005 | G34: 0.005 | H34: 0.003 | I34: 0.004 | J34: 0.004 | K34: 0.005
A35: 자본총계 | C35: 3807.366 | D35: 3812.881 | E35: 3807.956 | F35: 3876.516 | G35: 4005.48 | H35: 3278.662 | I35: 3443.509 | J35: 3737.416 | K35: 3812.881
A36: 현금흐름 요약 | B36: 분기 = TTM (있을 때만)
A37: 영업활동현금흐름 | D37: 418.599 | H37: 144.588 | I37: 385.131 | J37: 499.535 | K37: 418.599
A38: CAPEX (유·무형 취득) | B38: 양수로 입력 | D38: 843.081 | H38: 74.275 | I38: 232.026 | J38: 276.158 | K38: 843.081
A39: FCF | C39: =IF(OR(C37="",C38=""),"",IFERROR(C37-C38,"")) | D39: =IF(OR(D37="",D38=""),"",IFERROR(D37-D38,"")) | E39: =IF(OR(E37="",E38=""),"",IFERROR(E37-E38,"")) | F39: =IF(OR(F37="",F38=""),"",IFERROR(F37-F38,"")) | G39: =IF(OR(G37="",G38=""),"",IFERROR(G37-G38,"")) | H39: =IF(OR(H37="",H38=""),"",IFERROR(H37-H38,"")) | I39: =IF(OR(I37="",I38=""),"",IFERROR(I37-I38,"")) | J39: =IF(OR(J37="",J38=""),"",IFERROR(J37-J38,"")) | K39: =IF(OR(K37="",K38=""),"",IFERROR(K37-K38,""))
A40: 배당금 지급 | B40: 양수로 입력 | D40: 59.628 | H40: 59.354 | I40: 59.532 | J40: 59.696 | K40: 59.628
...

Sheet 섹터 데이터
A1: 9950 섹터·사업 데이터
A2: 2단계 보고서를 만들 때 모은 자료 · 월차 · 출처는 맨 오른쪽
A4: this quarter · q alone
A5: 항목 | B5: 값 | C5: 출처
A6: 매출 | B6: 21.15 | C6: 2단계 보고서 자료(회사 설명회 자료·공시)
A7: 영업이익 | B7: 0.96
A8: ordinary | B8: 1.02
A9: 순이익 | B9: 0.45
A10: EPS | B10: 15.39
A12: this quarter · q YoY base
A13: 항목 | B13: 값 | C13: 출처
A14: 매출 | B14: 19.84 | C14: 2단계 보고서 자료(회사 설명회 자료·공시)
A15: 영업이익 | B15: 0.59
A16: ordinary | B16: 1
A17: 순이익 | B17: 0.55
A19: this quarter · 상반기
A20: 항목 | B20: 값 | C20: 출처
A21: 영업이익 매출 | B21: 46.13 | C21: 2단계 보고서 자료(회사 설명회 자료·공시)
A22: 매출 | B22: 41.24
A23: gp | B23: 16.95
A24: royalty | B24: 4.89
A25: 영업이익 gross | B25: 21.85
A26: sga | B26: 20.83
A27: 영업이익 | B27: 1.01
A28: ordinary | B28: 2.43
A29: 순이익 | B29: 1.4
A30: EPS | B30: 47.73
A32: this quarter · 상반기 직전
A33: 항목 | B33: 값 | C33: 출처
A34: 영업이익 매출 | B34: 43.07 | C34: 2단계 보고서 자료(회사 설명회 자료·공시)
A35: 매출 | B35: 38.47
A36: gp | B36: 14.93
A37: royalty | B37: 4.6
A38: 영업이익 gross | B38: 19.53
A39: sga | B39: 18.83
A40: 영업이익 | B40: 0.7
A41: ordinary | B41: 2.45
A42: 순이익 | B42: 1.5
A43: EPS | B43: 51.17
A45: market
...

Sheet 출처
A1: 출처 · 쓴 결산단신
A3: 공시일 | B3: 문서 | C3: PDF
A4: 2026-10-30 | B4: 2027년 3월 결산기 ２분기 결산단신 | C4: https://www2.jpx.co.jp/disc/99500/140120261030560585.pdf
A5: 2026-07-31 | B5: 2027년 3월 결산기 １분기 결산단신 | C5: https://www2.jpx.co.jp/disc/99500/140120260731505543.pdf
A6: 2026-05-01 | B6: 2026년 3월 결산기 연간 결산단신 | C6: https://www2.jpx.co.jp/disc/99500/140120260501516029.pdf
A7: 2026-01-30 | B7: 2026년 3월 결산기 ３분기 결산단신 | C7: https://www2.jpx.co.jp/disc/99500/140120260130542562.pdf
A8: 2025-10-31 | B8: 2026년 3월 결산기 ２분기 결산단신 | C8: https://www2.jpx.co.jp/disc/99500/140120251031584029.pdf
A9: 2025-07-31 | B9: 2026년 3월 결산기 １분기 결산단신 | C9: https://www2.jpx.co.jp/disc/99500/140120250731524924.pdf
A10: 2025-04-30 | B10: 2025년 3월 결산기 연간 결산단신 | C10: https://www2.jpx.co.jp/disc/99500/140120250430527253.pdf
A11: 2025-01-31 | B11: 2025년 3월 결산기 ３분기 결산단신 | C11: https://www2.jpx.co.jp/disc/99500/140120250131559802.pdf
A12: 2024-10-31 | B12: 2025년 3월 결산기 ２분기 결산단신 | C12: https://www2.jpx.co.jp/disc/99500/140120241031507229.pdf
A13: 2024-07-31 | B13: 2025년 3월 결산기 １분기 결산단신 | C13: https://www2.jpx.co.jp/disc/99500/140120240731558675.pdf
A14: 2024-05-01 | B14: 2024년 3월 결산기 연간 결산단신 | C14: https://www2.jpx.co.jp/disc/99500/140120240501580565.pdf
... A24: 2018-04-27 | B24: 연간 결산단신 | C24: https://www2.jpx.co.jp/disc/99500/140120180426422092.pdf

Sheet 재무제표 한눈에 보기
A1: 9950 재무제표 한눈에 보기 — 최근 40개 분기(달력 분기, 3Q26 = 26.7~9) · 단위 억 엔
A2: 출처: 매출·영업이익 결산단신 XBRL · 재무상태표 등 결산단신 XBRL 36건(2018-01-29~2026-10-30). 부문·지역·수주·수출은 있을 때만(출처는 줄 끝). 총 차입금 = 이자 붙는 부채 전부(단기·장기 차입금, CP, 사채·전환사채, 리스부채)
A4: 항목 | B4: 2Q17 | C4: 3Q17 | D4: 4Q17 | E4: 1Q18 | F4: 2Q18 | G4: 3Q18 | H4: 4Q18 | I4: 1Q19 | J4: 2Q19 | K4: 3Q19 | L4: 4Q19 | M4: 1Q20 | N4: 2Q20 | O4: 3Q20 | P4: 4Q20 | Q4: 1Q21 | R4: 2Q21 | S4: 3Q21 | T4: 4Q21 | U4: 1Q22 | V4: 2Q22 | W4: 3Q22 | X4: 4Q22 | Y4: 1Q23 | Z4: 2Q23 | AA4: 3Q23 | AB4: 4Q23 | AC4: 1Q24 | AD4: 2Q24 | AE4: 3Q24 | AF4: 4Q24 | AG4: 1Q25 | AH4: 2Q25 | AI4: 3Q25 | AJ4: 4Q25 | AK4: 1Q26 | AL4: 2Q26 | AM4: 3Q26 | AN4: 4Q26 | AO4: 1Q27 | AP4: 출처
A5: 매출액 | B5: 17.5 | C5: 19.6 | D5: 17.5 | E5: 12.9 | F5: 18.7 | G5: 21.1 | H5: 19.4 | I5: 11.4 | J5: 18.8 | K5: 21.5 | L5: 19.2 | M5: 17.3 | N5: 10.3 | O5: 14.4 | P5: 16 | Q5: 35.8 | R5: 12.3 | S5: 13.9 | T5: 14.7 | U5: 12.2 | V5: 15.5 | W5: 16.8 | X5: 16.7 | Y5: 5 | Z5: 17 | AA5: 18.5 | AB5: 17.2 | AC5: 11.6 | AD5: 18.6 | AE5: 19.8 | AF5: 17.9 | AG5: 12.1 | AH5: 18.6 | AI5: 19.8 | AJ5: 19.4 | AK5: 16 | AL5: 20.1 | AM5: 21.2
A6: 매출액 YoY | F6: 6.9 | G6: 7.7 | H6: 10.9 | I6: -11.6 | J6: 0.5 | K6: 1.9 | L6: -1 | M6: 51.8 | N6: -45.2 | O6: -33 | P6: -16.7 | Q6: 106.9 | R6: 19.4 | S6: -3.5 | T6: -8.1 | U6: -65.9 | V6: 26 | W6: 20.9 | X6: 13.6 | Y6: -59 | Z6: 9.7 | AA6: 10.1 | AB6: 3 | AC6: 132 | AD6: 9.4 | AE6: 7 | AF6: 4.1 | AG6: 4.3 | AH6: 0 | AI6: 0 | AJ6: 8.4 | AK6: 32.2 | AL6: 8.1 | AM6: 7.1
A7: 영업이익 | B7: 0.8 | C7: 1.4 | D7: 0.7 | E7: 1.3 | F7: 0.4 | G7: 1.7 | H7: 1 | I7: -0.1 | J7: 0.9 | K7: 1.6 | L7: 0.5 | M7: -0.1 | N7: -3.6 | O7: -1 | P7: -0.2 | Q7: 6.8 | R7: -1.5 | S7: -0.7 | T7: 0 | U7: -4.2 | V7: 0.4 | W7: 0.8 | X7: 0.5 | Y7: -5.1 | Z7: 1.1 | AA7: 1.4 | AB7: 0.6 | AC7: -1.5 | AD7: 0.9 | AE7: 1.8 | AF7: 0.5 | AG7: -0.9 | AH7: 0.1 | AI7: 0.6 | AJ7: -0.3 | AK7: 2.2 | AL7: 0.1 | AM7: 1
A8: 영업이익률 | B8: 4.6 | C8: 7.1 | D8: 4 | E8: 10.1 | F8: 2.1 | G8: 8.1 | H8: 5.2 | I8: -0.9 | J8: 4.8 | K8: 7.4 | L8: 2.6 | M8: -0.6 | N8: -35 | O8: -6.9 | P8: -1.2 | Q8: 19 | R8: -12.2 | S8: -5 | T8: 0 | U8: -34.4 | V8: 2.6 | W8: 4.8 | X8: 3 | Y8: -102 | Z8: 6.5 | AA8: 7.6 | AB8: 3.5 | AC8: -12.9 | AD8: 4.8 | AE8: 9.1 | AF8: 2.8 | AG8: -7.4 | AH8: 0.5 | AI8: 3 | AJ8: -1.5 | AK8: 13.8 | AL8: 0.5 | AM8: 4.7
A9: 영업이익 YoY | F9: -50 | G9: 21.4 | H9: 42.9 | I9: -107.7 | J9: 125 | K9: -5.9 | L9: -50 | N9: -500 | O9: -162.5 | P9: -140 | U9: -161.8 | Z9: 175 | AA9: 75 | AB9: 20 | AD9: -18.2 | AE9: 28.6 | AF9: -16.7 | AH9: -88.9 | AI9: -66.7 | AJ9: -160 | AL9: 0 | AM9: 66.7
A10: 유동자산 | B10: 14.5 | E10: 14.9 | F10: 15.2 | G10: 18.1 | H10: 17.4 | I10: 17.9 | J10: 17.1 | K10: 19.6 | L10: 20 | M10: 20.6 | N10: 17.6 | O10: 18.3 | P10: 22.6 | Q10: 22.9 | R10: 21.3 | S10: 21.5 | T10: 20.8 | U10: 22.8 | V10: 21.8 | W10: 23.4 | X10: 23.6 | Y10: 19.6 | Z10: 18.5 | AA10: 20.8 | AB10: 20.5 | AC10: 20.3 | AD10: 26.1 | AE10: 26.1 | AF10: 23.7 | AG10: 21.6 | AH10: 20.7 | AI10: 21.4 | AJ10: 21.3 | AK10: 19.1 | AL10: 18 | AM10: 22 | AN10: 31.2
A11: 유동부채 | B11: 11.3 | E11: 7.9 | F11: 7.6 | G11: 11.3 | H11: 8.9 | I11: 8.6 | J11: 8.1 | K11: 9.9 | L11: 9.6 | M11: 9.4 | N11: 8.3 | O11: 12.5 | P11: 13 | Q11: 13.5 | R11: 12.7 | S11: 13.2 | T11: 12.2 | U11: 13.9 | V11: 13.5 | W11: 14.7 | X11: 14.5 | Y11: 11.3 | Z11: 9.8 | AA11: 10.7 | AB11: 9.8 | AC11: 10.1 | AD11: 15 | AE11: 15.2 | AF11: 13.4 | AG11: 11.4 | AH11: 11.7 | AI11: 12.7 | AJ11: 11.8 | AK11: 11.7 | AL11: 11.6 | AM11: 15.4 | AN11: 15.1
A12: 부채총계 | B12: 15.4 | E12: 11.7 | F12: 11.3 | G12: 13.7 | H12: 11.4 | I12: 11 | J12: 10.5 | K12: 12.2 | L12: 12 | M12: 11.8 | N12: 10.9 | O12: 15.2 | P12: 20.2 | Q12: 20.4 | R12: 19.4 | S12: 19.7 | T12: 18.5 | U12: 20 | V12: 19.3 | W12: 20.3 | X12: 19.8 | Y12: 16.4 | Z12: 14.7 | AA12: 15.4 | AB12: 14.3 | AC12: 14.4 | AD12: 23.8 | AE12: 23.3 | AF12: 21 | AG12: 18.7 | AH12: 18.8 | AI12: 19.5 | AJ12: 18.8 | AK12: 18.4 | AL12: 18 | AM12: 21.6 | AN12: 30.3
A13: 자기자본 | B13: 34.6 | E13: 40.7 | F13: 40.5 | G13: 41.1 | H13: 42.3 | I13: 42.5 | J13: 42.1 | K13: 42.8 | L13: 43.3 | M13: 43.5 | N13: 41 | O13: 38.4 | P13: 36.9 | Q13: 36.5 | R13: 33.9 | S13: 33 | T13: 32.9 | U13: 32.5 | V13: 31.6 | W13: 32.1 | X13: 33 | Y13: 32.8 | Z13: 32.2 | AA13: 33.8 | AB13: 35 | AC13: 34.4 | AD13: 33.8 | AE13: 35.1 | AF13: 37 | AG13: 37.4 | AH13: 36.7 | AI13: 37.2 | AJ13: 38.1 | AK13: 38.1 | AL13: 38.1 | AM13: 38.8 | AN13: 40.1
A14: 유동비율 | B14: 128.3 | E14: 188.6 | F14: 200 | G14: 160.2 | H14: 195.5 | I14: 208.1 | J14: 211.1 | K14: 198 | L14: 208.3 | M14: 219.1 | N14: 212 | O14: 146.4 | P14: 173.8 | Q14: 169.6 | R14: 167.7 | S14: 162.9 | T14: 170.5 | U14: 164 | V14: 161.5 | W14: 159.2 | X14: 162.8 | Y14: 173.5 | Z14: 188.8 | AA14: 194.4 | AB14: 209.2 | AC14: 201 | AD14: 174 | AE14: 171.7 | AF14: 176.9 | AG14: 189.5 | AH14: 176.9 | AI14: 168.5 | AJ14: 180.5 | AK14: 163.2 | AL14: 155.2 | AM14: 142.9 | AN14: 206.6
A15: 부채비율 | B15: 44.5 | E15: 28.7 | F15: 27.9 | G15: 33.3 | H15: 27 | I15: 25.9 | J15: 24.9 | K15: 28.5 | L15: 27.7 | M15: 27.1 | N15: 26.6 | O15: 39.6 | P15: 54.7 | Q15: 55.9 | R15: 57.2 | S15: 59.7 | T15: 56.2 | U15: 61.5 | V15: 61.1 | W15: 63.2 | X15: 60 | Y15: 50 | Z15: 45.7 | AA15: 45.6 | AB15: 40.9 | AC15: 41.9 | AD15: 70.4 | AE15: 66.4 | AF15: 56.8 | AG15: 50 | AH15: 51.2 | AI15: 52.4 | AJ15: 49.3 | AK15: 48.3 | AL15: 47.2 | AM15: 55.7 | AN15: 75.6
A16: 순차입금/자기자본 | B16: -18.5 | E16: -14.3 | F16: -19.3 | G16: -17.8 | H16: -20.3 | I16: -20.5 | J16: -24.2 | K16: -24.1 | L16: -25.6 | M16: -26.2 | N16: -25.9 | O16: -12.8 | P16: -9.8 | Q16: -7.1 | R16: -9.4 | S16: -9.4 | T16: -8.5 | U16: -13.5 | V16: -13.9 | W16: -13.4 | X16: -13.6 | Y16: -14.3 | Z16: -17.1 | AA16: -18.3 | AB16: -22.6 | AC16: -19.5 | AD16: -21 | AE16: -10.5 | AF16: -11.9 | AG16: -6.4 | AH16: -10.9 | AI16: -6.2 | AJ16: -8.7 | AK16: -2.1 | AL16: -5.2 | AM16: -3.9 | AN16: -5.2
A17: 재고자산 | B17: 0.9 | E17: 1.1 | F17: 1 | G17: 1.3 | H17: 1.1 | I17: 1.5 | J17: 1.2 | K17: 1.5 | L17: 1.3 | M17: 1.4 | N17: 1.3 | O17: 1.6 | P17: 1.5 | Q17: 1.6 | R17: 1.7 | S17: 1.8 | T17: 1.6 | U17: 1.9 | V17: 1.7 | W17: 2 | X17: 1.7 | Y17: 2.2 | Z17: 1.9 | AA17: 2 | AB17: 1.8 | AC17: 2.5 | AD17: 1.9 | AE17: 1.9 | AF17: 2.2 | AG17: 2.4 | AH17: 2.3 | AI17: 2.2 | AJ17: 2.2 | AK17: 2.3 | AL17: 2.2 | AM17: 2.4 | AN17: 2.6
A18: 재고자산 회전일수 | B18: 9 | E18: 16 | F18: 9 | G18: 11 | H18: 10 | I18: 24 | J18: 11 | K18: 12 | L18: 12 | M18: 14 | N18: 17 | O18: 17 | P18: 15 | Q18: 9 | R18: 20 | S18: 20 | T18: 17 | U18: 23 | V18: 17 | W18: 19 | X18: 16 | Y18: 46 | Z18: 18 | AA18: 16 | AB18: 16 | AC18: 37 | AD18: 15 | AE18: 15 | AF18: 19 | AG18: 30 | AH18: 18 | AI18: 17 | AJ18: 17 | AK18: 22 | AL18: 17 | AM18: 18
A19: 매출채권 회전일수 | B19: 21 | E19: 36 | F19: 19 | G19: 23 | H19: 27 | I19: 47 | J19: 21 | K19: 24 | L19: 28 | M19: 33 | N19: 42 | O19: 32 | P19: 30 | Q19: 17 | R19: 33 | S19: 32 | T19: 32 | U19: 44 | V19: 28 | W19: 35 | X19: 40 | Y19: 124 | Z19: 35 | AA19: 34 | AB19: 37 | AC19: 56 | AD19: 30 | AE19: 40 | AF19: 39 | AG19: 60 | AH19: 34 | AI19: 39 | AJ19: 39 | AK19: 55 | AL19: 36 | AM19: 41
A20: 매입채무 회전일수 | B20: 24 | E20: 45 | F20: 23 | G20: 26 | H20: 31 | I20: 60 | J20: 27 | K20: 27 | L20: 32 | M20: 36 | N20: 35 | O20: 27 | P20: 27 | Q20: 18 | R20: 28 | S20: 26 | T20: 24 | U20: 41 | V20: 25 | W20: 29 | X20: 29 | Y20: 79 | Z20: 29 | AA20: 26 | AB20: 32 | AC20: 60 | AD20: 28 | AE20: 32 | AF20: 35 | AG20: 48 | AH20: 30 | AI20: 32 | AJ20: 33 | AK20: 46 | AL20: 33 | AM20: 32
A21: 현금전환주기(CCC) | B21: 6 | E21: 7 | F21: 5 | G21: 8 | H21: 6 | I21: 11 | J21: 5 | K21: 9 | L21: 8 | M21: 11 | N21: 24 | O21: 22 | P21: 18 | Q21: 8 | R21: 25 | S21: 26 | T21: 25 | U21: 26 | V21: 20 | W21: 25 | X21: 27 | Y21: 91 | Z21: 24 | AA21: 24 | AB21: 21 | AC21: 33 | AD21: 17 | AE21: 23 | AF21: 23 | AG21: 42 | AH21: 22 | AI21: 24 | AJ21: 23 | AK21: 31 | AL21: 20 | AM21: 27
A22: 총 차입금 | B22: 1.1 | E22: 0.5 | F22: 0.4 | G22: 0.2 | H22: 0 | I22: 0 | J22: 0 | K22: 0 | L22: 0 | M22: 0 | N22: 0 | O22: 5 | P22: 10 | Q22: 10 | R22: 9.9 | S22: 9.7 | T22: 9.4 | U22: 9.1 | V22: 8.8 | W22: 8.6 | X22: 8.3 | Y22: 4 | Z22: 2.7 | AA22: 2.5 | AB22: 2.2 | AC22: 2 | AD22: 8.7 | AE22: 8.1 | AF22: 7.5 | AG22: 6.7 | AH22: 6.1 | AI22: 5.7 | AJ22: 5.5 | AK22: 5.1 | AL22: 4.8 | AM22: 7.4 | AN22: 16
A23: 현금 | B23: 7.5 | E23: 6.3 | F23: 8.2 | G23: 7.5 | H23: 8.6 | I23: 8.7 | J23: 10.2 | K23: 10.3 | L23: 11.1 | M23: 11.4 | N23: 10.6 | O23: 9.9 | P23: 13.6 | Q23: 12.6 | R23: 13.1 | S23: 12.8 | T23: 12.2 | U23: 13.5 | V23: 13.2 | W23: 12.9 | X23: 12.8 | Y23: 8.7 | Z23: 8.2 | AA23: 8.7 | AB23: 10.1 | AC23: 8.7 | AD23: 15.8 | AE23: 11.8 | AF23: 11.9 | AG23: 9.1 | AH23: 10.1 | AI23: 8 | AJ23: 8.8 | AK23: 5.9 | AL23: 6.8 | AM23: 8.9 | AN23: 18.1
A24: 부문별 매출 · 外食事業、報告セグメント [メンバー] | AB24: 14.7 | AF24: 15.1 | AG24: 10.2 | AJ24: 16.2 | AK24: 12.9 | AP24: 결산단신 부문 정보(외부 고객 매출)
A25: 부문별 매출 · 海外事業、報告セグメント [メンバー] | AB25: 2.8 | AD25: 3.1 | AE25: 3.5 | AF25: 3.4 | AG25: 1.5 | AH25: 3.5 | AI25: 3.6 | AJ25: 3.9 | AK25: 3.4 | AL25: 4.1 | AM25: 3.7 | AP25: 결산단신 부문 정보(외부 고객 매출)
